Workbook

Sheet 日报
A1: 46143 | F1: 注：“可用结存”列中红色数据代表库存量过低，黄色数据代表超出最高库存量。
A2: 序号 | B2: 供应商代码 | C2: 供应商名称 | D2: 硅翔料号 | E2: 零件编号 | F2: 零件名称 | G2: 车型 | H2: 上月结存 | I2: 累进 | J2: 累出 | K2: 当前库存 | L2: 不合格品库存 | M2: 可用结存 | N2: 最高库存量 | O2: 单车用量 | P2: 入库 | AU2: 出库
P3: 46143 | Q3: 46144 | R3: 46145 | S3: 46146 | T3: 46147 | U3: 46148 | V3: 46149 | W3: 46150 | X3: 46151 | Y3: 46152 | Z3: 46153 | AA3: 46154 | AB3: 46155 | AC3: 46156 | AD3: 46157 | AE3: 46158 | AF3: 46159 | AG3: 46160 | AH3: 46161 | AI3: 46162 | AJ3: 46163 | AK3: 46164 | AL3: 46165 | AM3: 46166 | AN3: 46167 | AO3: 46168 | AP3: 46169 | AQ3: 46170 | AR3: 46171 | AS3: 46172 | AT3: 46173 | AU3: 46143 | AV3: 46144 | AW3: 46145 | AX3: 46146 | AY3: 46147 | AZ3: 46148 | BA3: 46149 | BB3: 46150 | BC3: 46151 | BD3: 46152 | BE3: 46153 | BF3: 46154 | BG3: 46155 | BH3: 46156 | BI3: 46157 | BJ3: 46158 | BK3: 46159 | BL3: 46160 | BM3: 46161 | BN3: 46162 | BO3: 46163 | BP3: 46164 | BQ3: 46165 | BR3: 46166 | BS3: 46167 | BT3: 46168 | BU3: 46169 | BV3: 46170 | BW3: 46171 | BX3: 46172 | BY3: 46173 | CB3: ，
A4: 1 | B4: 1DC | C4: 东莞市硅翔绝缘材料有限公司 | D4: F01001001117 | E4: 3.2.49.08.01246-000 | F4: LX-B11RE10海外版-CCS总成 | H4: 718 | I4: =SUMIF(合格品入货记录!E:E,日报!E4,合格品入货记录!G:G) -> 0 | J4: =SUMIF(合格品出库记录!E:E,日报!E4,合格品出库记录!G:G) -> 330 | K4: =H4+I4-J4+L4 -> 388 | L4: =SUMIF(不良品库存!D:D,E4:E49,不良品库存!F:F) -> 0 | M4: =H4+I4-J4 -> 388 | P4: =IF(SUMIFS(合格品入货记录!$G:$G,合格品入货记录!$E:$E,日报!$E:$E,合格品入货记录!$A:$A,日报!P$3)<>0,SUMIFS(合格品入货记录!$G:$G,合格品入货记录!$E:$E,日报!$E:$E,合格品入货记录!$A:$A,日报!P$3),"") | Q4: =IF(SUMIFS(合格品入货记录!$G:$G,合格品入货记录!$E:$E,日报!$E:$E,合格品入货记录!$A:$A,日报!Q$3)<>0,SUMIFS(合格品入货记录!$G:$G,合格品入货记录!$E:$E,日报!$E:$E,合格品入货记录!$A:$A,日报!Q$3),"") | R4: =IF(SUMIFS(合格品入货记录!$G:$G,合格品入货记录!$E:$E,日报!$E:$E,合格品入货记录!$A:$A,日报!R$3)<>0,SUMIFS(合格品入货记录!$G:$G,合格品入货记录!$E:$E,日报!$E:$E,合格品入货记录!$A:$A,日报!R$3),"") | S4: =IF(SUMIFS(合格品入货记录!$G:$G,合格品入货记录!$E:$E,日报!$E:$E,合格品入货记录!$A:$A,日报!S$3)<>0,SUMIFS(合格品入货记录!$G:$G,合格品入货记录!$E:$E,日报!$E:$E,合格品入货记录!$A:$A,日报!S$3),"") | T4: =IF(SUMIFS(合格品入货记录!$G:$G,合格品入货记录!$E:$E,日报!$E:$E,合格品入货记录!$A:$A,日报!T$3)<>0,SUMIFS(合格品入货记录!$G:$G,合格品入货记录!$E:$E,日报!$E:$E,合格品入货记录!$A:$A,日报!T$3),"") | U4: =IF(SUMIFS(合格品入货记录!$G:$G,合格品入货记录!$E:$E,日报!$E:$E,合格品入货记录!$A:$A,日报!U$3)<>0,SUMIFS(合格品入货记录!$G:$G,合格品入货记录!$E:$E,日报!$E:$E,合格品入货记录!$A:$A,日报!U$3),"") | V4: =IF(SUMIFS(合格品入货记录!$G:$G,合格品入货记录!$E:$E,日报!$E:$E,合格品入货记录!$A:$A,日报!V$3)<>0,SUMIFS(合格品入货记录!$G:$G,合格品入货记录!$E:$E,日报!$E:$E,合格品入货记录!$A:$A,日报!V$3),"") | W4: =IF(SUMIFS(合格品入货记录!$G:$G,合格品入货记录!$E:$E,日报!$E:$E,合格品入货记录!$A:$A,日报!W$3)<>0,SUMIFS(合格品入货记录!$G:$G,合格品入货记录!$E:$E,日报!$E:$E,合格品入货记录!$A:$A,日报!W$3),"") | ... AT4: =IF(SUMIFS(合格品入货记录!$G:$G,合格品入货记录!$E:$E,日报!$E:$E,合格品入货记录!$A:$A,日报!AT$3)<>0,SUMIFS(合格品入货记录!$G:$G,合格品入货记录!$E:$E,日报!$E:$E,合格品入货记录!$A:$A,日报!AT$3),"") | AU4: =IF(SUMIFS(合格品出库记录!$G:$G,合格品出库记录!$E:$E,日报!$E:$E,合格品出库记录!$A:$A,日报!AU$3)<>0,SUMIFS(合格品出库记录!$G:$G,合格品出库记录!$E:$E,日报!$E:$E,合格品出库记录!$A:$A,日报!AU$3),"") | AV4: =IF(SUMIFS(合格品出库记录!$G:$G,合格品出库记录!$E:$E,日报!$E:$E,合格品出库记录!$A:$A,日报!AV$3)<>0,SUMIFS(合格品出库记录!$G:$G,合格品出库记录!$E:$E,日报!$E:$E,合格品出库记录!$A:$A,日报!AV$3),"") | AW4: =IF(SUMIFS(合格品出库记录!$G:$G,合格品出库记录!$E:$E,日报!$E:$E,合格品出库记录!$A:$A,日报!AW$3)<>0,SUMIFS(合格品出库记录!$G:$G,合格品出库记录!$E:$E,日报!$E:$E,合格品出库记录!$A:$A,日报!AW$3),"") | AX4: =IF(SUMIFS(合格品出库记录!$G:$G,合格品出库记录!$E:$E,日报!$E:$E,合格品出库记录!$A:$A,日报!AX$3)<>0,SUMIFS(合格品出库记录!$G:$G,合格品出库记录!$E:$E,日报!$E:$E,合格品出库记录!$A:$A,日报!AX$3),"") | AY4: =IF(SUMIFS(合格品出库记录!$G:$G,合格品出库记录!$E:$E,日报!$E:$E,合格品出库记录!$A:$A,日报!AY$3)<>0,SUMIFS(合格品出库记录!$G:$G,合格品出库记录!$E:$E,日报!$E:$E,合格品出库记录!$A:$A,日报!AY$3),"") | AZ4: =IF(SUMIFS(合格品出库记录!$G:$G,合格品出库记录!$E:$E,日报!$E:$E,合格品出库记录!$A:$A,日报!AZ$3)<>0,SUMIFS(合格品出库记录!$G:$G,合格品出库记录!$E:$E,日报!$E:$E,合格品出库记录!$A:$A,日报!AZ$3),"") -> 330 | BA4: =IF(SUMIFS(合格品出库记录!$G:$G,合格品出库记录!$E:$E,日报!$E:$E,合格品出库记录!$A:$A,日报!BA$3)<>0,SUMIFS(合格品出库记录!$G:$G,合格品出库记录!$E:$E,日报!$E:$E,合格品出库记录!$A:$A,日报!BA$3),"") | BB4: =IF(SUMIFS(合格品出库记录!$G:$G,合格品出库记录!$E:$E,日报!$E:$E,合格品出库记录!$A:$A,日报!BB$3)<>0,SUMIFS(合格品出库记录!$G:$G,合格品出库记录!$E:$E,日报!$E:$E,合格品出库记录!$A:$A,日报!BB$3),"") | ... BY4: =IF(SUMIFS(合格品出库记录!$G:$G,合格品出库记录!$E:$E,日报!$E:$E,合格品出库记录!$A:$A,日报!BY$3)<>0,SUMIFS(合格品出库记录!$G:$G,合格品出库记录!$E:$E,日报!$E:$E,合格品出库记录!$A:$A,日报!BY$3),"")
A5: 2 | B5: 1DC | C5: 东莞市硅翔绝缘材料有限公司 | D5: F01001000763 | E5: 3.2.49.08.00235-000 | F5: LPT03A_PBP-模组CCS总成1 | H5: 0 | I5: =SUMIF(合格品入货记录!E:E,日报!E5,合格品入货记录!G:G) -> 0 | J5: =SUMIF(合格品出库记录!E:E,日报!E5,合格品出库记录!G:G) -> 0 | K5: =H5+I5-J5+L5 -> 0 | L5: =SUMIF(不良品库存!D:D,E:E,不良品库存!F:F) -> 0 | M5: =H5+I5-J5 -> 0 | P5: =IF(SUMIFS(合格品入货记录!$G:$G,合格品入货记录!$E:$E,日报!$E:$E,合格品入货记录!$A:$A,日报!P$3)<>0,SUMIFS(合格品入货记录!$G:$G,合格品入货记录!$E:$E,日报!$E:$E,合格品入货记录!$A:$A,日报!P$3),"") | Q5: =IF(SUMIFS(合格品入货记录!$G:$G,合格品入货记录!$E:$E,日报!$E:$E,合格品入货记录!$A:$A,日报!Q$3)<>0,SUMIFS(合格品入货记录!$G:$G,合格品入货记录!$E:$E,日报!$E:$E,合格品入货记录!$A:$A,日报!Q$3),"") | R5: =IF(SUMIFS(合格品入货记录!$G:$G,合格品入货记录!$E:$E,日报!$E:$E,合格品入货记录!$A:$A,日报!R$3)<>0,SUMIFS(合格品入货记录!$G:$G,合格品入货记录!$E:$E,日报!$E:$E,合格品入货记录!$A:$A,日报!R$3),"") | S5: =IF(SUMIFS(合格品入货记录!$G:$G,合格品入货记录!$E:$E,日报!$E:$E,合格品入货记录!$A:$A,日报!S$3)<>0,SUMIFS(合格品入货记录!$G:$G,合格品入货记录!$E:$E,日报!$E:$E,合格品入货记录!$A:$A,日报!S$3),"") | T5: =IF(SUMIFS(合格品入货记录!$G:$G,合格品入货记录!$E:$E,日报!$E:$E,合格品入货记录!$A:$A,日报!T$3)<>0,SUMIFS(合格品入货记录!$G:$G,合格品入货记录!$E:$E,日报!$E:$E,合格品入货记录!$A:$A,日报!T$3),"") | U5: =IF(SUMIFS(合格品入货记录!$G:$G,合格品入货记录!$E:$E,日报!$E:$E,合格品入货记录!$A:$A,日报!U$3)<>0,SUMIFS(合格品入货记录!$G:$G,合格品入货记录!$E:$E,日报!$E:$E,合格品入货记录!$A:$A,日报!U$3),"") | V5: =IF(SUMIFS(合格品入货记录!$G:$G,合格品入货记录!$E:$E,日报!$E:$E,合格品入货记录!$A:$A,日报!V$3)<>0,SUMIFS(合格品入货记录!$G:$G,合格品入货记录!$E:$E,日报!$E:$E,合格品入货记录!$A:$A,日报!V$3),"") | W5: =IF(SUMIFS(合格品入货记录!$G:$G,合格品入货记录!$E:$E,日报!$E:$E,合格品入货记录!$A:$A,日报!W$3)<>0,SUMIFS(合格品入货记录!$G:$G,合格品入货记录!$E:$E,日报!$E:$E,合格品入货记录!$A:$A,日报!W$3),"") | ... AT5: =IF(SUMIFS(合格品入货记录!$G:$G,合格品入货记录!$E:$E,日报!$E:$E,合格品入货记录!$A:$A,日报!AT$3)<>0,SUMIFS(合格品入货记录!$G:$G,合格品入货记录!$E:$E,日报!$E:$E,合格品入货记录!$A:$A,日报!AT$3),"") | AU5: =IF(SUMIFS(合格品出库记录!$G:$G,合格品出库记录!$E:$E,日报!$E:$E,合格品出库记录!$A:$A,日报!AU$3)<>0,SUMIFS(合格品出库记录!$G:$G,合格品出库记录!$E:$E,日报!$E:$E,合格品出库记录!$A:$A,日报!AU$3),"") | AV5: =IF(SUMIFS(合格品出库记录!$G:$G,合格品出库记录!$E:$E,日报!$E:$E,合格品出库记录!$A:$A,日报!AV$3)<>0,SUMIFS(合格品出库记录!$G:$G,合格品出库记录!$E:$E,日报!$E:$E,合格品出库记录!$A:$A,日报!AV$3),"") | AW5: =IF(SUMIFS(合格品出库记录!$G:$G,合格品出库记录!$E:$E,日报!$E:$E,合格品出库记录!$A:$A,日报!AW$3)<>0,SUMIFS(合格品出库记录!$G:$G,合格品出库记录!$E:$E,日报!$E:$E,合格品出库记录!$A:$A,日报!AW$3),"") | AX5: =IF(SUMIFS(合格品出库记录!$G:$G,合格品出库记录!$E:$E,日报!$E:$E,合格品出库记录!$A:$A,日报!AX$3)<>0,SUMIFS(合格品出库记录!$G:$G,合格品出库记录!$E:$E,日报!$E:$E,合格品出库记录!$A:$A,日报!AX$3),"") | AY5: =IF(SUMIFS(合格品出库记录!$G:$G,合格品出库记录!$E:$E,日报!$E:$E,合格品出库记录!$A:$A,日报!AY$3)<>0,SUMIFS(合格品出库记录!$G:$G,合格品出库记录!$E:$E,日报!$E:$E,合格品出库记录!$A:$A,日报!AY$3),"") | AZ5: =IF(SUMIFS(合格品出库记录!$G:$G,合格品出库记录!$E:$E,日报!$E:$E,合格品出库记录!$A:$A,日报!AZ$3)<>0,SUMIFS(合格品出库记录!$G:$G,合格品出库记录!$E:$E,日报!$E:$E,合格品出库记录!$A:$A,日报!AZ$3),"") | BA5: =IF(SUMIFS(合格品出库记录!$G:$G,合格品出库记录!$E:$E,日报!$E:$E,合格品出库记录!$A:$A,日报!BA$3)<>0,SUMIFS(合格品出库记录!$G:$G,合格品出库记录!$E:$E,日报!$E:$E,合格品出库记录!$A:$A,日报!BA$3),"") | BB5: =IF(SUMIFS(合格品出库记录!$G:$G,合格品出库记录!$E:$E,日报!$E:$E,合格品出库记录!$A:$A,日报!BB$3)<>0,SUMIFS(合格品出库记录!$G:$G,合格品出库记录!$E:$E,日报!$E:$E,合格品出库记录!$A:$A,日报!BB$3),"") | ... BY5: =IF(SUMIFS(合格品出库记录!$G:$G,合格品出库记录!$E:$E,日报!$E:$E,合格品出库记录!$A:$A,日报!BY$3)<>0,SUMIFS(合格品出库记录!$G:$G,合格品出库记录!$E:$E,日报!$E:$E,合格品出库记录!$A:$A,日报!BY$3),"")
A6: 3 | B6: 1DC | C6: 东莞市硅翔绝缘材料有限公司 | D6: F01001000765 | E6: 3.2.49.08.00259-000 | F6: LPT03A_PBP-模组CCS总成 | H6: 63 | I6: =SUMIF(合格品入货记录!E:E,日报!E6,合格品入货记录!G:G) -> 0 | J6: =SUMIF(合格品出库记录!E:E,日报!E6,合格品出库记录!G:G) -> 0 | K6: =H6+I6-J6+L6 -> 63 | L6: =SUMIF(不良品库存!D:D,E:E,不良品库存!F:F) -> 0 | M6: =H6+I6-J6 -> 63 | P6: =IF(SUMIFS(合格品入货记录!$G:$G,合格品入货记录!$E:$E,日报!$E:$E,合格品入货记录!$A:$A,日报!P$3)<>0,SUMIFS(合格品入货记录!$G:$G,合格品入货记录!$E:$E,日报!$E:$E,合格品入货记录!$A:$A,日报!P$3),"") | Q6: =IF(SUMIFS(合格品入货记录!$G:$G,合格品入货记录!$E:$E,日报!$E:$E,合格品入货记录!$A:$A,日报!Q$3)<>0,SUMIFS(合格品入货记录!$G:$G,合格品入货记录!$E:$E,日报!$E:$E,合格品入货记录!$A:$A,日报!Q$3),"") | R6: =IF(SUMIFS(合格品入货记录!$G:$G,合格品入货记录!$E:$E,日报!$E:$E,合格品入货记录!$A:$A,日报!R$3)<>0,SUMIFS(合格品入货记录!$G:$G,合格品入货记录!$E:$E,日报!$E:$E,合格品入货记录!$A:$A,日报!R$3),"") | S6: =IF(SUMIFS(合格品入货记录!$G:$G,合格品入货记录!$E:$E,日报!$E:$E,合格品入货记录!$A:$A,日报!S$3)<>0,SUMIFS(合格品入货记录!$G:$G,合格品入货记录!$E:$E,日报!$E:$E,合格品入货记录!$A:$A,日报!S$3),"") | T6: =IF(SUMIFS(合格品入货记录!$G:$G,合格品入货记录!$E:$E,日报!$E:$E,合格品入货记录!$A:$A,日报!T$3)<>0,SUMIFS(合格品入货记录!$G:$G,合格品入货记录!$E:$E,日报!$E:$E,合格品入货记录!$A:$A,日报!T$3),"") | U6: =IF(SUMIFS(合格品入货记录!$G:$G,合格品入货记录!$E:$E,日报!$E:$E,合格品入货记录!$A:$A,日报!U$3)<>0,SUMIFS(合格品入货记录!$G:$G,合格品入货记录!$E:$E,日报!$E:$E,合格品入货记录!$A:$A,日报!U$3),"") | V6: =IF(SUMIFS(合格品入货记录!$G:$G,合格品入货记录!$E:$E,日报!$E:$E,合格品入货记录!$A:$A,日报!V$3)<>0,SUMIFS(合格品入货记录!$G:$G,合格品入货记录!$E:$E,日报!$E:$E,合格品入货记录!$A:$A,日报!V$3),"") | W6: =IF(SUMIFS(合格品入货记录!$G:$G,合格品入货记录!$E:$E,日报!$E:$E,合格品入货记录!$A:$A,日报!W$3)<>0,SUMIFS(合格品入货记录!$G:$G,合格品入货记录!$E:$E,日报!$E:$E,合格品入货记录!$A:$A,日报!W$3),"") | ... AT6: =IF(SUMIFS(合格品入货记录!$G:$G,合格品入货记录!$E:$E,日报!$E:$E,合格品入货记录!$A:$A,日报!AT$3)<>0,SUMIFS(合格品入货记录!$G:$G,合格品入货记录!$E:$E,日报!$E:$E,合格品入货记录!$A:$A,日报!AT$3),"") | AU6: =IF(SUMIFS(合格品出库记录!$G:$G,合格品出库记录!$E:$E,日报!$E:$E,合格品出库记录!$A:$A,日报!AU$3)<>0,SUMIFS(合格品出库记录!$G:$G,合格品出库记录!$E:$E,日报!$E:$E,合格品出库记录!$A:$A,日报!AU$3),"") | AV6: =IF(SUMIFS(合格品出库记录!$G:$G,合格品出库记录!$E:$E,日报!$E:$E,合格品出库记录!$A:$A,日报!AV$3)<>0,SUMIFS(合格品出库记录!$G:$G,合格品出库记录!$E:$E,日报!$E:$E,合格品出库记录!$A:$A,日报!AV$3),"") | AW6: =IF(SUMIFS(合格品出库记录!$G:$G,合格品出库记录!$E:$E,日报!$E:$E,合格品出库记录!$A:$A,日报!AW$3)<>0,SUMIFS(合格品出库记录!$G:$G,合格品出库记录!$E:$E,日报!$E:$E,合格品出库记录!$A:$A,日报!AW$3),"") | AX6: =IF(SUMIFS(合格品出库记录!$G:$G,合格品出库记录!$E:$E,日报!$E:$E,合格品出库记录!$A:$A,日报!AX$3)<>0,SUMIFS(合格品出库记录!$G:$G,合格品出库记录!$E:$E,日报!$E:$E,合格品出库记录!$A:$A,日报!AX$3),"") | AY6: =IF(SUMIFS(合格品出库记录!$G:$G,合格品出库记录!$E:$E,日报!$E:$E,合格品出库记录!$A:$A,日报!AY$3)<>0,SUMIFS(合格品出库记录!$G:$G,合格品出库记录!$E:$E,日报!$E:$E,合格品出库记录!$A:$A,日报!AY$3),"") | AZ6: =IF(SUMIFS(合格品出库记录!$G:$G,合格品出库记录!$E:$E,日报!$E:$E,合格品出库记录!$A:$A,日报!AZ$3)<>0,SUMIFS(合格品出库记录!$G:$G,合格品出库记录!$E:$E,日报!$E:$E,合格品出库记录!$A:$A,日报!AZ$3),"") | BA6: =IF(SUMIFS(合格品出库记录!$G:$G,合格品出库记录!$E:$E,日报!$E:$E,合格品出库记录!$A:$A,日报!BA$3)<>0,SUMIFS(合格品出库记录!$G:$G,合格品出库记录!$E:$E,日报!$E:$E,合格品出库记录!$A:$A,日报!BA$3),"") | BB6: =IF(SUMIFS(合格品出库记录!$G:$G,合格品出库记录!$E:$E,日报!$E:$E,合格品出库记录!$A:$A,日报!BB$3)<>0,SUMIFS(合格品出库记录!$G:$G,合格品出库记录!$E:$E,日报!$E:$E,合格品出库记录!$A:$A,日报!BB$3),"") | ... BY6: =IF(SUMIFS(合格品出库记录!$G:$G,合格品出库记录!$E:$E,日报!$E:$E,合格品出库记录!$A:$A,日报!BY$3)<>0,SUMIFS(合格品出库记录!$G:$G,合格品出库记录!$E:$E,日报!$E:$E,合格品出库记录!$A:$A,日报!BY$3),"")
A7: 4 | B7: 1DC | C7: 东莞市硅翔绝缘材料有限公司 | D7: F02001000532 | E7: 3.2.49.08.00658-000 | F7: LPT03A_pBP-RP加热膜－L | H7: 36 | I7: =SUMIF(合格品入货记录!E:E,日报!E7,合格品入货记录!G:G) -> 252 | J7: =SUMIF(合格品出库记录!E:E,日报!E7,合格品出库记录!G:G) -> 10 | K7: =H7+I7-J7+L7 -> 278 | L7: =SUMIF(不良品库存!D:D,E:E,不良品库存!F:F) -> 0 | M7: =H7+I7-J7 -> 278 | P7: =IF(SUMIFS(合格品入货记录!$G:$G,合格品入货记录!$E:$E,日报!$E:$E,合格品入货记录!$A:$A,日报!P$3)<>0,SUMIFS(合格品入货记录!$G:$G,合格品入货记录!$E:$E,日报!$E:$E,合格品入货记录!$A:$A,日报!P$3),"") | Q7: =IF(SUMIFS(合格品入货记录!$G:$G,合格品入货记录!$E:$E,日报!$E:$E,合格品入货记录!$A:$A,日报!Q$3)<>0,SUMIFS(合格品入货记录!$G:$G,合格品入货记录!$E:$E,日报!$E:$E,合格品入货记录!$A:$A,日报!Q$3),"") | R7: =IF(SUMIFS(合格品入货记录!$G:$G,合格品入货记录!$E:$E,日报!$E:$E,合格品入货记录!$A:$A,日报!R$3)<>0,SUMIFS(合格品入货记录!$G:$G,合格品入货记录!$E:$E,日报!$E:$E,合格品入货记录!$A:$A,日报!R$3),"") | S7: =IF(SUMIFS(合格品入货记录!$G:$G,合格品入货记录!$E:$E,日报!$E:$E,合格品入货记录!$A:$A,日报!S$3)<>0,SUMIFS(合格品入货记录!$G:$G,合格品入货记录!$E:$E,日报!$E:$E,合格品入货记录!$A:$A,日报!S$3),"") | T7: =IF(SUMIFS(合格品入货记录!$G:$G,合格品入货记录!$E:$E,日报!$E:$E,合格品入货记录!$A:$A,日报!T$3)<>0,SUMIFS(合格品入货记录!$G:$G,合格品入货记录!$E:$E,日报!$E:$E,合格品入货记录!$A:$A,日报!T$3),"") | U7: =IF(SUMIFS(合格品入货记录!$G:$G,合格品入货记录!$E:$E,日报!$E:$E,合格品入货记录!$A:$A,日报!U$3)<>0,SUMIFS(合格品入货记录!$G:$G,合格品入货记录!$E:$E,日报!$E:$E,合格品入货记录!$A:$A,日报!U$3),"") | V7: =IF(SUMIFS(合格品入货记录!$G:$G,合格品入货记录!$E:$E,日报!$E:$E,合格品入货记录!$A:$A,日报!V$3)<>0,SUMIFS(合格品入货记录!$G:$G,合格品入货记录!$E:$E,日报!$E:$E,合格品入货记录!$A:$A,日报!V$3),"") | W7: =IF(SUMIFS(合格品入货记录!$G:$G,合格品入货记录!$E:$E,日报!$E:$E,合格品入货记录!$A:$A,日报!W$3)<>0,SUMIFS(合格品入货记录!$G:$G,合格品入货记录!$E:$E,日报!$E:$E,合格品入货记录!$A:$A,日报!W$3),"") | ... AT7: =IF(SUMIFS(合格品入货记录!$G:$G,合格品入货记录!$E:$E,日报!$E:$E,合格品入货记录!$A:$A,日报!AT$3)<>0,SUMIFS(合格品入货记录!$G:$G,合格品入货记录!$E:$E,日报!$E:$E,合格品入货记录!$A:$A,日报!AT$3),"") | AU7: =IF(SUMIFS(合格品出库记录!$G:$G,合格品出库记录!$E:$E,日报!$E:$E,合格品出库记录!$A:$A,日报!AU$3)<>0,SUMIFS(合格品出库记录!$G:$G,合格品出库记录!$E:$E,日报!$E:$E,合格品出库记录!$A:$A,日报!AU$3),"") | AV7: =IF(SUMIFS(合格品出库记录!$G:$G,合格品出库记录!$E:$E,日报!$E:$E,合格品出库记录!$A:$A,日报!AV$3)<>0,SUMIFS(合格品出库记录!$G:$G,合格品出库记录!$E:$E,日报!$E:$E,合格品出库记录!$A:$A,日报!AV$3),"") | AW7: =IF(SUMIFS(合格品出库记录!$G:$G,合格品出库记录!$E:$E,日报!$E:$E,合格品出库记录!$A:$A,日报!AW$3)<>0,SUMIFS(合格品出库记录!$G:$G,合格品出库记录!$E:$E,日报!$E:$E,合格品出库记录!$A:$A,日报!AW$3),"") | AX7: =IF(SUMIFS(合格品出库记录!$G:$G,合格品出库记录!$E:$E,日报!$E:$E,合格品出库记录!$A:$A,日报!AX$3)<>0,SUMIFS(合格品出库记录!$G:$G,合格品出库记录!$E:$E,日报!$E:$E,合格品出库记录!$A:$A,日报!AX$3),"") | AY7: =IF(SUMIFS(合格品出库记录!$G:$G,合格品出库记录!$E:$E,日报!$E:$E,合格品出库记录!$A:$A,日报!AY$3)<>0,SUMIFS(合格品出库记录!$G:$G,合格品出库记录!$E:$E,日报!$E:$E,合格品出库记录!$A:$A,日报!AY$3),"") | AZ7: =IF(SUMIFS(合格品出库记录!$G:$G,合格品出库记录!$E:$E,日报!$E:$E,合格品出库记录!$A:$A,日报!AZ$3)<>0,SUMIFS(合格品出库记录!$G:$G,合格品出库记录!$E:$E,日报!$E:$E,合格品出库记录!$A:$A,日报!AZ$3),"") | BA7: =IF(SUMIFS(合格品出库记录!$G:$G,合格品出库记录!$E:$E,日报!$E:$E,合格品出库记录!$A:$A,日报!BA$3)<>0,SUMIFS(合格品出库记录!$G:$G,合格品出库记录!$E:$E,日报!$E:$E,合格品出库记录!$A:$A,日报!BA$3),"") | BB7: =IF(SUMIFS(合格品出库记录!$G:$G,合格品出库记录!$E:$E,日报!$E:$E,合格品出库记录!$A:$A,日报!BB$3)<>0,SUMIFS(合格品出库记录!$G:$G,合格品出库记录!$E:$E,日报!$E:$E,合格品出库记录!$A:$A,日报!BB$3),"") | ... BY7: =IF(SUMIFS(合格品出库记录!$G:$G,合格品出库记录!$E:$E,日报!$E:$E,合格品出库记录!$A:$A,日报!BY$3)<>0,SUMIFS(合格品出库记录!$G:$G,合格品出库记录!$E:$E,日报!$E:$E,合格品出库记录!$A:$A,日报!BY$3),"")
A8: 5 | B8: 1DC | C8: 东莞市硅翔绝缘材料有限公司 | D8: F02001000533 | E8: 3.2.49.08.00659-000 | F8: LPT03A_pBP-RP加热膜－R项目 | H8: 0 | I8: =SUMIF(合格品入货记录!E:E,日报!E8,合格品入货记录!G:G) -> 262 | J8: =SUMIF(合格品出库记录!E:E,日报!E8,合格品出库记录!G:G) -> 233 | K8: =H8+I8-J8+L8 -> 29 | M8: =H8+I8-J8 -> 29 | P8: =IF(SUMIFS(合格品入货记录!$G:$G,合格品入货记录!$E:$E,日报!$E:$E,合格品入货记录!$A:$A,日报!P$3)<>0,SUMIFS(合格品入货记录!$G:$G,合格品入货记录!$E:$E,日报!$E:$E,合格品入货记录!$A:$A,日报!P$3),"") | Q8: =IF(SUMIFS(合格品入货记录!$G:$G,合格品入货记录!$E:$E,日报!$E:$E,合格品入货记录!$A:$A,日报!Q$3)<>0,SUMIFS(合格品入货记录!$G:$G,合格品入货记录!$E:$E,日报!$E:$E,合格品入货记录!$A:$A,日报!Q$3),"") | R8: =IF(SUMIFS(合格品入货记录!$G:$G,合格品入货记录!$E:$E,日报!$E:$E,合格品入货记录!$A:$A,日报!R$3)<>0,SUMIFS(合格品入货记录!$G:$G,合格品入货记录!$E:$E,日报!$E:$E,合格品入货记录!$A:$A,日报!R$3),"") | S8: =IF(SUMIFS(合格品入货记录!$G:$G,合格品入货记录!$E:$E,日报!$E:$E,合格品入货记录!$A:$A,日报!S$3)<>0,SUMIFS(合格品入货记录!$G:$G,合格品入货记录!$E:$E,日报!$E:$E,合格品入货记录!$A:$A,日报!S$3),"") | T8: =IF(SUMIFS(合格品入货记录!$G:$G,合格品入货记录!$E:$E,日报!$E:$E,合格品入货记录!$A:$A,日报!T$3)<>0,SUMIFS(合格品入货记录!$G:$G,合格品入货记录!$E:$E,日报!$E:$E,合格品入货记录!$A:$A,日报!T$3),"") | U8: =IF(SUMIFS(合格品入货记录!$G:$G,合格品入货记录!$E:$E,日报!$E:$E,合格品入货记录!$A:$A,日报!U$3)<>0,SUMIFS(合格品入货记录!$G:$G,合格品入货记录!$E:$E,日报!$E:$E,合格品入货记录!$A:$A,日报!U$3),"") | V8: =IF(SUMIFS(合格品入货记录!$G:$G,合格品入货记录!$E:$E,日报!$E:$E,合格品入货记录!$A:$A,日报!V$3)<>0,SUMIFS(合格品入货记录!$G:$G,合格品入货记录!$E:$E,日报!$E:$E,合格品入货记录!$A:$A,日报!V$3),"") -> 262 | W8: =IF(SUMIFS(合格品入货记录!$G:$G,合格品入货记录!$E:$E,日报!$E:$E,合格品入货记录!$A:$A,日报!W$3)<>0,SUMIFS(合格品入货记录!$G:$G,合格品入货记录!$E:$E,日报!$E:$E,合格品入货记录!$A:$A,日报!W$3),"") | ... AT8: =IF(SUMIFS(合格品入货记录!$G:$G,合格品入货记录!$E:$E,日报!$E:$E,合格品入货记录!$A:$A,日报!AT$3)<>0,SUMIFS(合格品入货记录!$G:$G,合格品入货记录!$E:$E,日报!$E:$E,合格品入货记录!$A:$A,日报!AT$3),"") | AU8: =IF(SUMIFS(合格品出库记录!$G:$G,合格品出库记录!$E:$E,日报!$E:$E,合格品出库记录!$A:$A,日报!AU$3)<>0,SUMIFS(合格品出库记录!$G:$G,合格品出库记录!$E:$E,日报!$E:$E,合格品出库记录!$A:$A,日报!AU$3),"") | AV8: =IF(SUMIFS(合格品出库记录!$G:$G,合格品出库记录!$E:$E,日报!$E:$E,合格品出库记录!$A:$A,日报!AV$3)<>0,SUMIFS(合格品出库记录!$G:$G,合格品出库记录!$E:$E,日报!$E:$E,合格品出库记录!$A:$A,日报!AV$3),"") | AW8: =IF(SUMIFS(合格品出库记录!$G:$G,合格品出库记录!$E:$E,日报!$E:$E,合格品出库记录!$A:$A,日报!AW$3)<>0,SUMIFS(合格品出库记录!$G:$G,合格品出库记录!$E:$E,日报!$E:$E,合格品出库记录!$A:$A,日报!AW$3),"") | AX8: =IF(SUMIFS(合格品出库记录!$G:$G,合格品出库记录!$E:$E,日报!$E:$E,合格品出库记录!$A:$A,日报!AX$3)<>0,SUMIFS(合格品出库记录!$G:$G,合格品出库记录!$E:$E,日报!$E:$E,合格品出库记录!$A:$A,日报!AX$3),"") | AY8: =IF(SUMIFS(合格品出库记录!$G:$G,合格品出库记录!$E:$E,日报!$E:$E,合格品出库记录!$A:$A,日报!AY$3)<>0,SUMIFS(合格品出库记录!$G:$G,合格品出库记录!$E:$E,日报!$E:$E,合格品出库记录!$A:$A,日报!AY$3),"") | AZ8: =IF(SUMIFS(合格品出库记录!$G:$G,合格品出库记录!$E:$E,日报!$E:$E,合格品出库记录!$A:$A,日报!AZ$3)<>0,SUMIFS(合格品出库记录!$G:$G,合格品出库记录!$E:$E,日报!$E:$E,合格品出库记录!$A:$A,日报!AZ$3),"") | BA8: =IF(SUMIFS(合格品出库记录!$G:$G,合格品出库记录!$E:$E,日报!$E:$E,合格品出库记录!$A:$A,日报!BA$3)<>0,SUMIFS(合格品出库记录!$G:$G,合格品出库记录!$E:$E,日报!$E:$E,合格品出库记录!$A:$A,日报!BA$3),"") | BB8: =IF(SUMIFS(合格品出库记录!$G:$G,合格品出库记录!$E:$E,日报!$E:$E,合格品出库记录!$A:$A,日报!BB$3)<>0,SUMIFS(合格品出库记录!$G:$G,合格品出库记录!$E:$E,日报!$E:$E,合格品出库记录!$A:$A,日报!BB$3),"") | ... BY8: =IF(SUMIFS(合格品出库记录!$G:$G,合格品出库记录!$E:$E,日报!$E:$E,合格品出库记录!$A:$A,日报!BY$3)<>0,SUMIFS(合格品出库记录!$G:$G,合格品出库记录!$E:$E,日报!$E:$E,合格品出库记录!$A:$A,日报!BY$3),"")
A9: 6 | B9: 1DC | C9: 东莞市硅翔绝缘材料有限公司 | D9: F02001000534 | E9: 3.2.49.08.00660-000 | F9: LPT03A_pBP-RP加热膜－T1 | H9: 127 | I9: =SUMIF(合格品入货记录!E:E,日报!E9,合格品入货记录!G:G) -> 0 | J9: =SUMIF(合格品出库记录!E:E,日报!E9,合格品出库记录!G:G) -> 3 | K9: =H9+I9-J9+L9 -> 124 | L9: =SUMIF(不良品库存!D:D,E:E,不良品库存!F:F) -> 0 | M9: =H9+I9-J9 -> 124 | P9: =IF(SUMIFS(合格品入货记录!$G:$G,合格品入货记录!$E:$E,日报!$E:$E,合格品入货记录!$A:$A,日报!P$3)<>0,SUMIFS(合格品入货记录!$G:$G,合格品入货记录!$E:$E,日报!$E:$E,合格品入货记录!$A:$A,日报!P$3),"") | Q9: =IF(SUMIFS(合格品入货记录!$G:$G,合格品入货记录!$E:$E,日报!$E:$E,合格品入货记录!$A:$A,日报!Q$3)<>0,SUMIFS(合格品入货记录!$G:$G,合格品入货记录!$E:$E,日报!$E:$E,合格品入货记录!$A:$A,日报!Q$3),"") | R9: =IF(SUMIFS(合格品入货记录!$G:$G,合格品入货记录!$E:$E,日报!$E:$E,合格品入货记录!$A:$A,日报!R$3)<>0,SUMIFS(合格品入货记录!$G:$G,合格品入货记录!$E:$E,日报!$E:$E,合格品入货记录!$A:$A,日报!R$3),"") | S9: =IF(SUMIFS(合格品入货记录!$G:$G,合格品入货记录!$E:$E,日报!$E:$E,合格品入货记录!$A:$A,日报!S$3)<>0,SUMIFS(合格品入货记录!$G:$G,合格品入货记录!$E:$E,日报!$E:$E,合格品入货记录!$A:$A,日报!S$3),"") | T9: =IF(SUMIFS(合格品入货记录!$G:$G,合格品入货记录!$E:$E,日报!$E:$E,合格品入货记录!$A:$A,日报!T$3)<>0,SUMIFS(合格品入货记录!$G:$G,合格品入货记录!$E:$E,日报!$E:$E,合格品入货记录!$A:$A,日报!T$3),"") | U9: =IF(SUMIFS(合格品入货记录!$G:$G,合格品入货记录!$E:$E,日报!$E:$E,合格品入货记录!$A:$A,日报!U$3)<>0,SUMIFS(合格品入货记录!$G:$G,合格品入货记录!$E:$E,日报!$E:$E,合格品入货记录!$A:$A,日报!U$3),"") | V9: =IF(SUMIFS(合格品入货记录!$G:$G,合格品入货记录!$E:$E,日报!$E:$E,合格品入货记录!$A:$A,日报!V$3)<>0,SUMIFS(合格品入货记录!$G:$G,合格品入货记录!$E:$E,日报!$E:$E,合格品入货记录!$A:$A,日报!V$3),"") | W9: =IF(SUMIFS(合格品入货记录!$G:$G,合格品入货记录!$E:$E,日报!$E:$E,合格品入货记录!$A:$A,日报!W$3)<>0,SUMIFS(合格品入货记录!$G:$G,合格品入货记录!$E:$E,日报!$E:$E,合格品入货记录!$A:$A,日报!W$3),"") | ... AT9: =IF(SUMIFS(合格品入货记录!$G:$G,合格品入货记录!$E:$E,日报!$E:$E,合格品入货记录!$A:$A,日报!AT$3)<>0,SUMIFS(合格品入货记录!$G:$G,合格品入货记录!$E:$E,日报!$E:$E,合格品入货记录!$A:$A,日报!AT$3),"") | AU9: =IF(SUMIFS(合格品出库记录!$G:$G,合格品出库记录!$E:$E,日报!$E:$E,合格品出库记录!$A:$A,日报!AU$3)<>0,SUMIFS(合格品出库记录!$G:$G,合格品出库记录!$E:$E,日报!$E:$E,合格品出库记录!$A:$A,日报!AU$3),"") | AV9: =IF(SUMIFS(合格品出库记录!$G:$G,合格品出库记录!$E:$E,日报!$E:$E,合格品出库记录!$A:$A,日报!AV$3)<>0,SUMIFS(合格品出库记录!$G:$G,合格品出库记录!$E:$E,日报!$E:$E,合格品出库记录!$A:$A,日报!AV$3),"") | AW9: =IF(SUMIFS(合格品出库记录!$G:$G,合格品出库记录!$E:$E,日报!$E:$E,合格品出库记录!$A:$A,日报!AW$3)<>0,SUMIFS(合格品出库记录!$G:$G,合格品出库记录!$E:$E,日报!$E:$E,合格品出库记录!$A:$A,日报!AW$3),"") | AX9: =IF(SUMIFS(合格品出库记录!$G:$G,合格品出库记录!$E:$E,日报!$E:$E,合格品出库记录!$A:$A,日报!AX$3)<>0,SUMIFS(合格品出库记录!$G:$G,合格品出库记录!$E:$E,日报!$E:$E,合格品出库记录!$A:$A,日报!AX$3),"") | AY9: =IF(SUMIFS(合格品出库记录!$G:$G,合格品出库记录!$E:$E,日报!$E:$E,合格品出库记录!$A:$A,日报!AY$3)<>0,SUMIFS(合格品出库记录!$G:$G,合格品出库记录!$E:$E,日报!$E:$E,合格品出库记录!$A:$A,日报!AY$3),"") | AZ9: =IF(SUMIFS(合格品出库记录!$G:$G,合格品出库记录!$E:$E,日报!$E:$E,合格品出库记录!$A:$A,日报!AZ$3)<>0,SUMIFS(合格品出库记录!$G:$G,合格品出库记录!$E:$E,日报!$E:$E,合格品出库记录!$A:$A,日报!AZ$3),"") | BA9: =IF(SUMIFS(合格品出库记录!$G:$G,合格品出库记录!$E:$E,日报!$E:$E,合格品出库记录!$A:$A,日报!BA$3)<>0,SUMIFS(合格品出库记录!$G:$G,合格品出库记录!$E:$E,日报!$E:$E,合格品出库记录!$A:$A,日报!BA$3),"") | BB9: =IF(SUMIFS(合格品出库记录!$G:$G,合格品出库记录!$E:$E,日报!$E:$E,合格品出库记录!$A:$A,日报!BB$3)<>0,SUMIFS(合格品出库记录!$G:$G,合格品出库记录!$E:$E,日报!$E:$E,合格品出库记录!$A:$A,日报!BB$3),"") | ... BY9: =IF(SUMIFS(合格品出库记录!$G:$G,合格品出库记录!$E:$E,日报!$E:$E,合格品出库记录!$A:$A,日报!BY$3)<>0,SUMIFS(合格品出库记录!$G:$G,合格品出库记录!$E:$E,日报!$E:$E,合格品出库记录!$A:$A,日报!BY$3),"")
A10: 7 | B10: 1DC | C10: 东莞市硅翔绝缘材料有限公司 | D10: F01001000118 | E10: 3.2.49.08.00332-000 | F10: LP-C11RE0-CCS 总成-21B | H10: 2 | I10: =SUMIF(合格品入货记录!E:E,日报!E10,合格品入货记录!G:G) -> 0 | J10: =SUMIF(合格品出库记录!E:E,日报!E10,合格品出库记录!G:G) -> 0 | K10: =H10+I10-J10+L10 -> 2 | L10: =SUMIF(不良品库存!D:D,E:E,不良品库存!F:F) -> 0 | M10: =H10+I10-J10 -> 2 | P10: =IF(SUMIFS(合格品入货记录!$G:$G,合格品入货记录!$E:$E,日报!$E:$E,合格品入货记录!$A:$A,日报!P$3)<>0,SUMIFS(合格品入货记录!$G:$G,合格品入货记录!$E:$E,日报!$E:$E,合格品入货记录!$A:$A,日报!P$3),"") | Q10: =IF(SUMIFS(合格品入货记录!$G:$G,合格品入货记录!$E:$E,日报!$E:$E,合格品入货记录!$A:$A,日报!Q$3)<>0,SUMIFS(合格品入货记录!$G:$G,合格品入货记录!$E:$E,日报!$E:$E,合格品入货记录!$A:$A,日报!Q$3),"") | R10: =IF(SUMIFS(合格品入货记录!$G:$G,合格品入货记录!$E:$E,日报!$E:$E,合格品入货记录!$A:$A,日报!R$3)<>0,SUMIFS(合格品入货记录!$G:$G,合格品入货记录!$E:$E,日报!$E:$E,合格品入货记录!$A:$A,日报!R$3),"") | S10: =IF(SUMIFS(合格品入货记录!$G:$G,合格品入货记录!$E:$E,日报!$E:$E,合格品入货记录!$A:$A,日报!S$3)<>0,SUMIFS(合格品入货记录!$G:$G,合格品入货记录!$E:$E,日报!$E:$E,合格品入货记录!$A:$A,日报!S$3),"") | T10: =IF(SUMIFS(合格品入货记录!$G:$G,合格品入货记录!$E:$E,日报!$E:$E,合格品入货记录!$A:$A,日报!T$3)<>0,SUMIFS(合格品入货记录!$G:$G,合格品入货记录!$E:$E,日报!$E:$E,合格品入货记录!$A:$A,日报!T$3),"") | U10: =IF(SUMIFS(合格品入货记录!$G:$G,合格品入货记录!$E:$E,日报!$E:$E,合格品入货记录!$A:$A,日报!U$3)<>0,SUMIFS(合格品入货记录!$G:$G,合格品入货记录!$E:$E,日报!$E:$E,合格品入货记录!$A:$A,日报!U$3),"") | V10: =IF(SUMIFS(合格品入货记录!$G:$G,合格品入货记录!$E:$E,日报!$E:$E,合格品入货记录!$A:$A,日报!V$3)<>0,SUMIFS(合格品入货记录!$G:$G,合格品入货记录!$E:$E,日报!$E:$E,合格品入货记录!$A:$A,日报!V$3),"") | W10: =IF(SUMIFS(合格品入货记录!$G:$G,合格品入货记录!$E:$E,日报!$E:$E,合格品入货记录!$A:$A,日报!W$3)<>0,SUMIFS(合格品入货记录!$G:$G,合格品入货记录!$E:$E,日报!$E:$E,合格品入货记录!$A:$A,日报!W$3),"") | ... AT10: =IF(SUMIFS(合格品入货记录!$G:$G,合格品入货记录!$E:$E,日报!$E:$E,合格品入货记录!$A:$A,日报!AT$3)<>0,SUMIFS(合格品入货记录!$G:$G,合格品入货记录!$E:$E,日报!$E:$E,合格品入货记录!$A:$A,日报!AT$3),"") | AU10: =IF(SUMIFS(合格品出库记录!$G:$G,合格品出库记录!$E:$E,日报!$E:$E,合格品出库记录!$A:$A,日报!AU$3)<>0,SUMIFS(合格品出库记录!$G:$G,合格品出库记录!$E:$E,日报!$E:$E,合格品出库记录!$A:$A,日报!AU$3),"") | AV10: =IF(SUMIFS(合格品出库记录!$G:$G,合格品出库记录!$E:$E,日报!$E:$E,合格品出库记录!$A:$A,日报!AV$3)<>0,SUMIFS(合格品出库记录!$G:$G,合格品出库记录!$E:$E,日报!$E:$E,合格品出库记录!$A:$A,日报!AV$3),"") | AW10: =IF(SUMIFS(合格品出库记录!$G:$G,合格品出库记录!$E:$E,日报!$E:$E,合格品出库记录!$A:$A,日报!AW$3)<>0,SUMIFS(合格品出库记录!$G:$G,合格品出库记录!$E:$E,日报!$E:$E,合格品出库记录!$A:$A,日报!AW$3),"") | AX10: =IF(SUMIFS(合格品出库记录!$G:$G,合格品出库记录!$E:$E,日报!$E:$E,合格品出库记录!$A:$A,日报!AX$3)<>0,SUMIFS(合格品出库记录!$G:$G,合格品出库记录!$E:$E,日报!$E:$E,合格品出库记录!$A:$A,日报!AX$3),"") | AY10: =IF(SUMIFS(合格品出库记录!$G:$G,合格品出库记录!$E:$E,日报!$E:$E,合格品出库记录!$A:$A,日报!AY$3)<>0,SUMIFS(合格品出库记录!$G:$G,合格品出库记录!$E:$E,日报!$E:$E,合格品出库记录!$A:$A,日报!AY$3),"") | AZ10: =IF(SUMIFS(合格品出库记录!$G:$G,合格品出库记录!$E:$E,日报!$E:$E,合格品出库记录!$A:$A,日报!AZ$3)<>0,SUMIFS(合格品出库记录!$G:$G,合格品出库记录!$E:$E,日报!$E:$E,合格品出库记录!$A:$A,日报!AZ$3),"") | BA10: =IF(SUMIFS(合格品出库记录!$G:$G,合格品出库记录!$E:$E,日报!$E:$E,合格品出库记录!$A:$A,日报!BA$3)<>0,SUMIFS(合格品出库记录!$G:$G,合格品出库记录!$E:$E,日报!$E:$E,合格品出库记录!$A:$A,日报!BA$3),"") | BB10: =IF(SUMIFS(合格品出库记录!$G:$G,合格品出库记录!$E:$E,日报!$E:$E,合格品出库记录!$A:$A,日报!BB$3)<>0,SUMIFS(合格品出库记录!$G:$G,合格品出库记录!$E:$E,日报!$E:$E,合格品出库记录!$A:$A,日报!BB$3),"") | ... BY10: =IF(SUMIFS(合格品出库记录!$G:$G,合格品出库记录!$E:$E,日报!$E:$E,合格品出库记录!$A:$A,日报!BY$3)<>0,SUMIFS(合格品出库记录!$G:$G,合格品出库记录!$E:$E,日报!$E:$E,合格品出库记录!$A:$A,日报!BY$3),"")
A11: 8 | B11: 1DC | C11: 东莞市硅翔绝缘材料有限公司 | D11: F01001000117 | E11: 3.2.49.08.00331-000 | F11: LP-C11RE0-CCS 总成-21A | H11: 482 | I11: =SUMIF(合格品入货记录!E:E,日报!E11,合格品入货记录!G:G) -> 0 | J11: =SUMIF(合格品出库记录!E:E,日报!E11,合格品出库记录!G:G) -> 0 | K11: =H11+I11-J11+L11 -> 532 | L11: =SUMIF(不良品库存!D:D,E:E,不良品库存!F:F) -> 50 | M11: =H11+I11-J11 -> 482 | P11: =IF(SUMIFS(合格品入货记录!$G:$G,合格品入货记录!$E:$E,日报!$E:$E,合格品入货记录!$A:$A,日报!P$3)<>0,SUMIFS(合格品入货记录!$G:$G,合格品入货记录!$E:$E,日报!$E:$E,合格品入货记录!$A:$A,日报!P$3),"") | Q11: =IF(SUMIFS(合格品入货记录!$G:$G,合格品入货记录!$E:$E,日报!$E:$E,合格品入货记录!$A:$A,日报!Q$3)<>0,SUMIFS(合格品入货记录!$G:$G,合格品入货记录!$E:$E,日报!$E:$E,合格品入货记录!$A:$A,日报!Q$3),"") | R11: =IF(SUMIFS(合格品入货记录!$G:$G,合格品入货记录!$E:$E,日报!$E:$E,合格品入货记录!$A:$A,日报!R$3)<>0,SUMIFS(合格品入货记录!$G:$G,合格品入货记录!$E:$E,日报!$E:$E,合格品入货记录!$A:$A,日报!R$3),"") | S11: =IF(SUMIFS(合格品入货记录!$G:$G,合格品入货记录!$E:$E,日报!$E:$E,合格品入货记录!$A:$A,日报!S$3)<>0,SUMIFS(合格品入货记录!$G:$G,合格品入货记录!$E:$E,日报!$E:$E,合格品入货记录!$A:$A,日报!S$3),"") | T11: =IF(SUMIFS(合格品入货记录!$G:$G,合格品入货记录!$E:$E,日报!$E:$E,合格品入货记录!$A:$A,日报!T$3)<>0,SUMIFS(合格品入货记录!$G:$G,合格品入货记录!$E:$E,日报!$E:$E,合格品入货记录!$A:$A,日报!T$3),"") | U11: =IF(SUMIFS(合格品入货记录!$G:$G,合格品入货记录!$E:$E,日报!$E:$E,合格品入货记录!$A:$A,日报!U$3)<>0,SUMIFS(合格品入货记录!$G:$G,合格品入货记录!$E:$E,日报!$E:$E,合格品入货记录!$A:$A,日报!U$3),"") | V11: =IF(SUMIFS(合格品入货记录!$G:$G,合格品入货记录!$E:$E,日报!$E:$E,合格品入货记录!$A:$A,日报!V$3)<>0,SUMIFS(合格品入货记录!$G:$G,合格品入货记录!$E:$E,日报!$E:$E,合格品入货记录!$A:$A,日报!V$3),"") | W11: =IF(SUMIFS(合格品入货记录!$G:$G,合格品入货记录!$E:$E,日报!$E:$E,合格品入货记录!$A:$A,日报!W$3)<>0,SUMIFS(合格品入货记录!$G:$G,合格品入货记录!$E:$E,日报!$E:$E,合格品入货记录!$A:$A,日报!W$3),"") | ... AT11: =IF(SUMIFS(合格品入货记录!$G:$G,合格品入货记录!$E:$E,日报!$E:$E,合格品入货记录!$A:$A,日报!AT$3)<>0,SUMIFS(合格品入货记录!$G:$G,合格品入货记录!$E:$E,日报!$E:$E,合格品入货记录!$A:$A,日报!AT$3),"") | AU11: =IF(SUMIFS(合格品出库记录!$G:$G,合格品出库记录!$E:$E,日报!$E:$E,合格品出库记录!$A:$A,日报!AU$3)<>0,SUMIFS(合格品出库记录!$G:$G,合格品出库记录!$E:$E,日报!$E:$E,合格品出库记录!$A:$A,日报!AU$3),"") | AV11: =IF(SUMIFS(合格品出库记录!$G:$G,合格品出库记录!$E:$E,日报!$E:$E,合格品出库记录!$A:$A,日报!AV$3)<>0,SUMIFS(合格品出库记录!$G:$G,合格品出库记录!$E:$E,日报!$E:$E,合格品出库记录!$A:$A,日报!AV$3),"") | AW11: =IF(SUMIFS(合格品出库记录!$G:$G,合格品出库记录!$E:$E,日报!$E:$E,合格品出库记录!$A:$A,日报!AW$3)<>0,SUMIFS(合格品出库记录!$G:$G,合格品出库记录!$E:$E,日报!$E:$E,合格品出库记录!$A:$A,日报!AW$3),"") | AX11: =IF(SUMIFS(合格品出库记录!$G:$G,合格品出库记录!$E:$E,日报!$E:$E,合格品出库记录!$A:$A,日报!AX$3)<>0,SUMIFS(合格品出库记录!$G:$G,合格品出库记录!$E:$E,日报!$E:$E,合格品出库记录!$A:$A,日报!AX$3),"") | AY11: =IF(SUMIFS(合格品出库记录!$G:$G,合格品出库记录!$E:$E,日报!$E:$E,合格品出库记录!$A:$A,日报!AY$3)<>0,SUMIFS(合格品出库记录!$G:$G,合格品出库记录!$E:$E,日报!$E:$E,合格品出库记录!$A:$A,日报!AY$3),"") | AZ11: =IF(SUMIFS(合格品出库记录!$G:$G,合格品出库记录!$E:$E,日报!$E:$E,合格品出库记录!$A:$A,日报!AZ$3)<>0,SUMIFS(合格品出库记录!$G:$G,合格品出库记录!$E:$E,日报!$E:$E,合格品出库记录!$A:$A,日报!AZ$3),"") | BA11: =IF(SUMIFS(合格品出库记录!$G:$G,合格品出库记录!$E:$E,日报!$E:$E,合格品出库记录!$A:$A,日报!BA$3)<>0,SUMIFS(合格品出库记录!$G:$G,合格品出库记录!$E:$E,日报!$E:$E,合格品出库记录!$A:$A,日报!BA$3),"") | BB11: =IF(SUMIFS(合格品出库记录!$G:$G,合格品出库记录!$E:$E,日报!$E:$E,合格品出库记录!$A:$A,日报!BB$3)<>0,SUMIFS(合格品出库记录!$G:$G,合格品出库记录!$E:$E,日报!$E:$E,合格品出库记录!$A:$A,日报!BB$3),"") | ... BY11: =IF(SUMIFS(合格品出库记录!$G:$G,合格品出库记录!$E:$E,日报!$E:$E,合格品出库记录!$A:$A,日报!BY$3)<>0,SUMIFS(合格品出库记录!$G:$G,合格品出库记录!$E:$E,日报!$E:$E,合格品出库记录!$A:$A,日报!BY$3),"")
A12: 9 | B12: 1DC | C12: 东莞市硅翔绝缘材料有限公司 | D12: F02001000530 | E12: 3.2.49.08.00242-000 | F12: LPT03A_PBP-加热片-R | H12: 0 | I12: =SUMIF(合格品入货记录!E:E,日报!E12,合格品入货记录!G:G) -> 0 | J12: =SUMIF(合格品出库记录!E:E,日报!E12,合格品出库记录!G:G) -> 0 | K12: =H12+I12-J12+L12 -> 0 | L12: =SUMIF(不良品库存!D:D,E:E,不良品库存!F:F) -> 0 | M12: =H12+I12-J12 -> 0 | P12: =IF(SUMIFS(合格品入货记录!$G:$G,合格品入货记录!$E:$E,日报!$E:$E,合格品入货记录!$A:$A,日报!P$3)<>0,SUMIFS(合格品入货记录!$G:$G,合格品入货记录!$E:$E,日报!$E:$E,合格品入货记录!$A:$A,日报!P$3),"") | Q12: =IF(SUMIFS(合格品入货记录!$G:$G,合格品入货记录!$E:$E,日报!$E:$E,合格品入货记录!$A:$A,日报!Q$3)<>0,SUMIFS(合格品入货记录!$G:$G,合格品入货记录!$E:$E,日报!$E:$E,合格品入货记录!$A:$A,日报!Q$3),"") | R12: =IF(SUMIFS(合格品入货记录!$G:$G,合格品入货记录!$E:$E,日报!$E:$E,合格品入货记录!$A:$A,日报!R$3)<>0,SUMIFS(合格品入货记录!$G:$G,合格品入货记录!$E:$E,日报!$E:$E,合格品入货记录!$A:$A,日报!R$3),"") | S12: =IF(SUMIFS(合格品入货记录!$G:$G,合格品入货记录!$E:$E,日报!$E:$E,合格品入货记录!$A:$A,日报!S$3)<>0,SUMIFS(合格品入货记录!$G:$G,合格品入货记录!$E:$E,日报!$E:$E,合格品入货记录!$A:$A,日报!S$3),"") | T12: =IF(SUMIFS(合格品入货记录!$G:$G,合格品入货记录!$E:$E,日报!$E:$E,合格品入货记录!$A:$A,日报!T$3)<>0,SUMIFS(合格品入货记录!$G:$G,合格品入货记录!$E:$E,日报!$E:$E,合格品入货记录!$A:$A,日报!T$3),"") | U12: =IF(SUMIFS(合格品入货记录!$G:$G,合格品入货记录!$E:$E,日报!$E:$E,合格品入货记录!$A:$A,日报!U$3)<>0,SUMIFS(合格品入货记录!$G:$G,合格品入货记录!$E:$E,日报!$E:$E,合格品入货记录!$A:$A,日报!U$3),"") | V12: =IF(SUMIFS(合格品入货记录!$G:$G,合格品入货记录!$E:$E,日报!$E:$E,合格品入货记录!$A:$A,日报!V$3)<>0,SUMIFS(合格品入货记录!$G:$G,合格品入货记录!$E:$E,日报!$E:$E,合格品入货记录!$A:$A,日报!V$3),"") | W12: =IF(SUMIFS(合格品入货记录!$G:$G,合格品入货记录!$E:$E,日报!$E:$E,合格品入货记录!$A:$A,日报!W$3)<>0,SUMIFS(合格品入货记录!$G:$G,合格品入货记录!$E:$E,日报!$E:$E,合格品入货记录!$A:$A,日报!W$3),"") | ... AT12: =IF(SUMIFS(合格品入货记录!$G:$G,合格品入货记录!$E:$E,日报!$E:$E,合格品入货记录!$A:$A,日报!AT$3)<>0,SUMIFS(合格品入货记录!$G:$G,合格品入货记录!$E:$E,日报!$E:$E,合格品入货记录!$A:$A,日报!AT$3),"") | AU12: =IF(SUMIFS(合格品出库记录!$G:$G,合格品出库记录!$E:$E,日报!$E:$E,合格品出库记录!$A:$A,日报!AU$3)<>0,SUMIFS(合格品出库记录!$G:$G,合格品出库记录!$E:$E,日报!$E:$E,合格品出库记录!$A:$A,日报!AU$3),"") | AV12: =IF(SUMIFS(合格品出库记录!$G:$G,合格品出库记录!$E:$E,日报!$E:$E,合格品出库记录!$A:$A,日报!AV$3)<>0,SUMIFS(合格品出库记录!$G:$G,合格品出库记录!$E:$E,日报!$E:$E,合格品出库记录!$A:$A,日报!AV$3),"") | AW12: =IF(SUMIFS(合格品出库记录!$G:$G,合格品出库记录!$E:$E,日报!$E:$E,合格品出库记录!$A:$A,日报!AW$3)<>0,SUMIFS(合格品出库记录!$G:$G,合格品出库记录!$E:$E,日报!$E:$E,合格品出库记录!$A:$A,日报!AW$3),"") | AX12: =IF(SUMIFS(合格品出库记录!$G:$G,合格品出库记录!$E:$E,日报!$E:$E,合格品出库记录!$A:$A,日报!AX$3)<>0,SUMIFS(合格品出库记录!$G:$G,合格品出库记录!$E:$E,日报!$E:$E,合格品出库记录!$A:$A,日报!AX$3),"") | AY12: =IF(SUMIFS(合格品出库记录!$G:$G,合格品出库记录!$E:$E,日报!$E:$E,合格品出库记录!$A:$A,日报!AY$3)<>0,SUMIFS(合格品出库记录!$G:$G,合格品出库记录!$E:$E,日报!$E:$E,合格品出库记录!$A:$A,日报!AY$3),"") | AZ12: =IF(SUMIFS(合格品出库记录!$G:$G,合格品出库记录!$E:$E,日报!$E:$E,合格品出库记录!$A:$A,日报!AZ$3)<>0,SUMIFS(合格品出库记录!$G:$G,合格品出库记录!$E:$E,日报!$E:$E,合格品出库记录!$A:$A,日报!AZ$3),"") | BA12: =IF(SUMIFS(合格品出库记录!$G:$G,合格品出库记录!$E:$E,日报!$E:$E,合格品出库记录!$A:$A,日报!BA$3)<>0,SUMIFS(合格品出库记录!$G:$G,合格品出库记录!$E:$E,日报!$E:$E,合格品出库记录!$A:$A,日报!BA$3),"") | BB12: =IF(SUMIFS(合格品出库记录!$G:$G,合格品出库记录!$E:$E,日报!$E:$E,合格品出库记录!$A:$A,日报!BB$3)<>0,SUMIFS(合格品出库记录!$G:$G,合格品出库记录!$E:$E,日报!$E:$E,合格品出库记录!$A:$A,日报!BB$3),"") | ... BY12: =IF(SUMIFS(合格品出库记录!$G:$G,合格品出库记录!$E:$E,日报!$E:$E,合格品出库记录!$A:$A,日报!BY$3)<>0,SUMIFS(合格品出库记录!$G:$G,合格品出库记录!$E:$E,日报!$E:$E,合格品出库记录!$A:$A,日报!BY$3),"")
A13: 10 | B13: 1DC | C13: 东莞市硅翔绝缘材料有限公司 | D13: F01001000348 | E13: 3.2.49.08.00524-000 | F13: T03A_PBP-CCS总成-300-R | H13: 35 | I13: =SUMIF(合格品入货记录!E:E,日报!E13,合格品入货记录!G:G) -> 0 | J13: =SUMIF(合格品出库记录!E:E,日报!E13,合格品出库记录!G:G) -> 5 | K13: =H13+I13-J13+L13 -> 30 | L13: =SUMIF(不良品库存!D:D,E:E,不良品库存!F:F) -> 0 | M13: =H13+I13-J13 -> 30 | P13: =IF(SUMIFS(合格品入货记录!$G:$G,合格品入货记录!$E:$E,日报!$E:$E,合格品入货记录!$A:$A,日报!P$3)<>0,SUMIFS(合格品入货记录!$G:$G,合格品入货记录!$E:$E,日报!$E:$E,合格品入货记录!$A:$A,日报!P$3),"") | Q13: =IF(SUMIFS(合格品入货记录!$G:$G,合格品入货记录!$E:$E,日报!$E:$E,合格品入货记录!$A:$A,日报!Q$3)<>0,SUMIFS(合格品入货记录!$G:$G,合格品入货记录!$E:$E,日报!$E:$E,合格品入货记录!$A:$A,日报!Q$3),"") | R13: =IF(SUMIFS(合格品入货记录!$G:$G,合格品入货记录!$E:$E,日报!$E:$E,合格品入货记录!$A:$A,日报!R$3)<>0,SUMIFS(合格品入货记录!$G:$G,合格品入货记录!$E:$E,日报!$E:$E,合格品入货记录!$A:$A,日报!R$3),"") | S13: =IF(SUMIFS(合格品入货记录!$G:$G,合格品入货记录!$E:$E,日报!$E:$E,合格品入货记录!$A:$A,日报!S$3)<>0,SUMIFS(合格品入货记录!$G:$G,合格品入货记录!$E:$E,日报!$E:$E,合格品入货记录!$A:$A,日报!S$3),"") | T13: =IF(SUMIFS(合格品入货记录!$G:$G,合格品入货记录!$E:$E,日报!$E:$E,合格品入货记录!$A:$A,日报!T$3)<>0,SUMIFS(合格品入货记录!$G:$G,合格品入货记录!$E:$E,日报!$E:$E,合格品入货记录!$A:$A,日报!T$3),"") | U13: =IF(SUMIFS(合格品入货记录!$G:$G,合格品入货记录!$E:$E,日报!$E:$E,合格品入货记录!$A:$A,日报!U$3)<>0,SUMIFS(合格品入货记录!$G:$G,合格品入货记录!$E:$E,日报!$E:$E,合格品入货记录!$A:$A,日报!U$3),"") | V13: =IF(SUMIFS(合格品入货记录!$G:$G,合格品入货记录!$E:$E,日报!$E:$E,合格品入货记录!$A:$A,日报!V$3)<>0,SUMIFS(合格品入货记录!$G:$G,合格品入货记录!$E:$E,日报!$E:$E,合格品入货记录!$A:$A,日报!V$3),"") | W13: =IF(SUMIFS(合格品入货记录!$G:$G,合格品入货记录!$E:$E,日报!$E:$E,合格品入货记录!$A:$A,日报!W$3)<>0,SUMIFS(合格品入货记录!$G:$G,合格品入货记录!$E:$E,日报!$E:$E,合格品入货记录!$A:$A,日报!W$3),"") | ... AT13: =IF(SUMIFS(合格品入货记录!$G:$G,合格品入货记录!$E:$E,日报!$E:$E,合格品入货记录!$A:$A,日报!AT$3)<>0,SUMIFS(合格品入货记录!$G:$G,合格品入货记录!$E:$E,日报!$E:$E,合格品入货记录!$A:$A,日报!AT$3),"") | AU13: =IF(SUMIFS(合格品出库记录!$G:$G,合格品出库记录!$E:$E,日报!$E:$E,合格品出库记录!$A:$A,日报!AU$3)<>0,SUMIFS(合格品出库记录!$G:$G,合格品出库记录!$E:$E,日报!$E:$E,合格品出库记录!$A:$A,日报!AU$3),"") | AV13: =IF(SUMIFS(合格品出库记录!$G:$G,合格品出库记录!$E:$E,日报!$E:$E,合格品出库记录!$A:$A,日报!AV$3)<>0,SUMIFS(合格品出库记录!$G:$G,合格品出库记录!$E:$E,日报!$E:$E,合格品出库记录!$A:$A,日报!AV$3),"") | AW13: =IF(SUMIFS(合格品出库记录!$G:$G,合格品出库记录!$E:$E,日报!$E:$E,合格品出库记录!$A:$A,日报!AW$3)<>0,SUMIFS(合格品出库记录!$G:$G,合格品出库记录!$E:$E,日报!$E:$E,合格品出库记录!$A:$A,日报!AW$3),"") | AX13: =IF(SUMIFS(合格品出库记录!$G:$G,合格品出库记录!$E:$E,日报!$E:$E,合格品出库记录!$A:$A,日报!AX$3)<>0,SUMIFS(合格品出库记录!$G:$G,合格品出库记录!$E:$E,日报!$E:$E,合格品出库记录!$A:$A,日报!AX$3),"") | AY13: =IF(SUMIFS(合格品出库记录!$G:$G,合格品出库记录!$E:$E,日报!$E:$E,合格品出库记录!$A:$A,日报!AY$3)<>0,SUMIFS(合格品出库记录!$G:$G,合格品出库记录!$E:$E,日报!$E:$E,合格品出库记录!$A:$A,日报!AY$3),"") | AZ13: =IF(SUMIFS(合格品出库记录!$G:$G,合格品出库记录!$E:$E,日报!$E:$E,合格品出库记录!$A:$A,日报!AZ$3)<>0,SUMIFS(合格品出库记录!$G:$G,合格品出库记录!$E:$E,日报!$E:$E,合格品出库记录!$A:$A,日报!AZ$3),"") | BA13: =IF(SUMIFS(合格品出库记录!$G:$G,合格品出库记录!$E:$E,日报!$E:$E,合格品出库记录!$A:$A,日报!BA$3)<>0,SUMIFS(合格品出库记录!$G:$G,合格品出库记录!$E:$E,日报!$E:$E,合格品出库记录!$A:$A,日报!BA$3),"") | BB13: =IF(SUMIFS(合格品出库记录!$G:$G,合格品出库记录!$E:$E,日报!$E:$E,合格品出库记录!$A:$A,日报!BB$3)<>0,SUMIFS(合格品出库记录!$G:$G,合格品出库记录!$E:$E,日报!$E:$E,合格品出库记录!$A:$A,日报!BB$3),"") | ... BY13: =IF(SUMIFS(合格品出库记录!$G:$G,合格品出库记录!$E:$E,日报!$E:$E,合格品出库记录!$A:$A,日报!BY$3)<>0,SUMIFS(合格品出库记录!$G:$G,合格品出库记录!$E:$E,日报!$E:$E,合格品出库记录!$A:$A,日报!BY$3),"")
A14: 11 | B14: 1DC | C14: 东莞市硅翔绝缘材料有限公司 | D14: F01001000350 | E14: 3.2.49.08.00732-000 | F14: LXC01-模组CCS总成-21B | H14: 675 | I14: =SUMIF(合格品入货记录!E:E,日报!E14,合格品入货记录!G:G) -> 0 | J14: =SUMIF(合格品出库记录!E:E,日报!E14,合格品出库记录!G:G) -> 0 | K14: =H14+I14-J14+L14 -> 675 | L14: =SUMIF(不良品库存!D:D,E:E,不良品库存!F:F) -> 0 | M14: =H14+I14-J14 -> 675 | P14: =IF(SUMIFS(合格品入货记录!$G:$G,合格品入货记录!$E:$E,日报!$E:$E,合格品入货记录!$A:$A,日报!P$3)<>0,SUMIFS(合格品入货记录!$G:$G,合格品入货记录!$E:$E,日报!$E:$E,合格品入货记录!$A:$A,日报!P$3),"") | Q14: =IF(SUMIFS(合格品入货记录!$G:$G,合格品入货记录!$E:$E,日报!$E:$E,合格品入货记录!$A:$A,日报!Q$3)<>0,SUMIFS(合格品入货记录!$G:$G,合格品入货记录!$E:$E,日报!$E:$E,合格品入货记录!$A:$A,日报!Q$3),"") | R14: =IF(SUMIFS(合格品入货记录!$G:$G,合格品入货记录!$E:$E,日报!$E:$E,合格品入货记录!$A:$A,日报!R$3)<>0,SUMIFS(合格品入货记录!$G:$G,合格品入货记录!$E:$E,日报!$E:$E,合格品入货记录!$A:$A,日报!R$3),"") | S14: =IF(SUMIFS(合格品入货记录!$G:$G,合格品入货记录!$E:$E,日报!$E:$E,合格品入货记录!$A:$A,日报!S$3)<>0,SUMIFS(合格品入货记录!$G:$G,合格品入货记录!$E:$E,日报!$E:$E,合格品入货记录!$A:$A,日报!S$3),"") | T14: =IF(SUMIFS(合格品入货记录!$G:$G,合格品入货记录!$E:$E,日报!$E:$E,合格品入货记录!$A:$A,日报!T$3)<>0,SUMIFS(合格品入货记录!$G:$G,合格品入货记录!$E:$E,日报!$E:$E,合格品入货记录!$A:$A,日报!T$3),"") | U14: =IF(SUMIFS(合格品入货记录!$G:$G,合格品入货记录!$E:$E,日报!$E:$E,合格品入货记录!$A:$A,日报!U$3)<>0,SUMIFS(合格品入货记录!$G:$G,合格品入货记录!$E:$E,日报!$E:$E,合格品入货记录!$A:$A,日报!U$3),"") | V14: =IF(SUMIFS(合格品入货记录!$G:$G,合格品入货记录!$E:$E,日报!$E:$E,合格品入货记录!$A:$A,日报!V$3)<>0,SUMIFS(合格品入货记录!$G:$G,合格品入货记录!$E:$E,日报!$E:$E,合格品入货记录!$A:$A,日报!V$3),"") | W14: =IF(SUMIFS(合格品入货记录!$G:$G,合格品入货记录!$E:$E,日报!$E:$E,合格品入货记录!$A:$A,日报!W$3)<>0,SUMIFS(合格品入货记录!$G:$G,合格品入货记录!$E:$E,日报!$E:$E,合格品入货记录!$A:$A,日报!W$3),"") | ... AT14: =IF(SUMIFS(合格品入货记录!$G:$G,合格品入货记录!$E:$E,日报!$E:$E,合格品入货记录!$A:$A,日报!AT$3)<>0,SUMIFS(合格品入货记录!$G:$G,合格品入货记录!$E:$E,日报!$E:$E,合格品入货记录!$A:$A,日报!AT$3),"") | AU14: =IF(SUMIFS(合格品出库记录!$G:$G,合格品出库记录!$E:$E,日报!$E:$E,合格品出库记录!$A:$A,日报!AU$3)<>0,SUMIFS(合格品出库记录!$G:$G,合格品出库记录!$E:$E,日报!$E:$E,合格品出库记录!$A:$A,日报!AU$3),"") | AV14: =IF(SUMIFS(合格品出库记录!$G:$G,合格品出库记录!$E:$E,日报!$E:$E,合格品出库记录!$A:$A,日报!AV$3)<>0,SUMIFS(合格品出库记录!$G:$G,合格品出库记录!$E:$E,日报!$E:$E,合格品出库记录!$A:$A,日报!AV$3),"") | AW14: =IF(SUMIFS(合格品出库记录!$G:$G,合格品出库记录!$E:$E,日报!$E:$E,合格品出库记录!$A:$A,日报!AW$3)<>0,SUMIFS(合格品出库记录!$G:$G,合格品出库记录!$E:$E,日报!$E:$E,合格品出库记录!$A:$A,日报!AW$3),"") | AX14: =IF(SUMIFS(合格品出库记录!$G:$G,合格品出库记录!$E:$E,日报!$E:$E,合格品出库记录!$A:$A,日报!AX$3)<>0,SUMIFS(合格品出库记录!$G:$G,合格品出库记录!$E:$E,日报!$E:$E,合格品出库记录!$A:$A,日报!AX$3),"") | AY14: =IF(SUMIFS(合格品出库记录!$G:$G,合格品出库记录!$E:$E,日报!$E:$E,合格品出库记录!$A:$A,日报!AY$3)<>0,SUMIFS(合格品出库记录!$G:$G,合格品出库记录!$E:$E,日报!$E:$E,合格品出库记录!$A:$A,日报!AY$3),"") | AZ14: =IF(SUMIFS(合格品出库记录!$G:$G,合格品出库记录!$E:$E,日报!$E:$E,合格品出库记录!$A:$A,日报!AZ$3)<>0,SUMIFS(合格品出库记录!$G:$G,合格品出库记录!$E:$E,日报!$E:$E,合格品出库记录!$A:$A,日报!AZ$3),"") | BA14: =IF(SUMIFS(合格品出库记录!$G:$G,合格品出库记录!$E:$E,日报!$E:$E,合格品出库记录!$A:$A,日报!BA$3)<>0,SUMIFS(合格品出库记录!$G:$G,合格品出库记录!$E:$E,日报!$E:$E,合格品出库记录!$A:$A,日报!BA$3),"") | BB14: =IF(SUMIFS(合格品出库记录!$G:$G,合格品出库记录!$E:$E,日报!$E:$E,合格品出库记录!$A:$A,日报!BB$3)<>0,SUMIFS(合格品出库记录!$G:$G,合格品出库记录!$E:$E,日报!$E:$E,合格品出库记录!$A:$A,日报!BB$3),"") | ... BY14: =IF(SUMIFS(合格品出库记录!$G:$G,合格品出库记录!$E:$E,日报!$E:$E,合格品出库记录!$A:$A,日报!BY$3)<>0,SUMIFS(合格品出库记录!$G:$G,合格品出库记录!$E:$E,日报!$E:$E,合格品出库记录!$A:$A,日报!BY$3),"")
A15: 12 | B15: 1DC | C15: 东莞市硅翔绝缘材料有限公司 | D15: F01001000349 | E15: 3.2.49.08.00731-000 | F15: LXC01-模组CCS总成-21A | H15: 1030 | I15: =SUMIF(合格品入货记录!E:E,日报!E15,合格品入货记录!G:G) -> 0 | J15: =SUMIF(合格品出库记录!E:E,日报!E15,合格品出库记录!G:G) -> 0 | K15: =H15+I15-J15+L15 -> 1030 | L15: =SUMIF(不良品库存!D:D,E:E,不良品库存!F:F) -> 0 | M15: =H15+I15-J15 -> 1030 | P15: =IF(SUMIFS(合格品入货记录!$G:$G,合格品入货记录!$E:$E,日报!$E:$E,合格品入货记录!$A:$A,日报!P$3)<>0,SUMIFS(合格品入货记录!$G:$G,合格品入货记录!$E:$E,日报!$E:$E,合格品入货记录!$A:$A,日报!P$3),"") | Q15: =IF(SUMIFS(合格品入货记录!$G:$G,合格品入货记录!$E:$E,日报!$E:$E,合格品入货记录!$A:$A,日报!Q$3)<>0,SUMIFS(合格品入货记录!$G:$G,合格品入货记录!$E:$E,日报!$E:$E,合格品入货记录!$A:$A,日报!Q$3),"") | R15: =IF(SUMIFS(合格品入货记录!$G:$G,合格品入货记录!$E:$E,日报!$E:$E,合格品入货记录!$A:$A,日报!R$3)<>0,SUMIFS(合格品入货记录!$G:$G,合格品入货记录!$E:$E,日报!$E:$E,合格品入货记录!$A:$A,日报!R$3),"") | S15: =IF(SUMIFS(合格品入货记录!$G:$G,合格品入货记录!$E:$E,日报!$E:$E,合格品入货记录!$A:$A,日报!S$3)<>0,SUMIFS(合格品入货记录!$G:$G,合格品入货记录!$E:$E,日报!$E:$E,合格品入货记录!$A:$A,日报!S$3),"") | T15: =IF(SUMIFS(合格品入货记录!$G:$G,合格品入货记录!$E:$E,日报!$E:$E,合格品入货记录!$A:$A,日报!T$3)<>0,SUMIFS(合格品入货记录!$G:$G,合格品入货记录!$E:$E,日报!$E:$E,合格品入货记录!$A:$A,日报!T$3),"") | U15: =IF(SUMIFS(合格品入货记录!$G:$G,合格品入货记录!$E:$E,日报!$E:$E,合格品入货记录!$A:$A,日报!U$3)<>0,SUMIFS(合格品入货记录!$G:$G,合格品入货记录!$E:$E,日报!$E:$E,合格品入货记录!$A:$A,日报!U$3),"") | V15: =IF(SUMIFS(合格品入货记录!$G:$G,合格品入货记录!$E:$E,日报!$E:$E,合格品入货记录!$A:$A,日报!V$3)<>0,SUMIFS(合格品入货记录!$G:$G,合格品入货记录!$E:$E,日报!$E:$E,合格品入货记录!$A:$A,日报!V$3),"") | W15: =IF(SUMIFS(合格品入货记录!$G:$G,合格品入货记录!$E:$E,日报!$E:$E,合格品入货记录!$A:$A,日报!W$3)<>0,SUMIFS(合格品入货记录!$G:$G,合格品入货记录!$E:$E,日报!$E:$E,合格品入货记录!$A:$A,日报!W$3),"") | ... AT15: =IF(SUMIFS(合格品入货记录!$G:$G,合格品入货记录!$E:$E,日报!$E:$E,合格品入货记录!$A:$A,日报!AT$3)<>0,SUMIFS(合格品入货记录!$G:$G,合格品入货记录!$E:$E,日报!$E:$E,合格品入货记录!$A:$A,日报!AT$3),"") | AU15: =IF(SUMIFS(合格品出库记录!$G:$G,合格品出库记录!$E:$E,日报!$E:$E,合格品出库记录!$A:$A,日报!AU$3)<>0,SUMIFS(合格品出库记录!$G:$G,合格品出库记录!$E:$E,日报!$E:$E,合格品出库记录!$A:$A,日报!AU$3),"") | AV15: =IF(SUMIFS(合格品出库记录!$G:$G,合格品出库记录!$E:$E,日报!$E:$E,合格品出库记录!$A:$A,日报!AV$3)<>0,SUMIFS(合格品出库记录!$G:$G,合格品出库记录!$E:$E,日报!$E:$E,合格品出库记录!$A:$A,日报!AV$3),"") | AW15: =IF(SUMIFS(合格品出库记录!$G:$G,合格品出库记录!$E:$E,日报!$E:$E,合格品出库记录!$A:$A,日报!AW$3)<>0,SUMIFS(合格品出库记录!$G:$G,合格品出库记录!$E:$E,日报!$E:$E,合格品出库记录!$A:$A,日报!AW$3),"") | AX15: =IF(SUMIFS(合格品出库记录!$G:$G,合格品出库记录!$E:$E,日报!$E:$E,合格品出库记录!$A:$A,日报!AX$3)<>0,SUMIFS(合格品出库记录!$G:$G,合格品出库记录!$E:$E,日报!$E:$E,合格品出库记录!$A:$A,日报!AX$3),"") | AY15: =IF(SUMIFS(合格品出库记录!$G:$G,合格品出库记录!$E:$E,日报!$E:$E,合格品出库记录!$A:$A,日报!AY$3)<>0,SUMIFS(合格品出库记录!$G:$G,合格品出库记录!$E:$E,日报!$E:$E,合格品出库记录!$A:$A,日报!AY$3),"") | AZ15: =IF(SUMIFS(合格品出库记录!$G:$G,合格品出库记录!$E:$E,日报!$E:$E,合格品出库记录!$A:$A,日报!AZ$3)<>0,SUMIFS(合格品出库记录!$G:$G,合格品出库记录!$E:$E,日报!$E:$E,合格品出库记录!$A:$A,日报!AZ$3),"") | BA15: =IF(SUMIFS(合格品出库记录!$G:$G,合格品出库记录!$E:$E,日报!$E:$E,合格品出库记录!$A:$A,日报!BA$3)<>0,SUMIFS(合格品出库记录!$G:$G,合格品出库记录!$E:$E,日报!$E:$E,合格品出库记录!$A:$A,日报!BA$3),"") | BB15: =IF(SUMIFS(合格品出库记录!$G:$G,合格品出库记录!$E:$E,日报!$E:$E,合格品出库记录!$A:$A,日报!BB$3)<>0,SUMIFS(合格品出库记录!$G:$G,合格品出库记录!$E:$E,日报!$E:$E,合格品出库记录!$A:$A,日报!BB$3),"") | ... BY15: =IF(SUMIFS(合格品出库记录!$G:$G,合格品出库记录!$E:$E,日报!$E:$E,合格品出库记录!$A:$A,日报!BY$3)<>0,SUMIFS(合格品出库记录!$G:$G,合格品出库记录!$E:$E,日报!$E:$E,合格品出库记录!$A:$A,日报!BY$3),"")
A16: 13 | B16: 1DC | C16: 东莞市硅翔绝缘材料有限公司 | D16: F01001000352 | E16: 3.2.49.08.00712-000 | F16: LPT03A-PBP模组CCS总成2-NJ | H16: 0 | I16: =SUMIF(合格品入货记录!E:E,日报!E16,合格品入货记录!G:G) -> 0 | J16: =SUMIF(合格品出库记录!E:E,日报!E16,合格品出库记录!G:G) -> 0 | K16: =H16+I16-J16+L16 -> 0 | L16: =SUMIF(不良品库存!D:D,E:E,不良品库存!F:F) -> 0 | M16: =H16+I16-J16 -> 0 | P16: =IF(SUMIFS(合格品入货记录!$G:$G,合格品入货记录!$E:$E,日报!$E:$E,合格品入货记录!$A:$A,日报!P$3)<>0,SUMIFS(合格品入货记录!$G:$G,合格品入货记录!$E:$E,日报!$E:$E,合格品入货记录!$A:$A,日报!P$3),"") | Q16: =IF(SUMIFS(合格品入货记录!$G:$G,合格品入货记录!$E:$E,日报!$E:$E,合格品入货记录!$A:$A,日报!Q$3)<>0,SUMIFS(合格品入货记录!$G:$G,合格品入货记录!$E:$E,日报!$E:$E,合格品入货记录!$A:$A,日报!Q$3),"") | R16: =IF(SUMIFS(合格品入货记录!$G:$G,合格品入货记录!$E:$E,日报!$E:$E,合格品入货记录!$A:$A,日报!R$3)<>0,SUMIFS(合格品入货记录!$G:$G,合格品入货记录!$E:$E,日报!$E:$E,合格品入货记录!$A:$A,日报!R$3),"") | S16: =IF(SUMIFS(合格品入货记录!$G:$G,合格品入货记录!$E:$E,日报!$E:$E,合格品入货记录!$A:$A,日报!S$3)<>0,SUMIFS(合格品入货记录!$G:$G,合格品入货记录!$E:$E,日报!$E:$E,合格品入货记录!$A:$A,日报!S$3),"") | T16: =IF(SUMIFS(合格品入货记录!$G:$G,合格品入货记录!$E:$E,日报!$E:$E,合格品入货记录!$A:$A,日报!T$3)<>0,SUMIFS(合格品入货记录!$G:$G,合格品入货记录!$E:$E,日报!$E:$E,合格品入货记录!$A:$A,日报!T$3),"") | U16: =IF(SUMIFS(合格品入货记录!$G:$G,合格品入货记录!$E:$E,日报!$E:$E,合格品入货记录!$A:$A,日报!U$3)<>0,SUMIFS(合格品入货记录!$G:$G,合格品入货记录!$E:$E,日报!$E:$E,合格品入货记录!$A:$A,日报!U$3),"") | V16: =IF(SUMIFS(合格品入货记录!$G:$G,合格品入货记录!$E:$E,日报!$E:$E,合格品入货记录!$A:$A,日报!V$3)<>0,SUMIFS(合格品入货记录!$G:$G,合格品入货记录!$E:$E,日报!$E:$E,合格品入货记录!$A:$A,日报!V$3),"") | W16: =IF(SUMIFS(合格品入货记录!$G:$G,合格品入货记录!$E:$E,日报!$E:$E,合格品入货记录!$A:$A,日报!W$3)<>0,SUMIFS(合格品入货记录!$G:$G,合格品入货记录!$E:$E,日报!$E:$E,合格品入货记录!$A:$A,日报!W$3),"") | ... AT16: =IF(SUMIFS(合格品入货记录!$G:$G,合格品入货记录!$E:$E,日报!$E:$E,合格品入货记录!$A:$A,日报!AT$3)<>0,SUMIFS(合格品入货记录!$G:$G,合格品入货记录!$E:$E,日报!$E:$E,合格品入货记录!$A:$A,日报!AT$3),"") | AU16: =IF(SUMIFS(合格品出库记录!$G:$G,合格品出库记录!$E:$E,日报!$E:$E,合格品出库记录!$A:$A,日报!AU$3)<>0,SUMIFS(合格品出库记录!$G:$G,合格品出库记录!$E:$E,日报!$E:$E,合格品出库记录!$A:$A,日报!AU$3),"") | AV16: =IF(SUMIFS(合格品出库记录!$G:$G,合格品出库记录!$E:$E,日报!$E:$E,合格品出库记录!$A:$A,日报!AV$3)<>0,SUMIFS(合格品出库记录!$G:$G,合格品出库记录!$E:$E,日报!$E:$E,合格品出库记录!$A:$A,日报!AV$3),"") | AW16: =IF(SUMIFS(合格品出库记录!$G:$G,合格品出库记录!$E:$E,日报!$E:$E,合格品出库记录!$A:$A,日报!AW$3)<>0,SUMIFS(合格品出库记录!$G:$G,合格品出库记录!$E:$E,日报!$E:$E,合格品出库记录!$A:$A,日报!AW$3),"") | AX16: =IF(SUMIFS(合格品出库记录!$G:$G,合格品出库记录!$E:$E,日报!$E:$E,合格品出库记录!$A:$A,日报!AX$3)<>0,SUMIFS(合格品出库记录!$G:$G,合格品出库记录!$E:$E,日报!$E:$E,合格品出库记录!$A:$A,日报!AX$3),"") | AY16: =IF(SUMIFS(合格品出库记录!$G:$G,合格品出库记录!$E:$E,日报!$E:$E,合格品出库记录!$A:$A,日报!AY$3)<>0,SUMIFS(合格品出库记录!$G:$G,合格品出库记录!$E:$E,日报!$E:$E,合格品出库记录!$A:$A,日报!AY$3),"") | AZ16: =IF(SUMIFS(合格品出库记录!$G:$G,合格品出库记录!$E:$E,日报!$E:$E,合格品出库记录!$A:$A,日报!AZ$3)<>0,SUMIFS(合格品出库记录!$G:$G,合格品出库记录!$E:$E,日报!$E:$E,合格品出库记录!$A:$A,日报!AZ$3),"") | BA16: =IF(SUMIFS(合格品出库记录!$G:$G,合格品出库记录!$E:$E,日报!$E:$E,合格品出库记录!$A:$A,日报!BA$3)<>0,SUMIFS(合格品出库记录!$G:$G,合格品出库记录!$E:$E,日报!$E:$E,合格品出库记录!$A:$A,日报!BA$3),"") | BB16: =IF(SUMIFS(合格品出库记录!$G:$G,合格品出库记录!$E:$E,日报!$E:$E,合格品出库记录!$A:$A,日报!BB$3)<>0,SUMIFS(合格品出库记录!$G:$G,合格品出库记录!$E:$E,日报!$E:$E,合格品出库记录!$A:$A,日报!BB$3),"") | ... BY16: =IF(SUMIFS(合格品出库记录!$G:$G,合格品出库记录!$E:$E,日报!$E:$E,合格品出库记录!$A:$A,日报!BY$3)<>0,SUMIFS(合格品出库记录!$G:$G,合格品出库记录!$E:$E,日报!$E:$E,合格品出库记录!$A:$A,日报!BY$3),"")
A17: 14 | B17: 1DC | C17: 东莞市硅翔绝缘材料有限公司 | D17: F01001000351 | E17: 3.2.49.08.00709-000 | F17: LPT03A-PBP模组CCS总成1-NJ | H17: 42 | I17: =SUMIF(合格品入货记录!E:E,日报!E17,合格品入货记录!G:G) -> 0 | J17: =SUMIF(合格品出库记录!E:E,日报!E17,合格品出库记录!G:G) -> 4 | K17: =H17+I17-J17+L17 -> 38 | L17: =SUMIF(不良品库存!D:D,E:E,不良品库存!F:F) -> 0 | M17: =H17+I17-J17 -> 38 | P17: =IF(SUMIFS(合格品入货记录!$G:$G,合格品入货记录!$E:$E,日报!$E:$E,合格品入货记录!$A:$A,日报!P$3)<>0,SUMIFS(合格品入货记录!$G:$G,合格品入货记录!$E:$E,日报!$E:$E,合格品入货记录!$A:$A,日报!P$3),"") | Q17: =IF(SUMIFS(合格品入货记录!$G:$G,合格品入货记录!$E:$E,日报!$E:$E,合格品入货记录!$A:$A,日报!Q$3)<>0,SUMIFS(合格品入货记录!$G:$G,合格品入货记录!$E:$E,日报!$E:$E,合格品入货记录!$A:$A,日报!Q$3),"") | R17: =IF(SUMIFS(合格品入货记录!$G:$G,合格品入货记录!$E:$E,日报!$E:$E,合格品入货记录!$A:$A,日报!R$3)<>0,SUMIFS(合格品入货记录!$G:$G,合格品入货记录!$E:$E,日报!$E:$E,合格品入货记录!$A:$A,日报!R$3),"") | S17: =IF(SUMIFS(合格品入货记录!$G:$G,合格品入货记录!$E:$E,日报!$E:$E,合格品入货记录!$A:$A,日报!S$3)<>0,SUMIFS(合格品入货记录!$G:$G,合格品入货记录!$E:$E,日报!$E:$E,合格品入货记录!$A:$A,日报!S$3),"") | T17: =IF(SUMIFS(合格品入货记录!$G:$G,合格品入货记录!$E:$E,日报!$E:$E,合格品入货记录!$A:$A,日报!T$3)<>0,SUMIFS(合格品入货记录!$G:$G,合格品入货记录!$E:$E,日报!$E:$E,合格品入货记录!$A:$A,日报!T$3),"") | U17: =IF(SUMIFS(合格品入货记录!$G:$G,合格品入货记录!$E:$E,日报!$E:$E,合格品入货记录!$A:$A,日报!U$3)<>0,SUMIFS(合格品入货记录!$G:$G,合格品入货记录!$E:$E,日报!$E:$E,合格品入货记录!$A:$A,日报!U$3),"") | V17: =IF(SUMIFS(合格品入货记录!$G:$G,合格品入货记录!$E:$E,日报!$E:$E,合格品入货记录!$A:$A,日报!V$3)<>0,SUMIFS(合格品入货记录!$G:$G,合格品入货记录!$E:$E,日报!$E:$E,合格品入货记录!$A:$A,日报!V$3),"") | W17: =IF(SUMIFS(合格品入货记录!$G:$G,合格品入货记录!$E:$E,日报!$E:$E,合格品入货记录!$A:$A,日报!W$3)<>0,SUMIFS(合格品入货记录!$G:$G,合格品入货记录!$E:$E,日报!$E:$E,合格品入货记录!$A:$A,日报!W$3),"") | ... AT17: =IF(SUMIFS(合格品入货记录!$G:$G,合格品入货记录!$E:$E,日报!$E:$E,合格品入货记录!$A:$A,日报!AT$3)<>0,SUMIFS(合格品入货记录!$G:$G,合格品入货记录!$E:$E,日报!$E:$E,合格品入货记录!$A:$A,日报!AT$3),"") | AU17: =IF(SUMIFS(合格品出库记录!$G:$G,合格品出库记录!$E:$E,日报!$E:$E,合格品出库记录!$A:$A,日报!AU$3)<>0,SUMIFS(合格品出库记录!$G:$G,合格品出库记录!$E:$E,日报!$E:$E,合格品出库记录!$A:$A,日报!AU$3),"") | AV17: =IF(SUMIFS(合格品出库记录!$G:$G,合格品出库记录!$E:$E,日报!$E:$E,合格品出库记录!$A:$A,日报!AV$3)<>0,SUMIFS(合格品出库记录!$G:$G,合格品出库记录!$E:$E,日报!$E:$E,合格品出库记录!$A:$A,日报!AV$3),"") | AW17: =IF(SUMIFS(合格品出库记录!$G:$G,合格品出库记录!$E:$E,日报!$E:$E,合格品出库记录!$A:$A,日报!AW$3)<>0,SUMIFS(合格品出库记录!$G:$G,合格品出库记录!$E:$E,日报!$E:$E,合格品出库记录!$A:$A,日报!AW$3),"") | AX17: =IF(SUMIFS(合格品出库记录!$G:$G,合格品出库记录!$E:$E,日报!$E:$E,合格品出库记录!$A:$A,日报!AX$3)<>0,SUMIFS(合格品出库记录!$G:$G,合格品出库记录!$E:$E,日报!$E:$E,合格品出库记录!$A:$A,日报!AX$3),"") | AY17: =IF(SUMIFS(合格品出库记录!$G:$G,合格品出库记录!$E:$E,日报!$E:$E,合格品出库记录!$A:$A,日报!AY$3)<>0,SUMIFS(合格品出库记录!$G:$G,合格品出库记录!$E:$E,日报!$E:$E,合格品出库记录!$A:$A,日报!AY$3),"") | AZ17: =IF(SUMIFS(合格品出库记录!$G:$G,合格品出库记录!$E:$E,日报!$E:$E,合格品出库记录!$A:$A,日报!AZ$3)<>0,SUMIFS(合格品出库记录!$G:$G,合格品出库记录!$E:$E,日报!$E:$E,合格品出库记录!$A:$A,日报!AZ$3),"") -> 4 | BA17: =IF(SUMIFS(合格品出库记录!$G:$G,合格品出库记录!$E:$E,日报!$E:$E,合格品出库记录!$A:$A,日报!BA$3)<>0,SUMIFS(合格品出库记录!$G:$G,合格品出库记录!$E:$E,日报!$E:$E,合格品出库记录!$A:$A,日报!BA$3),"") | BB17: =IF(SUMIFS(合格品出库记录!$G:$G,合格品出库记录!$E:$E,日报!$E:$E,合格品出库记录!$A:$A,日报!BB$3)<>0,SUMIFS(合格品出库记录!$G:$G,合格品出库记录!$E:$E,日报!$E:$E,合格品出库记录!$A:$A,日报!BB$3),"") | ... BY17: =IF(SUMIFS(合格品出库记录!$G:$G,合格品出库记录!$E:$E,日报!$E:$E,合格品出库记录!$A:$A,日报!BY$3)<>0,SUMIFS(合格品出库记录!$G:$G,合格品出库记录!$E:$E,日报!$E:$E,合格品出库记录!$A:$A,日报!BY$3),"")
A18: 15 | B18: 1DC | C18: 东莞市硅翔绝缘材料有限公司 | D18: F02001000538 | E18: 3.2.49.08.00661-000 | F18: LPT03A_PBP_32S加热片_L | H18: 19 | I18: =SUMIF(合格品入货记录!E:E,日报!E18,合格品入货记录!G:G) -> 0 | J18: =SUMIF(合格品出库记录!E:E,日报!E18,合格品出库记录!G:G) -> 6 | K18: =H18+I18-J18+L18 -> 13 | L18: =SUMIF(不良品库存!D:D,E:E,不良品库存!F:F) -> 0 | M18: =H18+I18-J18 -> 13 | P18: =IF(SUMIFS(合格品入货记录!$G:$G,合格品入货记录!$E:$E,日报!$E:$E,合格品入货记录!$A:$A,日报!P$3)<>0,SUMIFS(合格品入货记录!$G:$G,合格品入货记录!$E:$E,日报!$E:$E,合格品入货记录!$A:$A,日报!P$3),"") | Q18: =IF(SUMIFS(合格品入货记录!$G:$G,合格品入货记录!$E:$E,日报!$E:$E,合格品入货记录!$A:$A,日报!Q$3)<>0,SUMIFS(合格品入货记录!$G:$G,合格品入货记录!$E:$E,日报!$E:$E,合格品入货记录!$A:$A,日报!Q$3),"") | R18: =IF(SUMIFS(合格品入货记录!$G:$G,合格品入货记录!$E:$E,日报!$E:$E,合格品入货记录!$A:$A,日报!R$3)<>0,SUMIFS(合格品入货记录!$G:$G,合格品入货记录!$E:$E,日报!$E:$E,合格品入货记录!$A:$A,日报!R$3),"") | S18: =IF(SUMIFS(合格品入货记录!$G:$G,合格品入货记录!$E:$E,日报!$E:$E,合格品入货记录!$A:$A,日报!S$3)<>0,SUMIFS(合格品入货记录!$G:$G,合格品入货记录!$E:$E,日报!$E:$E,合格品入货记录!$A:$A,日报!S$3),"") | T18: =IF(SUMIFS(合格品入货记录!$G:$G,合格品入货记录!$E:$E,日报!$E:$E,合格品入货记录!$A:$A,日报!T$3)<>0,SUMIFS(合格品入货记录!$G:$G,合格品入货记录!$E:$E,日报!$E:$E,合格品入货记录!$A:$A,日报!T$3),"") | U18: =IF(SUMIFS(合格品入货记录!$G:$G,合格品入货记录!$E:$E,日报!$E:$E,合格品入货记录!$A:$A,日报!U$3)<>0,SUMIFS(合格品入货记录!$G:$G,合格品入货记录!$E:$E,日报!$E:$E,合格品入货记录!$A:$A,日报!U$3),"") | V18: =IF(SUMIFS(合格品入货记录!$G:$G,合格品入货记录!$E:$E,日报!$E:$E,合格品入货记录!$A:$A,日报!V$3)<>0,SUMIFS(合格品入货记录!$G:$G,合格品入货记录!$E:$E,日报!$E:$E,合格品入货记录!$A:$A,日报!V$3),"") | W18: =IF(SUMIFS(合格品入货记录!$G:$G,合格品入货记录!$E:$E,日报!$E:$E,合格品入货记录!$A:$A,日报!W$3)<>0,SUMIFS(合格品入货记录!$G:$G,合格品入货记录!$E:$E,日报!$E:$E,合格品入货记录!$A:$A,日报!W$3),"") | ... AT18: =IF(SUMIFS(合格品入货记录!$G:$G,合格品入货记录!$E:$E,日报!$E:$E,合格品入货记录!$A:$A,日报!AT$3)<>0,SUMIFS(合格品入货记录!$G:$G,合格品入货记录!$E:$E,日报!$E:$E,合格品入货记录!$A:$A,日报!AT$3),"") | AU18: =IF(SUMIFS(合格品出库记录!$G:$G,合格品出库记录!$E:$E,日报!$E:$E,合格品出库记录!$A:$A,日报!AU$3)<>0,SUMIFS(合格品出库记录!$G:$G,合格品出库记录!$E:$E,日报!$E:$E,合格品出库记录!$A:$A,日报!AU$3),"") | AV18: =IF(SUMIFS(合格品出库记录!$G:$G,合格品出库记录!$E:$E,日报!$E:$E,合格品出库记录!$A:$A,日报!AV$3)<>0,SUMIFS(合格品出库记录!$G:$G,合格品出库记录!$E:$E,日报!$E:$E,合格品出库记录!$A:$A,日报!AV$3),"") | AW18: =IF(SUMIFS(合格品出库记录!$G:$G,合格品出库记录!$E:$E,日报!$E:$E,合格品出库记录!$A:$A,日报!AW$3)<>0,SUMIFS(合格品出库记录!$G:$G,合格品出库记录!$E:$E,日报!$E:$E,合格品出库记录!$A:$A,日报!AW$3),"") | AX18: =IF(SUMIFS(合格品出库记录!$G:$G,合格品出库记录!$E:$E,日报!$E:$E,合格品出库记录!$A:$A,日报!AX$3)<>0,SUMIFS(合格品出库记录!$G:$G,合格品出库记录!$E:$E,日报!$E:$E,合格品出库记录!$A:$A,日报!AX$3),"") | AY18: =IF(SUMIFS(合格品出库记录!$G:$G,合格品出库记录!$E:$E,日报!$E:$E,合格品出库记录!$A:$A,日报!AY$3)<>0,SUMIFS(合格品出库记录!$G:$G,合格品出库记录!$E:$E,日报!$E:$E,合格品出库记录!$A:$A,日报!AY$3),"") | AZ18: =IF(SUMIFS(合格品出库记录!$G:$G,合格品出库记录!$E:$E,日报!$E:$E,合格品出库记录!$A:$A,日报!AZ$3)<>0,SUMIFS(合格品出库记录!$G:$G,合格品出库记录!$E:$E,日报!$E:$E,合格品出库记录!$A:$A,日报!AZ$3),"") | BA18: =IF(SUMIFS(合格品出库记录!$G:$G,合格品出库记录!$E:$E,日报!$E:$E,合格品出库记录!$A:$A,日报!BA$3)<>0,SUMIFS(合格品出库记录!$G:$G,合格品出库记录!$E:$E,日报!$E:$E,合格品出库记录!$A:$A,日报!BA$3),"") | BB18: =IF(SUMIFS(合格品出库记录!$G:$G,合格品出库记录!$E:$E,日报!$E:$E,合格品出库记录!$A:$A,日报!BB$3)<>0,SUMIFS(合格品出库记录!$G:$G,合格品出库记录!$E:$E,日报!$E:$E,合格品出库记录!$A:$A,日报!BB$3),"") | ... BY18: =IF(SUMIFS(合格品出库记录!$G:$G,合格品出库记录!$E:$E,日报!$E:$E,合格品出库记录!$A:$A,日报!BY$3)<>0,SUMIFS(合格品出库记录!$G:$G,合格品出库记录!$E:$E,日报!$E:$E,合格品出库记录!$A:$A,日报!BY$3),"")
A19: 16 | B19: 1DC | C19: 东莞市硅翔绝缘材料有限公司 | D19: F02001000539 | E19: 3.2.49.08.00662-000 | F19: LPT03A_PBP_32S加热片_R | H19: 19 | I19: =SUMIF(合格品入货记录!E:E,日报!E19,合格品入货记录!G:G) -> 0 | J19: =SUMIF(合格品出库记录!E:E,日报!E19,合格品出库记录!G:G) -> 6 | K19: =H19+I19-J19+L19 -> 13 | L19: =SUMIF(不良品库存!D:D,E:E,不良品库存!F:F) -> 0 | M19: =H19+I19-J19 -> 13 | P19: =IF(SUMIFS(合格品入货记录!$G:$G,合格品入货记录!$E:$E,日报!$E:$E,合格品入货记录!$A:$A,日报!P$3)<>0,SUMIFS(合格品入货记录!$G:$G,合格品入货记录!$E:$E,日报!$E:$E,合格品入货记录!$A:$A,日报!P$3),"") | Q19: =IF(SUMIFS(合格品入货记录!$G:$G,合格品入货记录!$E:$E,日报!$E:$E,合格品入货记录!$A:$A,日报!Q$3)<>0,SUMIFS(合格品入货记录!$G:$G,合格品入货记录!$E:$E,日报!$E:$E,合格品入货记录!$A:$A,日报!Q$3),"") | R19: =IF(SUMIFS(合格品入货记录!$G:$G,合格品入货记录!$E:$E,日报!$E:$E,合格品入货记录!$A:$A,日报!R$3)<>0,SUMIFS(合格品入货记录!$G:$G,合格品入货记录!$E:$E,日报!$E:$E,合格品入货记录!$A:$A,日报!R$3),"") | S19: =IF(SUMIFS(合格品入货记录!$G:$G,合格品入货记录!$E:$E,日报!$E:$E,合格品入货记录!$A:$A,日报!S$3)<>0,SUMIFS(合格品入货记录!$G:$G,合格品入货记录!$E:$E,日报!$E:$E,合格品入货记录!$A:$A,日报!S$3),"") | T19: =IF(SUMIFS(合格品入货记录!$G:$G,合格品入货记录!$E:$E,日报!$E:$E,合格品入货记录!$A:$A,日报!T$3)<>0,SUMIFS(合格品入货记录!$G:$G,合格品入货记录!$E:$E,日报!$E:$E,合格品入货记录!$A:$A,日报!T$3),"") | U19: =IF(SUMIFS(合格品入货记录!$G:$G,合格品入货记录!$E:$E,日报!$E:$E,合格品入货记录!$A:$A,日报!U$3)<>0,SUMIFS(合格品入货记录!$G:$G,合格品入货记录!$E:$E,日报!$E:$E,合格品入货记录!$A:$A,日报!U$3),"") | V19: =IF(SUMIFS(合格品入货记录!$G:$G,合格品入货记录!$E:$E,日报!$E:$E,合格品入货记录!$A:$A,日报!V$3)<>0,SUMIFS(合格品入货记录!$G:$G,合格品入货记录!$E:$E,日报!$E:$E,合格品入货记录!$A:$A,日报!V$3),"") | W19: =IF(SUMIFS(合格品入货记录!$G:$G,合格品入货记录!$E:$E,日报!$E:$E,合格品入货记录!$A:$A,日报!W$3)<>0,SUMIFS(合格品入货记录!$G:$G,合格品入货记录!$E:$E,日报!$E:$E,合格品入货记录!$A:$A,日报!W$3),"") | ... AT19: =IF(SUMIFS(合格品入货记录!$G:$G,合格品入货记录!$E:$E,日报!$E:$E,合格品入货记录!$A:$A,日报!AT$3)<>0,SUMIFS(合格品入货记录!$G:$G,合格品入货记录!$E:$E,日报!$E:$E,合格品入货记录!$A:$A,日报!AT$3),"") | AU19: =IF(SUMIFS(合格品出库记录!$G:$G,合格品出库记录!$E:$E,日报!$E:$E,合格品出库记录!$A:$A,日报!AU$3)<>0,SUMIFS(合格品出库记录!$G:$G,合格品出库记录!$E:$E,日报!$E:$E,合格品出库记录!$A:$A,日报!AU$3),"") | AV19: =IF(SUMIFS(合格品出库记录!$G:$G,合格品出库记录!$E:$E,日报!$E:$E,合格品出库记录!$A:$A,日报!AV$3)<>0,SUMIFS(合格品出库记录!$G:$G,合格品出库记录!$E:$E,日报!$E:$E,合格品出库记录!$A:$A,日报!AV$3),"") | AW19: =IF(SUMIFS(合格品出库记录!$G:$G,合格品出库记录!$E:$E,日报!$E:$E,合格品出库记录!$A:$A,日报!AW$3)<>0,SUMIFS(合格品出库记录!$G:$G,合格品出库记录!$E:$E,日报!$E:$E,合格品出库记录!$A:$A,日报!AW$3),"") | AX19: =IF(SUMIFS(合格品出库记录!$G:$G,合格品出库记录!$E:$E,日报!$E:$E,合格品出库记录!$A:$A,日报!AX$3)<>0,SUMIFS(合格品出库记录!$G:$G,合格品出库记录!$E:$E,日报!$E:$E,合格品出库记录!$A:$A,日报!AX$3),"") | AY19: =IF(SUMIFS(合格品出库记录!$G:$G,合格品出库记录!$E:$E,日报!$E:$E,合格品出库记录!$A:$A,日报!AY$3)<>0,SUMIFS(合格品出库记录!$G:$G,合格品出库记录!$E:$E,日报!$E:$E,合格品出库记录!$A:$A,日报!AY$3),"") | AZ19: =IF(SUMIFS(合格品出库记录!$G:$G,合格品出库记录!$E:$E,日报!$E:$E,合格品出库记录!$A:$A,日报!AZ$3)<>0,SUMIFS(合格品出库记录!$G:$G,合格品出库记录!$E:$E,日报!$E:$E,合格品出库记录!$A:$A,日报!AZ$3),"") | BA19: =IF(SUMIFS(合格品出库记录!$G:$G,合格品出库记录!$E:$E,日报!$E:$E,合格品出库记录!$A:$A,日报!BA$3)<>0,SUMIFS(合格品出库记录!$G:$G,合格品出库记录!$E:$E,日报!$E:$E,合格品出库记录!$A:$A,日报!BA$3),"") | BB19: =IF(SUMIFS(合格品出库记录!$G:$G,合格品出库记录!$E:$E,日报!$E:$E,合格品出库记录!$A:$A,日报!BB$3)<>0,SUMIFS(合格品出库记录!$G:$G,合格品出库记录!$E:$E,日报!$E:$E,合格品出库记录!$A:$A,日报!BB$3),"") | ... BY19: =IF(SUMIFS(合格品出库记录!$G:$G,合格品出库记录!$E:$E,日报!$E:$E,合格品出库记录!$A:$A,日报!BY$3)<>0,SUMIFS(合格品出库记录!$G:$G,合格品出库记录!$E:$E,日报!$E:$E,合格品出库记录!$A:$A,日报!BY$3),"")
A20: 17 | B20: 1DC | C20: 东莞市硅翔绝缘材料有限公司 | D20: F02001000528 | E20: 3.2.49.08.00514-000 | F20: LPT03A_PBP-RP加热片-R | H20: 0 | I20: =SUMIF(合格品入货记录!E:E,日报!E20,合格品入货记录!G:G) -> 0 | J20: =SUMIF(合格品出库记录!E:E,日报!E20,合格品出库记录!G:G) -> 0 | K20: =H20+I20-J20+L20 -> 0 | L20: =SUMIF(不良品库存!D:D,E:E,不良品库存!F:F) -> 0 | M20: =H20+I20-J20 -> 0 | P20: =IF(SUMIFS(合格品入货记录!$G:$G,合格品入货记录!$E:$E,日报!$E:$E,合格品入货记录!$A:$A,日报!P$3)<>0,SUMIFS(合格品入货记录!$G:$G,合格品入货记录!$E:$E,日报!$E:$E,合格品入货记录!$A:$A,日报!P$3),"") | Q20: =IF(SUMIFS(合格品入货记录!$G:$G,合格品入货记录!$E:$E,日报!$E:$E,合格品入货记录!$A:$A,日报!Q$3)<>0,SUMIFS(合格品入货记录!$G:$G,合格品入货记录!$E:$E,日报!$E:$E,合格品入货记录!$A:$A,日报!Q$3),"") | R20: =IF(SUMIFS(合格品入货记录!$G:$G,合格品入货记录!$E:$E,日报!$E:$E,合格品入货记录!$A:$A,日报!R$3)<>0,SUMIFS(合格品入货记录!$G:$G,合格品入货记录!$E:$E,日报!$E:$E,合格品入货记录!$A:$A,日报!R$3),"") | S20: =IF(SUMIFS(合格品入货记录!$G:$G,合格品入货记录!$E:$E,日报!$E:$E,合格品入货记录!$A:$A,日报!S$3)<>0,SUMIFS(合格品入货记录!$G:$G,合格品入货记录!$E:$E,日报!$E:$E,合格品入货记录!$A:$A,日报!S$3),"") | T20: =IF(SUMIFS(合格品入货记录!$G:$G,合格品入货记录!$E:$E,日报!$E:$E,合格品入货记录!$A:$A,日报!T$3)<>0,SUMIFS(合格品入货记录!$G:$G,合格品入货记录!$E:$E,日报!$E:$E,合格品入货记录!$A:$A,日报!T$3),"") | U20: =IF(SUMIFS(合格品入货记录!$G:$G,合格品入货记录!$E:$E,日报!$E:$E,合格品入货记录!$A:$A,日报!U$3)<>0,SUMIFS(合格品入货记录!$G:$G,合格品入货记录!$E:$E,日报!$E:$E,合格品入货记录!$A:$A,日报!U$3),"") | V20: =IF(SUMIFS(合格品入货记录!$G:$G,合格品入货记录!$E:$E,日报!$E:$E,合格品入货记录!$A:$A,日报!V$3)<>0,SUMIFS(合格品入货记录!$G:$G,合格品入货记录!$E:$E,日报!$E:$E,合格品入货记录!$A:$A,日报!V$3),"") | W20: =IF(SUMIFS(合格品入货记录!$G:$G,合格品入货记录!$E:$E,日报!$E:$E,合格品入货记录!$A:$A,日报!W$3)<>0,SUMIFS(合格品入货记录!$G:$G,合格品入货记录!$E:$E,日报!$E:$E,合格品入货记录!$A:$A,日报!W$3),"") | ... AT20: =IF(SUMIFS(合格品入货记录!$G:$G,合格品入货记录!$E:$E,日报!$E:$E,合格品入货记录!$A:$A,日报!AT$3)<>0,SUMIFS(合格品入货记录!$G:$G,合格品入货记录!$E:$E,日报!$E:$E,合格品入货记录!$A:$A,日报!AT$3),"") | AU20: =IF(SUMIFS(合格品出库记录!$G:$G,合格品出库记录!$E:$E,日报!$E:$E,合格品出库记录!$A:$A,日报!AU$3)<>0,SUMIFS(合格品出库记录!$G:$G,合格品出库记录!$E:$E,日报!$E:$E,合格品出库记录!$A:$A,日报!AU$3),"") | AV20: =IF(SUMIFS(合格品出库记录!$G:$G,合格品出库记录!$E:$E,日报!$E:$E,合格品出库记录!$A:$A,日报!AV$3)<>0,SUMIFS(合格品出库记录!$G:$G,合格品出库记录!$E:$E,日报!$E:$E,合格品出库记录!$A:$A,日报!AV$3),"") | AW20: =IF(SUMIFS(合格品出库记录!$G:$G,合格品出库记录!$E:$E,日报!$E:$E,合格品出库记录!$A:$A,日报!AW$3)<>0,SUMIFS(合格品出库记录!$G:$G,合格品出库记录!$E:$E,日报!$E:$E,合格品出库记录!$A:$A,日报!AW$3),"") | AX20: =IF(SUMIFS(合格品出库记录!$G:$G,合格品出库记录!$E:$E,日报!$E:$E,合格品出库记录!$A:$A,日报!AX$3)<>0,SUMIFS(合格品出库记录!$G:$G,合格品出库记录!$E:$E,日报!$E:$E,合格品出库记录!$A:$A,日报!AX$3),"") | AY20: =IF(SUMIFS(合格品出库记录!$G:$G,合格品出库记录!$E:$E,日报!$E:$E,合格品出库记录!$A:$A,日报!AY$3)<>0,SUMIFS(合格品出库记录!$G:$G,合格品出库记录!$E:$E,日报!$E:$E,合格品出库记录!$A:$A,日报!AY$3),"") | AZ20: =IF(SUMIFS(合格品出库记录!$G:$G,合格品出库记录!$E:$E,日报!$E:$E,合格品出库记录!$A:$A,日报!AZ$3)<>0,SUMIFS(合格品出库记录!$G:$G,合格品出库记录!$E:$E,日报!$E:$E,合格品出库记录!$A:$A,日报!AZ$3),"") | BA20: =IF(SUMIFS(合格品出库记录!$G:$G,合格品出库记录!$E:$E,日报!$E:$E,合格品出库记录!$A:$A,日报!BA$3)<>0,SUMIFS(合格品出库记录!$G:$G,合格品出库记录!$E:$E,日报!$E:$E,合格品出库记录!$A:$A,日报!BA$3),"") | BB20: =IF(SUMIFS(合格品出库记录!$G:$G,合格品出库记录!$E:$E,日报!$E:$E,合格品出库记录!$A:$A,日报!BB$3)<>0,SUMIFS(合格品出库记录!$G:$G,合格品出库记录!$E:$E,日报!$E:$E,合格品出库记录!$A:$A,日报!BB$3),"") | ... BY20: =IF(SUMIFS(合格品出库记录!$G:$G,合格品出库记录!$E:$E,日报!$E:$E,合格品出库记录!$A:$A,日报!BY$3)<>0,SUMIFS(合格品出库记录!$G:$G,合格品出库记录!$E:$E,日报!$E:$E,合格品出库记录!$A:$A,日报!BY$3),"")
... A70: 68 | B70: 1DC | C70: 东莞市硅翔绝缘材料有限公司 | D70: F01001002817 | E70: 3.1.02.30.01301 | F70: LXC10EV10C-CCS-B | H70: 76 | I70: =SUMIF(合格品入货记录!E:E,日报!E70,合格品入货记录!G:G) -> 0 | J70: =SUMIF(合格品出库记录!E:E,日报!E70,合格品出库记录!G:G) -> 0 | K70: =H70+I70-J70+L70 -> 76 | L70: =SUMIF(不良品库存!D:D,E:E,不良品库存!F:F) -> 0 | M70: =H70+I70-J70 -> 76 | P70: =IF(SUMIFS(合格品入货记录!$G:$G,合格品入货记录!$E:$E,日报!$E:$E,合格品入货记录!$A:$A,日报!P$3)<>0,SUMIFS(合格品入货记录!$G:$G,合格品入货记录!$E:$E,日报!$E:$E,合格品入货记录!$A:$A,日报!P$3),"") | Q70: =IF(SUMIFS(合格品入货记录!$G:$G,合格品入货记录!$E:$E,日报!$E:$E,合格品入货记录!$A:$A,日报!Q$3)<>0,SUMIFS(合格品入货记录!$G:$G,合格品入货记录!$E:$E,日报!$E:$E,合格品入货记录!$A:$A,日报!Q$3),"") | R70: =IF(SUMIFS(合格品入货记录!$G:$G,合格品入货记录!$E:$E,日报!$E:$E,合格品入货记录!$A:$A,日报!R$3)<>0,SUMIFS(合格品入货记录!$G:$G,合格品入货记录!$E:$E,日报!$E:$E,合格品入货记录!$A:$A,日报!R$3),"") | S70: =IF(SUMIFS(合格品入货记录!$G:$G,合格品入货记录!$E:$E,日报!$E:$E,合格品入货记录!$A:$A,日报!S$3)<>0,SUMIFS(合格品入货记录!$G:$G,合格品入货记录!$E:$E,日报!$E:$E,合格品入货记录!$A:$A,日报!S$3),"") | T70: =IF(SUMIFS(合格品入货记录!$G:$G,合格品入货记录!$E:$E,日报!$E:$E,合格品入货记录!$A:$A,日报!T$3)<>0,SUMIFS(合格品入货记录!$G:$G,合格品入货记录!$E:$E,日报!$E:$E,合格品入货记录!$A:$A,日报!T$3),"") | U70: =IF(SUMIFS(合格品入货记录!$G:$G,合格品入货记录!$E:$E,日报!$E:$E,合格品入货记录!$A:$A,日报!U$3)<>0,SUMIFS(合格品入货记录!$G:$G,合格品入货记录!$E:$E,日报!$E:$E,合格品入货记录!$A:$A,日报!U$3),"") | V70: =IF(SUMIFS(合格品入货记录!$G:$G,合格品入货记录!$E:$E,日报!$E:$E,合格品入货记录!$A:$A,日报!V$3)<>0,SUMIFS(合格品入货记录!$G:$G,合格品入货记录!$E:$E,日报!$E:$E,合格品入货记录!$A:$A,日报!V$3),"") | W70: =IF(SUMIFS(合格品入货记录!$G:$G,合格品入货记录!$E:$E,日报!$E:$E,合格品入货记录!$A:$A,日报!W$3)<>0,SUMIFS(合格品入货记录!$G:$G,合格品入货记录!$E:$E,日报!$E:$E,合格品入货记录!$A:$A,日报!W$3),"") | ... AT70: =IF(SUMIFS(合格品入货记录!$G:$G,合格品入货记录!$E:$E,日报!$E:$E,合格品入货记录!$A:$A,日报!AT$3)<>0,SUMIFS(合格品入货记录!$G:$G,合格品入货记录!$E:$E,日报!$E:$E,合格品入货记录!$A:$A,日报!AT$3),"") | AU70: =IF(SUMIFS(合格品出库记录!$G:$G,合格品出库记录!$E:$E,日报!$E:$E,合格品出库记录!$A:$A,日报!AU$3)<>0,SUMIFS(合格品出库记录!$G:$G,合格品出库记录!$E:$E,日报!$E:$E,合格品出库记录!$A:$A,日报!AU$3),"") | AV70: =IF(SUMIFS(合格品出库记录!$G:$G,合格品出库记录!$E:$E,日报!$E:$E,合格品出库记录!$A:$A,日报!AV$3)<>0,SUMIFS(合格品出库记录!$G:$G,合格品出库记录!$E:$E,日报!$E:$E,合格品出库记录!$A:$A,日报!AV$3),"") | AW70: =IF(SUMIFS(合格品出库记录!$G:$G,合格品出库记录!$E:$E,日报!$E:$E,合格品出库记录!$A:$A,日报!AW$3)<>0,SUMIFS(合格品出库记录!$G:$G,合格品出库记录!$E:$E,日报!$E:$E,合格品出库记录!$A:$A,日报!AW$3),"") | AX70: =IF(SUMIFS(合格品出库记录!$G:$G,合格品出库记录!$E:$E,日报!$E:$E,合格品出库记录!$A:$A,日报!AX$3)<>0,SUMIFS(合格品出库记录!$G:$G,合格品出库记录!$E:$E,日报!$E:$E,合格品出库记录!$A:$A,日报!AX$3),"") | AY70: =IF(SUMIFS(合格品出库记录!$G:$G,合格品出库记录!$E:$E,日报!$E:$E,合格品出库记录!$A:$A,日报!AY$3)<>0,SUMIFS(合格品出库记录!$G:$G,合格品出库记录!$E:$E,日报!$E:$E,合格品出库记录!$A:$A,日报!AY$3),"") | AZ70: =IF(SUMIFS(合格品出库记录!$G:$G,合格品出库记录!$E:$E,日报!$E:$E,合格品出库记录!$A:$A,日报!AZ$3)<>0,SUMIFS(合格品出库记录!$G:$G,合格品出库记录!$E:$E,日报!$E:$E,合格品出库记录!$A:$A,日报!AZ$3),"") | BA70: =IF(SUMIFS(合格品出库记录!$G:$G,合格品出库记录!$E:$E,日报!$E:$E,合格品出库记录!$A:$A,日报!BA$3)<>0,SUMIFS(合格品出库记录!$G:$G,合格品出库记录!$E:$E,日报!$E:$E,合格品出库记录!$A:$A,日报!BA$3),"") | BB70: =IF(SUMIFS(合格品出库记录!$G:$G,合格品出库记录!$E:$E,日报!$E:$E,合格品出库记录!$A:$A,日报!BB$3)<>0,SUMIFS(合格品出库记录!$G:$G,合格品出库记录!$E:$E,日报!$E:$E,合格品出库记录!$A:$A,日报!BB$3),"") | ... BY70: =IF(SUMIFS(合格品出库记录!$G:$G,合格品出库记录!$E:$E,日报!$E:$E,合格品出库记录!$A:$A,日报!BY$3)<>0,SUMIFS(合格品出库记录!$G:$G,合格品出库记录!$E:$E,日报!$E:$E,合格品出库记录!$A:$A,日报!BY$3),"")
A71: 69 | B71: 1DC | C71: 东莞市硅翔绝缘材料有限公司 | D71: F01001002784 | E71: 3.1.02.30.01290 | F71: LXB11RE10A-CCS | H71: 144 | I71: =SUMIF(合格品入货记录!E:E,日报!E71,合格品入货记录!G:G) -> 0 | J71: =SUMIF(合格品出库记录!E:E,日报!E71,合格品出库记录!G:G) -> 0 | K71: =H71+I71-J71+L71 -> 144 | L71: =SUMIF(不良品库存!D:D,E:E,不良品库存!F:F) -> 0 | M71: =H71+I71-J71 -> 144 | P71: =IF(SUMIFS(合格品入货记录!$G:$G,合格品入货记录!$E:$E,日报!$E:$E,合格品入货记录!$A:$A,日报!P$3)<>0,SUMIFS(合格品入货记录!$G:$G,合格品入货记录!$E:$E,日报!$E:$E,合格品入货记录!$A:$A,日报!P$3),"") | Q71: =IF(SUMIFS(合格品入货记录!$G:$G,合格品入货记录!$E:$E,日报!$E:$E,合格品入货记录!$A:$A,日报!Q$3)<>0,SUMIFS(合格品入货记录!$G:$G,合格品入货记录!$E:$E,日报!$E:$E,合格品入货记录!$A:$A,日报!Q$3),"") | R71: =IF(SUMIFS(合格品入货记录!$G:$G,合格品入货记录!$E:$E,日报!$E:$E,合格品入货记录!$A:$A,日报!R$3)<>0,SUMIFS(合格品入货记录!$G:$G,合格品入货记录!$E:$E,日报!$E:$E,合格品入货记录!$A:$A,日报!R$3),"") | S71: =IF(SUMIFS(合格品入货记录!$G:$G,合格品入货记录!$E:$E,日报!$E:$E,合格品入货记录!$A:$A,日报!S$3)<>0,SUMIFS(合格品入货记录!$G:$G,合格品入货记录!$E:$E,日报!$E:$E,合格品入货记录!$A:$A,日报!S$3),"") | T71: =IF(SUMIFS(合格品入货记录!$G:$G,合格品入货记录!$E:$E,日报!$E:$E,合格品入货记录!$A:$A,日报!T$3)<>0,SUMIFS(合格品入货记录!$G:$G,合格品入货记录!$E:$E,日报!$E:$E,合格品入货记录!$A:$A,日报!T$3),"") | U71: =IF(SUMIFS(合格品入货记录!$G:$G,合格品入货记录!$E:$E,日报!$E:$E,合格品入货记录!$A:$A,日报!U$3)<>0,SUMIFS(合格品入货记录!$G:$G,合格品入货记录!$E:$E,日报!$E:$E,合格品入货记录!$A:$A,日报!U$3),"") | V71: =IF(SUMIFS(合格品入货记录!$G:$G,合格品入货记录!$E:$E,日报!$E:$E,合格品入货记录!$A:$A,日报!V$3)<>0,SUMIFS(合格品入货记录!$G:$G,合格品入货记录!$E:$E,日报!$E:$E,合格品入货记录!$A:$A,日报!V$3),"") | W71: =IF(SUMIFS(合格品入货记录!$G:$G,合格品入货记录!$E:$E,日报!$E:$E,合格品入货记录!$A:$A,日报!W$3)<>0,SUMIFS(合格品入货记录!$G:$G,合格品入货记录!$E:$E,日报!$E:$E,合格品入货记录!$A:$A,日报!W$3),"") | ... AT71: =IF(SUMIFS(合格品入货记录!$G:$G,合格品入货记录!$E:$E,日报!$E:$E,合格品入货记录!$A:$A,日报!AT$3)<>0,SUMIFS(合格品入货记录!$G:$G,合格品入货记录!$E:$E,日报!$E:$E,合格品入货记录!$A:$A,日报!AT$3),"") | AU71: =IF(SUMIFS(合格品出库记录!$G:$G,合格品出库记录!$E:$E,日报!$E:$E,合格品出库记录!$A:$A,日报!AU$3)<>0,SUMIFS(合格品出库记录!$G:$G,合格品出库记录!$E:$E,日报!$E:$E,合格品出库记录!$A:$A,日报!AU$3),"") | AV71: =IF(SUMIFS(合格品出库记录!$G:$G,合格品出库记录!$E:$E,日报!$E:$E,合格品出库记录!$A:$A,日报!AV$3)<>0,SUMIFS(合格品出库记录!$G:$G,合格品出库记录!$E:$E,日报!$E:$E,合格品出库记录!$A:$A,日报!AV$3),"") | AW71: =IF(SUMIFS(合格品出库记录!$G:$G,合格品出库记录!$E:$E,日报!$E:$E,合格品出库记录!$A:$A,日报!AW$3)<>0,SUMIFS(合格品出库记录!$G:$G,合格品出库记录!$E:$E,日报!$E:$E,合格品出库记录!$A:$A,日报!AW$3),"") | AX71: =IF(SUMIFS(合格品出库记录!$G:$G,合格品出库记录!$E:$E,日报!$E:$E,合格品出库记录!$A:$A,日报!AX$3)<>0,SUMIFS(合格品出库记录!$G:$G,合格品出库记录!$E:$E,日报!$E:$E,合格品出库记录!$A:$A,日报!AX$3),"") | AY71: =IF(SUMIFS(合格品出库记录!$G:$G,合格品出库记录!$E:$E,日报!$E:$E,合格品出库记录!$A:$A,日报!AY$3)<>0,SUMIFS(合格品出库记录!$G:$G,合格品出库记录!$E:$E,日报!$E:$E,合格品出库记录!$A:$A,日报!AY$3),"") | AZ71: =IF(SUMIFS(合格品出库记录!$G:$G,合格品出库记录!$E:$E,日报!$E:$E,合格品出库记录!$A:$A,日报!AZ$3)<>0,SUMIFS(合格品出库记录!$G:$G,合格品出库记录!$E:$E,日报!$E:$E,合格品出库记录!$A:$A,日报!AZ$3),"") | BA71: =IF(SUMIFS(合格品出库记录!$G:$G,合格品出库记录!$E:$E,日报!$E:$E,合格品出库记录!$A:$A,日报!BA$3)<>0,SUMIFS(合格品出库记录!$G:$G,合格品出库记录!$E:$E,日报!$E:$E,合格品出库记录!$A:$A,日报!BA$3),"") | BB71: =IF(SUMIFS(合格品出库记录!$G:$G,合格品出库记录!$E:$E,日报!$E:$E,合格品出库记录!$A:$A,日报!BB$3)<>0,SUMIFS(合格品出库记录!$G:$G,合格品出库记录!$E:$E,日报!$E:$E,合格品出库记录!$A:$A,日报!BB$3),"") | ... BX71: =IF(SUMIFS(合格品出库记录!$G:$G,合格品出库记录!$E:$E,日报!$E:$E,合格品出库记录!$A:$A,日报!BX$3)<>0,SUMIFS(合格品出库记录!$G:$G,合格品出库记录!$E:$E,日报!$E:$E,合格品出库记录!$A:$A,日报!BX$3),"")
