Workbook

Sheet 日报
A1: 46143 | E1: 注：“可用结存”列中红色数据代表库存量过低，黄色数据代表超出最高库存量。
A2: 序号 | B2: 供应商代码 | C2: 供应商名称 | D2: 零件编号 | E2: 零件名称 | F2: SNP | G2: 上月结存 | H2: 累进 | I2: 累出 | J2: 零跑退回良品 | K2: 当前库存 | L2: 不合格品库存 | M2: 可用结存 | N2: 最高库存量 | O2: 单车用量 | P2: 入库 | AU2: 出库 | BZ2: 领跑良品退回
P3: 46143 | Q3: 46144 | R3: 46145 | S3: 46146 | T3: 46147 | U3: 46148 | V3: 46149 | W3: 46150 | X3: 46151 | Y3: 46152 | Z3: 46153 | AA3: 46154 | AB3: 46155 | AC3: 46156 | AD3: 46157 | AE3: 46158 | AF3: 46159 | AG3: 46160 | AH3: 46161 | AI3: 46162 | AJ3: 46163 | AK3: 46164 | AL3: 46165 | AM3: 46166 | AN3: 46167 | AO3: 46168 | AP3: 46169 | AQ3: 46170 | AR3: 46171 | AS3: 46172 | AT3: 46173 | AU3: 46143 | AV3: 46144 | AW3: 46145 | AX3: 46146 | AY3: 46147 | AZ3: 46148 | BA3: 46149 | BB3: 46150 | BC3: 46151 | BD3: 46152 | BE3: 46153 | BF3: 46154 | BG3: 46155 | BH3: 46156 | BI3: 46157 | BJ3: 46158 | BK3: 46159 | BL3: 46160 | BM3: 46161 | BN3: 46162 | BO3: 46163 | BP3: 46164 | BQ3: 46165 | BR3: 46166 | BS3: 46167 | BT3: 46168 | BU3: 46169 | BV3: 46170 | BW3: 46171 | BX3: 46172 | BY3: 46173 | BZ3: 46143 | CA3: 46144 | CB3: 46145 | CC3: 46146 | CD3: 46147 | CE3: 46148 | CF3: 46149 | CG3: 46150 | CH3: 46151 | CI3: 46152 | CJ3: 46153 | CK3: 46154 | CL3: 46155 | CM3: 46156 | CN3: 46157 | CO3: 46158 | CP3: 46159 | CQ3: 46160 | CR3: 46161 | CS3: 46162 | CT3: 46163 | CU3: 46164 | CV3: 46165 | CW3: 46166 | CX3: 46167 | CY3: 46168 | CZ3: 46169 | DA3: 46170 | DB3: 46171 | DC3: 46172 | DD3: 46173
A4: 48 | B4: 1DC | C4: 东莞市硅翔绝缘材料有限公司 | D4: 3.2.49.08.00346-000 | E4: T03A_PBP-模组（南京国轩电芯）CCS总成1 | F4: =IFERROR(VLOOKUP(D51,'[1]#REF'!D:F,3,FALSE),"0") -> 0 | G4: 22 | H4: =SUMIF(合格品入库记录!E:E,日报!D51,合格品入库记录!G:G) -> 0 | I4: =SUMIF(合格品出库记录!E:E,日报!D51,合格品出库记录!G:G) -> 0 | J4: =SUMIF(领跑良品退回!E:E,D51,领跑良品退回!G:G) -> 0 | K4: =M51+L51 -> 0 | L4: =SUMIF(不良品库存!D:D,D:D,不良品库存!F:F) -> 0 | M4: =G51+H51-I51+J51 -> 0 | N4: #N/A | P4: =IF(SUMIFS(合格品入库记录!$G:$G,合格品入库记录!$E:$E,日报!$D:$D,合格品入库记录!$A:$A,日报!P$3)<>0,SUMIFS(合格品入库记录!$G:$G,合格品入库记录!$E:$E,日报!$D:$D,合格品入库记录!$A:$A,日报!P$3),"") | Q4: =IF(SUMIFS(合格品入库记录!$G:$G,合格品入库记录!$E:$E,日报!$D:$D,合格品入库记录!$A:$A,日报!Q$3)<>0,SUMIFS(合格品入库记录!$G:$G,合格品入库记录!$E:$E,日报!$D:$D,合格品入库记录!$A:$A,日报!Q$3),"") | R4: =IF(SUMIFS(合格品入库记录!$G:$G,合格品入库记录!$E:$E,日报!$D:$D,合格品入库记录!$A:$A,日报!R$3)<>0,SUMIFS(合格品入库记录!$G:$G,合格品入库记录!$E:$E,日报!$D:$D,合格品入库记录!$A:$A,日报!R$3),"") | S4: =IF(SUMIFS(合格品入库记录!$G:$G,合格品入库记录!$E:$E,日报!$D:$D,合格品入库记录!$A:$A,日报!S$3)<>0,SUMIFS(合格品入库记录!$G:$G,合格品入库记录!$E:$E,日报!$D:$D,合格品入库记录!$A:$A,日报!S$3),"") | T4: =IF(SUMIFS(合格品入库记录!$G:$G,合格品入库记录!$E:$E,日报!$D:$D,合格品入库记录!$A:$A,日报!T$3)<>0,SUMIFS(合格品入库记录!$G:$G,合格品入库记录!$E:$E,日报!$D:$D,合格品入库记录!$A:$A,日报!T$3),"") | U4: =IF(SUMIFS(合格品入库记录!$G:$G,合格品入库记录!$E:$E,日报!$D:$D,合格品入库记录!$A:$A,日报!U$3)<>0,SUMIFS(合格品入库记录!$G:$G,合格品入库记录!$E:$E,日报!$D:$D,合格品入库记录!$A:$A,日报!U$3),"") | V4: =IF(SUMIFS(合格品入库记录!$G:$G,合格品入库记录!$E:$E,日报!$D:$D,合格品入库记录!$A:$A,日报!V$3)<>0,SUMIFS(合格品入库记录!$G:$G,合格品入库记录!$E:$E,日报!$D:$D,合格品入库记录!$A:$A,日报!V$3),"") | W4: =IF(SUMIFS(合格品入库记录!$G:$G,合格品入库记录!$E:$E,日报!$D:$D,合格品入库记录!$A:$A,日报!W$3)<>0,SUMIFS(合格品入库记录!$G:$G,合格品入库记录!$E:$E,日报!$D:$D,合格品入库记录!$A:$A,日报!W$3),"") | ... AT4: =IF(SUMIFS(合格品入库记录!$G:$G,合格品入库记录!$E:$E,日报!$D:$D,合格品入库记录!$A:$A,日报!AT$3)<>0,SUMIFS(合格品入库记录!$G:$G,合格品入库记录!$E:$E,日报!$D:$D,合格品入库记录!$A:$A,日报!AT$3),"") | AU4: =IF(SUMIFS(合格品出库记录!$G:$G,合格品出库记录!$E:$E,日报!$D:$D,合格品出库记录!$A:$A,日报!AU$3)<>0,SUMIFS(合格品出库记录!$G:$G,合格品出库记录!$E:$E,日报!$D:$D,合格品出库记录!$A:$A,日报!AU$3),"") | AV4: =IF(SUMIFS(合格品出库记录!$G:$G,合格品出库记录!$E:$E,日报!$D:$D,合格品出库记录!$A:$A,日报!AV$3)<>0,SUMIFS(合格品出库记录!$G:$G,合格品出库记录!$E:$E,日报!$D:$D,合格品出库记录!$A:$A,日报!AV$3),"") | AW4: =IF(SUMIFS(合格品出库记录!$G:$G,合格品出库记录!$E:$E,日报!$D:$D,合格品出库记录!$A:$A,日报!AW$3)<>0,SUMIFS(合格品出库记录!$G:$G,合格品出库记录!$E:$E,日报!$D:$D,合格品出库记录!$A:$A,日报!AW$3),"") | AX4: =IF(SUMIFS(合格品出库记录!$G:$G,合格品出库记录!$E:$E,日报!$D:$D,合格品出库记录!$A:$A,日报!AX$3)<>0,SUMIFS(合格品出库记录!$G:$G,合格品出库记录!$E:$E,日报!$D:$D,合格品出库记录!$A:$A,日报!AX$3),"") | AY4: =IF(SUMIFS(合格品出库记录!$G:$G,合格品出库记录!$E:$E,日报!$D:$D,合格品出库记录!$A:$A,日报!AY$3)<>0,SUMIFS(合格品出库记录!$G:$G,合格品出库记录!$E:$E,日报!$D:$D,合格品出库记录!$A:$A,日报!AY$3),"") | AZ4: =IF(SUMIFS(合格品出库记录!$G:$G,合格品出库记录!$E:$E,日报!$D:$D,合格品出库记录!$A:$A,日报!AZ$3)<>0,SUMIFS(合格品出库记录!$G:$G,合格品出库记录!$E:$E,日报!$D:$D,合格品出库记录!$A:$A,日报!AZ$3),"") | BA4: =IF(SUMIFS(合格品出库记录!$G:$G,合格品出库记录!$E:$E,日报!$D:$D,合格品出库记录!$A:$A,日报!BA$3)<>0,SUMIFS(合格品出库记录!$G:$G,合格品出库记录!$E:$E,日报!$D:$D,合格品出库记录!$A:$A,日报!BA$3),"") | BB4: =IF(SUMIFS(合格品出库记录!$G:$G,合格品出库记录!$E:$E,日报!$D:$D,合格品出库记录!$A:$A,日报!BB$3)<>0,SUMIFS(合格品出库记录!$G:$G,合格品出库记录!$E:$E,日报!$D:$D,合格品出库记录!$A:$A,日报!BB$3),"") | ... BY4: =IF(SUMIFS(合格品出库记录!$G:$G,合格品出库记录!$E:$E,日报!$D:$D,合格品出库记录!$A:$A,日报!BY$3)<>0,SUMIFS(合格品出库记录!$G:$G,合格品出库记录!$E:$E,日报!$D:$D,合格品出库记录!$A:$A,日报!BY$3),"") | BZ4: =IF(SUMIFS(领跑良品退回!$G:$G,领跑良品退回!$E:$E,日报!$D:$D,领跑良品退回!$A:$A,日报!BZ$3)<>0,SUMIFS(领跑良品退回!$G:$G,领跑良品退回!$E:$E,日报!$D:$D,领跑良品退回!$A:$A,日报!BZ$3),"") | CA4: =IF(SUMIFS(领跑良品退回!$G:$G,领跑良品退回!$E:$E,日报!$D:$D,领跑良品退回!$A:$A,日报!CA$3)<>0,SUMIFS(领跑良品退回!$G:$G,领跑良品退回!$E:$E,日报!$D:$D,领跑良品退回!$A:$A,日报!CA$3),"") | CB4: =IF(SUMIFS(领跑良品退回!$G:$G,领跑良品退回!$E:$E,日报!$D:$D,领跑良品退回!$A:$A,日报!CB$3)<>0,SUMIFS(领跑良品退回!$G:$G,领跑良品退回!$E:$E,日报!$D:$D,领跑良品退回!$A:$A,日报!CB$3),"") | CC4: =IF(SUMIFS(领跑良品退回!$G:$G,领跑良品退回!$E:$E,日报!$D:$D,领跑良品退回!$A:$A,日报!CC$3)<>0,SUMIFS(领跑良品退回!$G:$G,领跑良品退回!$E:$E,日报!$D:$D,领跑良品退回!$A:$A,日报!CC$3),"") | CD4: =IF(SUMIFS(领跑良品退回!$G:$G,领跑良品退回!$E:$E,日报!$D:$D,领跑良品退回!$A:$A,日报!CD$3)<>0,SUMIFS(领跑良品退回!$G:$G,领跑良品退回!$E:$E,日报!$D:$D,领跑良品退回!$A:$A,日报!CD$3),"") | CE4: =IF(SUMIFS(领跑良品退回!$G:$G,领跑良品退回!$E:$E,日报!$D:$D,领跑良品退回!$A:$A,日报!CE$3)<>0,SUMIFS(领跑良品退回!$G:$G,领跑良品退回!$E:$E,日报!$D:$D,领跑良品退回!$A:$A,日报!CE$3),"") | CF4: =IF(SUMIFS(领跑良品退回!$G:$G,领跑良品退回!$E:$E,日报!$D:$D,领跑良品退回!$A:$A,日报!CF$3)<>0,SUMIFS(领跑良品退回!$G:$G,领跑良品退回!$E:$E,日报!$D:$D,领跑良品退回!$A:$A,日报!CF$3),"") | CG4: =IF(SUMIFS(领跑良品退回!$G:$G,领跑良品退回!$E:$E,日报!$D:$D,领跑良品退回!$A:$A,日报!CG$3)<>0,SUMIFS(领跑良品退回!$G:$G,领跑良品退回!$E:$E,日报!$D:$D,领跑良品退回!$A:$A,日报!CG$3),"") | ... DD4: =IF(SUMIFS(领跑良品退回!$G:$G,领跑良品退回!$E:$E,日报!$D:$D,领跑良品退回!$A:$A,日报!DD$3)<>0,SUMIFS(领跑良品退回!$G:$G,领跑良品退回!$E:$E,日报!$D:$D,领跑良品退回!$A:$A,日报!DD$3),"")
A5: 49 | B5: 1DC | C5: 东莞市硅翔绝缘材料有限公司 | D5: 3.2.49.08.00347-000 | E5: T03A_PBP-模组（南京国轩电芯）CCS总成2 | F5: =IFERROR(VLOOKUP(D52,'[1]#REF'!D:F,3,FALSE),"0") -> 0 | G5: 10 | H5: =SUMIF(合格品入库记录!E:E,日报!D52,合格品入库记录!G:G) -> 2175 | I5: =SUMIF(合格品出库记录!E:E,日报!D52,合格品出库记录!G:G) -> 2190 | J5: =SUMIF(领跑良品退回!E:E,D52,领跑良品退回!G:G) -> 0 | K5: =M52+L52 -> 8018 | L5: =SUMIF(不良品库存!D:D,D:D,不良品库存!F:F) -> 0 | M5: =G52+H52-I52+J52 -> -1636 | N5: 0 | P5: =IF(SUMIFS(合格品入库记录!$G:$G,合格品入库记录!$E:$E,日报!$D:$D,合格品入库记录!$A:$A,日报!P$3)<>0,SUMIFS(合格品入库记录!$G:$G,合格品入库记录!$E:$E,日报!$D:$D,合格品入库记录!$A:$A,日报!P$3),"") | Q5: =IF(SUMIFS(合格品入库记录!$G:$G,合格品入库记录!$E:$E,日报!$D:$D,合格品入库记录!$A:$A,日报!Q$3)<>0,SUMIFS(合格品入库记录!$G:$G,合格品入库记录!$E:$E,日报!$D:$D,合格品入库记录!$A:$A,日报!Q$3),"") | R5: =IF(SUMIFS(合格品入库记录!$G:$G,合格品入库记录!$E:$E,日报!$D:$D,合格品入库记录!$A:$A,日报!R$3)<>0,SUMIFS(合格品入库记录!$G:$G,合格品入库记录!$E:$E,日报!$D:$D,合格品入库记录!$A:$A,日报!R$3),"") | S5: =IF(SUMIFS(合格品入库记录!$G:$G,合格品入库记录!$E:$E,日报!$D:$D,合格品入库记录!$A:$A,日报!S$3)<>0,SUMIFS(合格品入库记录!$G:$G,合格品入库记录!$E:$E,日报!$D:$D,合格品入库记录!$A:$A,日报!S$3),"") | T5: =IF(SUMIFS(合格品入库记录!$G:$G,合格品入库记录!$E:$E,日报!$D:$D,合格品入库记录!$A:$A,日报!T$3)<>0,SUMIFS(合格品入库记录!$G:$G,合格品入库记录!$E:$E,日报!$D:$D,合格品入库记录!$A:$A,日报!T$3),"") | U5: =IF(SUMIFS(合格品入库记录!$G:$G,合格品入库记录!$E:$E,日报!$D:$D,合格品入库记录!$A:$A,日报!U$3)<>0,SUMIFS(合格品入库记录!$G:$G,合格品入库记录!$E:$E,日报!$D:$D,合格品入库记录!$A:$A,日报!U$3),"") | V5: =IF(SUMIFS(合格品入库记录!$G:$G,合格品入库记录!$E:$E,日报!$D:$D,合格品入库记录!$A:$A,日报!V$3)<>0,SUMIFS(合格品入库记录!$G:$G,合格品入库记录!$E:$E,日报!$D:$D,合格品入库记录!$A:$A,日报!V$3),"") | W5: =IF(SUMIFS(合格品入库记录!$G:$G,合格品入库记录!$E:$E,日报!$D:$D,合格品入库记录!$A:$A,日报!W$3)<>0,SUMIFS(合格品入库记录!$G:$G,合格品入库记录!$E:$E,日报!$D:$D,合格品入库记录!$A:$A,日报!W$3),"") | ... AT5: =IF(SUMIFS(合格品入库记录!$G:$G,合格品入库记录!$E:$E,日报!$D:$D,合格品入库记录!$A:$A,日报!AT$3)<>0,SUMIFS(合格品入库记录!$G:$G,合格品入库记录!$E:$E,日报!$D:$D,合格品入库记录!$A:$A,日报!AT$3),"") | AU5: =IF(SUMIFS(合格品出库记录!$G:$G,合格品出库记录!$E:$E,日报!$D:$D,合格品出库记录!$A:$A,日报!AU$3)<>0,SUMIFS(合格品出库记录!$G:$G,合格品出库记录!$E:$E,日报!$D:$D,合格品出库记录!$A:$A,日报!AU$3),"") | AV5: =IF(SUMIFS(合格品出库记录!$G:$G,合格品出库记录!$E:$E,日报!$D:$D,合格品出库记录!$A:$A,日报!AV$3)<>0,SUMIFS(合格品出库记录!$G:$G,合格品出库记录!$E:$E,日报!$D:$D,合格品出库记录!$A:$A,日报!AV$3),"") | AW5: =IF(SUMIFS(合格品出库记录!$G:$G,合格品出库记录!$E:$E,日报!$D:$D,合格品出库记录!$A:$A,日报!AW$3)<>0,SUMIFS(合格品出库记录!$G:$G,合格品出库记录!$E:$E,日报!$D:$D,合格品出库记录!$A:$A,日报!AW$3),"") | AX5: =IF(SUMIFS(合格品出库记录!$G:$G,合格品出库记录!$E:$E,日报!$D:$D,合格品出库记录!$A:$A,日报!AX$3)<>0,SUMIFS(合格品出库记录!$G:$G,合格品出库记录!$E:$E,日报!$D:$D,合格品出库记录!$A:$A,日报!AX$3),"") | AY5: =IF(SUMIFS(合格品出库记录!$G:$G,合格品出库记录!$E:$E,日报!$D:$D,合格品出库记录!$A:$A,日报!AY$3)<>0,SUMIFS(合格品出库记录!$G:$G,合格品出库记录!$E:$E,日报!$D:$D,合格品出库记录!$A:$A,日报!AY$3),"") | AZ5: =IF(SUMIFS(合格品出库记录!$G:$G,合格品出库记录!$E:$E,日报!$D:$D,合格品出库记录!$A:$A,日报!AZ$3)<>0,SUMIFS(合格品出库记录!$G:$G,合格品出库记录!$E:$E,日报!$D:$D,合格品出库记录!$A:$A,日报!AZ$3),"") | BA5: =IF(SUMIFS(合格品出库记录!$G:$G,合格品出库记录!$E:$E,日报!$D:$D,合格品出库记录!$A:$A,日报!BA$3)<>0,SUMIFS(合格品出库记录!$G:$G,合格品出库记录!$E:$E,日报!$D:$D,合格品出库记录!$A:$A,日报!BA$3),"") | BB5: =IF(SUMIFS(合格品出库记录!$G:$G,合格品出库记录!$E:$E,日报!$D:$D,合格品出库记录!$A:$A,日报!BB$3)<>0,SUMIFS(合格品出库记录!$G:$G,合格品出库记录!$E:$E,日报!$D:$D,合格品出库记录!$A:$A,日报!BB$3),"") | ... BY5: =IF(SUMIFS(合格品出库记录!$G:$G,合格品出库记录!$E:$E,日报!$D:$D,合格品出库记录!$A:$A,日报!BY$3)<>0,SUMIFS(合格品出库记录!$G:$G,合格品出库记录!$E:$E,日报!$D:$D,合格品出库记录!$A:$A,日报!BY$3),"") | BZ5: =IF(SUMIFS(领跑良品退回!$G:$G,领跑良品退回!$E:$E,日报!$D:$D,领跑良品退回!$A:$A,日报!BZ$3)<>0,SUMIFS(领跑良品退回!$G:$G,领跑良品退回!$E:$E,日报!$D:$D,领跑良品退回!$A:$A,日报!BZ$3),"") | CA5: =IF(SUMIFS(领跑良品退回!$G:$G,领跑良品退回!$E:$E,日报!$D:$D,领跑良品退回!$A:$A,日报!CA$3)<>0,SUMIFS(领跑良品退回!$G:$G,领跑良品退回!$E:$E,日报!$D:$D,领跑良品退回!$A:$A,日报!CA$3),"") | CB5: =IF(SUMIFS(领跑良品退回!$G:$G,领跑良品退回!$E:$E,日报!$D:$D,领跑良品退回!$A:$A,日报!CB$3)<>0,SUMIFS(领跑良品退回!$G:$G,领跑良品退回!$E:$E,日报!$D:$D,领跑良品退回!$A:$A,日报!CB$3),"") | CC5: =IF(SUMIFS(领跑良品退回!$G:$G,领跑良品退回!$E:$E,日报!$D:$D,领跑良品退回!$A:$A,日报!CC$3)<>0,SUMIFS(领跑良品退回!$G:$G,领跑良品退回!$E:$E,日报!$D:$D,领跑良品退回!$A:$A,日报!CC$3),"") | CD5: =IF(SUMIFS(领跑良品退回!$G:$G,领跑良品退回!$E:$E,日报!$D:$D,领跑良品退回!$A:$A,日报!CD$3)<>0,SUMIFS(领跑良品退回!$G:$G,领跑良品退回!$E:$E,日报!$D:$D,领跑良品退回!$A:$A,日报!CD$3),"") | CE5: =IF(SUMIFS(领跑良品退回!$G:$G,领跑良品退回!$E:$E,日报!$D:$D,领跑良品退回!$A:$A,日报!CE$3)<>0,SUMIFS(领跑良品退回!$G:$G,领跑良品退回!$E:$E,日报!$D:$D,领跑良品退回!$A:$A,日报!CE$3),"") | CF5: =IF(SUMIFS(领跑良品退回!$G:$G,领跑良品退回!$E:$E,日报!$D:$D,领跑良品退回!$A:$A,日报!CF$3)<>0,SUMIFS(领跑良品退回!$G:$G,领跑良品退回!$E:$E,日报!$D:$D,领跑良品退回!$A:$A,日报!CF$3),"") | CG5: =IF(SUMIFS(领跑良品退回!$G:$G,领跑良品退回!$E:$E,日报!$D:$D,领跑良品退回!$A:$A,日报!CG$3)<>0,SUMIFS(领跑良品退回!$G:$G,领跑良品退回!$E:$E,日报!$D:$D,领跑良品退回!$A:$A,日报!CG$3),"") | ... DD5: =IF(SUMIFS(领跑良品退回!$G:$G,领跑良品退回!$E:$E,日报!$D:$D,领跑良品退回!$A:$A,日报!DD$3)<>0,SUMIFS(领跑良品退回!$G:$G,领跑良品退回!$E:$E,日报!$D:$D,领跑良品退回!$A:$A,日报!DD$3),"")
A6: 50 | B6: 1DC | C6: 东莞市硅翔绝缘材料有限公司 | D6: 3.2.49.08.01246-000 | E6: LX-B11RE10海外版-CCS总成 | F6: =IFERROR(VLOOKUP(D53,'[1]#REF'!D:F,3,FALSE),"0") -> 0 | G6: 718 | H6: =SUMIF(合格品入库记录!E:E,日报!D53,合格品入库记录!G:G) -> 0 | I6: =SUMIF(合格品出库记录!E:E,日报!D53,合格品出库记录!G:G) -> 0 | J6: =SUMIF(领跑良品退回!E:E,D53,领跑良品退回!G:G) -> 0 | K6: =M53+L53 -> 6623 | L6: =SUMIF(不良品库存!D:D,D:D,不良品库存!F:F) -> 0 | M6: =G53+H53-I53+J53 -> 960 | N6: 180 | P6: =IF(SUMIFS(合格品入库记录!$G:$G,合格品入库记录!$E:$E,日报!$D:$D,合格品入库记录!$A:$A,日报!P$3)<>0,SUMIFS(合格品入库记录!$G:$G,合格品入库记录!$E:$E,日报!$D:$D,合格品入库记录!$A:$A,日报!P$3),"") | Q6: =IF(SUMIFS(合格品入库记录!$G:$G,合格品入库记录!$E:$E,日报!$D:$D,合格品入库记录!$A:$A,日报!Q$3)<>0,SUMIFS(合格品入库记录!$G:$G,合格品入库记录!$E:$E,日报!$D:$D,合格品入库记录!$A:$A,日报!Q$3),"") | R6: =IF(SUMIFS(合格品入库记录!$G:$G,合格品入库记录!$E:$E,日报!$D:$D,合格品入库记录!$A:$A,日报!R$3)<>0,SUMIFS(合格品入库记录!$G:$G,合格品入库记录!$E:$E,日报!$D:$D,合格品入库记录!$A:$A,日报!R$3),"") | S6: =IF(SUMIFS(合格品入库记录!$G:$G,合格品入库记录!$E:$E,日报!$D:$D,合格品入库记录!$A:$A,日报!S$3)<>0,SUMIFS(合格品入库记录!$G:$G,合格品入库记录!$E:$E,日报!$D:$D,合格品入库记录!$A:$A,日报!S$3),"") | T6: =IF(SUMIFS(合格品入库记录!$G:$G,合格品入库记录!$E:$E,日报!$D:$D,合格品入库记录!$A:$A,日报!T$3)<>0,SUMIFS(合格品入库记录!$G:$G,合格品入库记录!$E:$E,日报!$D:$D,合格品入库记录!$A:$A,日报!T$3),"") | U6: =IF(SUMIFS(合格品入库记录!$G:$G,合格品入库记录!$E:$E,日报!$D:$D,合格品入库记录!$A:$A,日报!U$3)<>0,SUMIFS(合格品入库记录!$G:$G,合格品入库记录!$E:$E,日报!$D:$D,合格品入库记录!$A:$A,日报!U$3),"") | V6: =IF(SUMIFS(合格品入库记录!$G:$G,合格品入库记录!$E:$E,日报!$D:$D,合格品入库记录!$A:$A,日报!V$3)<>0,SUMIFS(合格品入库记录!$G:$G,合格品入库记录!$E:$E,日报!$D:$D,合格品入库记录!$A:$A,日报!V$3),"") | W6: =IF(SUMIFS(合格品入库记录!$G:$G,合格品入库记录!$E:$E,日报!$D:$D,合格品入库记录!$A:$A,日报!W$3)<>0,SUMIFS(合格品入库记录!$G:$G,合格品入库记录!$E:$E,日报!$D:$D,合格品入库记录!$A:$A,日报!W$3),"") | ... AT6: =IF(SUMIFS(合格品入库记录!$G:$G,合格品入库记录!$E:$E,日报!$D:$D,合格品入库记录!$A:$A,日报!AT$3)<>0,SUMIFS(合格品入库记录!$G:$G,合格品入库记录!$E:$E,日报!$D:$D,合格品入库记录!$A:$A,日报!AT$3),"") | AU6: =IF(SUMIFS(合格品出库记录!$G:$G,合格品出库记录!$E:$E,日报!$D:$D,合格品出库记录!$A:$A,日报!AU$3)<>0,SUMIFS(合格品出库记录!$G:$G,合格品出库记录!$E:$E,日报!$D:$D,合格品出库记录!$A:$A,日报!AU$3),"") | AV6: =IF(SUMIFS(合格品出库记录!$G:$G,合格品出库记录!$E:$E,日报!$D:$D,合格品出库记录!$A:$A,日报!AV$3)<>0,SUMIFS(合格品出库记录!$G:$G,合格品出库记录!$E:$E,日报!$D:$D,合格品出库记录!$A:$A,日报!AV$3),"") | AW6: =IF(SUMIFS(合格品出库记录!$G:$G,合格品出库记录!$E:$E,日报!$D:$D,合格品出库记录!$A:$A,日报!AW$3)<>0,SUMIFS(合格品出库记录!$G:$G,合格品出库记录!$E:$E,日报!$D:$D,合格品出库记录!$A:$A,日报!AW$3),"") | AX6: =IF(SUMIFS(合格品出库记录!$G:$G,合格品出库记录!$E:$E,日报!$D:$D,合格品出库记录!$A:$A,日报!AX$3)<>0,SUMIFS(合格品出库记录!$G:$G,合格品出库记录!$E:$E,日报!$D:$D,合格品出库记录!$A:$A,日报!AX$3),"") | AY6: =IF(SUMIFS(合格品出库记录!$G:$G,合格品出库记录!$E:$E,日报!$D:$D,合格品出库记录!$A:$A,日报!AY$3)<>0,SUMIFS(合格品出库记录!$G:$G,合格品出库记录!$E:$E,日报!$D:$D,合格品出库记录!$A:$A,日报!AY$3),"") | AZ6: =IF(SUMIFS(合格品出库记录!$G:$G,合格品出库记录!$E:$E,日报!$D:$D,合格品出库记录!$A:$A,日报!AZ$3)<>0,SUMIFS(合格品出库记录!$G:$G,合格品出库记录!$E:$E,日报!$D:$D,合格品出库记录!$A:$A,日报!AZ$3),"") -> 330 | BA6: =IF(SUMIFS(合格品出库记录!$G:$G,合格品出库记录!$E:$E,日报!$D:$D,合格品出库记录!$A:$A,日报!BA$3)<>0,SUMIFS(合格品出库记录!$G:$G,合格品出库记录!$E:$E,日报!$D:$D,合格品出库记录!$A:$A,日报!BA$3),"") | BB6: =IF(SUMIFS(合格品出库记录!$G:$G,合格品出库记录!$E:$E,日报!$D:$D,合格品出库记录!$A:$A,日报!BB$3)<>0,SUMIFS(合格品出库记录!$G:$G,合格品出库记录!$E:$E,日报!$D:$D,合格品出库记录!$A:$A,日报!BB$3),"") | ... BY6: =IF(SUMIFS(合格品出库记录!$G:$G,合格品出库记录!$E:$E,日报!$D:$D,合格品出库记录!$A:$A,日报!BY$3)<>0,SUMIFS(合格品出库记录!$G:$G,合格品出库记录!$E:$E,日报!$D:$D,合格品出库记录!$A:$A,日报!BY$3),"") | BZ6: =IF(SUMIFS(领跑良品退回!$G:$G,领跑良品退回!$E:$E,日报!$D:$D,领跑良品退回!$A:$A,日报!BZ$3)<>0,SUMIFS(领跑良品退回!$G:$G,领跑良品退回!$E:$E,日报!$D:$D,领跑良品退回!$A:$A,日报!BZ$3),"") | CA6: =IF(SUMIFS(领跑良品退回!$G:$G,领跑良品退回!$E:$E,日报!$D:$D,领跑良品退回!$A:$A,日报!CA$3)<>0,SUMIFS(领跑良品退回!$G:$G,领跑良品退回!$E:$E,日报!$D:$D,领跑良品退回!$A:$A,日报!CA$3),"") | CB6: =IF(SUMIFS(领跑良品退回!$G:$G,领跑良品退回!$E:$E,日报!$D:$D,领跑良品退回!$A:$A,日报!CB$3)<>0,SUMIFS(领跑良品退回!$G:$G,领跑良品退回!$E:$E,日报!$D:$D,领跑良品退回!$A:$A,日报!CB$3),"") | CC6: =IF(SUMIFS(领跑良品退回!$G:$G,领跑良品退回!$E:$E,日报!$D:$D,领跑良品退回!$A:$A,日报!CC$3)<>0,SUMIFS(领跑良品退回!$G:$G,领跑良品退回!$E:$E,日报!$D:$D,领跑良品退回!$A:$A,日报!CC$3),"") | CD6: =IF(SUMIFS(领跑良品退回!$G:$G,领跑良品退回!$E:$E,日报!$D:$D,领跑良品退回!$A:$A,日报!CD$3)<>0,SUMIFS(领跑良品退回!$G:$G,领跑良品退回!$E:$E,日报!$D:$D,领跑良品退回!$A:$A,日报!CD$3),"") | CE6: =IF(SUMIFS(领跑良品退回!$G:$G,领跑良品退回!$E:$E,日报!$D:$D,领跑良品退回!$A:$A,日报!CE$3)<>0,SUMIFS(领跑良品退回!$G:$G,领跑良品退回!$E:$E,日报!$D:$D,领跑良品退回!$A:$A,日报!CE$3),"") | CF6: =IF(SUMIFS(领跑良品退回!$G:$G,领跑良品退回!$E:$E,日报!$D:$D,领跑良品退回!$A:$A,日报!CF$3)<>0,SUMIFS(领跑良品退回!$G:$G,领跑良品退回!$E:$E,日报!$D:$D,领跑良品退回!$A:$A,日报!CF$3),"") | CG6: =IF(SUMIFS(领跑良品退回!$G:$G,领跑良品退回!$E:$E,日报!$D:$D,领跑良品退回!$A:$A,日报!CG$3)<>0,SUMIFS(领跑良品退回!$G:$G,领跑良品退回!$E:$E,日报!$D:$D,领跑良品退回!$A:$A,日报!CG$3),"") | ... DD6: =IF(SUMIFS(领跑良品退回!$G:$G,领跑良品退回!$E:$E,日报!$D:$D,领跑良品退回!$A:$A,日报!DD$3)<>0,SUMIFS(领跑良品退回!$G:$G,领跑良品退回!$E:$E,日报!$D:$D,领跑良品退回!$A:$A,日报!DD$3),"")
A7: 51 | B7: 1DC | C7: 东莞市硅翔绝缘材料有限公司 | D7: 3.2.49.08.00235-000 | E7: LPT03A_PBP-模组CCS总成1 | F7: =IFERROR(VLOOKUP(D54,'[1]#REF'!D:F,3,FALSE),"0") -> 0 | G7: 0 | H7: =SUMIF(合格品入库记录!E:E,日报!D54,合格品入库记录!G:G) -> 0 | I7: =SUMIF(合格品出库记录!E:E,日报!D54,合格品出库记录!G:G) -> 0 | J7: =SUMIF(领跑良品退回!E:E,D54,领跑良品退回!G:G) -> 0 | K7: =M54+L54 -> 37332 | L7: =SUMIF(不良品库存!D:D,D:D,不良品库存!F:F) -> 0 | M7: =G54+H54-I54+J54 -> -10064 | N7: 0 | P7: =IF(SUMIFS(合格品入库记录!$G:$G,合格品入库记录!$E:$E,日报!$D:$D,合格品入库记录!$A:$A,日报!P$3)<>0,SUMIFS(合格品入库记录!$G:$G,合格品入库记录!$E:$E,日报!$D:$D,合格品入库记录!$A:$A,日报!P$3),"") | Q7: =IF(SUMIFS(合格品入库记录!$G:$G,合格品入库记录!$E:$E,日报!$D:$D,合格品入库记录!$A:$A,日报!Q$3)<>0,SUMIFS(合格品入库记录!$G:$G,合格品入库记录!$E:$E,日报!$D:$D,合格品入库记录!$A:$A,日报!Q$3),"") | R7: =IF(SUMIFS(合格品入库记录!$G:$G,合格品入库记录!$E:$E,日报!$D:$D,合格品入库记录!$A:$A,日报!R$3)<>0,SUMIFS(合格品入库记录!$G:$G,合格品入库记录!$E:$E,日报!$D:$D,合格品入库记录!$A:$A,日报!R$3),"") | S7: =IF(SUMIFS(合格品入库记录!$G:$G,合格品入库记录!$E:$E,日报!$D:$D,合格品入库记录!$A:$A,日报!S$3)<>0,SUMIFS(合格品入库记录!$G:$G,合格品入库记录!$E:$E,日报!$D:$D,合格品入库记录!$A:$A,日报!S$3),"") | T7: =IF(SUMIFS(合格品入库记录!$G:$G,合格品入库记录!$E:$E,日报!$D:$D,合格品入库记录!$A:$A,日报!T$3)<>0,SUMIFS(合格品入库记录!$G:$G,合格品入库记录!$E:$E,日报!$D:$D,合格品入库记录!$A:$A,日报!T$3),"") | U7: =IF(SUMIFS(合格品入库记录!$G:$G,合格品入库记录!$E:$E,日报!$D:$D,合格品入库记录!$A:$A,日报!U$3)<>0,SUMIFS(合格品入库记录!$G:$G,合格品入库记录!$E:$E,日报!$D:$D,合格品入库记录!$A:$A,日报!U$3),"") | V7: =IF(SUMIFS(合格品入库记录!$G:$G,合格品入库记录!$E:$E,日报!$D:$D,合格品入库记录!$A:$A,日报!V$3)<>0,SUMIFS(合格品入库记录!$G:$G,合格品入库记录!$E:$E,日报!$D:$D,合格品入库记录!$A:$A,日报!V$3),"") | W7: =IF(SUMIFS(合格品入库记录!$G:$G,合格品入库记录!$E:$E,日报!$D:$D,合格品入库记录!$A:$A,日报!W$3)<>0,SUMIFS(合格品入库记录!$G:$G,合格品入库记录!$E:$E,日报!$D:$D,合格品入库记录!$A:$A,日报!W$3),"") | ... AT7: =IF(SUMIFS(合格品入库记录!$G:$G,合格品入库记录!$E:$E,日报!$D:$D,合格品入库记录!$A:$A,日报!AT$3)<>0,SUMIFS(合格品入库记录!$G:$G,合格品入库记录!$E:$E,日报!$D:$D,合格品入库记录!$A:$A,日报!AT$3),"") | AU7: =IF(SUMIFS(合格品出库记录!$G:$G,合格品出库记录!$E:$E,日报!$D:$D,合格品出库记录!$A:$A,日报!AU$3)<>0,SUMIFS(合格品出库记录!$G:$G,合格品出库记录!$E:$E,日报!$D:$D,合格品出库记录!$A:$A,日报!AU$3),"") | AV7: =IF(SUMIFS(合格品出库记录!$G:$G,合格品出库记录!$E:$E,日报!$D:$D,合格品出库记录!$A:$A,日报!AV$3)<>0,SUMIFS(合格品出库记录!$G:$G,合格品出库记录!$E:$E,日报!$D:$D,合格品出库记录!$A:$A,日报!AV$3),"") | AW7: =IF(SUMIFS(合格品出库记录!$G:$G,合格品出库记录!$E:$E,日报!$D:$D,合格品出库记录!$A:$A,日报!AW$3)<>0,SUMIFS(合格品出库记录!$G:$G,合格品出库记录!$E:$E,日报!$D:$D,合格品出库记录!$A:$A,日报!AW$3),"") | AX7: =IF(SUMIFS(合格品出库记录!$G:$G,合格品出库记录!$E:$E,日报!$D:$D,合格品出库记录!$A:$A,日报!AX$3)<>0,SUMIFS(合格品出库记录!$G:$G,合格品出库记录!$E:$E,日报!$D:$D,合格品出库记录!$A:$A,日报!AX$3),"") | AY7: =IF(SUMIFS(合格品出库记录!$G:$G,合格品出库记录!$E:$E,日报!$D:$D,合格品出库记录!$A:$A,日报!AY$3)<>0,SUMIFS(合格品出库记录!$G:$G,合格品出库记录!$E:$E,日报!$D:$D,合格品出库记录!$A:$A,日报!AY$3),"") | AZ7: =IF(SUMIFS(合格品出库记录!$G:$G,合格品出库记录!$E:$E,日报!$D:$D,合格品出库记录!$A:$A,日报!AZ$3)<>0,SUMIFS(合格品出库记录!$G:$G,合格品出库记录!$E:$E,日报!$D:$D,合格品出库记录!$A:$A,日报!AZ$3),"") | BA7: =IF(SUMIFS(合格品出库记录!$G:$G,合格品出库记录!$E:$E,日报!$D:$D,合格品出库记录!$A:$A,日报!BA$3)<>0,SUMIFS(合格品出库记录!$G:$G,合格品出库记录!$E:$E,日报!$D:$D,合格品出库记录!$A:$A,日报!BA$3),"") | BB7: =IF(SUMIFS(合格品出库记录!$G:$G,合格品出库记录!$E:$E,日报!$D:$D,合格品出库记录!$A:$A,日报!BB$3)<>0,SUMIFS(合格品出库记录!$G:$G,合格品出库记录!$E:$E,日报!$D:$D,合格品出库记录!$A:$A,日报!BB$3),"") | ... BY7: =IF(SUMIFS(合格品出库记录!$G:$G,合格品出库记录!$E:$E,日报!$D:$D,合格品出库记录!$A:$A,日报!BY$3)<>0,SUMIFS(合格品出库记录!$G:$G,合格品出库记录!$E:$E,日报!$D:$D,合格品出库记录!$A:$A,日报!BY$3),"") | BZ7: =IF(SUMIFS(领跑良品退回!$G:$G,领跑良品退回!$E:$E,日报!$D:$D,领跑良品退回!$A:$A,日报!BZ$3)<>0,SUMIFS(领跑良品退回!$G:$G,领跑良品退回!$E:$E,日报!$D:$D,领跑良品退回!$A:$A,日报!BZ$3),"") | CA7: =IF(SUMIFS(领跑良品退回!$G:$G,领跑良品退回!$E:$E,日报!$D:$D,领跑良品退回!$A:$A,日报!CA$3)<>0,SUMIFS(领跑良品退回!$G:$G,领跑良品退回!$E:$E,日报!$D:$D,领跑良品退回!$A:$A,日报!CA$3),"") | CB7: =IF(SUMIFS(领跑良品退回!$G:$G,领跑良品退回!$E:$E,日报!$D:$D,领跑良品退回!$A:$A,日报!CB$3)<>0,SUMIFS(领跑良品退回!$G:$G,领跑良品退回!$E:$E,日报!$D:$D,领跑良品退回!$A:$A,日报!CB$3),"") | CC7: =IF(SUMIFS(领跑良品退回!$G:$G,领跑良品退回!$E:$E,日报!$D:$D,领跑良品退回!$A:$A,日报!CC$3)<>0,SUMIFS(领跑良品退回!$G:$G,领跑良品退回!$E:$E,日报!$D:$D,领跑良品退回!$A:$A,日报!CC$3),"") | CD7: =IF(SUMIFS(领跑良品退回!$G:$G,领跑良品退回!$E:$E,日报!$D:$D,领跑良品退回!$A:$A,日报!CD$3)<>0,SUMIFS(领跑良品退回!$G:$G,领跑良品退回!$E:$E,日报!$D:$D,领跑良品退回!$A:$A,日报!CD$3),"") | CE7: =IF(SUMIFS(领跑良品退回!$G:$G,领跑良品退回!$E:$E,日报!$D:$D,领跑良品退回!$A:$A,日报!CE$3)<>0,SUMIFS(领跑良品退回!$G:$G,领跑良品退回!$E:$E,日报!$D:$D,领跑良品退回!$A:$A,日报!CE$3),"") | CF7: =IF(SUMIFS(领跑良品退回!$G:$G,领跑良品退回!$E:$E,日报!$D:$D,领跑良品退回!$A:$A,日报!CF$3)<>0,SUMIFS(领跑良品退回!$G:$G,领跑良品退回!$E:$E,日报!$D:$D,领跑良品退回!$A:$A,日报!CF$3),"") | CG7: =IF(SUMIFS(领跑良品退回!$G:$G,领跑良品退回!$E:$E,日报!$D:$D,领跑良品退回!$A:$A,日报!CG$3)<>0,SUMIFS(领跑良品退回!$G:$G,领跑良品退回!$E:$E,日报!$D:$D,领跑良品退回!$A:$A,日报!CG$3),"") | ... DD7: =IF(SUMIFS(领跑良品退回!$G:$G,领跑良品退回!$E:$E,日报!$D:$D,领跑良品退回!$A:$A,日报!DD$3)<>0,SUMIFS(领跑良品退回!$G:$G,领跑良品退回!$E:$E,日报!$D:$D,领跑良品退回!$A:$A,日报!DD$3),"")
A8: 52 | B8: 1DC | C8: 东莞市硅翔绝缘材料有限公司 | D8: 3.2.49.08.00259-000 | E8: LPT03A_PBP-模组CCS总成 | F8: =IFERROR(VLOOKUP(D55,'[1]#REF'!D:F,3,FALSE),"0") -> 0 | G8: 63 | H8: =SUMIF(合格品入库记录!E:E,日报!D55,合格品入库记录!G:G) -> 0 | I8: =SUMIF(合格品出库记录!E:E,日报!D55,合格品出库记录!G:G) -> 1 | J8: =SUMIF(领跑良品退回!E:E,D55,领跑良品退回!G:G) -> 0 | K8: =M55+L55 -> 11685 | L8: =SUMIF(不良品库存!D:D,D:D,不良品库存!F:F) -> 0 | M8: =G55+H55-I55+J55 -> -3596 | N8: 0 | P8: =IF(SUMIFS(合格品入库记录!$G:$G,合格品入库记录!$E:$E,日报!$D:$D,合格品入库记录!$A:$A,日报!P$3)<>0,SUMIFS(合格品入库记录!$G:$G,合格品入库记录!$E:$E,日报!$D:$D,合格品入库记录!$A:$A,日报!P$3),"") | Q8: =IF(SUMIFS(合格品入库记录!$G:$G,合格品入库记录!$E:$E,日报!$D:$D,合格品入库记录!$A:$A,日报!Q$3)<>0,SUMIFS(合格品入库记录!$G:$G,合格品入库记录!$E:$E,日报!$D:$D,合格品入库记录!$A:$A,日报!Q$3),"") | R8: =IF(SUMIFS(合格品入库记录!$G:$G,合格品入库记录!$E:$E,日报!$D:$D,合格品入库记录!$A:$A,日报!R$3)<>0,SUMIFS(合格品入库记录!$G:$G,合格品入库记录!$E:$E,日报!$D:$D,合格品入库记录!$A:$A,日报!R$3),"") | S8: =IF(SUMIFS(合格品入库记录!$G:$G,合格品入库记录!$E:$E,日报!$D:$D,合格品入库记录!$A:$A,日报!S$3)<>0,SUMIFS(合格品入库记录!$G:$G,合格品入库记录!$E:$E,日报!$D:$D,合格品入库记录!$A:$A,日报!S$3),"") | T8: =IF(SUMIFS(合格品入库记录!$G:$G,合格品入库记录!$E:$E,日报!$D:$D,合格品入库记录!$A:$A,日报!T$3)<>0,SUMIFS(合格品入库记录!$G:$G,合格品入库记录!$E:$E,日报!$D:$D,合格品入库记录!$A:$A,日报!T$3),"") | U8: =IF(SUMIFS(合格品入库记录!$G:$G,合格品入库记录!$E:$E,日报!$D:$D,合格品入库记录!$A:$A,日报!U$3)<>0,SUMIFS(合格品入库记录!$G:$G,合格品入库记录!$E:$E,日报!$D:$D,合格品入库记录!$A:$A,日报!U$3),"") | V8: =IF(SUMIFS(合格品入库记录!$G:$G,合格品入库记录!$E:$E,日报!$D:$D,合格品入库记录!$A:$A,日报!V$3)<>0,SUMIFS(合格品入库记录!$G:$G,合格品入库记录!$E:$E,日报!$D:$D,合格品入库记录!$A:$A,日报!V$3),"") | W8: =IF(SUMIFS(合格品入库记录!$G:$G,合格品入库记录!$E:$E,日报!$D:$D,合格品入库记录!$A:$A,日报!W$3)<>0,SUMIFS(合格品入库记录!$G:$G,合格品入库记录!$E:$E,日报!$D:$D,合格品入库记录!$A:$A,日报!W$3),"") | ... AT8: =IF(SUMIFS(合格品入库记录!$G:$G,合格品入库记录!$E:$E,日报!$D:$D,合格品入库记录!$A:$A,日报!AT$3)<>0,SUMIFS(合格品入库记录!$G:$G,合格品入库记录!$E:$E,日报!$D:$D,合格品入库记录!$A:$A,日报!AT$3),"") | AU8: =IF(SUMIFS(合格品出库记录!$G:$G,合格品出库记录!$E:$E,日报!$D:$D,合格品出库记录!$A:$A,日报!AU$3)<>0,SUMIFS(合格品出库记录!$G:$G,合格品出库记录!$E:$E,日报!$D:$D,合格品出库记录!$A:$A,日报!AU$3),"") | AV8: =IF(SUMIFS(合格品出库记录!$G:$G,合格品出库记录!$E:$E,日报!$D:$D,合格品出库记录!$A:$A,日报!AV$3)<>0,SUMIFS(合格品出库记录!$G:$G,合格品出库记录!$E:$E,日报!$D:$D,合格品出库记录!$A:$A,日报!AV$3),"") | AW8: =IF(SUMIFS(合格品出库记录!$G:$G,合格品出库记录!$E:$E,日报!$D:$D,合格品出库记录!$A:$A,日报!AW$3)<>0,SUMIFS(合格品出库记录!$G:$G,合格品出库记录!$E:$E,日报!$D:$D,合格品出库记录!$A:$A,日报!AW$3),"") | AX8: =IF(SUMIFS(合格品出库记录!$G:$G,合格品出库记录!$E:$E,日报!$D:$D,合格品出库记录!$A:$A,日报!AX$3)<>0,SUMIFS(合格品出库记录!$G:$G,合格品出库记录!$E:$E,日报!$D:$D,合格品出库记录!$A:$A,日报!AX$3),"") | AY8: =IF(SUMIFS(合格品出库记录!$G:$G,合格品出库记录!$E:$E,日报!$D:$D,合格品出库记录!$A:$A,日报!AY$3)<>0,SUMIFS(合格品出库记录!$G:$G,合格品出库记录!$E:$E,日报!$D:$D,合格品出库记录!$A:$A,日报!AY$3),"") | AZ8: =IF(SUMIFS(合格品出库记录!$G:$G,合格品出库记录!$E:$E,日报!$D:$D,合格品出库记录!$A:$A,日报!AZ$3)<>0,SUMIFS(合格品出库记录!$G:$G,合格品出库记录!$E:$E,日报!$D:$D,合格品出库记录!$A:$A,日报!AZ$3),"") | BA8: =IF(SUMIFS(合格品出库记录!$G:$G,合格品出库记录!$E:$E,日报!$D:$D,合格品出库记录!$A:$A,日报!BA$3)<>0,SUMIFS(合格品出库记录!$G:$G,合格品出库记录!$E:$E,日报!$D:$D,合格品出库记录!$A:$A,日报!BA$3),"") | BB8: =IF(SUMIFS(合格品出库记录!$G:$G,合格品出库记录!$E:$E,日报!$D:$D,合格品出库记录!$A:$A,日报!BB$3)<>0,SUMIFS(合格品出库记录!$G:$G,合格品出库记录!$E:$E,日报!$D:$D,合格品出库记录!$A:$A,日报!BB$3),"") | ... BY8: =IF(SUMIFS(合格品出库记录!$G:$G,合格品出库记录!$E:$E,日报!$D:$D,合格品出库记录!$A:$A,日报!BY$3)<>0,SUMIFS(合格品出库记录!$G:$G,合格品出库记录!$E:$E,日报!$D:$D,合格品出库记录!$A:$A,日报!BY$3),"") | BZ8: =IF(SUMIFS(领跑良品退回!$G:$G,领跑良品退回!$E:$E,日报!$D:$D,领跑良品退回!$A:$A,日报!BZ$3)<>0,SUMIFS(领跑良品退回!$G:$G,领跑良品退回!$E:$E,日报!$D:$D,领跑良品退回!$A:$A,日报!BZ$3),"") | CA8: =IF(SUMIFS(领跑良品退回!$G:$G,领跑良品退回!$E:$E,日报!$D:$D,领跑良品退回!$A:$A,日报!CA$3)<>0,SUMIFS(领跑良品退回!$G:$G,领跑良品退回!$E:$E,日报!$D:$D,领跑良品退回!$A:$A,日报!CA$3),"") | CB8: =IF(SUMIFS(领跑良品退回!$G:$G,领跑良品退回!$E:$E,日报!$D:$D,领跑良品退回!$A:$A,日报!CB$3)<>0,SUMIFS(领跑良品退回!$G:$G,领跑良品退回!$E:$E,日报!$D:$D,领跑良品退回!$A:$A,日报!CB$3),"") | CC8: =IF(SUMIFS(领跑良品退回!$G:$G,领跑良品退回!$E:$E,日报!$D:$D,领跑良品退回!$A:$A,日报!CC$3)<>0,SUMIFS(领跑良品退回!$G:$G,领跑良品退回!$E:$E,日报!$D:$D,领跑良品退回!$A:$A,日报!CC$3),"") | CD8: =IF(SUMIFS(领跑良品退回!$G:$G,领跑良品退回!$E:$E,日报!$D:$D,领跑良品退回!$A:$A,日报!CD$3)<>0,SUMIFS(领跑良品退回!$G:$G,领跑良品退回!$E:$E,日报!$D:$D,领跑良品退回!$A:$A,日报!CD$3),"") | CE8: =IF(SUMIFS(领跑良品退回!$G:$G,领跑良品退回!$E:$E,日报!$D:$D,领跑良品退回!$A:$A,日报!CE$3)<>0,SUMIFS(领跑良品退回!$G:$G,领跑良品退回!$E:$E,日报!$D:$D,领跑良品退回!$A:$A,日报!CE$3),"") | CF8: =IF(SUMIFS(领跑良品退回!$G:$G,领跑良品退回!$E:$E,日报!$D:$D,领跑良品退回!$A:$A,日报!CF$3)<>0,SUMIFS(领跑良品退回!$G:$G,领跑良品退回!$E:$E,日报!$D:$D,领跑良品退回!$A:$A,日报!CF$3),"") | CG8: =IF(SUMIFS(领跑良品退回!$G:$G,领跑良品退回!$E:$E,日报!$D:$D,领跑良品退回!$A:$A,日报!CG$3)<>0,SUMIFS(领跑良品退回!$G:$G,领跑良品退回!$E:$E,日报!$D:$D,领跑良品退回!$A:$A,日报!CG$3),"") | ... DD8: =IF(SUMIFS(领跑良品退回!$G:$G,领跑良品退回!$E:$E,日报!$D:$D,领跑良品退回!$A:$A,日报!DD$3)<>0,SUMIFS(领跑良品退回!$G:$G,领跑良品退回!$E:$E,日报!$D:$D,领跑良品退回!$A:$A,日报!DD$3),"")
A9: 53 | B9: 1DC | C9: 东莞市硅翔绝缘材料有限公司 | D9: 3.2.49.08.00658-000 | E9: LPT03A_pBP-RP加热膜－L | F9: =IFERROR(VLOOKUP(D56,'[1]#REF'!D:F,3,FALSE),"0") -> 0 | G9: 36 | H9: =SUMIF(合格品入库记录!E:E,日报!D56,合格品入库记录!G:G) -> 0 | I9: =SUMIF(合格品出库记录!E:E,日报!D56,合格品出库记录!G:G) -> 7 | J9: =SUMIF(领跑良品退回!E:E,D56,领跑良品退回!G:G) -> 0 | K9: =M56+L56 -> 7802 | L9: =SUMIF(不良品库存!D:D,D:D,不良品库存!F:F) -> 0 | M9: =G56+H56-I56+J56 -> -1580 | N9: 4000 | P9: =IF(SUMIFS(合格品入库记录!$G:$G,合格品入库记录!$E:$E,日报!$D:$D,合格品入库记录!$A:$A,日报!P$3)<>0,SUMIFS(合格品入库记录!$G:$G,合格品入库记录!$E:$E,日报!$D:$D,合格品入库记录!$A:$A,日报!P$3),"") | Q9: =IF(SUMIFS(合格品入库记录!$G:$G,合格品入库记录!$E:$E,日报!$D:$D,合格品入库记录!$A:$A,日报!Q$3)<>0,SUMIFS(合格品入库记录!$G:$G,合格品入库记录!$E:$E,日报!$D:$D,合格品入库记录!$A:$A,日报!Q$3),"") | R9: =IF(SUMIFS(合格品入库记录!$G:$G,合格品入库记录!$E:$E,日报!$D:$D,合格品入库记录!$A:$A,日报!R$3)<>0,SUMIFS(合格品入库记录!$G:$G,合格品入库记录!$E:$E,日报!$D:$D,合格品入库记录!$A:$A,日报!R$3),"") | S9: =IF(SUMIFS(合格品入库记录!$G:$G,合格品入库记录!$E:$E,日报!$D:$D,合格品入库记录!$A:$A,日报!S$3)<>0,SUMIFS(合格品入库记录!$G:$G,合格品入库记录!$E:$E,日报!$D:$D,合格品入库记录!$A:$A,日报!S$3),"") | T9: =IF(SUMIFS(合格品入库记录!$G:$G,合格品入库记录!$E:$E,日报!$D:$D,合格品入库记录!$A:$A,日报!T$3)<>0,SUMIFS(合格品入库记录!$G:$G,合格品入库记录!$E:$E,日报!$D:$D,合格品入库记录!$A:$A,日报!T$3),"") | U9: =IF(SUMIFS(合格品入库记录!$G:$G,合格品入库记录!$E:$E,日报!$D:$D,合格品入库记录!$A:$A,日报!U$3)<>0,SUMIFS(合格品入库记录!$G:$G,合格品入库记录!$E:$E,日报!$D:$D,合格品入库记录!$A:$A,日报!U$3),"") | V9: =IF(SUMIFS(合格品入库记录!$G:$G,合格品入库记录!$E:$E,日报!$D:$D,合格品入库记录!$A:$A,日报!V$3)<>0,SUMIFS(合格品入库记录!$G:$G,合格品入库记录!$E:$E,日报!$D:$D,合格品入库记录!$A:$A,日报!V$3),"") | W9: =IF(SUMIFS(合格品入库记录!$G:$G,合格品入库记录!$E:$E,日报!$D:$D,合格品入库记录!$A:$A,日报!W$3)<>0,SUMIFS(合格品入库记录!$G:$G,合格品入库记录!$E:$E,日报!$D:$D,合格品入库记录!$A:$A,日报!W$3),"") | ... AT9: =IF(SUMIFS(合格品入库记录!$G:$G,合格品入库记录!$E:$E,日报!$D:$D,合格品入库记录!$A:$A,日报!AT$3)<>0,SUMIFS(合格品入库记录!$G:$G,合格品入库记录!$E:$E,日报!$D:$D,合格品入库记录!$A:$A,日报!AT$3),"") | AU9: =IF(SUMIFS(合格品出库记录!$G:$G,合格品出库记录!$E:$E,日报!$D:$D,合格品出库记录!$A:$A,日报!AU$3)<>0,SUMIFS(合格品出库记录!$G:$G,合格品出库记录!$E:$E,日报!$D:$D,合格品出库记录!$A:$A,日报!AU$3),"") | AV9: =IF(SUMIFS(合格品出库记录!$G:$G,合格品出库记录!$E:$E,日报!$D:$D,合格品出库记录!$A:$A,日报!AV$3)<>0,SUMIFS(合格品出库记录!$G:$G,合格品出库记录!$E:$E,日报!$D:$D,合格品出库记录!$A:$A,日报!AV$3),"") | AW9: =IF(SUMIFS(合格品出库记录!$G:$G,合格品出库记录!$E:$E,日报!$D:$D,合格品出库记录!$A:$A,日报!AW$3)<>0,SUMIFS(合格品出库记录!$G:$G,合格品出库记录!$E:$E,日报!$D:$D,合格品出库记录!$A:$A,日报!AW$3),"") | AX9: =IF(SUMIFS(合格品出库记录!$G:$G,合格品出库记录!$E:$E,日报!$D:$D,合格品出库记录!$A:$A,日报!AX$3)<>0,SUMIFS(合格品出库记录!$G:$G,合格品出库记录!$E:$E,日报!$D:$D,合格品出库记录!$A:$A,日报!AX$3),"") | AY9: =IF(SUMIFS(合格品出库记录!$G:$G,合格品出库记录!$E:$E,日报!$D:$D,合格品出库记录!$A:$A,日报!AY$3)<>0,SUMIFS(合格品出库记录!$G:$G,合格品出库记录!$E:$E,日报!$D:$D,合格品出库记录!$A:$A,日报!AY$3),"") | AZ9: =IF(SUMIFS(合格品出库记录!$G:$G,合格品出库记录!$E:$E,日报!$D:$D,合格品出库记录!$A:$A,日报!AZ$3)<>0,SUMIFS(合格品出库记录!$G:$G,合格品出库记录!$E:$E,日报!$D:$D,合格品出库记录!$A:$A,日报!AZ$3),"") | BA9: =IF(SUMIFS(合格品出库记录!$G:$G,合格品出库记录!$E:$E,日报!$D:$D,合格品出库记录!$A:$A,日报!BA$3)<>0,SUMIFS(合格品出库记录!$G:$G,合格品出库记录!$E:$E,日报!$D:$D,合格品出库记录!$A:$A,日报!BA$3),"") | BB9: =IF(SUMIFS(合格品出库记录!$G:$G,合格品出库记录!$E:$E,日报!$D:$D,合格品出库记录!$A:$A,日报!BB$3)<>0,SUMIFS(合格品出库记录!$G:$G,合格品出库记录!$E:$E,日报!$D:$D,合格品出库记录!$A:$A,日报!BB$3),"") | ... BY9: =IF(SUMIFS(合格品出库记录!$G:$G,合格品出库记录!$E:$E,日报!$D:$D,合格品出库记录!$A:$A,日报!BY$3)<>0,SUMIFS(合格品出库记录!$G:$G,合格品出库记录!$E:$E,日报!$D:$D,合格品出库记录!$A:$A,日报!BY$3),"") | BZ9: =IF(SUMIFS(领跑良品退回!$G:$G,领跑良品退回!$E:$E,日报!$D:$D,领跑良品退回!$A:$A,日报!BZ$3)<>0,SUMIFS(领跑良品退回!$G:$G,领跑良品退回!$E:$E,日报!$D:$D,领跑良品退回!$A:$A,日报!BZ$3),"") | CA9: =IF(SUMIFS(领跑良品退回!$G:$G,领跑良品退回!$E:$E,日报!$D:$D,领跑良品退回!$A:$A,日报!CA$3)<>0,SUMIFS(领跑良品退回!$G:$G,领跑良品退回!$E:$E,日报!$D:$D,领跑良品退回!$A:$A,日报!CA$3),"") | CB9: =IF(SUMIFS(领跑良品退回!$G:$G,领跑良品退回!$E:$E,日报!$D:$D,领跑良品退回!$A:$A,日报!CB$3)<>0,SUMIFS(领跑良品退回!$G:$G,领跑良品退回!$E:$E,日报!$D:$D,领跑良品退回!$A:$A,日报!CB$3),"") | CC9: =IF(SUMIFS(领跑良品退回!$G:$G,领跑良品退回!$E:$E,日报!$D:$D,领跑良品退回!$A:$A,日报!CC$3)<>0,SUMIFS(领跑良品退回!$G:$G,领跑良品退回!$E:$E,日报!$D:$D,领跑良品退回!$A:$A,日报!CC$3),"") | CD9: =IF(SUMIFS(领跑良品退回!$G:$G,领跑良品退回!$E:$E,日报!$D:$D,领跑良品退回!$A:$A,日报!CD$3)<>0,SUMIFS(领跑良品退回!$G:$G,领跑良品退回!$E:$E,日报!$D:$D,领跑良品退回!$A:$A,日报!CD$3),"") | CE9: =IF(SUMIFS(领跑良品退回!$G:$G,领跑良品退回!$E:$E,日报!$D:$D,领跑良品退回!$A:$A,日报!CE$3)<>0,SUMIFS(领跑良品退回!$G:$G,领跑良品退回!$E:$E,日报!$D:$D,领跑良品退回!$A:$A,日报!CE$3),"") | CF9: =IF(SUMIFS(领跑良品退回!$G:$G,领跑良品退回!$E:$E,日报!$D:$D,领跑良品退回!$A:$A,日报!CF$3)<>0,SUMIFS(领跑良品退回!$G:$G,领跑良品退回!$E:$E,日报!$D:$D,领跑良品退回!$A:$A,日报!CF$3),"") | CG9: =IF(SUMIFS(领跑良品退回!$G:$G,领跑良品退回!$E:$E,日报!$D:$D,领跑良品退回!$A:$A,日报!CG$3)<>0,SUMIFS(领跑良品退回!$G:$G,领跑良品退回!$E:$E,日报!$D:$D,领跑良品退回!$A:$A,日报!CG$3),"") | ... DD9: =IF(SUMIFS(领跑良品退回!$G:$G,领跑良品退回!$E:$E,日报!$D:$D,领跑良品退回!$A:$A,日报!DD$3)<>0,SUMIFS(领跑良品退回!$G:$G,领跑良品退回!$E:$E,日报!$D:$D,领跑良品退回!$A:$A,日报!DD$3),"")
A10: 54 | B10: 1DC | C10: 东莞市硅翔绝缘材料有限公司 | D10: 3.2.49.08.00659-000 | E10: LPT03A_pBP-RP加热膜－R项目 | F10: =IFERROR(VLOOKUP(D57,'[1]#REF'!D:F,3,FALSE),"0") -> 0 | G10: 0 | H10: =SUMIF(合格品入库记录!E:E,日报!D57,合格品入库记录!G:G) -> 0 | I10: =SUMIF(合格品出库记录!E:E,日报!D57,合格品出库记录!G:G) -> 0 | J10: =SUMIF(领跑良品退回!E:E,D57,领跑良品退回!G:G) -> 0 | K10: =M57+L57 -> 2655 | L10: =SUMIF(不良品库存!D:D,D:D,不良品库存!F:F) -> 0 | M10: =G57+H57-I57+J57 -> -442 | N10: 4000 | P10: =IF(SUMIFS(合格品入库记录!$G:$G,合格品入库记录!$E:$E,日报!$D:$D,合格品入库记录!$A:$A,日报!P$3)<>0,SUMIFS(合格品入库记录!$G:$G,合格品入库记录!$E:$E,日报!$D:$D,合格品入库记录!$A:$A,日报!P$3),"") | Q10: =IF(SUMIFS(合格品入库记录!$G:$G,合格品入库记录!$E:$E,日报!$D:$D,合格品入库记录!$A:$A,日报!Q$3)<>0,SUMIFS(合格品入库记录!$G:$G,合格品入库记录!$E:$E,日报!$D:$D,合格品入库记录!$A:$A,日报!Q$3),"") | R10: =IF(SUMIFS(合格品入库记录!$G:$G,合格品入库记录!$E:$E,日报!$D:$D,合格品入库记录!$A:$A,日报!R$3)<>0,SUMIFS(合格品入库记录!$G:$G,合格品入库记录!$E:$E,日报!$D:$D,合格品入库记录!$A:$A,日报!R$3),"") | S10: =IF(SUMIFS(合格品入库记录!$G:$G,合格品入库记录!$E:$E,日报!$D:$D,合格品入库记录!$A:$A,日报!S$3)<>0,SUMIFS(合格品入库记录!$G:$G,合格品入库记录!$E:$E,日报!$D:$D,合格品入库记录!$A:$A,日报!S$3),"") | T10: =IF(SUMIFS(合格品入库记录!$G:$G,合格品入库记录!$E:$E,日报!$D:$D,合格品入库记录!$A:$A,日报!T$3)<>0,SUMIFS(合格品入库记录!$G:$G,合格品入库记录!$E:$E,日报!$D:$D,合格品入库记录!$A:$A,日报!T$3),"") | U10: =IF(SUMIFS(合格品入库记录!$G:$G,合格品入库记录!$E:$E,日报!$D:$D,合格品入库记录!$A:$A,日报!U$3)<>0,SUMIFS(合格品入库记录!$G:$G,合格品入库记录!$E:$E,日报!$D:$D,合格品入库记录!$A:$A,日报!U$3),"") | V10: =IF(SUMIFS(合格品入库记录!$G:$G,合格品入库记录!$E:$E,日报!$D:$D,合格品入库记录!$A:$A,日报!V$3)<>0,SUMIFS(合格品入库记录!$G:$G,合格品入库记录!$E:$E,日报!$D:$D,合格品入库记录!$A:$A,日报!V$3),"") -> 262 | W10: =IF(SUMIFS(合格品入库记录!$G:$G,合格品入库记录!$E:$E,日报!$D:$D,合格品入库记录!$A:$A,日报!W$3)<>0,SUMIFS(合格品入库记录!$G:$G,合格品入库记录!$E:$E,日报!$D:$D,合格品入库记录!$A:$A,日报!W$3),"") | ... AT10: =IF(SUMIFS(合格品入库记录!$G:$G,合格品入库记录!$E:$E,日报!$D:$D,合格品入库记录!$A:$A,日报!AT$3)<>0,SUMIFS(合格品入库记录!$G:$G,合格品入库记录!$E:$E,日报!$D:$D,合格品入库记录!$A:$A,日报!AT$3),"") | AU10: =IF(SUMIFS(合格品出库记录!$G:$G,合格品出库记录!$E:$E,日报!$D:$D,合格品出库记录!$A:$A,日报!AU$3)<>0,SUMIFS(合格品出库记录!$G:$G,合格品出库记录!$E:$E,日报!$D:$D,合格品出库记录!$A:$A,日报!AU$3),"") | AV10: =IF(SUMIFS(合格品出库记录!$G:$G,合格品出库记录!$E:$E,日报!$D:$D,合格品出库记录!$A:$A,日报!AV$3)<>0,SUMIFS(合格品出库记录!$G:$G,合格品出库记录!$E:$E,日报!$D:$D,合格品出库记录!$A:$A,日报!AV$3),"") | AW10: =IF(SUMIFS(合格品出库记录!$G:$G,合格品出库记录!$E:$E,日报!$D:$D,合格品出库记录!$A:$A,日报!AW$3)<>0,SUMIFS(合格品出库记录!$G:$G,合格品出库记录!$E:$E,日报!$D:$D,合格品出库记录!$A:$A,日报!AW$3),"") | AX10: =IF(SUMIFS(合格品出库记录!$G:$G,合格品出库记录!$E:$E,日报!$D:$D,合格品出库记录!$A:$A,日报!AX$3)<>0,SUMIFS(合格品出库记录!$G:$G,合格品出库记录!$E:$E,日报!$D:$D,合格品出库记录!$A:$A,日报!AX$3),"") | AY10: =IF(SUMIFS(合格品出库记录!$G:$G,合格品出库记录!$E:$E,日报!$D:$D,合格品出库记录!$A:$A,日报!AY$3)<>0,SUMIFS(合格品出库记录!$G:$G,合格品出库记录!$E:$E,日报!$D:$D,合格品出库记录!$A:$A,日报!AY$3),"") | AZ10: =IF(SUMIFS(合格品出库记录!$G:$G,合格品出库记录!$E:$E,日报!$D:$D,合格品出库记录!$A:$A,日报!AZ$3)<>0,SUMIFS(合格品出库记录!$G:$G,合格品出库记录!$E:$E,日报!$D:$D,合格品出库记录!$A:$A,日报!AZ$3),"") | BA10: =IF(SUMIFS(合格品出库记录!$G:$G,合格品出库记录!$E:$E,日报!$D:$D,合格品出库记录!$A:$A,日报!BA$3)<>0,SUMIFS(合格品出库记录!$G:$G,合格品出库记录!$E:$E,日报!$D:$D,合格品出库记录!$A:$A,日报!BA$3),"") | BB10: =IF(SUMIFS(合格品出库记录!$G:$G,合格品出库记录!$E:$E,日报!$D:$D,合格品出库记录!$A:$A,日报!BB$3)<>0,SUMIFS(合格品出库记录!$G:$G,合格品出库记录!$E:$E,日报!$D:$D,合格品出库记录!$A:$A,日报!BB$3),"") | ... BY10: =IF(SUMIFS(合格品出库记录!$G:$G,合格品出库记录!$E:$E,日报!$D:$D,合格品出库记录!$A:$A,日报!BY$3)<>0,SUMIFS(合格品出库记录!$G:$G,合格品出库记录!$E:$E,日报!$D:$D,合格品出库记录!$A:$A,日报!BY$3),"") | BZ10: =IF(SUMIFS(领跑良品退回!$G:$G,领跑良品退回!$E:$E,日报!$D:$D,领跑良品退回!$A:$A,日报!BZ$3)<>0,SUMIFS(领跑良品退回!$G:$G,领跑良品退回!$E:$E,日报!$D:$D,领跑良品退回!$A:$A,日报!BZ$3),"") | CA10: =IF(SUMIFS(领跑良品退回!$G:$G,领跑良品退回!$E:$E,日报!$D:$D,领跑良品退回!$A:$A,日报!CA$3)<>0,SUMIFS(领跑良品退回!$G:$G,领跑良品退回!$E:$E,日报!$D:$D,领跑良品退回!$A:$A,日报!CA$3),"") | CB10: =IF(SUMIFS(领跑良品退回!$G:$G,领跑良品退回!$E:$E,日报!$D:$D,领跑良品退回!$A:$A,日报!CB$3)<>0,SUMIFS(领跑良品退回!$G:$G,领跑良品退回!$E:$E,日报!$D:$D,领跑良品退回!$A:$A,日报!CB$3),"") | CC10: =IF(SUMIFS(领跑良品退回!$G:$G,领跑良品退回!$E:$E,日报!$D:$D,领跑良品退回!$A:$A,日报!CC$3)<>0,SUMIFS(领跑良品退回!$G:$G,领跑良品退回!$E:$E,日报!$D:$D,领跑良品退回!$A:$A,日报!CC$3),"") | CD10: =IF(SUMIFS(领跑良品退回!$G:$G,领跑良品退回!$E:$E,日报!$D:$D,领跑良品退回!$A:$A,日报!CD$3)<>0,SUMIFS(领跑良品退回!$G:$G,领跑良品退回!$E:$E,日报!$D:$D,领跑良品退回!$A:$A,日报!CD$3),"") | CE10: =IF(SUMIFS(领跑良品退回!$G:$G,领跑良品退回!$E:$E,日报!$D:$D,领跑良品退回!$A:$A,日报!CE$3)<>0,SUMIFS(领跑良品退回!$G:$G,领跑良品退回!$E:$E,日报!$D:$D,领跑良品退回!$A:$A,日报!CE$3),"") | CF10: =IF(SUMIFS(领跑良品退回!$G:$G,领跑良品退回!$E:$E,日报!$D:$D,领跑良品退回!$A:$A,日报!CF$3)<>0,SUMIFS(领跑良品退回!$G:$G,领跑良品退回!$E:$E,日报!$D:$D,领跑良品退回!$A:$A,日报!CF$3),"") | CG10: =IF(SUMIFS(领跑良品退回!$G:$G,领跑良品退回!$E:$E,日报!$D:$D,领跑良品退回!$A:$A,日报!CG$3)<>0,SUMIFS(领跑良品退回!$G:$G,领跑良品退回!$E:$E,日报!$D:$D,领跑良品退回!$A:$A,日报!CG$3),"") | ... DD10: =IF(SUMIFS(领跑良品退回!$G:$G,领跑良品退回!$E:$E,日报!$D:$D,领跑良品退回!$A:$A,日报!DD$3)<>0,SUMIFS(领跑良品退回!$G:$G,领跑良品退回!$E:$E,日报!$D:$D,领跑良品退回!$A:$A,日报!DD$3),"")
A11: 55 | B11: 1DC | C11: 东莞市硅翔绝缘材料有限公司 | D11: 3.2.49.08.00660-000 | E11: LPT03A_pBP-RP加热膜－T1 | F11: =IFERROR(VLOOKUP(D58,'[1]#REF'!D:F,3,FALSE),"0") -> 0 | G11: 127 | H11: =SUMIF(合格品入库记录!E:E,日报!D58,合格品入库记录!G:G) -> 0 | I11: =SUMIF(合格品出库记录!E:E,日报!D58,合格品出库记录!G:G) -> 0 | J11: =SUMIF(领跑良品退回!E:E,D58,领跑良品退回!G:G) -> 0 | K11: =M58+L58 -> 2576 | L11: =SUMIF(不良品库存!D:D,D:D,不良品库存!F:F) -> 0 | M11: =G58+H58-I58+J58 -> -353 | N11: 2400 | P11: =IF(SUMIFS(合格品入库记录!$G:$G,合格品入库记录!$E:$E,日报!$D:$D,合格品入库记录!$A:$A,日报!P$3)<>0,SUMIFS(合格品入库记录!$G:$G,合格品入库记录!$E:$E,日报!$D:$D,合格品入库记录!$A:$A,日报!P$3),"") | Q11: =IF(SUMIFS(合格品入库记录!$G:$G,合格品入库记录!$E:$E,日报!$D:$D,合格品入库记录!$A:$A,日报!Q$3)<>0,SUMIFS(合格品入库记录!$G:$G,合格品入库记录!$E:$E,日报!$D:$D,合格品入库记录!$A:$A,日报!Q$3),"") | R11: =IF(SUMIFS(合格品入库记录!$G:$G,合格品入库记录!$E:$E,日报!$D:$D,合格品入库记录!$A:$A,日报!R$3)<>0,SUMIFS(合格品入库记录!$G:$G,合格品入库记录!$E:$E,日报!$D:$D,合格品入库记录!$A:$A,日报!R$3),"") | S11: =IF(SUMIFS(合格品入库记录!$G:$G,合格品入库记录!$E:$E,日报!$D:$D,合格品入库记录!$A:$A,日报!S$3)<>0,SUMIFS(合格品入库记录!$G:$G,合格品入库记录!$E:$E,日报!$D:$D,合格品入库记录!$A:$A,日报!S$3),"") | T11: =IF(SUMIFS(合格品入库记录!$G:$G,合格品入库记录!$E:$E,日报!$D:$D,合格品入库记录!$A:$A,日报!T$3)<>0,SUMIFS(合格品入库记录!$G:$G,合格品入库记录!$E:$E,日报!$D:$D,合格品入库记录!$A:$A,日报!T$3),"") | U11: =IF(SUMIFS(合格品入库记录!$G:$G,合格品入库记录!$E:$E,日报!$D:$D,合格品入库记录!$A:$A,日报!U$3)<>0,SUMIFS(合格品入库记录!$G:$G,合格品入库记录!$E:$E,日报!$D:$D,合格品入库记录!$A:$A,日报!U$3),"") | V11: =IF(SUMIFS(合格品入库记录!$G:$G,合格品入库记录!$E:$E,日报!$D:$D,合格品入库记录!$A:$A,日报!V$3)<>0,SUMIFS(合格品入库记录!$G:$G,合格品入库记录!$E:$E,日报!$D:$D,合格品入库记录!$A:$A,日报!V$3),"") | W11: =IF(SUMIFS(合格品入库记录!$G:$G,合格品入库记录!$E:$E,日报!$D:$D,合格品入库记录!$A:$A,日报!W$3)<>0,SUMIFS(合格品入库记录!$G:$G,合格品入库记录!$E:$E,日报!$D:$D,合格品入库记录!$A:$A,日报!W$3),"") | ... AT11: =IF(SUMIFS(合格品入库记录!$G:$G,合格品入库记录!$E:$E,日报!$D:$D,合格品入库记录!$A:$A,日报!AT$3)<>0,SUMIFS(合格品入库记录!$G:$G,合格品入库记录!$E:$E,日报!$D:$D,合格品入库记录!$A:$A,日报!AT$3),"") | AU11: =IF(SUMIFS(合格品出库记录!$G:$G,合格品出库记录!$E:$E,日报!$D:$D,合格品出库记录!$A:$A,日报!AU$3)<>0,SUMIFS(合格品出库记录!$G:$G,合格品出库记录!$E:$E,日报!$D:$D,合格品出库记录!$A:$A,日报!AU$3),"") | AV11: =IF(SUMIFS(合格品出库记录!$G:$G,合格品出库记录!$E:$E,日报!$D:$D,合格品出库记录!$A:$A,日报!AV$3)<>0,SUMIFS(合格品出库记录!$G:$G,合格品出库记录!$E:$E,日报!$D:$D,合格品出库记录!$A:$A,日报!AV$3),"") | AW11: =IF(SUMIFS(合格品出库记录!$G:$G,合格品出库记录!$E:$E,日报!$D:$D,合格品出库记录!$A:$A,日报!AW$3)<>0,SUMIFS(合格品出库记录!$G:$G,合格品出库记录!$E:$E,日报!$D:$D,合格品出库记录!$A:$A,日报!AW$3),"") | AX11: =IF(SUMIFS(合格品出库记录!$G:$G,合格品出库记录!$E:$E,日报!$D:$D,合格品出库记录!$A:$A,日报!AX$3)<>0,SUMIFS(合格品出库记录!$G:$G,合格品出库记录!$E:$E,日报!$D:$D,合格品出库记录!$A:$A,日报!AX$3),"") | AY11: =IF(SUMIFS(合格品出库记录!$G:$G,合格品出库记录!$E:$E,日报!$D:$D,合格品出库记录!$A:$A,日报!AY$3)<>0,SUMIFS(合格品出库记录!$G:$G,合格品出库记录!$E:$E,日报!$D:$D,合格品出库记录!$A:$A,日报!AY$3),"") | AZ11: =IF(SUMIFS(合格品出库记录!$G:$G,合格品出库记录!$E:$E,日报!$D:$D,合格品出库记录!$A:$A,日报!AZ$3)<>0,SUMIFS(合格品出库记录!$G:$G,合格品出库记录!$E:$E,日报!$D:$D,合格品出库记录!$A:$A,日报!AZ$3),"") | BA11: =IF(SUMIFS(合格品出库记录!$G:$G,合格品出库记录!$E:$E,日报!$D:$D,合格品出库记录!$A:$A,日报!BA$3)<>0,SUMIFS(合格品出库记录!$G:$G,合格品出库记录!$E:$E,日报!$D:$D,合格品出库记录!$A:$A,日报!BA$3),"") | BB11: =IF(SUMIFS(合格品出库记录!$G:$G,合格品出库记录!$E:$E,日报!$D:$D,合格品出库记录!$A:$A,日报!BB$3)<>0,SUMIFS(合格品出库记录!$G:$G,合格品出库记录!$E:$E,日报!$D:$D,合格品出库记录!$A:$A,日报!BB$3),"") | ... BY11: =IF(SUMIFS(合格品出库记录!$G:$G,合格品出库记录!$E:$E,日报!$D:$D,合格品出库记录!$A:$A,日报!BY$3)<>0,SUMIFS(合格品出库记录!$G:$G,合格品出库记录!$E:$E,日报!$D:$D,合格品出库记录!$A:$A,日报!BY$3),"") | BZ11: =IF(SUMIFS(领跑良品退回!$G:$G,领跑良品退回!$E:$E,日报!$D:$D,领跑良品退回!$A:$A,日报!BZ$3)<>0,SUMIFS(领跑良品退回!$G:$G,领跑良品退回!$E:$E,日报!$D:$D,领跑良品退回!$A:$A,日报!BZ$3),"") | CA11: =IF(SUMIFS(领跑良品退回!$G:$G,领跑良品退回!$E:$E,日报!$D:$D,领跑良品退回!$A:$A,日报!CA$3)<>0,SUMIFS(领跑良品退回!$G:$G,领跑良品退回!$E:$E,日报!$D:$D,领跑良品退回!$A:$A,日报!CA$3),"") | CB11: =IF(SUMIFS(领跑良品退回!$G:$G,领跑良品退回!$E:$E,日报!$D:$D,领跑良品退回!$A:$A,日报!CB$3)<>0,SUMIFS(领跑良品退回!$G:$G,领跑良品退回!$E:$E,日报!$D:$D,领跑良品退回!$A:$A,日报!CB$3),"") | CC11: =IF(SUMIFS(领跑良品退回!$G:$G,领跑良品退回!$E:$E,日报!$D:$D,领跑良品退回!$A:$A,日报!CC$3)<>0,SUMIFS(领跑良品退回!$G:$G,领跑良品退回!$E:$E,日报!$D:$D,领跑良品退回!$A:$A,日报!CC$3),"") | CD11: =IF(SUMIFS(领跑良品退回!$G:$G,领跑良品退回!$E:$E,日报!$D:$D,领跑良品退回!$A:$A,日报!CD$3)<>0,SUMIFS(领跑良品退回!$G:$G,领跑良品退回!$E:$E,日报!$D:$D,领跑良品退回!$A:$A,日报!CD$3),"") | CE11: =IF(SUMIFS(领跑良品退回!$G:$G,领跑良品退回!$E:$E,日报!$D:$D,领跑良品退回!$A:$A,日报!CE$3)<>0,SUMIFS(领跑良品退回!$G:$G,领跑良品退回!$E:$E,日报!$D:$D,领跑良品退回!$A:$A,日报!CE$3),"") | CF11: =IF(SUMIFS(领跑良品退回!$G:$G,领跑良品退回!$E:$E,日报!$D:$D,领跑良品退回!$A:$A,日报!CF$3)<>0,SUMIFS(领跑良品退回!$G:$G,领跑良品退回!$E:$E,日报!$D:$D,领跑良品退回!$A:$A,日报!CF$3),"") | CG11: =IF(SUMIFS(领跑良品退回!$G:$G,领跑良品退回!$E:$E,日报!$D:$D,领跑良品退回!$A:$A,日报!CG$3)<>0,SUMIFS(领跑良品退回!$G:$G,领跑良品退回!$E:$E,日报!$D:$D,领跑良品退回!$A:$A,日报!CG$3),"") | ... DD11: =IF(SUMIFS(领跑良品退回!$G:$G,领跑良品退回!$E:$E,日报!$D:$D,领跑良品退回!$A:$A,日报!DD$3)<>0,SUMIFS(领跑良品退回!$G:$G,领跑良品退回!$E:$E,日报!$D:$D,领跑良品退回!$A:$A,日报!DD$3),"")
A12: 56 | B12: 1DC | C12: 东莞市硅翔绝缘材料有限公司 | D12: 3.2.49.08.00835-000 | E12: T03-2001P40S-FPC-L | F12: =IFERROR(VLOOKUP(D59,'[1]#REF'!D:F,3,FALSE),"0") -> 0 | G12: 0 | H12: =SUMIF(合格品入库记录!E:E,日报!D59,合格品入库记录!G:G) -> 0 | I12: =SUMIF(合格品出库记录!E:E,日报!D59,合格品出库记录!G:G) -> 0 | J12: =SUMIF(领跑良品退回!E:E,D59,领跑良品退回!G:G) -> 0 | K12: =M59+L59 -> 0 | L12: =SUMIF(不良品库存!D:D,D:D,不良品库存!F:F) -> 0 | M12: =G59+H59-I59+J59 -> 12 | N12: #N/A | P12: =IF(SUMIFS(合格品入库记录!$G:$G,合格品入库记录!$E:$E,日报!$D:$D,合格品入库记录!$A:$A,日报!P$3)<>0,SUMIFS(合格品入库记录!$G:$G,合格品入库记录!$E:$E,日报!$D:$D,合格品入库记录!$A:$A,日报!P$3),"") | Q12: =IF(SUMIFS(合格品入库记录!$G:$G,合格品入库记录!$E:$E,日报!$D:$D,合格品入库记录!$A:$A,日报!Q$3)<>0,SUMIFS(合格品入库记录!$G:$G,合格品入库记录!$E:$E,日报!$D:$D,合格品入库记录!$A:$A,日报!Q$3),"") | R12: =IF(SUMIFS(合格品入库记录!$G:$G,合格品入库记录!$E:$E,日报!$D:$D,合格品入库记录!$A:$A,日报!R$3)<>0,SUMIFS(合格品入库记录!$G:$G,合格品入库记录!$E:$E,日报!$D:$D,合格品入库记录!$A:$A,日报!R$3),"") | S12: =IF(SUMIFS(合格品入库记录!$G:$G,合格品入库记录!$E:$E,日报!$D:$D,合格品入库记录!$A:$A,日报!S$3)<>0,SUMIFS(合格品入库记录!$G:$G,合格品入库记录!$E:$E,日报!$D:$D,合格品入库记录!$A:$A,日报!S$3),"") | T12: =IF(SUMIFS(合格品入库记录!$G:$G,合格品入库记录!$E:$E,日报!$D:$D,合格品入库记录!$A:$A,日报!T$3)<>0,SUMIFS(合格品入库记录!$G:$G,合格品入库记录!$E:$E,日报!$D:$D,合格品入库记录!$A:$A,日报!T$3),"") | U12: =IF(SUMIFS(合格品入库记录!$G:$G,合格品入库记录!$E:$E,日报!$D:$D,合格品入库记录!$A:$A,日报!U$3)<>0,SUMIFS(合格品入库记录!$G:$G,合格品入库记录!$E:$E,日报!$D:$D,合格品入库记录!$A:$A,日报!U$3),"") | V12: =IF(SUMIFS(合格品入库记录!$G:$G,合格品入库记录!$E:$E,日报!$D:$D,合格品入库记录!$A:$A,日报!V$3)<>0,SUMIFS(合格品入库记录!$G:$G,合格品入库记录!$E:$E,日报!$D:$D,合格品入库记录!$A:$A,日报!V$3),"") | W12: =IF(SUMIFS(合格品入库记录!$G:$G,合格品入库记录!$E:$E,日报!$D:$D,合格品入库记录!$A:$A,日报!W$3)<>0,SUMIFS(合格品入库记录!$G:$G,合格品入库记录!$E:$E,日报!$D:$D,合格品入库记录!$A:$A,日报!W$3),"") | ... AT12: =IF(SUMIFS(合格品入库记录!$G:$G,合格品入库记录!$E:$E,日报!$D:$D,合格品入库记录!$A:$A,日报!AT$3)<>0,SUMIFS(合格品入库记录!$G:$G,合格品入库记录!$E:$E,日报!$D:$D,合格品入库记录!$A:$A,日报!AT$3),"") | AU12: =IF(SUMIFS(合格品出库记录!$G:$G,合格品出库记录!$E:$E,日报!$D:$D,合格品出库记录!$A:$A,日报!AU$3)<>0,SUMIFS(合格品出库记录!$G:$G,合格品出库记录!$E:$E,日报!$D:$D,合格品出库记录!$A:$A,日报!AU$3),"") | AV12: =IF(SUMIFS(合格品出库记录!$G:$G,合格品出库记录!$E:$E,日报!$D:$D,合格品出库记录!$A:$A,日报!AV$3)<>0,SUMIFS(合格品出库记录!$G:$G,合格品出库记录!$E:$E,日报!$D:$D,合格品出库记录!$A:$A,日报!AV$3),"") | AW12: =IF(SUMIFS(合格品出库记录!$G:$G,合格品出库记录!$E:$E,日报!$D:$D,合格品出库记录!$A:$A,日报!AW$3)<>0,SUMIFS(合格品出库记录!$G:$G,合格品出库记录!$E:$E,日报!$D:$D,合格品出库记录!$A:$A,日报!AW$3),"") | AX12: =IF(SUMIFS(合格品出库记录!$G:$G,合格品出库记录!$E:$E,日报!$D:$D,合格品出库记录!$A:$A,日报!AX$3)<>0,SUMIFS(合格品出库记录!$G:$G,合格品出库记录!$E:$E,日报!$D:$D,合格品出库记录!$A:$A,日报!AX$3),"") | AY12: =IF(SUMIFS(合格品出库记录!$G:$G,合格品出库记录!$E:$E,日报!$D:$D,合格品出库记录!$A:$A,日报!AY$3)<>0,SUMIFS(合格品出库记录!$G:$G,合格品出库记录!$E:$E,日报!$D:$D,合格品出库记录!$A:$A,日报!AY$3),"") | AZ12: =IF(SUMIFS(合格品出库记录!$G:$G,合格品出库记录!$E:$E,日报!$D:$D,合格品出库记录!$A:$A,日报!AZ$3)<>0,SUMIFS(合格品出库记录!$G:$G,合格品出库记录!$E:$E,日报!$D:$D,合格品出库记录!$A:$A,日报!AZ$3),"") | BA12: =IF(SUMIFS(合格品出库记录!$G:$G,合格品出库记录!$E:$E,日报!$D:$D,合格品出库记录!$A:$A,日报!BA$3)<>0,SUMIFS(合格品出库记录!$G:$G,合格品出库记录!$E:$E,日报!$D:$D,合格品出库记录!$A:$A,日报!BA$3),"") | BB12: =IF(SUMIFS(合格品出库记录!$G:$G,合格品出库记录!$E:$E,日报!$D:$D,合格品出库记录!$A:$A,日报!BB$3)<>0,SUMIFS(合格品出库记录!$G:$G,合格品出库记录!$E:$E,日报!$D:$D,合格品出库记录!$A:$A,日报!BB$3),"") | ... BY12: =IF(SUMIFS(合格品出库记录!$G:$G,合格品出库记录!$E:$E,日报!$D:$D,合格品出库记录!$A:$A,日报!BY$3)<>0,SUMIFS(合格品出库记录!$G:$G,合格品出库记录!$E:$E,日报!$D:$D,合格品出库记录!$A:$A,日报!BY$3),"") | BZ12: =IF(SUMIFS(领跑良品退回!$G:$G,领跑良品退回!$E:$E,日报!$D:$D,领跑良品退回!$A:$A,日报!BZ$3)<>0,SUMIFS(领跑良品退回!$G:$G,领跑良品退回!$E:$E,日报!$D:$D,领跑良品退回!$A:$A,日报!BZ$3),"") | CA12: =IF(SUMIFS(领跑良品退回!$G:$G,领跑良品退回!$E:$E,日报!$D:$D,领跑良品退回!$A:$A,日报!CA$3)<>0,SUMIFS(领跑良品退回!$G:$G,领跑良品退回!$E:$E,日报!$D:$D,领跑良品退回!$A:$A,日报!CA$3),"") | CB12: =IF(SUMIFS(领跑良品退回!$G:$G,领跑良品退回!$E:$E,日报!$D:$D,领跑良品退回!$A:$A,日报!CB$3)<>0,SUMIFS(领跑良品退回!$G:$G,领跑良品退回!$E:$E,日报!$D:$D,领跑良品退回!$A:$A,日报!CB$3),"") | CC12: =IF(SUMIFS(领跑良品退回!$G:$G,领跑良品退回!$E:$E,日报!$D:$D,领跑良品退回!$A:$A,日报!CC$3)<>0,SUMIFS(领跑良品退回!$G:$G,领跑良品退回!$E:$E,日报!$D:$D,领跑良品退回!$A:$A,日报!CC$3),"") | CD12: =IF(SUMIFS(领跑良品退回!$G:$G,领跑良品退回!$E:$E,日报!$D:$D,领跑良品退回!$A:$A,日报!CD$3)<>0,SUMIFS(领跑良品退回!$G:$G,领跑良品退回!$E:$E,日报!$D:$D,领跑良品退回!$A:$A,日报!CD$3),"") | CE12: =IF(SUMIFS(领跑良品退回!$G:$G,领跑良品退回!$E:$E,日报!$D:$D,领跑良品退回!$A:$A,日报!CE$3)<>0,SUMIFS(领跑良品退回!$G:$G,领跑良品退回!$E:$E,日报!$D:$D,领跑良品退回!$A:$A,日报!CE$3),"") | CF12: =IF(SUMIFS(领跑良品退回!$G:$G,领跑良品退回!$E:$E,日报!$D:$D,领跑良品退回!$A:$A,日报!CF$3)<>0,SUMIFS(领跑良品退回!$G:$G,领跑良品退回!$E:$E,日报!$D:$D,领跑良品退回!$A:$A,日报!CF$3),"") | CG12: =IF(SUMIFS(领跑良品退回!$G:$G,领跑良品退回!$E:$E,日报!$D:$D,领跑良品退回!$A:$A,日报!CG$3)<>0,SUMIFS(领跑良品退回!$G:$G,领跑良品退回!$E:$E,日报!$D:$D,领跑良品退回!$A:$A,日报!CG$3),"") | ... DD12: =IF(SUMIFS(领跑良品退回!$G:$G,领跑良品退回!$E:$E,日报!$D:$D,领跑良品退回!$A:$A,日报!DD$3)<>0,SUMIFS(领跑良品退回!$G:$G,领跑良品退回!$E:$E,日报!$D:$D,领跑良品退回!$A:$A,日报!DD$3),"")
A13: 57 | B13: 1DC | C13: 东莞市硅翔绝缘材料有限公司 | D13: 3.2.49.08.00836-000 | E13: T03-2001P40S-FPC-R | F13: =IFERROR(VLOOKUP(D60,'[1]#REF'!D:F,3,FALSE),"0") -> 0 | G13: 0 | H13: =SUMIF(合格品入库记录!E:E,日报!D60,合格品入库记录!G:G) -> 0 | I13: =SUMIF(合格品出库记录!E:E,日报!D60,合格品出库记录!G:G) -> 0 | J13: =SUMIF(领跑良品退回!E:E,D60,领跑良品退回!G:G) -> 0 | K13: =M60+L60 -> 0 | L13: =SUMIF(不良品库存!D:D,D:D,不良品库存!F:F) -> 0 | M13: =G60+H60-I60+J60 -> 34 | N13: #N/A | P13: =IF(SUMIFS(合格品入库记录!$G:$G,合格品入库记录!$E:$E,日报!$D:$D,合格品入库记录!$A:$A,日报!P$3)<>0,SUMIFS(合格品入库记录!$G:$G,合格品入库记录!$E:$E,日报!$D:$D,合格品入库记录!$A:$A,日报!P$3),"") | Q13: =IF(SUMIFS(合格品入库记录!$G:$G,合格品入库记录!$E:$E,日报!$D:$D,合格品入库记录!$A:$A,日报!Q$3)<>0,SUMIFS(合格品入库记录!$G:$G,合格品入库记录!$E:$E,日报!$D:$D,合格品入库记录!$A:$A,日报!Q$3),"") | R13: =IF(SUMIFS(合格品入库记录!$G:$G,合格品入库记录!$E:$E,日报!$D:$D,合格品入库记录!$A:$A,日报!R$3)<>0,SUMIFS(合格品入库记录!$G:$G,合格品入库记录!$E:$E,日报!$D:$D,合格品入库记录!$A:$A,日报!R$3),"") | S13: =IF(SUMIFS(合格品入库记录!$G:$G,合格品入库记录!$E:$E,日报!$D:$D,合格品入库记录!$A:$A,日报!S$3)<>0,SUMIFS(合格品入库记录!$G:$G,合格品入库记录!$E:$E,日报!$D:$D,合格品入库记录!$A:$A,日报!S$3),"") | T13: =IF(SUMIFS(合格品入库记录!$G:$G,合格品入库记录!$E:$E,日报!$D:$D,合格品入库记录!$A:$A,日报!T$3)<>0,SUMIFS(合格品入库记录!$G:$G,合格品入库记录!$E:$E,日报!$D:$D,合格品入库记录!$A:$A,日报!T$3),"") | U13: =IF(SUMIFS(合格品入库记录!$G:$G,合格品入库记录!$E:$E,日报!$D:$D,合格品入库记录!$A:$A,日报!U$3)<>0,SUMIFS(合格品入库记录!$G:$G,合格品入库记录!$E:$E,日报!$D:$D,合格品入库记录!$A:$A,日报!U$3),"") | V13: =IF(SUMIFS(合格品入库记录!$G:$G,合格品入库记录!$E:$E,日报!$D:$D,合格品入库记录!$A:$A,日报!V$3)<>0,SUMIFS(合格品入库记录!$G:$G,合格品入库记录!$E:$E,日报!$D:$D,合格品入库记录!$A:$A,日报!V$3),"") | W13: =IF(SUMIFS(合格品入库记录!$G:$G,合格品入库记录!$E:$E,日报!$D:$D,合格品入库记录!$A:$A,日报!W$3)<>0,SUMIFS(合格品入库记录!$G:$G,合格品入库记录!$E:$E,日报!$D:$D,合格品入库记录!$A:$A,日报!W$3),"") | ... AT13: =IF(SUMIFS(合格品入库记录!$G:$G,合格品入库记录!$E:$E,日报!$D:$D,合格品入库记录!$A:$A,日报!AT$3)<>0,SUMIFS(合格品入库记录!$G:$G,合格品入库记录!$E:$E,日报!$D:$D,合格品入库记录!$A:$A,日报!AT$3),"") | AU13: =IF(SUMIFS(合格品出库记录!$G:$G,合格品出库记录!$E:$E,日报!$D:$D,合格品出库记录!$A:$A,日报!AU$3)<>0,SUMIFS(合格品出库记录!$G:$G,合格品出库记录!$E:$E,日报!$D:$D,合格品出库记录!$A:$A,日报!AU$3),"") | AV13: =IF(SUMIFS(合格品出库记录!$G:$G,合格品出库记录!$E:$E,日报!$D:$D,合格品出库记录!$A:$A,日报!AV$3)<>0,SUMIFS(合格品出库记录!$G:$G,合格品出库记录!$E:$E,日报!$D:$D,合格品出库记录!$A:$A,日报!AV$3),"") | AW13: =IF(SUMIFS(合格品出库记录!$G:$G,合格品出库记录!$E:$E,日报!$D:$D,合格品出库记录!$A:$A,日报!AW$3)<>0,SUMIFS(合格品出库记录!$G:$G,合格品出库记录!$E:$E,日报!$D:$D,合格品出库记录!$A:$A,日报!AW$3),"") | AX13: =IF(SUMIFS(合格品出库记录!$G:$G,合格品出库记录!$E:$E,日报!$D:$D,合格品出库记录!$A:$A,日报!AX$3)<>0,SUMIFS(合格品出库记录!$G:$G,合格品出库记录!$E:$E,日报!$D:$D,合格品出库记录!$A:$A,日报!AX$3),"") | AY13: =IF(SUMIFS(合格品出库记录!$G:$G,合格品出库记录!$E:$E,日报!$D:$D,合格品出库记录!$A:$A,日报!AY$3)<>0,SUMIFS(合格品出库记录!$G:$G,合格品出库记录!$E:$E,日报!$D:$D,合格品出库记录!$A:$A,日报!AY$3),"") | AZ13: =IF(SUMIFS(合格品出库记录!$G:$G,合格品出库记录!$E:$E,日报!$D:$D,合格品出库记录!$A:$A,日报!AZ$3)<>0,SUMIFS(合格品出库记录!$G:$G,合格品出库记录!$E:$E,日报!$D:$D,合格品出库记录!$A:$A,日报!AZ$3),"") | BA13: =IF(SUMIFS(合格品出库记录!$G:$G,合格品出库记录!$E:$E,日报!$D:$D,合格品出库记录!$A:$A,日报!BA$3)<>0,SUMIFS(合格品出库记录!$G:$G,合格品出库记录!$E:$E,日报!$D:$D,合格品出库记录!$A:$A,日报!BA$3),"") | BB13: =IF(SUMIFS(合格品出库记录!$G:$G,合格品出库记录!$E:$E,日报!$D:$D,合格品出库记录!$A:$A,日报!BB$3)<>0,SUMIFS(合格品出库记录!$G:$G,合格品出库记录!$E:$E,日报!$D:$D,合格品出库记录!$A:$A,日报!BB$3),"") | ... BY13: =IF(SUMIFS(合格品出库记录!$G:$G,合格品出库记录!$E:$E,日报!$D:$D,合格品出库记录!$A:$A,日报!BY$3)<>0,SUMIFS(合格品出库记录!$G:$G,合格品出库记录!$E:$E,日报!$D:$D,合格品出库记录!$A:$A,日报!BY$3),"") | BZ13: =IF(SUMIFS(领跑良品退回!$G:$G,领跑良品退回!$E:$E,日报!$D:$D,领跑良品退回!$A:$A,日报!BZ$3)<>0,SUMIFS(领跑良品退回!$G:$G,领跑良品退回!$E:$E,日报!$D:$D,领跑良品退回!$A:$A,日报!BZ$3),"") | CA13: =IF(SUMIFS(领跑良品退回!$G:$G,领跑良品退回!$E:$E,日报!$D:$D,领跑良品退回!$A:$A,日报!CA$3)<>0,SUMIFS(领跑良品退回!$G:$G,领跑良品退回!$E:$E,日报!$D:$D,领跑良品退回!$A:$A,日报!CA$3),"") | CB13: =IF(SUMIFS(领跑良品退回!$G:$G,领跑良品退回!$E:$E,日报!$D:$D,领跑良品退回!$A:$A,日报!CB$3)<>0,SUMIFS(领跑良品退回!$G:$G,领跑良品退回!$E:$E,日报!$D:$D,领跑良品退回!$A:$A,日报!CB$3),"") | CC13: =IF(SUMIFS(领跑良品退回!$G:$G,领跑良品退回!$E:$E,日报!$D:$D,领跑良品退回!$A:$A,日报!CC$3)<>0,SUMIFS(领跑良品退回!$G:$G,领跑良品退回!$E:$E,日报!$D:$D,领跑良品退回!$A:$A,日报!CC$3),"") | CD13: =IF(SUMIFS(领跑良品退回!$G:$G,领跑良品退回!$E:$E,日报!$D:$D,领跑良品退回!$A:$A,日报!CD$3)<>0,SUMIFS(领跑良品退回!$G:$G,领跑良品退回!$E:$E,日报!$D:$D,领跑良品退回!$A:$A,日报!CD$3),"") | CE13: =IF(SUMIFS(领跑良品退回!$G:$G,领跑良品退回!$E:$E,日报!$D:$D,领跑良品退回!$A:$A,日报!CE$3)<>0,SUMIFS(领跑良品退回!$G:$G,领跑良品退回!$E:$E,日报!$D:$D,领跑良品退回!$A:$A,日报!CE$3),"") | CF13: =IF(SUMIFS(领跑良品退回!$G:$G,领跑良品退回!$E:$E,日报!$D:$D,领跑良品退回!$A:$A,日报!CF$3)<>0,SUMIFS(领跑良品退回!$G:$G,领跑良品退回!$E:$E,日报!$D:$D,领跑良品退回!$A:$A,日报!CF$3),"") | CG13: =IF(SUMIFS(领跑良品退回!$G:$G,领跑良品退回!$E:$E,日报!$D:$D,领跑良品退回!$A:$A,日报!CG$3)<>0,SUMIFS(领跑良品退回!$G:$G,领跑良品退回!$E:$E,日报!$D:$D,领跑良品退回!$A:$A,日报!CG$3),"") | ... DD13: =IF(SUMIFS(领跑良品退回!$G:$G,领跑良品退回!$E:$E,日报!$D:$D,领跑良品退回!$A:$A,日报!DD$3)<>0,SUMIFS(领跑良品退回!$G:$G,领跑良品退回!$E:$E,日报!$D:$D,领跑良品退回!$A:$A,日报!DD$3),"")
A14: 58 | B14: 1DC | C14: 东莞市硅翔绝缘材料有限公司 | D14: 3.2.49.08.00332-000 | E14: LP-C11RE0-CCS 总成-21B | F14: =IFERROR(VLOOKUP(D61,'[1]#REF'!D:F,3,FALSE),"0") -> 0 | G14: 2 | H14: =SUMIF(合格品入库记录!E:E,日报!D61,合格品入库记录!G:G) -> 0 | I14: =SUMIF(合格品出库记录!E:E,日报!D61,合格品出库记录!G:G) -> 0 | J14: =SUMIF(领跑良品退回!E:E,D61,领跑良品退回!G:G) -> 0 | K14: =M61+L61 -> 0 | L14: =SUMIF(不良品库存!D:D,D:D,不良品库存!F:F) -> 0 | M14: =G61+H61-I61+J61 -> 0 | N14: 1280 | P14: =IF(SUMIFS(合格品入库记录!$G:$G,合格品入库记录!$E:$E,日报!$D:$D,合格品入库记录!$A:$A,日报!P$3)<>0,SUMIFS(合格品入库记录!$G:$G,合格品入库记录!$E:$E,日报!$D:$D,合格品入库记录!$A:$A,日报!P$3),"") | Q14: =IF(SUMIFS(合格品入库记录!$G:$G,合格品入库记录!$E:$E,日报!$D:$D,合格品入库记录!$A:$A,日报!Q$3)<>0,SUMIFS(合格品入库记录!$G:$G,合格品入库记录!$E:$E,日报!$D:$D,合格品入库记录!$A:$A,日报!Q$3),"") | R14: =IF(SUMIFS(合格品入库记录!$G:$G,合格品入库记录!$E:$E,日报!$D:$D,合格品入库记录!$A:$A,日报!R$3)<>0,SUMIFS(合格品入库记录!$G:$G,合格品入库记录!$E:$E,日报!$D:$D,合格品入库记录!$A:$A,日报!R$3),"") | S14: =IF(SUMIFS(合格品入库记录!$G:$G,合格品入库记录!$E:$E,日报!$D:$D,合格品入库记录!$A:$A,日报!S$3)<>0,SUMIFS(合格品入库记录!$G:$G,合格品入库记录!$E:$E,日报!$D:$D,合格品入库记录!$A:$A,日报!S$3),"") | T14: =IF(SUMIFS(合格品入库记录!$G:$G,合格品入库记录!$E:$E,日报!$D:$D,合格品入库记录!$A:$A,日报!T$3)<>0,SUMIFS(合格品入库记录!$G:$G,合格品入库记录!$E:$E,日报!$D:$D,合格品入库记录!$A:$A,日报!T$3),"") | U14: =IF(SUMIFS(合格品入库记录!$G:$G,合格品入库记录!$E:$E,日报!$D:$D,合格品入库记录!$A:$A,日报!U$3)<>0,SUMIFS(合格品入库记录!$G:$G,合格品入库记录!$E:$E,日报!$D:$D,合格品入库记录!$A:$A,日报!U$3),"") | V14: =IF(SUMIFS(合格品入库记录!$G:$G,合格品入库记录!$E:$E,日报!$D:$D,合格品入库记录!$A:$A,日报!V$3)<>0,SUMIFS(合格品入库记录!$G:$G,合格品入库记录!$E:$E,日报!$D:$D,合格品入库记录!$A:$A,日报!V$3),"") | W14: =IF(SUMIFS(合格品入库记录!$G:$G,合格品入库记录!$E:$E,日报!$D:$D,合格品入库记录!$A:$A,日报!W$3)<>0,SUMIFS(合格品入库记录!$G:$G,合格品入库记录!$E:$E,日报!$D:$D,合格品入库记录!$A:$A,日报!W$3),"") | ... AT14: =IF(SUMIFS(合格品入库记录!$G:$G,合格品入库记录!$E:$E,日报!$D:$D,合格品入库记录!$A:$A,日报!AT$3)<>0,SUMIFS(合格品入库记录!$G:$G,合格品入库记录!$E:$E,日报!$D:$D,合格品入库记录!$A:$A,日报!AT$3),"") | AU14: =IF(SUMIFS(合格品出库记录!$G:$G,合格品出库记录!$E:$E,日报!$D:$D,合格品出库记录!$A:$A,日报!AU$3)<>0,SUMIFS(合格品出库记录!$G:$G,合格品出库记录!$E:$E,日报!$D:$D,合格品出库记录!$A:$A,日报!AU$3),"") | AV14: =IF(SUMIFS(合格品出库记录!$G:$G,合格品出库记录!$E:$E,日报!$D:$D,合格品出库记录!$A:$A,日报!AV$3)<>0,SUMIFS(合格品出库记录!$G:$G,合格品出库记录!$E:$E,日报!$D:$D,合格品出库记录!$A:$A,日报!AV$3),"") | AW14: =IF(SUMIFS(合格品出库记录!$G:$G,合格品出库记录!$E:$E,日报!$D:$D,合格品出库记录!$A:$A,日报!AW$3)<>0,SUMIFS(合格品出库记录!$G:$G,合格品出库记录!$E:$E,日报!$D:$D,合格品出库记录!$A:$A,日报!AW$3),"") | AX14: =IF(SUMIFS(合格品出库记录!$G:$G,合格品出库记录!$E:$E,日报!$D:$D,合格品出库记录!$A:$A,日报!AX$3)<>0,SUMIFS(合格品出库记录!$G:$G,合格品出库记录!$E:$E,日报!$D:$D,合格品出库记录!$A:$A,日报!AX$3),"") | AY14: =IF(SUMIFS(合格品出库记录!$G:$G,合格品出库记录!$E:$E,日报!$D:$D,合格品出库记录!$A:$A,日报!AY$3)<>0,SUMIFS(合格品出库记录!$G:$G,合格品出库记录!$E:$E,日报!$D:$D,合格品出库记录!$A:$A,日报!AY$3),"") | AZ14: =IF(SUMIFS(合格品出库记录!$G:$G,合格品出库记录!$E:$E,日报!$D:$D,合格品出库记录!$A:$A,日报!AZ$3)<>0,SUMIFS(合格品出库记录!$G:$G,合格品出库记录!$E:$E,日报!$D:$D,合格品出库记录!$A:$A,日报!AZ$3),"") | BA14: =IF(SUMIFS(合格品出库记录!$G:$G,合格品出库记录!$E:$E,日报!$D:$D,合格品出库记录!$A:$A,日报!BA$3)<>0,SUMIFS(合格品出库记录!$G:$G,合格品出库记录!$E:$E,日报!$D:$D,合格品出库记录!$A:$A,日报!BA$3),"") | BB14: =IF(SUMIFS(合格品出库记录!$G:$G,合格品出库记录!$E:$E,日报!$D:$D,合格品出库记录!$A:$A,日报!BB$3)<>0,SUMIFS(合格品出库记录!$G:$G,合格品出库记录!$E:$E,日报!$D:$D,合格品出库记录!$A:$A,日报!BB$3),"") | ... BY14: =IF(SUMIFS(合格品出库记录!$G:$G,合格品出库记录!$E:$E,日报!$D:$D,合格品出库记录!$A:$A,日报!BY$3)<>0,SUMIFS(合格品出库记录!$G:$G,合格品出库记录!$E:$E,日报!$D:$D,合格品出库记录!$A:$A,日报!BY$3),"") | BZ14: =IF(SUMIFS(领跑良品退回!$G:$G,领跑良品退回!$E:$E,日报!$D:$D,领跑良品退回!$A:$A,日报!BZ$3)<>0,SUMIFS(领跑良品退回!$G:$G,领跑良品退回!$E:$E,日报!$D:$D,领跑良品退回!$A:$A,日报!BZ$3),"") | CA14: =IF(SUMIFS(领跑良品退回!$G:$G,领跑良品退回!$E:$E,日报!$D:$D,领跑良品退回!$A:$A,日报!CA$3)<>0,SUMIFS(领跑良品退回!$G:$G,领跑良品退回!$E:$E,日报!$D:$D,领跑良品退回!$A:$A,日报!CA$3),"") | CB14: =IF(SUMIFS(领跑良品退回!$G:$G,领跑良品退回!$E:$E,日报!$D:$D,领跑良品退回!$A:$A,日报!CB$3)<>0,SUMIFS(领跑良品退回!$G:$G,领跑良品退回!$E:$E,日报!$D:$D,领跑良品退回!$A:$A,日报!CB$3),"") | CC14: =IF(SUMIFS(领跑良品退回!$G:$G,领跑良品退回!$E:$E,日报!$D:$D,领跑良品退回!$A:$A,日报!CC$3)<>0,SUMIFS(领跑良品退回!$G:$G,领跑良品退回!$E:$E,日报!$D:$D,领跑良品退回!$A:$A,日报!CC$3),"") | CD14: =IF(SUMIFS(领跑良品退回!$G:$G,领跑良品退回!$E:$E,日报!$D:$D,领跑良品退回!$A:$A,日报!CD$3)<>0,SUMIFS(领跑良品退回!$G:$G,领跑良品退回!$E:$E,日报!$D:$D,领跑良品退回!$A:$A,日报!CD$3),"") | CE14: =IF(SUMIFS(领跑良品退回!$G:$G,领跑良品退回!$E:$E,日报!$D:$D,领跑良品退回!$A:$A,日报!CE$3)<>0,SUMIFS(领跑良品退回!$G:$G,领跑良品退回!$E:$E,日报!$D:$D,领跑良品退回!$A:$A,日报!CE$3),"") | CF14: =IF(SUMIFS(领跑良品退回!$G:$G,领跑良品退回!$E:$E,日报!$D:$D,领跑良品退回!$A:$A,日报!CF$3)<>0,SUMIFS(领跑良品退回!$G:$G,领跑良品退回!$E:$E,日报!$D:$D,领跑良品退回!$A:$A,日报!CF$3),"") | CG14: =IF(SUMIFS(领跑良品退回!$G:$G,领跑良品退回!$E:$E,日报!$D:$D,领跑良品退回!$A:$A,日报!CG$3)<>0,SUMIFS(领跑良品退回!$G:$G,领跑良品退回!$E:$E,日报!$D:$D,领跑良品退回!$A:$A,日报!CG$3),"") | ... DD14: =IF(SUMIFS(领跑良品退回!$G:$G,领跑良品退回!$E:$E,日报!$D:$D,领跑良品退回!$A:$A,日报!DD$3)<>0,SUMIFS(领跑良品退回!$G:$G,领跑良品退回!$E:$E,日报!$D:$D,领跑良品退回!$A:$A,日报!DD$3),"")
A15: 59 | B15: 1DC | C15: 东莞市硅翔绝缘材料有限公司 | D15: 3.2.49.08.00331-000 | E15: LP-C11RE0-CCS 总成-21A | F15: =IFERROR(VLOOKUP(D62,'[1]#REF'!D:F,3,FALSE),"0") -> 0 | G15: 482 | H15: =SUMIF(合格品入库记录!E:E,日报!D62,合格品入库记录!G:G) -> 0 | I15: =SUMIF(合格品出库记录!E:E,日报!D62,合格品出库记录!G:G) -> 700 | J15: =SUMIF(领跑良品退回!E:E,D62,领跑良品退回!G:G) -> 0 | K15: =M62+L62 -> 100 | L15: =SUMIF(不良品库存!D:D,D:D,不良品库存!F:F) -> 50 | M15: =G62+H62-I62+J62 -> 700 | N15: 1280 | P15: =IF(SUMIFS(合格品入库记录!$G:$G,合格品入库记录!$E:$E,日报!$D:$D,合格品入库记录!$A:$A,日报!P$3)<>0,SUMIFS(合格品入库记录!$G:$G,合格品入库记录!$E:$E,日报!$D:$D,合格品入库记录!$A:$A,日报!P$3),"") | Q15: =IF(SUMIFS(合格品入库记录!$G:$G,合格品入库记录!$E:$E,日报!$D:$D,合格品入库记录!$A:$A,日报!Q$3)<>0,SUMIFS(合格品入库记录!$G:$G,合格品入库记录!$E:$E,日报!$D:$D,合格品入库记录!$A:$A,日报!Q$3),"") | R15: =IF(SUMIFS(合格品入库记录!$G:$G,合格品入库记录!$E:$E,日报!$D:$D,合格品入库记录!$A:$A,日报!R$3)<>0,SUMIFS(合格品入库记录!$G:$G,合格品入库记录!$E:$E,日报!$D:$D,合格品入库记录!$A:$A,日报!R$3),"") | S15: =IF(SUMIFS(合格品入库记录!$G:$G,合格品入库记录!$E:$E,日报!$D:$D,合格品入库记录!$A:$A,日报!S$3)<>0,SUMIFS(合格品入库记录!$G:$G,合格品入库记录!$E:$E,日报!$D:$D,合格品入库记录!$A:$A,日报!S$3),"") | T15: =IF(SUMIFS(合格品入库记录!$G:$G,合格品入库记录!$E:$E,日报!$D:$D,合格品入库记录!$A:$A,日报!T$3)<>0,SUMIFS(合格品入库记录!$G:$G,合格品入库记录!$E:$E,日报!$D:$D,合格品入库记录!$A:$A,日报!T$3),"") | U15: =IF(SUMIFS(合格品入库记录!$G:$G,合格品入库记录!$E:$E,日报!$D:$D,合格品入库记录!$A:$A,日报!U$3)<>0,SUMIFS(合格品入库记录!$G:$G,合格品入库记录!$E:$E,日报!$D:$D,合格品入库记录!$A:$A,日报!U$3),"") | V15: =IF(SUMIFS(合格品入库记录!$G:$G,合格品入库记录!$E:$E,日报!$D:$D,合格品入库记录!$A:$A,日报!V$3)<>0,SUMIFS(合格品入库记录!$G:$G,合格品入库记录!$E:$E,日报!$D:$D,合格品入库记录!$A:$A,日报!V$3),"") | W15: =IF(SUMIFS(合格品入库记录!$G:$G,合格品入库记录!$E:$E,日报!$D:$D,合格品入库记录!$A:$A,日报!W$3)<>0,SUMIFS(合格品入库记录!$G:$G,合格品入库记录!$E:$E,日报!$D:$D,合格品入库记录!$A:$A,日报!W$3),"") | ... AT15: =IF(SUMIFS(合格品入库记录!$G:$G,合格品入库记录!$E:$E,日报!$D:$D,合格品入库记录!$A:$A,日报!AT$3)<>0,SUMIFS(合格品入库记录!$G:$G,合格品入库记录!$E:$E,日报!$D:$D,合格品入库记录!$A:$A,日报!AT$3),"") | AU15: =IF(SUMIFS(合格品出库记录!$G:$G,合格品出库记录!$E:$E,日报!$D:$D,合格品出库记录!$A:$A,日报!AU$3)<>0,SUMIFS(合格品出库记录!$G:$G,合格品出库记录!$E:$E,日报!$D:$D,合格品出库记录!$A:$A,日报!AU$3),"") | AV15: =IF(SUMIFS(合格品出库记录!$G:$G,合格品出库记录!$E:$E,日报!$D:$D,合格品出库记录!$A:$A,日报!AV$3)<>0,SUMIFS(合格品出库记录!$G:$G,合格品出库记录!$E:$E,日报!$D:$D,合格品出库记录!$A:$A,日报!AV$3),"") | AW15: =IF(SUMIFS(合格品出库记录!$G:$G,合格品出库记录!$E:$E,日报!$D:$D,合格品出库记录!$A:$A,日报!AW$3)<>0,SUMIFS(合格品出库记录!$G:$G,合格品出库记录!$E:$E,日报!$D:$D,合格品出库记录!$A:$A,日报!AW$3),"") | AX15: =IF(SUMIFS(合格品出库记录!$G:$G,合格品出库记录!$E:$E,日报!$D:$D,合格品出库记录!$A:$A,日报!AX$3)<>0,SUMIFS(合格品出库记录!$G:$G,合格品出库记录!$E:$E,日报!$D:$D,合格品出库记录!$A:$A,日报!AX$3),"") | AY15: =IF(SUMIFS(合格品出库记录!$G:$G,合格品出库记录!$E:$E,日报!$D:$D,合格品出库记录!$A:$A,日报!AY$3)<>0,SUMIFS(合格品出库记录!$G:$G,合格品出库记录!$E:$E,日报!$D:$D,合格品出库记录!$A:$A,日报!AY$3),"") | AZ15: =IF(SUMIFS(合格品出库记录!$G:$G,合格品出库记录!$E:$E,日报!$D:$D,合格品出库记录!$A:$A,日报!AZ$3)<>0,SUMIFS(合格品出库记录!$G:$G,合格品出库记录!$E:$E,日报!$D:$D,合格品出库记录!$A:$A,日报!AZ$3),"") | BA15: =IF(SUMIFS(合格品出库记录!$G:$G,合格品出库记录!$E:$E,日报!$D:$D,合格品出库记录!$A:$A,日报!BA$3)<>0,SUMIFS(合格品出库记录!$G:$G,合格品出库记录!$E:$E,日报!$D:$D,合格品出库记录!$A:$A,日报!BA$3),"") | BB15: =IF(SUMIFS(合格品出库记录!$G:$G,合格品出库记录!$E:$E,日报!$D:$D,合格品出库记录!$A:$A,日报!BB$3)<>0,SUMIFS(合格品出库记录!$G:$G,合格品出库记录!$E:$E,日报!$D:$D,合格品出库记录!$A:$A,日报!BB$3),"") | ... BY15: =IF(SUMIFS(合格品出库记录!$G:$G,合格品出库记录!$E:$E,日报!$D:$D,合格品出库记录!$A:$A,日报!BY$3)<>0,SUMIFS(合格品出库记录!$G:$G,合格品出库记录!$E:$E,日报!$D:$D,合格品出库记录!$A:$A,日报!BY$3),"") | BZ15: =IF(SUMIFS(领跑良品退回!$G:$G,领跑良品退回!$E:$E,日报!$D:$D,领跑良品退回!$A:$A,日报!BZ$3)<>0,SUMIFS(领跑良品退回!$G:$G,领跑良品退回!$E:$E,日报!$D:$D,领跑良品退回!$A:$A,日报!BZ$3),"") | CA15: =IF(SUMIFS(领跑良品退回!$G:$G,领跑良品退回!$E:$E,日报!$D:$D,领跑良品退回!$A:$A,日报!CA$3)<>0,SUMIFS(领跑良品退回!$G:$G,领跑良品退回!$E:$E,日报!$D:$D,领跑良品退回!$A:$A,日报!CA$3),"") | CB15: =IF(SUMIFS(领跑良品退回!$G:$G,领跑良品退回!$E:$E,日报!$D:$D,领跑良品退回!$A:$A,日报!CB$3)<>0,SUMIFS(领跑良品退回!$G:$G,领跑良品退回!$E:$E,日报!$D:$D,领跑良品退回!$A:$A,日报!CB$3),"") | CC15: =IF(SUMIFS(领跑良品退回!$G:$G,领跑良品退回!$E:$E,日报!$D:$D,领跑良品退回!$A:$A,日报!CC$3)<>0,SUMIFS(领跑良品退回!$G:$G,领跑良品退回!$E:$E,日报!$D:$D,领跑良品退回!$A:$A,日报!CC$3),"") | CD15: =IF(SUMIFS(领跑良品退回!$G:$G,领跑良品退回!$E:$E,日报!$D:$D,领跑良品退回!$A:$A,日报!CD$3)<>0,SUMIFS(领跑良品退回!$G:$G,领跑良品退回!$E:$E,日报!$D:$D,领跑良品退回!$A:$A,日报!CD$3),"") | CE15: =IF(SUMIFS(领跑良品退回!$G:$G,领跑良品退回!$E:$E,日报!$D:$D,领跑良品退回!$A:$A,日报!CE$3)<>0,SUMIFS(领跑良品退回!$G:$G,领跑良品退回!$E:$E,日报!$D:$D,领跑良品退回!$A:$A,日报!CE$3),"") | CF15: =IF(SUMIFS(领跑良品退回!$G:$G,领跑良品退回!$E:$E,日报!$D:$D,领跑良品退回!$A:$A,日报!CF$3)<>0,SUMIFS(领跑良品退回!$G:$G,领跑良品退回!$E:$E,日报!$D:$D,领跑良品退回!$A:$A,日报!CF$3),"") | CG15: =IF(SUMIFS(领跑良品退回!$G:$G,领跑良品退回!$E:$E,日报!$D:$D,领跑良品退回!$A:$A,日报!CG$3)<>0,SUMIFS(领跑良品退回!$G:$G,领跑良品退回!$E:$E,日报!$D:$D,领跑良品退回!$A:$A,日报!CG$3),"") | ... DD15: =IF(SUMIFS(领跑良品退回!$G:$G,领跑良品退回!$E:$E,日报!$D:$D,领跑良品退回!$A:$A,日报!DD$3)<>0,SUMIFS(领跑良品退回!$G:$G,领跑良品退回!$E:$E,日报!$D:$D,领跑良品退回!$A:$A,日报!DD$3),"")
A16: 60 | B16: 1DC | C16: 东莞市硅翔绝缘材料有限公司 | D16: 3.2.49.08.00242-000 | E16: LPT03A_PBP-加热片-R | F16: =IFERROR(VLOOKUP(D63,'[1]#REF'!D:F,3,FALSE),"0") -> 0 | G16: 0 | H16: =SUMIF(合格品入库记录!E:E,日报!D63,合格品入库记录!G:G) -> 0 | I16: =SUMIF(合格品出库记录!E:E,日报!D63,合格品出库记录!G:G) -> 0 | J16: =SUMIF(领跑良品退回!E:E,D63,领跑良品退回!G:G) -> 0 | K16: =M63+L63 -> 174 | L16: =SUMIF(不良品库存!D:D,D:D,不良品库存!F:F) -> 0 | M16: =G63+H63-I63+J63 -> 0 | N16: #N/A | P16: =IF(SUMIFS(合格品入库记录!$G:$G,合格品入库记录!$E:$E,日报!$D:$D,合格品入库记录!$A:$A,日报!P$3)<>0,SUMIFS(合格品入库记录!$G:$G,合格品入库记录!$E:$E,日报!$D:$D,合格品入库记录!$A:$A,日报!P$3),"") | Q16: =IF(SUMIFS(合格品入库记录!$G:$G,合格品入库记录!$E:$E,日报!$D:$D,合格品入库记录!$A:$A,日报!Q$3)<>0,SUMIFS(合格品入库记录!$G:$G,合格品入库记录!$E:$E,日报!$D:$D,合格品入库记录!$A:$A,日报!Q$3),"") | R16: =IF(SUMIFS(合格品入库记录!$G:$G,合格品入库记录!$E:$E,日报!$D:$D,合格品入库记录!$A:$A,日报!R$3)<>0,SUMIFS(合格品入库记录!$G:$G,合格品入库记录!$E:$E,日报!$D:$D,合格品入库记录!$A:$A,日报!R$3),"") | S16: =IF(SUMIFS(合格品入库记录!$G:$G,合格品入库记录!$E:$E,日报!$D:$D,合格品入库记录!$A:$A,日报!S$3)<>0,SUMIFS(合格品入库记录!$G:$G,合格品入库记录!$E:$E,日报!$D:$D,合格品入库记录!$A:$A,日报!S$3),"") | T16: =IF(SUMIFS(合格品入库记录!$G:$G,合格品入库记录!$E:$E,日报!$D:$D,合格品入库记录!$A:$A,日报!T$3)<>0,SUMIFS(合格品入库记录!$G:$G,合格品入库记录!$E:$E,日报!$D:$D,合格品入库记录!$A:$A,日报!T$3),"") | U16: =IF(SUMIFS(合格品入库记录!$G:$G,合格品入库记录!$E:$E,日报!$D:$D,合格品入库记录!$A:$A,日报!U$3)<>0,SUMIFS(合格品入库记录!$G:$G,合格品入库记录!$E:$E,日报!$D:$D,合格品入库记录!$A:$A,日报!U$3),"") | V16: =IF(SUMIFS(合格品入库记录!$G:$G,合格品入库记录!$E:$E,日报!$D:$D,合格品入库记录!$A:$A,日报!V$3)<>0,SUMIFS(合格品入库记录!$G:$G,合格品入库记录!$E:$E,日报!$D:$D,合格品入库记录!$A:$A,日报!V$3),"") | W16: =IF(SUMIFS(合格品入库记录!$G:$G,合格品入库记录!$E:$E,日报!$D:$D,合格品入库记录!$A:$A,日报!W$3)<>0,SUMIFS(合格品入库记录!$G:$G,合格品入库记录!$E:$E,日报!$D:$D,合格品入库记录!$A:$A,日报!W$3),"") | ... AT16: =IF(SUMIFS(合格品入库记录!$G:$G,合格品入库记录!$E:$E,日报!$D:$D,合格品入库记录!$A:$A,日报!AT$3)<>0,SUMIFS(合格品入库记录!$G:$G,合格品入库记录!$E:$E,日报!$D:$D,合格品入库记录!$A:$A,日报!AT$3),"") | AU16: =IF(SUMIFS(合格品出库记录!$G:$G,合格品出库记录!$E:$E,日报!$D:$D,合格品出库记录!$A:$A,日报!AU$3)<>0,SUMIFS(合格品出库记录!$G:$G,合格品出库记录!$E:$E,日报!$D:$D,合格品出库记录!$A:$A,日报!AU$3),"") | AV16: =IF(SUMIFS(合格品出库记录!$G:$G,合格品出库记录!$E:$E,日报!$D:$D,合格品出库记录!$A:$A,日报!AV$3)<>0,SUMIFS(合格品出库记录!$G:$G,合格品出库记录!$E:$E,日报!$D:$D,合格品出库记录!$A:$A,日报!AV$3),"") | AW16: =IF(SUMIFS(合格品出库记录!$G:$G,合格品出库记录!$E:$E,日报!$D:$D,合格品出库记录!$A:$A,日报!AW$3)<>0,SUMIFS(合格品出库记录!$G:$G,合格品出库记录!$E:$E,日报!$D:$D,合格品出库记录!$A:$A,日报!AW$3),"") | AX16: =IF(SUMIFS(合格品出库记录!$G:$G,合格品出库记录!$E:$E,日报!$D:$D,合格品出库记录!$A:$A,日报!AX$3)<>0,SUMIFS(合格品出库记录!$G:$G,合格品出库记录!$E:$E,日报!$D:$D,合格品出库记录!$A:$A,日报!AX$3),"") | AY16: =IF(SUMIFS(合格品出库记录!$G:$G,合格品出库记录!$E:$E,日报!$D:$D,合格品出库记录!$A:$A,日报!AY$3)<>0,SUMIFS(合格品出库记录!$G:$G,合格品出库记录!$E:$E,日报!$D:$D,合格品出库记录!$A:$A,日报!AY$3),"") | AZ16: =IF(SUMIFS(合格品出库记录!$G:$G,合格品出库记录!$E:$E,日报!$D:$D,合格品出库记录!$A:$A,日报!AZ$3)<>0,SUMIFS(合格品出库记录!$G:$G,合格品出库记录!$E:$E,日报!$D:$D,合格品出库记录!$A:$A,日报!AZ$3),"") | BA16: =IF(SUMIFS(合格品出库记录!$G:$G,合格品出库记录!$E:$E,日报!$D:$D,合格品出库记录!$A:$A,日报!BA$3)<>0,SUMIFS(合格品出库记录!$G:$G,合格品出库记录!$E:$E,日报!$D:$D,合格品出库记录!$A:$A,日报!BA$3),"") | BB16: =IF(SUMIFS(合格品出库记录!$G:$G,合格品出库记录!$E:$E,日报!$D:$D,合格品出库记录!$A:$A,日报!BB$3)<>0,SUMIFS(合格品出库记录!$G:$G,合格品出库记录!$E:$E,日报!$D:$D,合格品出库记录!$A:$A,日报!BB$3),"") | ... BY16: =IF(SUMIFS(合格品出库记录!$G:$G,合格品出库记录!$E:$E,日报!$D:$D,合格品出库记录!$A:$A,日报!BY$3)<>0,SUMIFS(合格品出库记录!$G:$G,合格品出库记录!$E:$E,日报!$D:$D,合格品出库记录!$A:$A,日报!BY$3),"") | BZ16: =IF(SUMIFS(领跑良品退回!$G:$G,领跑良品退回!$E:$E,日报!$D:$D,领跑良品退回!$A:$A,日报!BZ$3)<>0,SUMIFS(领跑良品退回!$G:$G,领跑良品退回!$E:$E,日报!$D:$D,领跑良品退回!$A:$A,日报!BZ$3),"") | CA16: =IF(SUMIFS(领跑良品退回!$G:$G,领跑良品退回!$E:$E,日报!$D:$D,领跑良品退回!$A:$A,日报!CA$3)<>0,SUMIFS(领跑良品退回!$G:$G,领跑良品退回!$E:$E,日报!$D:$D,领跑良品退回!$A:$A,日报!CA$3),"") | CB16: =IF(SUMIFS(领跑良品退回!$G:$G,领跑良品退回!$E:$E,日报!$D:$D,领跑良品退回!$A:$A,日报!CB$3)<>0,SUMIFS(领跑良品退回!$G:$G,领跑良品退回!$E:$E,日报!$D:$D,领跑良品退回!$A:$A,日报!CB$3),"") | CC16: =IF(SUMIFS(领跑良品退回!$G:$G,领跑良品退回!$E:$E,日报!$D:$D,领跑良品退回!$A:$A,日报!CC$3)<>0,SUMIFS(领跑良品退回!$G:$G,领跑良品退回!$E:$E,日报!$D:$D,领跑良品退回!$A:$A,日报!CC$3),"") | CD16: =IF(SUMIFS(领跑良品退回!$G:$G,领跑良品退回!$E:$E,日报!$D:$D,领跑良品退回!$A:$A,日报!CD$3)<>0,SUMIFS(领跑良品退回!$G:$G,领跑良品退回!$E:$E,日报!$D:$D,领跑良品退回!$A:$A,日报!CD$3),"") | CE16: =IF(SUMIFS(领跑良品退回!$G:$G,领跑良品退回!$E:$E,日报!$D:$D,领跑良品退回!$A:$A,日报!CE$3)<>0,SUMIFS(领跑良品退回!$G:$G,领跑良品退回!$E:$E,日报!$D:$D,领跑良品退回!$A:$A,日报!CE$3),"") | CF16: =IF(SUMIFS(领跑良品退回!$G:$G,领跑良品退回!$E:$E,日报!$D:$D,领跑良品退回!$A:$A,日报!CF$3)<>0,SUMIFS(领跑良品退回!$G:$G,领跑良品退回!$E:$E,日报!$D:$D,领跑良品退回!$A:$A,日报!CF$3),"") | CG16: =IF(SUMIFS(领跑良品退回!$G:$G,领跑良品退回!$E:$E,日报!$D:$D,领跑良品退回!$A:$A,日报!CG$3)<>0,SUMIFS(领跑良品退回!$G:$G,领跑良品退回!$E:$E,日报!$D:$D,领跑良品退回!$A:$A,日报!CG$3),"") | ... DD16: =IF(SUMIFS(领跑良品退回!$G:$G,领跑良品退回!$E:$E,日报!$D:$D,领跑良品退回!$A:$A,日报!DD$3)<>0,SUMIFS(领跑良品退回!$G:$G,领跑良品退回!$E:$E,日报!$D:$D,领跑良品退回!$A:$A,日报!DD$3),"")
