Workbook

Sheet 日报
A1: 46143 | E1: 注：“可用结存”列中红色数据代表库存量过低，黄色数据代表超出最高库存量。
A2: 序号 | B2: 供应商代码 | C2: 供应商名称 | D2: 零件编号 | E2: 零件名称 | F2: SNP | G2: 上月结存 | H2: 累进 | I2: 累出 | J2: 零跑退回良品 | K2: 当前库存 | L2: 不合格品库存 | M2: 可用结存 | N2: 最高库存量 | O2: 单车用量 | P2: 入库 | AU2: 出库 | BZ2: 领跑良品退回
P3: 46143 | Q3: 46144 | R3: 46145 | S3: 46146 | T3: 46147 | U3: 46148 | V3: 46149 | W3: 46150 | X3: 46151 | Y3: 46152 | Z3: 46153 | AA3: 46154 | AB3: 46155 | AC3: 46156 | AD3: 46157 | AE3: 46158 | AF3: 46159 | AG3: 46160 | AH3: 46161 | AI3: 46162 | AJ3: 46163 | AK3: 46164 | AL3: 46165 | AM3: 46166 | AN3: 46167 | AO3: 46168 | AP3: 46169 | AQ3: 46170 | AR3: 46171 | AS3: 46172 | AT3: 46173 | AU3: 46143 | AV3: 46144 | AW3: 46145 | AX3: 46146 | AY3: 46147 | AZ3: 46148 | BA3: 46149 | BB3: 46150 | BC3: 46151 | BD3: 46152 | BE3: 46153 | BF3: 46154 | BG3: 46155 | BH3: 46156 | BI3: 46157 | BJ3: 46158 | BK3: 46159 | BL3: 46160 | BM3: 46161 | BN3: 46162 | BO3: 46163 | BP3: 46164 | BQ3: 46165 | BR3: 46166 | BS3: 46167 | BT3: 46168 | BU3: 46169 | BV3: 46170 | BW3: 46171 | BX3: 46172 | BY3: 46173 | BZ3: 46143 | CA3: 46144 | CB3: 46145 | CC3: 46146 | CD3: 46147 | CE3: 46148 | CF3: 46149 | CG3: 46150 | CH3: 46151 | CI3: 46152 | CJ3: 46153 | CK3: 46154 | CL3: 46155 | CM3: 46156 | CN3: 46157 | CO3: 46158 | CP3: 46159 | CQ3: 46160 | CR3: 46161 | CS3: 46162 | CT3: 46163 | CU3: 46164 | CV3: 46165 | CW3: 46166 | CX3: 46167 | CY3: 46168 | CZ3: 46169 | DA3: 46170 | DB3: 46171 | DC3: 46172 | DD3: 46173
A4: 1 | B4: 1AC | C4: 宁波天下汽配有限公司 | D4: 3.2.42.20.00028-000 | E4: 三相线接线盒 | F4: =IFERROR(VLOOKUP(D4,基础信息!D:F,3,FALSE),"0") -> 224 | G4: 0 | H4: =SUMIF(合格品入库记录!E:E,日报!D4,合格品入库记录!G:G) -> 1792 | I4: =SUMIF(合格品出库记录!E:E,日报!D4,合格品出库记录!G:G) -> 0 | J4: =SUMIF(领跑良品退回!E:E,D4,领跑良品退回!G:G) -> 0 | K4: =M4+L4 -> 2485 | L4: =SUMIF(不良品库存!D:D,D:D,不良品库存!F:F) -> 693 | M4: =G4+H4-I4+J4 -> 1792 | N4: 5376 | O4: 1 | P4: =IF(SUMIFS(合格品入库记录!$G:$G,合格品入库记录!$E:$E,日报!$D:$D,合格品入库记录!$A:$A,日报!P$3)<>0,SUMIFS(合格品入库记录!$G:$G,合格品入库记录!$E:$E,日报!$D:$D,合格品入库记录!$A:$A,日报!P$3),"") | Q4: =IF(SUMIFS(合格品入库记录!$G:$G,合格品入库记录!$E:$E,日报!$D:$D,合格品入库记录!$A:$A,日报!Q$3)<>0,SUMIFS(合格品入库记录!$G:$G,合格品入库记录!$E:$E,日报!$D:$D,合格品入库记录!$A:$A,日报!Q$3),"") | R4: =IF(SUMIFS(合格品入库记录!$G:$G,合格品入库记录!$E:$E,日报!$D:$D,合格品入库记录!$A:$A,日报!R$3)<>0,SUMIFS(合格品入库记录!$G:$G,合格品入库记录!$E:$E,日报!$D:$D,合格品入库记录!$A:$A,日报!R$3),"") | S4: =IF(SUMIFS(合格品入库记录!$G:$G,合格品入库记录!$E:$E,日报!$D:$D,合格品入库记录!$A:$A,日报!S$3)<>0,SUMIFS(合格品入库记录!$G:$G,合格品入库记录!$E:$E,日报!$D:$D,合格品入库记录!$A:$A,日报!S$3),"") | T4: =IF(SUMIFS(合格品入库记录!$G:$G,合格品入库记录!$E:$E,日报!$D:$D,合格品入库记录!$A:$A,日报!T$3)<>0,SUMIFS(合格品入库记录!$G:$G,合格品入库记录!$E:$E,日报!$D:$D,合格品入库记录!$A:$A,日报!T$3),"") -> 1792 | U4: =IF(SUMIFS(合格品入库记录!$G:$G,合格品入库记录!$E:$E,日报!$D:$D,合格品入库记录!$A:$A,日报!U$3)<>0,SUMIFS(合格品入库记录!$G:$G,合格品入库记录!$E:$E,日报!$D:$D,合格品入库记录!$A:$A,日报!U$3),"") | V4: =IF(SUMIFS(合格品入库记录!$G:$G,合格品入库记录!$E:$E,日报!$D:$D,合格品入库记录!$A:$A,日报!V$3)<>0,SUMIFS(合格品入库记录!$G:$G,合格品入库记录!$E:$E,日报!$D:$D,合格品入库记录!$A:$A,日报!V$3),"") | W4: =IF(SUMIFS(合格品入库记录!$G:$G,合格品入库记录!$E:$E,日报!$D:$D,合格品入库记录!$A:$A,日报!W$3)<>0,SUMIFS(合格品入库记录!$G:$G,合格品入库记录!$E:$E,日报!$D:$D,合格品入库记录!$A:$A,日报!W$3),"") | ... AT4: =IF(SUMIFS(合格品入库记录!$G:$G,合格品入库记录!$E:$E,日报!$D:$D,合格品入库记录!$A:$A,日报!AT$3)<>0,SUMIFS(合格品入库记录!$G:$G,合格品入库记录!$E:$E,日报!$D:$D,合格品入库记录!$A:$A,日报!AT$3),"") | AU4: =IF(SUMIFS(合格品出库记录!$G:$G,合格品出库记录!$E:$E,日报!$D:$D,合格品出库记录!$A:$A,日报!AU$3)<>0,SUMIFS(合格品出库记录!$G:$G,合格品出库记录!$E:$E,日报!$D:$D,合格品出库记录!$A:$A,日报!AU$3),"") | AV4: =IF(SUMIFS(合格品出库记录!$G:$G,合格品出库记录!$E:$E,日报!$D:$D,合格品出库记录!$A:$A,日报!AV$3)<>0,SUMIFS(合格品出库记录!$G:$G,合格品出库记录!$E:$E,日报!$D:$D,合格品出库记录!$A:$A,日报!AV$3),"") | AW4: =IF(SUMIFS(合格品出库记录!$G:$G,合格品出库记录!$E:$E,日报!$D:$D,合格品出库记录!$A:$A,日报!AW$3)<>0,SUMIFS(合格品出库记录!$G:$G,合格品出库记录!$E:$E,日报!$D:$D,合格品出库记录!$A:$A,日报!AW$3),"") | AX4: =IF(SUMIFS(合格品出库记录!$G:$G,合格品出库记录!$E:$E,日报!$D:$D,合格品出库记录!$A:$A,日报!AX$3)<>0,SUMIFS(合格品出库记录!$G:$G,合格品出库记录!$E:$E,日报!$D:$D,合格品出库记录!$A:$A,日报!AX$3),"") | AY4: =IF(SUMIFS(合格品出库记录!$G:$G,合格品出库记录!$E:$E,日报!$D:$D,合格品出库记录!$A:$A,日报!AY$3)<>0,SUMIFS(合格品出库记录!$G:$G,合格品出库记录!$E:$E,日报!$D:$D,合格品出库记录!$A:$A,日报!AY$3),"") | AZ4: =IF(SUMIFS(合格品出库记录!$G:$G,合格品出库记录!$E:$E,日报!$D:$D,合格品出库记录!$A:$A,日报!AZ$3)<>0,SUMIFS(合格品出库记录!$G:$G,合格品出库记录!$E:$E,日报!$D:$D,合格品出库记录!$A:$A,日报!AZ$3),"") | BA4: =IF(SUMIFS(合格品出库记录!$G:$G,合格品出库记录!$E:$E,日报!$D:$D,合格品出库记录!$A:$A,日报!BA$3)<>0,SUMIFS(合格品出库记录!$G:$G,合格品出库记录!$E:$E,日报!$D:$D,合格品出库记录!$A:$A,日报!BA$3),"") | BB4: =IF(SUMIFS(合格品出库记录!$G:$G,合格品出库记录!$E:$E,日报!$D:$D,合格品出库记录!$A:$A,日报!BB$3)<>0,SUMIFS(合格品出库记录!$G:$G,合格品出库记录!$E:$E,日报!$D:$D,合格品出库记录!$A:$A,日报!BB$3),"") | ... BY4: =IF(SUMIFS(合格品出库记录!$G:$G,合格品出库记录!$E:$E,日报!$D:$D,合格品出库记录!$A:$A,日报!BY$3)<>0,SUMIFS(合格品出库记录!$G:$G,合格品出库记录!$E:$E,日报!$D:$D,合格品出库记录!$A:$A,日报!BY$3),"") | BZ4: =IF(SUMIFS(领跑良品退回!$G:$G,领跑良品退回!$E:$E,日报!$D:$D,领跑良品退回!$A:$A,日报!BZ$3)<>0,SUMIFS(领跑良品退回!$G:$G,领跑良品退回!$E:$E,日报!$D:$D,领跑良品退回!$A:$A,日报!BZ$3),"") | CA4: =IF(SUMIFS(领跑良品退回!$G:$G,领跑良品退回!$E:$E,日报!$D:$D,领跑良品退回!$A:$A,日报!CA$3)<>0,SUMIFS(领跑良品退回!$G:$G,领跑良品退回!$E:$E,日报!$D:$D,领跑良品退回!$A:$A,日报!CA$3),"") | CB4: =IF(SUMIFS(领跑良品退回!$G:$G,领跑良品退回!$E:$E,日报!$D:$D,领跑良品退回!$A:$A,日报!CB$3)<>0,SUMIFS(领跑良品退回!$G:$G,领跑良品退回!$E:$E,日报!$D:$D,领跑良品退回!$A:$A,日报!CB$3),"") | CC4: =IF(SUMIFS(领跑良品退回!$G:$G,领跑良品退回!$E:$E,日报!$D:$D,领跑良品退回!$A:$A,日报!CC$3)<>0,SUMIFS(领跑良品退回!$G:$G,领跑良品退回!$E:$E,日报!$D:$D,领跑良品退回!$A:$A,日报!CC$3),"") | CD4: =IF(SUMIFS(领跑良品退回!$G:$G,领跑良品退回!$E:$E,日报!$D:$D,领跑良品退回!$A:$A,日报!CD$3)<>0,SUMIFS(领跑良品退回!$G:$G,领跑良品退回!$E:$E,日报!$D:$D,领跑良品退回!$A:$A,日报!CD$3),"") | CE4: =IF(SUMIFS(领跑良品退回!$G:$G,领跑良品退回!$E:$E,日报!$D:$D,领跑良品退回!$A:$A,日报!CE$3)<>0,SUMIFS(领跑良品退回!$G:$G,领跑良品退回!$E:$E,日报!$D:$D,领跑良品退回!$A:$A,日报!CE$3),"") | CF4: =IF(SUMIFS(领跑良品退回!$G:$G,领跑良品退回!$E:$E,日报!$D:$D,领跑良品退回!$A:$A,日报!CF$3)<>0,SUMIFS(领跑良品退回!$G:$G,领跑良品退回!$E:$E,日报!$D:$D,领跑良品退回!$A:$A,日报!CF$3),"") | CG4: =IF(SUMIFS(领跑良品退回!$G:$G,领跑良品退回!$E:$E,日报!$D:$D,领跑良品退回!$A:$A,日报!CG$3)<>0,SUMIFS(领跑良品退回!$G:$G,领跑良品退回!$E:$E,日报!$D:$D,领跑良品退回!$A:$A,日报!CG$3),"") | ... DD4: =IF(SUMIFS(领跑良品退回!$G:$G,领跑良品退回!$E:$E,日报!$D:$D,领跑良品退回!$A:$A,日报!DD$3)<>0,SUMIFS(领跑良品退回!$G:$G,领跑良品退回!$E:$E,日报!$D:$D,领跑良品退回!$A:$A,日报!DD$3),"")
A5: 2 | B5: 1AC | C5: 宁波天下汽配有限公司 | D5: 3.2.42.20.00006-000 | E5: 水管接头L | F5: =IFERROR(VLOOKUP(D5,基础信息!D:F,3,FALSE),"0") -> 750 | G5: 0 | H5: =SUMIF(合格品入库记录!E:E,日报!D5,合格品入库记录!G:G) -> 4500 | I5: =SUMIF(合格品出库记录!E:E,日报!D5,合格品出库记录!G:G) -> 0 | J5: =SUMIF(领跑良品退回!E:E,D5,领跑良品退回!G:G) -> 0 | K5: =M5+L5 -> 4588 | L5: =SUMIF(不良品库存!D:D,D:D,不良品库存!F:F) -> 88 | M5: =G5+H5-I5+J5 -> 4500 | N5: 13500 | O5: 3 | P5: =IF(SUMIFS(合格品入库记录!$G:$G,合格品入库记录!$E:$E,日报!$D:$D,合格品入库记录!$A:$A,日报!P$3)<>0,SUMIFS(合格品入库记录!$G:$G,合格品入库记录!$E:$E,日报!$D:$D,合格品入库记录!$A:$A,日报!P$3),"") | Q5: =IF(SUMIFS(合格品入库记录!$G:$G,合格品入库记录!$E:$E,日报!$D:$D,合格品入库记录!$A:$A,日报!Q$3)<>0,SUMIFS(合格品入库记录!$G:$G,合格品入库记录!$E:$E,日报!$D:$D,合格品入库记录!$A:$A,日报!Q$3),"") | R5: =IF(SUMIFS(合格品入库记录!$G:$G,合格品入库记录!$E:$E,日报!$D:$D,合格品入库记录!$A:$A,日报!R$3)<>0,SUMIFS(合格品入库记录!$G:$G,合格品入库记录!$E:$E,日报!$D:$D,合格品入库记录!$A:$A,日报!R$3),"") | S5: =IF(SUMIFS(合格品入库记录!$G:$G,合格品入库记录!$E:$E,日报!$D:$D,合格品入库记录!$A:$A,日报!S$3)<>0,SUMIFS(合格品入库记录!$G:$G,合格品入库记录!$E:$E,日报!$D:$D,合格品入库记录!$A:$A,日报!S$3),"") | T5: =IF(SUMIFS(合格品入库记录!$G:$G,合格品入库记录!$E:$E,日报!$D:$D,合格品入库记录!$A:$A,日报!T$3)<>0,SUMIFS(合格品入库记录!$G:$G,合格品入库记录!$E:$E,日报!$D:$D,合格品入库记录!$A:$A,日报!T$3),"") -> 4500 | U5: =IF(SUMIFS(合格品入库记录!$G:$G,合格品入库记录!$E:$E,日报!$D:$D,合格品入库记录!$A:$A,日报!U$3)<>0,SUMIFS(合格品入库记录!$G:$G,合格品入库记录!$E:$E,日报!$D:$D,合格品入库记录!$A:$A,日报!U$3),"") | V5: =IF(SUMIFS(合格品入库记录!$G:$G,合格品入库记录!$E:$E,日报!$D:$D,合格品入库记录!$A:$A,日报!V$3)<>0,SUMIFS(合格品入库记录!$G:$G,合格品入库记录!$E:$E,日报!$D:$D,合格品入库记录!$A:$A,日报!V$3),"") | W5: =IF(SUMIFS(合格品入库记录!$G:$G,合格品入库记录!$E:$E,日报!$D:$D,合格品入库记录!$A:$A,日报!W$3)<>0,SUMIFS(合格品入库记录!$G:$G,合格品入库记录!$E:$E,日报!$D:$D,合格品入库记录!$A:$A,日报!W$3),"") | ... AT5: =IF(SUMIFS(合格品入库记录!$G:$G,合格品入库记录!$E:$E,日报!$D:$D,合格品入库记录!$A:$A,日报!AT$3)<>0,SUMIFS(合格品入库记录!$G:$G,合格品入库记录!$E:$E,日报!$D:$D,合格品入库记录!$A:$A,日报!AT$3),"") | AU5: =IF(SUMIFS(合格品出库记录!$G:$G,合格品出库记录!$E:$E,日报!$D:$D,合格品出库记录!$A:$A,日报!AU$3)<>0,SUMIFS(合格品出库记录!$G:$G,合格品出库记录!$E:$E,日报!$D:$D,合格品出库记录!$A:$A,日报!AU$3),"") | AV5: =IF(SUMIFS(合格品出库记录!$G:$G,合格品出库记录!$E:$E,日报!$D:$D,合格品出库记录!$A:$A,日报!AV$3)<>0,SUMIFS(合格品出库记录!$G:$G,合格品出库记录!$E:$E,日报!$D:$D,合格品出库记录!$A:$A,日报!AV$3),"") | AW5: =IF(SUMIFS(合格品出库记录!$G:$G,合格品出库记录!$E:$E,日报!$D:$D,合格品出库记录!$A:$A,日报!AW$3)<>0,SUMIFS(合格品出库记录!$G:$G,合格品出库记录!$E:$E,日报!$D:$D,合格品出库记录!$A:$A,日报!AW$3),"") | AX5: =IF(SUMIFS(合格品出库记录!$G:$G,合格品出库记录!$E:$E,日报!$D:$D,合格品出库记录!$A:$A,日报!AX$3)<>0,SUMIFS(合格品出库记录!$G:$G,合格品出库记录!$E:$E,日报!$D:$D,合格品出库记录!$A:$A,日报!AX$3),"") | AY5: =IF(SUMIFS(合格品出库记录!$G:$G,合格品出库记录!$E:$E,日报!$D:$D,合格品出库记录!$A:$A,日报!AY$3)<>0,SUMIFS(合格品出库记录!$G:$G,合格品出库记录!$E:$E,日报!$D:$D,合格品出库记录!$A:$A,日报!AY$3),"") | AZ5: =IF(SUMIFS(合格品出库记录!$G:$G,合格品出库记录!$E:$E,日报!$D:$D,合格品出库记录!$A:$A,日报!AZ$3)<>0,SUMIFS(合格品出库记录!$G:$G,合格品出库记录!$E:$E,日报!$D:$D,合格品出库记录!$A:$A,日报!AZ$3),"") | BA5: =IF(SUMIFS(合格品出库记录!$G:$G,合格品出库记录!$E:$E,日报!$D:$D,合格品出库记录!$A:$A,日报!BA$3)<>0,SUMIFS(合格品出库记录!$G:$G,合格品出库记录!$E:$E,日报!$D:$D,合格品出库记录!$A:$A,日报!BA$3),"") | BB5: =IF(SUMIFS(合格品出库记录!$G:$G,合格品出库记录!$E:$E,日报!$D:$D,合格品出库记录!$A:$A,日报!BB$3)<>0,SUMIFS(合格品出库记录!$G:$G,合格品出库记录!$E:$E,日报!$D:$D,合格品出库记录!$A:$A,日报!BB$3),"") | ... BY5: =IF(SUMIFS(合格品出库记录!$G:$G,合格品出库记录!$E:$E,日报!$D:$D,合格品出库记录!$A:$A,日报!BY$3)<>0,SUMIFS(合格品出库记录!$G:$G,合格品出库记录!$E:$E,日报!$D:$D,合格品出库记录!$A:$A,日报!BY$3),"") | BZ5: =IF(SUMIFS(领跑良品退回!$G:$G,领跑良品退回!$E:$E,日报!$D:$D,领跑良品退回!$A:$A,日报!BZ$3)<>0,SUMIFS(领跑良品退回!$G:$G,领跑良品退回!$E:$E,日报!$D:$D,领跑良品退回!$A:$A,日报!BZ$3),"") | CA5: =IF(SUMIFS(领跑良品退回!$G:$G,领跑良品退回!$E:$E,日报!$D:$D,领跑良品退回!$A:$A,日报!CA$3)<>0,SUMIFS(领跑良品退回!$G:$G,领跑良品退回!$E:$E,日报!$D:$D,领跑良品退回!$A:$A,日报!CA$3),"") | CB5: =IF(SUMIFS(领跑良品退回!$G:$G,领跑良品退回!$E:$E,日报!$D:$D,领跑良品退回!$A:$A,日报!CB$3)<>0,SUMIFS(领跑良品退回!$G:$G,领跑良品退回!$E:$E,日报!$D:$D,领跑良品退回!$A:$A,日报!CB$3),"") | CC5: =IF(SUMIFS(领跑良品退回!$G:$G,领跑良品退回!$E:$E,日报!$D:$D,领跑良品退回!$A:$A,日报!CC$3)<>0,SUMIFS(领跑良品退回!$G:$G,领跑良品退回!$E:$E,日报!$D:$D,领跑良品退回!$A:$A,日报!CC$3),"") | CD5: =IF(SUMIFS(领跑良品退回!$G:$G,领跑良品退回!$E:$E,日报!$D:$D,领跑良品退回!$A:$A,日报!CD$3)<>0,SUMIFS(领跑良品退回!$G:$G,领跑良品退回!$E:$E,日报!$D:$D,领跑良品退回!$A:$A,日报!CD$3),"") | CE5: =IF(SUMIFS(领跑良品退回!$G:$G,领跑良品退回!$E:$E,日报!$D:$D,领跑良品退回!$A:$A,日报!CE$3)<>0,SUMIFS(领跑良品退回!$G:$G,领跑良品退回!$E:$E,日报!$D:$D,领跑良品退回!$A:$A,日报!CE$3),"") | CF5: =IF(SUMIFS(领跑良品退回!$G:$G,领跑良品退回!$E:$E,日报!$D:$D,领跑良品退回!$A:$A,日报!CF$3)<>0,SUMIFS(领跑良品退回!$G:$G,领跑良品退回!$E:$E,日报!$D:$D,领跑良品退回!$A:$A,日报!CF$3),"") | CG5: =IF(SUMIFS(领跑良品退回!$G:$G,领跑良品退回!$E:$E,日报!$D:$D,领跑良品退回!$A:$A,日报!CG$3)<>0,SUMIFS(领跑良品退回!$G:$G,领跑良品退回!$E:$E,日报!$D:$D,领跑良品退回!$A:$A,日报!CG$3),"") | ... DD5: =IF(SUMIFS(领跑良品退回!$G:$G,领跑良品退回!$E:$E,日报!$D:$D,领跑良品退回!$A:$A,日报!DD$3)<>0,SUMIFS(领跑良品退回!$G:$G,领跑良品退回!$E:$E,日报!$D:$D,领跑良品退回!$A:$A,日报!DD$3),"")
A6: 3 | B6: 1AC | C6: 宁波天下汽配有限公司 | D6: 3.2.42.20.00007-000 | E6: 水管接头R | F6: =IFERROR(VLOOKUP(D6,基础信息!D:F,3,FALSE),"0") -> 750 | G6: 0 | H6: =SUMIF(合格品入库记录!E:E,日报!D6,合格品入库记录!G:G) -> 1500 | I6: =SUMIF(合格品出库记录!E:E,日报!D6,合格品出库记录!G:G) -> 0 | J6: =SUMIF(领跑良品退回!E:E,D6,领跑良品退回!G:G) -> 0 | K6: =M6+L6 -> 1501 | L6: =SUMIF(不良品库存!D:D,D:D,不良品库存!F:F) -> 1 | M6: =G6+H6-I6+J6 -> 1500 | N6: 18000 | O6: 1 | P6: =IF(SUMIFS(合格品入库记录!$G:$G,合格品入库记录!$E:$E,日报!$D:$D,合格品入库记录!$A:$A,日报!P$3)<>0,SUMIFS(合格品入库记录!$G:$G,合格品入库记录!$E:$E,日报!$D:$D,合格品入库记录!$A:$A,日报!P$3),"") | Q6: =IF(SUMIFS(合格品入库记录!$G:$G,合格品入库记录!$E:$E,日报!$D:$D,合格品入库记录!$A:$A,日报!Q$3)<>0,SUMIFS(合格品入库记录!$G:$G,合格品入库记录!$E:$E,日报!$D:$D,合格品入库记录!$A:$A,日报!Q$3),"") | R6: =IF(SUMIFS(合格品入库记录!$G:$G,合格品入库记录!$E:$E,日报!$D:$D,合格品入库记录!$A:$A,日报!R$3)<>0,SUMIFS(合格品入库记录!$G:$G,合格品入库记录!$E:$E,日报!$D:$D,合格品入库记录!$A:$A,日报!R$3),"") | S6: =IF(SUMIFS(合格品入库记录!$G:$G,合格品入库记录!$E:$E,日报!$D:$D,合格品入库记录!$A:$A,日报!S$3)<>0,SUMIFS(合格品入库记录!$G:$G,合格品入库记录!$E:$E,日报!$D:$D,合格品入库记录!$A:$A,日报!S$3),"") | T6: =IF(SUMIFS(合格品入库记录!$G:$G,合格品入库记录!$E:$E,日报!$D:$D,合格品入库记录!$A:$A,日报!T$3)<>0,SUMIFS(合格品入库记录!$G:$G,合格品入库记录!$E:$E,日报!$D:$D,合格品入库记录!$A:$A,日报!T$3),"") -> 1500 | U6: =IF(SUMIFS(合格品入库记录!$G:$G,合格品入库记录!$E:$E,日报!$D:$D,合格品入库记录!$A:$A,日报!U$3)<>0,SUMIFS(合格品入库记录!$G:$G,合格品入库记录!$E:$E,日报!$D:$D,合格品入库记录!$A:$A,日报!U$3),"") | V6: =IF(SUMIFS(合格品入库记录!$G:$G,合格品入库记录!$E:$E,日报!$D:$D,合格品入库记录!$A:$A,日报!V$3)<>0,SUMIFS(合格品入库记录!$G:$G,合格品入库记录!$E:$E,日报!$D:$D,合格品入库记录!$A:$A,日报!V$3),"") | W6: =IF(SUMIFS(合格品入库记录!$G:$G,合格品入库记录!$E:$E,日报!$D:$D,合格品入库记录!$A:$A,日报!W$3)<>0,SUMIFS(合格品入库记录!$G:$G,合格品入库记录!$E:$E,日报!$D:$D,合格品入库记录!$A:$A,日报!W$3),"") | ... AT6: =IF(SUMIFS(合格品入库记录!$G:$G,合格品入库记录!$E:$E,日报!$D:$D,合格品入库记录!$A:$A,日报!AT$3)<>0,SUMIFS(合格品入库记录!$G:$G,合格品入库记录!$E:$E,日报!$D:$D,合格品入库记录!$A:$A,日报!AT$3),"") | AU6: =IF(SUMIFS(合格品出库记录!$G:$G,合格品出库记录!$E:$E,日报!$D:$D,合格品出库记录!$A:$A,日报!AU$3)<>0,SUMIFS(合格品出库记录!$G:$G,合格品出库记录!$E:$E,日报!$D:$D,合格品出库记录!$A:$A,日报!AU$3),"") | AV6: =IF(SUMIFS(合格品出库记录!$G:$G,合格品出库记录!$E:$E,日报!$D:$D,合格品出库记录!$A:$A,日报!AV$3)<>0,SUMIFS(合格品出库记录!$G:$G,合格品出库记录!$E:$E,日报!$D:$D,合格品出库记录!$A:$A,日报!AV$3),"") | AW6: =IF(SUMIFS(合格品出库记录!$G:$G,合格品出库记录!$E:$E,日报!$D:$D,合格品出库记录!$A:$A,日报!AW$3)<>0,SUMIFS(合格品出库记录!$G:$G,合格品出库记录!$E:$E,日报!$D:$D,合格品出库记录!$A:$A,日报!AW$3),"") | AX6: =IF(SUMIFS(合格品出库记录!$G:$G,合格品出库记录!$E:$E,日报!$D:$D,合格品出库记录!$A:$A,日报!AX$3)<>0,SUMIFS(合格品出库记录!$G:$G,合格品出库记录!$E:$E,日报!$D:$D,合格品出库记录!$A:$A,日报!AX$3),"") | AY6: =IF(SUMIFS(合格品出库记录!$G:$G,合格品出库记录!$E:$E,日报!$D:$D,合格品出库记录!$A:$A,日报!AY$3)<>0,SUMIFS(合格品出库记录!$G:$G,合格品出库记录!$E:$E,日报!$D:$D,合格品出库记录!$A:$A,日报!AY$3),"") | AZ6: =IF(SUMIFS(合格品出库记录!$G:$G,合格品出库记录!$E:$E,日报!$D:$D,合格品出库记录!$A:$A,日报!AZ$3)<>0,SUMIFS(合格品出库记录!$G:$G,合格品出库记录!$E:$E,日报!$D:$D,合格品出库记录!$A:$A,日报!AZ$3),"") | BA6: =IF(SUMIFS(合格品出库记录!$G:$G,合格品出库记录!$E:$E,日报!$D:$D,合格品出库记录!$A:$A,日报!BA$3)<>0,SUMIFS(合格品出库记录!$G:$G,合格品出库记录!$E:$E,日报!$D:$D,合格品出库记录!$A:$A,日报!BA$3),"") | BB6: =IF(SUMIFS(合格品出库记录!$G:$G,合格品出库记录!$E:$E,日报!$D:$D,合格品出库记录!$A:$A,日报!BB$3)<>0,SUMIFS(合格品出库记录!$G:$G,合格品出库记录!$E:$E,日报!$D:$D,合格品出库记录!$A:$A,日报!BB$3),"") | ... BY6: =IF(SUMIFS(合格品出库记录!$G:$G,合格品出库记录!$E:$E,日报!$D:$D,合格品出库记录!$A:$A,日报!BY$3)<>0,SUMIFS(合格品出库记录!$G:$G,合格品出库记录!$E:$E,日报!$D:$D,合格品出库记录!$A:$A,日报!BY$3),"") | BZ6: =IF(SUMIFS(领跑良品退回!$G:$G,领跑良品退回!$E:$E,日报!$D:$D,领跑良品退回!$A:$A,日报!BZ$3)<>0,SUMIFS(领跑良品退回!$G:$G,领跑良品退回!$E:$E,日报!$D:$D,领跑良品退回!$A:$A,日报!BZ$3),"") | CA6: =IF(SUMIFS(领跑良品退回!$G:$G,领跑良品退回!$E:$E,日报!$D:$D,领跑良品退回!$A:$A,日报!CA$3)<>0,SUMIFS(领跑良品退回!$G:$G,领跑良品退回!$E:$E,日报!$D:$D,领跑良品退回!$A:$A,日报!CA$3),"") | CB6: =IF(SUMIFS(领跑良品退回!$G:$G,领跑良品退回!$E:$E,日报!$D:$D,领跑良品退回!$A:$A,日报!CB$3)<>0,SUMIFS(领跑良品退回!$G:$G,领跑良品退回!$E:$E,日报!$D:$D,领跑良品退回!$A:$A,日报!CB$3),"") | CC6: =IF(SUMIFS(领跑良品退回!$G:$G,领跑良品退回!$E:$E,日报!$D:$D,领跑良品退回!$A:$A,日报!CC$3)<>0,SUMIFS(领跑良品退回!$G:$G,领跑良品退回!$E:$E,日报!$D:$D,领跑良品退回!$A:$A,日报!CC$3),"") | CD6: =IF(SUMIFS(领跑良品退回!$G:$G,领跑良品退回!$E:$E,日报!$D:$D,领跑良品退回!$A:$A,日报!CD$3)<>0,SUMIFS(领跑良品退回!$G:$G,领跑良品退回!$E:$E,日报!$D:$D,领跑良品退回!$A:$A,日报!CD$3),"") | CE6: =IF(SUMIFS(领跑良品退回!$G:$G,领跑良品退回!$E:$E,日报!$D:$D,领跑良品退回!$A:$A,日报!CE$3)<>0,SUMIFS(领跑良品退回!$G:$G,领跑良品退回!$E:$E,日报!$D:$D,领跑良品退回!$A:$A,日报!CE$3),"") | CF6: =IF(SUMIFS(领跑良品退回!$G:$G,领跑良品退回!$E:$E,日报!$D:$D,领跑良品退回!$A:$A,日报!CF$3)<>0,SUMIFS(领跑良品退回!$G:$G,领跑良品退回!$E:$E,日报!$D:$D,领跑良品退回!$A:$A,日报!CF$3),"") | CG6: =IF(SUMIFS(领跑良品退回!$G:$G,领跑良品退回!$E:$E,日报!$D:$D,领跑良品退回!$A:$A,日报!CG$3)<>0,SUMIFS(领跑良品退回!$G:$G,领跑良品退回!$E:$E,日报!$D:$D,领跑良品退回!$A:$A,日报!CG$3),"") | ... DD6: =IF(SUMIFS(领跑良品退回!$G:$G,领跑良品退回!$E:$E,日报!$D:$D,领跑良品退回!$A:$A,日报!DD$3)<>0,SUMIFS(领跑良品退回!$G:$G,领跑良品退回!$E:$E,日报!$D:$D,领跑良品退回!$A:$A,日报!DD$3),"")
A7: 4 | B7: 1AC | C7: 宁波天下汽配有限公司 | D7: 3.2.42.20.00039-000 | E7: PDU绝缘接线座 | F7: =IFERROR(VLOOKUP(D7,基础信息!D:F,3,FALSE),"0") -> 0 | G7: 500 | H7: =SUMIF(合格品入库记录!E:E,日报!D7,合格品入库记录!G:G) -> 680 | I7: =SUMIF(合格品出库记录!E:E,日报!D7,合格品出库记录!G:G) -> 0 | J7: =SUMIF(领跑良品退回!E:E,D7,领跑良品退回!G:G) -> 0 | K7: =M7+L7 -> 1308 | L7: =SUMIF(不良品库存!D:D,D:D,不良品库存!F:F) -> 128 | M7: =G7+H7-I7+J7 -> 1180 | N7: #N/A | O7: 1 | P7: =IF(SUMIFS(合格品入库记录!$G:$G,合格品入库记录!$E:$E,日报!$D:$D,合格品入库记录!$A:$A,日报!P$3)<>0,SUMIFS(合格品入库记录!$G:$G,合格品入库记录!$E:$E,日报!$D:$D,合格品入库记录!$A:$A,日报!P$3),"") | Q7: =IF(SUMIFS(合格品入库记录!$G:$G,合格品入库记录!$E:$E,日报!$D:$D,合格品入库记录!$A:$A,日报!Q$3)<>0,SUMIFS(合格品入库记录!$G:$G,合格品入库记录!$E:$E,日报!$D:$D,合格品入库记录!$A:$A,日报!Q$3),"") | R7: =IF(SUMIFS(合格品入库记录!$G:$G,合格品入库记录!$E:$E,日报!$D:$D,合格品入库记录!$A:$A,日报!R$3)<>0,SUMIFS(合格品入库记录!$G:$G,合格品入库记录!$E:$E,日报!$D:$D,合格品入库记录!$A:$A,日报!R$3),"") | S7: =IF(SUMIFS(合格品入库记录!$G:$G,合格品入库记录!$E:$E,日报!$D:$D,合格品入库记录!$A:$A,日报!S$3)<>0,SUMIFS(合格品入库记录!$G:$G,合格品入库记录!$E:$E,日报!$D:$D,合格品入库记录!$A:$A,日报!S$3),"") | T7: =IF(SUMIFS(合格品入库记录!$G:$G,合格品入库记录!$E:$E,日报!$D:$D,合格品入库记录!$A:$A,日报!T$3)<>0,SUMIFS(合格品入库记录!$G:$G,合格品入库记录!$E:$E,日报!$D:$D,合格品入库记录!$A:$A,日报!T$3),"") -> 680 | U7: =IF(SUMIFS(合格品入库记录!$G:$G,合格品入库记录!$E:$E,日报!$D:$D,合格品入库记录!$A:$A,日报!U$3)<>0,SUMIFS(合格品入库记录!$G:$G,合格品入库记录!$E:$E,日报!$D:$D,合格品入库记录!$A:$A,日报!U$3),"") | V7: =IF(SUMIFS(合格品入库记录!$G:$G,合格品入库记录!$E:$E,日报!$D:$D,合格品入库记录!$A:$A,日报!V$3)<>0,SUMIFS(合格品入库记录!$G:$G,合格品入库记录!$E:$E,日报!$D:$D,合格品入库记录!$A:$A,日报!V$3),"") | W7: =IF(SUMIFS(合格品入库记录!$G:$G,合格品入库记录!$E:$E,日报!$D:$D,合格品入库记录!$A:$A,日报!W$3)<>0,SUMIFS(合格品入库记录!$G:$G,合格品入库记录!$E:$E,日报!$D:$D,合格品入库记录!$A:$A,日报!W$3),"") | ... AT7: =IF(SUMIFS(合格品入库记录!$G:$G,合格品入库记录!$E:$E,日报!$D:$D,合格品入库记录!$A:$A,日报!AT$3)<>0,SUMIFS(合格品入库记录!$G:$G,合格品入库记录!$E:$E,日报!$D:$D,合格品入库记录!$A:$A,日报!AT$3),"") | AU7: =IF(SUMIFS(合格品出库记录!$G:$G,合格品出库记录!$E:$E,日报!$D:$D,合格品出库记录!$A:$A,日报!AU$3)<>0,SUMIFS(合格品出库记录!$G:$G,合格品出库记录!$E:$E,日报!$D:$D,合格品出库记录!$A:$A,日报!AU$3),"") | AV7: =IF(SUMIFS(合格品出库记录!$G:$G,合格品出库记录!$E:$E,日报!$D:$D,合格品出库记录!$A:$A,日报!AV$3)<>0,SUMIFS(合格品出库记录!$G:$G,合格品出库记录!$E:$E,日报!$D:$D,合格品出库记录!$A:$A,日报!AV$3),"") | AW7: =IF(SUMIFS(合格品出库记录!$G:$G,合格品出库记录!$E:$E,日报!$D:$D,合格品出库记录!$A:$A,日报!AW$3)<>0,SUMIFS(合格品出库记录!$G:$G,合格品出库记录!$E:$E,日报!$D:$D,合格品出库记录!$A:$A,日报!AW$3),"") | AX7: =IF(SUMIFS(合格品出库记录!$G:$G,合格品出库记录!$E:$E,日报!$D:$D,合格品出库记录!$A:$A,日报!AX$3)<>0,SUMIFS(合格品出库记录!$G:$G,合格品出库记录!$E:$E,日报!$D:$D,合格品出库记录!$A:$A,日报!AX$3),"") | AY7: =IF(SUMIFS(合格品出库记录!$G:$G,合格品出库记录!$E:$E,日报!$D:$D,合格品出库记录!$A:$A,日报!AY$3)<>0,SUMIFS(合格品出库记录!$G:$G,合格品出库记录!$E:$E,日报!$D:$D,合格品出库记录!$A:$A,日报!AY$3),"") | AZ7: =IF(SUMIFS(合格品出库记录!$G:$G,合格品出库记录!$E:$E,日报!$D:$D,合格品出库记录!$A:$A,日报!AZ$3)<>0,SUMIFS(合格品出库记录!$G:$G,合格品出库记录!$E:$E,日报!$D:$D,合格品出库记录!$A:$A,日报!AZ$3),"") | BA7: =IF(SUMIFS(合格品出库记录!$G:$G,合格品出库记录!$E:$E,日报!$D:$D,合格品出库记录!$A:$A,日报!BA$3)<>0,SUMIFS(合格品出库记录!$G:$G,合格品出库记录!$E:$E,日报!$D:$D,合格品出库记录!$A:$A,日报!BA$3),"") | BB7: =IF(SUMIFS(合格品出库记录!$G:$G,合格品出库记录!$E:$E,日报!$D:$D,合格品出库记录!$A:$A,日报!BB$3)<>0,SUMIFS(合格品出库记录!$G:$G,合格品出库记录!$E:$E,日报!$D:$D,合格品出库记录!$A:$A,日报!BB$3),"") | ... BY7: =IF(SUMIFS(合格品出库记录!$G:$G,合格品出库记录!$E:$E,日报!$D:$D,合格品出库记录!$A:$A,日报!BY$3)<>0,SUMIFS(合格品出库记录!$G:$G,合格品出库记录!$E:$E,日报!$D:$D,合格品出库记录!$A:$A,日报!BY$3),"") | BZ7: =IF(SUMIFS(领跑良品退回!$G:$G,领跑良品退回!$E:$E,日报!$D:$D,领跑良品退回!$A:$A,日报!BZ$3)<>0,SUMIFS(领跑良品退回!$G:$G,领跑良品退回!$E:$E,日报!$D:$D,领跑良品退回!$A:$A,日报!BZ$3),"") | CA7: =IF(SUMIFS(领跑良品退回!$G:$G,领跑良品退回!$E:$E,日报!$D:$D,领跑良品退回!$A:$A,日报!CA$3)<>0,SUMIFS(领跑良品退回!$G:$G,领跑良品退回!$E:$E,日报!$D:$D,领跑良品退回!$A:$A,日报!CA$3),"") | CB7: =IF(SUMIFS(领跑良品退回!$G:$G,领跑良品退回!$E:$E,日报!$D:$D,领跑良品退回!$A:$A,日报!CB$3)<>0,SUMIFS(领跑良品退回!$G:$G,领跑良品退回!$E:$E,日报!$D:$D,领跑良品退回!$A:$A,日报!CB$3),"") | CC7: =IF(SUMIFS(领跑良品退回!$G:$G,领跑良品退回!$E:$E,日报!$D:$D,领跑良品退回!$A:$A,日报!CC$3)<>0,SUMIFS(领跑良品退回!$G:$G,领跑良品退回!$E:$E,日报!$D:$D,领跑良品退回!$A:$A,日报!CC$3),"") | CD7: =IF(SUMIFS(领跑良品退回!$G:$G,领跑良品退回!$E:$E,日报!$D:$D,领跑良品退回!$A:$A,日报!CD$3)<>0,SUMIFS(领跑良品退回!$G:$G,领跑良品退回!$E:$E,日报!$D:$D,领跑良品退回!$A:$A,日报!CD$3),"") | CE7: =IF(SUMIFS(领跑良品退回!$G:$G,领跑良品退回!$E:$E,日报!$D:$D,领跑良品退回!$A:$A,日报!CE$3)<>0,SUMIFS(领跑良品退回!$G:$G,领跑良品退回!$E:$E,日报!$D:$D,领跑良品退回!$A:$A,日报!CE$3),"") | CF7: =IF(SUMIFS(领跑良品退回!$G:$G,领跑良品退回!$E:$E,日报!$D:$D,领跑良品退回!$A:$A,日报!CF$3)<>0,SUMIFS(领跑良品退回!$G:$G,领跑良品退回!$E:$E,日报!$D:$D,领跑良品退回!$A:$A,日报!CF$3),"") | CG7: =IF(SUMIFS(领跑良品退回!$G:$G,领跑良品退回!$E:$E,日报!$D:$D,领跑良品退回!$A:$A,日报!CG$3)<>0,SUMIFS(领跑良品退回!$G:$G,领跑良品退回!$E:$E,日报!$D:$D,领跑良品退回!$A:$A,日报!CG$3),"") | ... DD7: =IF(SUMIFS(领跑良品退回!$G:$G,领跑良品退回!$E:$E,日报!$D:$D,领跑良品退回!$A:$A,日报!DD$3)<>0,SUMIFS(领跑良品退回!$G:$G,领跑良品退回!$E:$E,日报!$D:$D,领跑良品退回!$A:$A,日报!DD$3),"")
A8: 5 | B8: 1AC | C8: 宁波天下汽配有限公司 | D8: 3.2.42.20.00040-000 | E8: PTC保险丝安装座 | F8: =IFERROR(VLOOKUP(D8,基础信息!D:F,3,FALSE),"0") -> 366 | G8: 0 | H8: =SUMIF(合格品入库记录!E:E,日报!D8,合格品入库记录!G:G) -> 1098 | I8: =SUMIF(合格品出库记录!E:E,日报!D8,合格品出库记录!G:G) -> 0 | J8: =SUMIF(领跑良品退回!E:E,D8,领跑良品退回!G:G) -> 0 | K8: =M8+L8 -> 1101 | L8: =SUMIF(不良品库存!D:D,D:D,不良品库存!F:F) -> 3 | M8: =G8+H8-I8+J8 -> 1098 | N8: 8784 | O8: 1 | P8: =IF(SUMIFS(合格品入库记录!$G:$G,合格品入库记录!$E:$E,日报!$D:$D,合格品入库记录!$A:$A,日报!P$3)<>0,SUMIFS(合格品入库记录!$G:$G,合格品入库记录!$E:$E,日报!$D:$D,合格品入库记录!$A:$A,日报!P$3),"") | Q8: =IF(SUMIFS(合格品入库记录!$G:$G,合格品入库记录!$E:$E,日报!$D:$D,合格品入库记录!$A:$A,日报!Q$3)<>0,SUMIFS(合格品入库记录!$G:$G,合格品入库记录!$E:$E,日报!$D:$D,合格品入库记录!$A:$A,日报!Q$3),"") | R8: =IF(SUMIFS(合格品入库记录!$G:$G,合格品入库记录!$E:$E,日报!$D:$D,合格品入库记录!$A:$A,日报!R$3)<>0,SUMIFS(合格品入库记录!$G:$G,合格品入库记录!$E:$E,日报!$D:$D,合格品入库记录!$A:$A,日报!R$3),"") | S8: =IF(SUMIFS(合格品入库记录!$G:$G,合格品入库记录!$E:$E,日报!$D:$D,合格品入库记录!$A:$A,日报!S$3)<>0,SUMIFS(合格品入库记录!$G:$G,合格品入库记录!$E:$E,日报!$D:$D,合格品入库记录!$A:$A,日报!S$3),"") | T8: =IF(SUMIFS(合格品入库记录!$G:$G,合格品入库记录!$E:$E,日报!$D:$D,合格品入库记录!$A:$A,日报!T$3)<>0,SUMIFS(合格品入库记录!$G:$G,合格品入库记录!$E:$E,日报!$D:$D,合格品入库记录!$A:$A,日报!T$3),"") -> 1098 | U8: =IF(SUMIFS(合格品入库记录!$G:$G,合格品入库记录!$E:$E,日报!$D:$D,合格品入库记录!$A:$A,日报!U$3)<>0,SUMIFS(合格品入库记录!$G:$G,合格品入库记录!$E:$E,日报!$D:$D,合格品入库记录!$A:$A,日报!U$3),"") | V8: =IF(SUMIFS(合格品入库记录!$G:$G,合格品入库记录!$E:$E,日报!$D:$D,合格品入库记录!$A:$A,日报!V$3)<>0,SUMIFS(合格品入库记录!$G:$G,合格品入库记录!$E:$E,日报!$D:$D,合格品入库记录!$A:$A,日报!V$3),"") | W8: =IF(SUMIFS(合格品入库记录!$G:$G,合格品入库记录!$E:$E,日报!$D:$D,合格品入库记录!$A:$A,日报!W$3)<>0,SUMIFS(合格品入库记录!$G:$G,合格品入库记录!$E:$E,日报!$D:$D,合格品入库记录!$A:$A,日报!W$3),"") | ... AT8: =IF(SUMIFS(合格品入库记录!$G:$G,合格品入库记录!$E:$E,日报!$D:$D,合格品入库记录!$A:$A,日报!AT$3)<>0,SUMIFS(合格品入库记录!$G:$G,合格品入库记录!$E:$E,日报!$D:$D,合格品入库记录!$A:$A,日报!AT$3),"") | AU8: =IF(SUMIFS(合格品出库记录!$G:$G,合格品出库记录!$E:$E,日报!$D:$D,合格品出库记录!$A:$A,日报!AU$3)<>0,SUMIFS(合格品出库记录!$G:$G,合格品出库记录!$E:$E,日报!$D:$D,合格品出库记录!$A:$A,日报!AU$3),"") | AV8: =IF(SUMIFS(合格品出库记录!$G:$G,合格品出库记录!$E:$E,日报!$D:$D,合格品出库记录!$A:$A,日报!AV$3)<>0,SUMIFS(合格品出库记录!$G:$G,合格品出库记录!$E:$E,日报!$D:$D,合格品出库记录!$A:$A,日报!AV$3),"") | AW8: =IF(SUMIFS(合格品出库记录!$G:$G,合格品出库记录!$E:$E,日报!$D:$D,合格品出库记录!$A:$A,日报!AW$3)<>0,SUMIFS(合格品出库记录!$G:$G,合格品出库记录!$E:$E,日报!$D:$D,合格品出库记录!$A:$A,日报!AW$3),"") | AX8: =IF(SUMIFS(合格品出库记录!$G:$G,合格品出库记录!$E:$E,日报!$D:$D,合格品出库记录!$A:$A,日报!AX$3)<>0,SUMIFS(合格品出库记录!$G:$G,合格品出库记录!$E:$E,日报!$D:$D,合格品出库记录!$A:$A,日报!AX$3),"") | AY8: =IF(SUMIFS(合格品出库记录!$G:$G,合格品出库记录!$E:$E,日报!$D:$D,合格品出库记录!$A:$A,日报!AY$3)<>0,SUMIFS(合格品出库记录!$G:$G,合格品出库记录!$E:$E,日报!$D:$D,合格品出库记录!$A:$A,日报!AY$3),"") | AZ8: =IF(SUMIFS(合格品出库记录!$G:$G,合格品出库记录!$E:$E,日报!$D:$D,合格品出库记录!$A:$A,日报!AZ$3)<>0,SUMIFS(合格品出库记录!$G:$G,合格品出库记录!$E:$E,日报!$D:$D,合格品出库记录!$A:$A,日报!AZ$3),"") | BA8: =IF(SUMIFS(合格品出库记录!$G:$G,合格品出库记录!$E:$E,日报!$D:$D,合格品出库记录!$A:$A,日报!BA$3)<>0,SUMIFS(合格品出库记录!$G:$G,合格品出库记录!$E:$E,日报!$D:$D,合格品出库记录!$A:$A,日报!BA$3),"") | BB8: =IF(SUMIFS(合格品出库记录!$G:$G,合格品出库记录!$E:$E,日报!$D:$D,合格品出库记录!$A:$A,日报!BB$3)<>0,SUMIFS(合格品出库记录!$G:$G,合格品出库记录!$E:$E,日报!$D:$D,合格品出库记录!$A:$A,日报!BB$3),"") | ... BY8: =IF(SUMIFS(合格品出库记录!$G:$G,合格品出库记录!$E:$E,日报!$D:$D,合格品出库记录!$A:$A,日报!BY$3)<>0,SUMIFS(合格品出库记录!$G:$G,合格品出库记录!$E:$E,日报!$D:$D,合格品出库记录!$A:$A,日报!BY$3),"") | BZ8: =IF(SUMIFS(领跑良品退回!$G:$G,领跑良品退回!$E:$E,日报!$D:$D,领跑良品退回!$A:$A,日报!BZ$3)<>0,SUMIFS(领跑良品退回!$G:$G,领跑良品退回!$E:$E,日报!$D:$D,领跑良品退回!$A:$A,日报!BZ$3),"") | CA8: =IF(SUMIFS(领跑良品退回!$G:$G,领跑良品退回!$E:$E,日报!$D:$D,领跑良品退回!$A:$A,日报!CA$3)<>0,SUMIFS(领跑良品退回!$G:$G,领跑良品退回!$E:$E,日报!$D:$D,领跑良品退回!$A:$A,日报!CA$3),"") | CB8: =IF(SUMIFS(领跑良品退回!$G:$G,领跑良品退回!$E:$E,日报!$D:$D,领跑良品退回!$A:$A,日报!CB$3)<>0,SUMIFS(领跑良品退回!$G:$G,领跑良品退回!$E:$E,日报!$D:$D,领跑良品退回!$A:$A,日报!CB$3),"") | CC8: =IF(SUMIFS(领跑良品退回!$G:$G,领跑良品退回!$E:$E,日报!$D:$D,领跑良品退回!$A:$A,日报!CC$3)<>0,SUMIFS(领跑良品退回!$G:$G,领跑良品退回!$E:$E,日报!$D:$D,领跑良品退回!$A:$A,日报!CC$3),"") | CD8: =IF(SUMIFS(领跑良品退回!$G:$G,领跑良品退回!$E:$E,日报!$D:$D,领跑良品退回!$A:$A,日报!CD$3)<>0,SUMIFS(领跑良品退回!$G:$G,领跑良品退回!$E:$E,日报!$D:$D,领跑良品退回!$A:$A,日报!CD$3),"") | CE8: =IF(SUMIFS(领跑良品退回!$G:$G,领跑良品退回!$E:$E,日报!$D:$D,领跑良品退回!$A:$A,日报!CE$3)<>0,SUMIFS(领跑良品退回!$G:$G,领跑良品退回!$E:$E,日报!$D:$D,领跑良品退回!$A:$A,日报!CE$3),"") | CF8: =IF(SUMIFS(领跑良品退回!$G:$G,领跑良品退回!$E:$E,日报!$D:$D,领跑良品退回!$A:$A,日报!CF$3)<>0,SUMIFS(领跑良品退回!$G:$G,领跑良品退回!$E:$E,日报!$D:$D,领跑良品退回!$A:$A,日报!CF$3),"") | CG8: =IF(SUMIFS(领跑良品退回!$G:$G,领跑良品退回!$E:$E,日报!$D:$D,领跑良品退回!$A:$A,日报!CG$3)<>0,SUMIFS(领跑良品退回!$G:$G,领跑良品退回!$E:$E,日报!$D:$D,领跑良品退回!$A:$A,日报!CG$3),"") | ... DD8: =IF(SUMIFS(领跑良品退回!$G:$G,领跑良品退回!$E:$E,日报!$D:$D,领跑良品退回!$A:$A,日报!DD$3)<>0,SUMIFS(领跑良品退回!$G:$G,领跑良品退回!$E:$E,日报!$D:$D,领跑良品退回!$A:$A,日报!DD$3),"")
A9: 6 | B9: 1AC | C9: 宁波天下汽配有限公司 | D9: 3.2.42.20.00042-000 | E9: LPT03_IPUPDU接线盒盖本色 | F9: =IFERROR(VLOOKUP(D9,基础信息!D:F,3,FALSE),"0") -> 0 | G9: 521 | H9: =SUMIF(合格品入库记录!E:E,日报!D9,合格品入库记录!G:G) -> 680 | I9: =SUMIF(合格品出库记录!E:E,日报!D9,合格品出库记录!G:G) -> 0 | J9: =SUMIF(领跑良品退回!E:E,D9,领跑良品退回!G:G) -> 0 | K9: =M9+L9 -> 1257 | L9: =SUMIF(不良品库存!D:D,D:D,不良品库存!F:F) -> 56 | M9: =G9+H9-I9+J9 -> 1201 | N9: #N/A | O9: 1 | P9: =IF(SUMIFS(合格品入库记录!$G:$G,合格品入库记录!$E:$E,日报!$D:$D,合格品入库记录!$A:$A,日报!P$3)<>0,SUMIFS(合格品入库记录!$G:$G,合格品入库记录!$E:$E,日报!$D:$D,合格品入库记录!$A:$A,日报!P$3),"") | Q9: =IF(SUMIFS(合格品入库记录!$G:$G,合格品入库记录!$E:$E,日报!$D:$D,合格品入库记录!$A:$A,日报!Q$3)<>0,SUMIFS(合格品入库记录!$G:$G,合格品入库记录!$E:$E,日报!$D:$D,合格品入库记录!$A:$A,日报!Q$3),"") | R9: =IF(SUMIFS(合格品入库记录!$G:$G,合格品入库记录!$E:$E,日报!$D:$D,合格品入库记录!$A:$A,日报!R$3)<>0,SUMIFS(合格品入库记录!$G:$G,合格品入库记录!$E:$E,日报!$D:$D,合格品入库记录!$A:$A,日报!R$3),"") | S9: =IF(SUMIFS(合格品入库记录!$G:$G,合格品入库记录!$E:$E,日报!$D:$D,合格品入库记录!$A:$A,日报!S$3)<>0,SUMIFS(合格品入库记录!$G:$G,合格品入库记录!$E:$E,日报!$D:$D,合格品入库记录!$A:$A,日报!S$3),"") | T9: =IF(SUMIFS(合格品入库记录!$G:$G,合格品入库记录!$E:$E,日报!$D:$D,合格品入库记录!$A:$A,日报!T$3)<>0,SUMIFS(合格品入库记录!$G:$G,合格品入库记录!$E:$E,日报!$D:$D,合格品入库记录!$A:$A,日报!T$3),"") -> 680 | U9: =IF(SUMIFS(合格品入库记录!$G:$G,合格品入库记录!$E:$E,日报!$D:$D,合格品入库记录!$A:$A,日报!U$3)<>0,SUMIFS(合格品入库记录!$G:$G,合格品入库记录!$E:$E,日报!$D:$D,合格品入库记录!$A:$A,日报!U$3),"") | V9: =IF(SUMIFS(合格品入库记录!$G:$G,合格品入库记录!$E:$E,日报!$D:$D,合格品入库记录!$A:$A,日报!V$3)<>0,SUMIFS(合格品入库记录!$G:$G,合格品入库记录!$E:$E,日报!$D:$D,合格品入库记录!$A:$A,日报!V$3),"") | W9: =IF(SUMIFS(合格品入库记录!$G:$G,合格品入库记录!$E:$E,日报!$D:$D,合格品入库记录!$A:$A,日报!W$3)<>0,SUMIFS(合格品入库记录!$G:$G,合格品入库记录!$E:$E,日报!$D:$D,合格品入库记录!$A:$A,日报!W$3),"") | ... AT9: =IF(SUMIFS(合格品入库记录!$G:$G,合格品入库记录!$E:$E,日报!$D:$D,合格品入库记录!$A:$A,日报!AT$3)<>0,SUMIFS(合格品入库记录!$G:$G,合格品入库记录!$E:$E,日报!$D:$D,合格品入库记录!$A:$A,日报!AT$3),"") | AU9: =IF(SUMIFS(合格品出库记录!$G:$G,合格品出库记录!$E:$E,日报!$D:$D,合格品出库记录!$A:$A,日报!AU$3)<>0,SUMIFS(合格品出库记录!$G:$G,合格品出库记录!$E:$E,日报!$D:$D,合格品出库记录!$A:$A,日报!AU$3),"") | AV9: =IF(SUMIFS(合格品出库记录!$G:$G,合格品出库记录!$E:$E,日报!$D:$D,合格品出库记录!$A:$A,日报!AV$3)<>0,SUMIFS(合格品出库记录!$G:$G,合格品出库记录!$E:$E,日报!$D:$D,合格品出库记录!$A:$A,日报!AV$3),"") | AW9: =IF(SUMIFS(合格品出库记录!$G:$G,合格品出库记录!$E:$E,日报!$D:$D,合格品出库记录!$A:$A,日报!AW$3)<>0,SUMIFS(合格品出库记录!$G:$G,合格品出库记录!$E:$E,日报!$D:$D,合格品出库记录!$A:$A,日报!AW$3),"") | AX9: =IF(SUMIFS(合格品出库记录!$G:$G,合格品出库记录!$E:$E,日报!$D:$D,合格品出库记录!$A:$A,日报!AX$3)<>0,SUMIFS(合格品出库记录!$G:$G,合格品出库记录!$E:$E,日报!$D:$D,合格品出库记录!$A:$A,日报!AX$3),"") | AY9: =IF(SUMIFS(合格品出库记录!$G:$G,合格品出库记录!$E:$E,日报!$D:$D,合格品出库记录!$A:$A,日报!AY$3)<>0,SUMIFS(合格品出库记录!$G:$G,合格品出库记录!$E:$E,日报!$D:$D,合格品出库记录!$A:$A,日报!AY$3),"") | AZ9: =IF(SUMIFS(合格品出库记录!$G:$G,合格品出库记录!$E:$E,日报!$D:$D,合格品出库记录!$A:$A,日报!AZ$3)<>0,SUMIFS(合格品出库记录!$G:$G,合格品出库记录!$E:$E,日报!$D:$D,合格品出库记录!$A:$A,日报!AZ$3),"") | BA9: =IF(SUMIFS(合格品出库记录!$G:$G,合格品出库记录!$E:$E,日报!$D:$D,合格品出库记录!$A:$A,日报!BA$3)<>0,SUMIFS(合格品出库记录!$G:$G,合格品出库记录!$E:$E,日报!$D:$D,合格品出库记录!$A:$A,日报!BA$3),"") | BB9: =IF(SUMIFS(合格品出库记录!$G:$G,合格品出库记录!$E:$E,日报!$D:$D,合格品出库记录!$A:$A,日报!BB$3)<>0,SUMIFS(合格品出库记录!$G:$G,合格品出库记录!$E:$E,日报!$D:$D,合格品出库记录!$A:$A,日报!BB$3),"") | ... BY9: =IF(SUMIFS(合格品出库记录!$G:$G,合格品出库记录!$E:$E,日报!$D:$D,合格品出库记录!$A:$A,日报!BY$3)<>0,SUMIFS(合格品出库记录!$G:$G,合格品出库记录!$E:$E,日报!$D:$D,合格品出库记录!$A:$A,日报!BY$3),"") | BZ9: =IF(SUMIFS(领跑良品退回!$G:$G,领跑良品退回!$E:$E,日报!$D:$D,领跑良品退回!$A:$A,日报!BZ$3)<>0,SUMIFS(领跑良品退回!$G:$G,领跑良品退回!$E:$E,日报!$D:$D,领跑良品退回!$A:$A,日报!BZ$3),"") | CA9: =IF(SUMIFS(领跑良品退回!$G:$G,领跑良品退回!$E:$E,日报!$D:$D,领跑良品退回!$A:$A,日报!CA$3)<>0,SUMIFS(领跑良品退回!$G:$G,领跑良品退回!$E:$E,日报!$D:$D,领跑良品退回!$A:$A,日报!CA$3),"") | CB9: =IF(SUMIFS(领跑良品退回!$G:$G,领跑良品退回!$E:$E,日报!$D:$D,领跑良品退回!$A:$A,日报!CB$3)<>0,SUMIFS(领跑良品退回!$G:$G,领跑良品退回!$E:$E,日报!$D:$D,领跑良品退回!$A:$A,日报!CB$3),"") | CC9: =IF(SUMIFS(领跑良品退回!$G:$G,领跑良品退回!$E:$E,日报!$D:$D,领跑良品退回!$A:$A,日报!CC$3)<>0,SUMIFS(领跑良品退回!$G:$G,领跑良品退回!$E:$E,日报!$D:$D,领跑良品退回!$A:$A,日报!CC$3),"") | CD9: =IF(SUMIFS(领跑良品退回!$G:$G,领跑良品退回!$E:$E,日报!$D:$D,领跑良品退回!$A:$A,日报!CD$3)<>0,SUMIFS(领跑良品退回!$G:$G,领跑良品退回!$E:$E,日报!$D:$D,领跑良品退回!$A:$A,日报!CD$3),"") | CE9: =IF(SUMIFS(领跑良品退回!$G:$G,领跑良品退回!$E:$E,日报!$D:$D,领跑良品退回!$A:$A,日报!CE$3)<>0,SUMIFS(领跑良品退回!$G:$G,领跑良品退回!$E:$E,日报!$D:$D,领跑良品退回!$A:$A,日报!CE$3),"") | CF9: =IF(SUMIFS(领跑良品退回!$G:$G,领跑良品退回!$E:$E,日报!$D:$D,领跑良品退回!$A:$A,日报!CF$3)<>0,SUMIFS(领跑良品退回!$G:$G,领跑良品退回!$E:$E,日报!$D:$D,领跑良品退回!$A:$A,日报!CF$3),"") | CG9: =IF(SUMIFS(领跑良品退回!$G:$G,领跑良品退回!$E:$E,日报!$D:$D,领跑良品退回!$A:$A,日报!CG$3)<>0,SUMIFS(领跑良品退回!$G:$G,领跑良品退回!$E:$E,日报!$D:$D,领跑良品退回!$A:$A,日报!CG$3),"") | ... DD9: =IF(SUMIFS(领跑良品退回!$G:$G,领跑良品退回!$E:$E,日报!$D:$D,领跑良品退回!$A:$A,日报!DD$3)<>0,SUMIFS(领跑良品退回!$G:$G,领跑良品退回!$E:$E,日报!$D:$D,领跑良品退回!$A:$A,日报!DD$3),"")
A10: 7 | B10: 1AC | C10: 宁波天下汽配有限公司 | D10: 3.2.42.20.00046-000 | E10: LPT03_IPU转接板安装板本色 | F10: =IFERROR(VLOOKUP(D10,基础信息!D:F,3,FALSE),"0") -> 300 | G10: 1006 | H10: =SUMIF(合格品入库记录!E:E,日报!D10,合格品入库记录!G:G) -> 0 | I10: =SUMIF(合格品出库记录!E:E,日报!D10,合格品出库记录!G:G) -> 0 | J10: =SUMIF(领跑良品退回!E:E,D10,领跑良品退回!G:G) -> 0 | K10: =M10+L10 -> 1015 | L10: =SUMIF(不良品库存!D:D,D:D,不良品库存!F:F) -> 9 | M10: =G10+H10-I10+J10 -> 1006 | N10: 7200 | O10: 1 | P10: =IF(SUMIFS(合格品入库记录!$G:$G,合格品入库记录!$E:$E,日报!$D:$D,合格品入库记录!$A:$A,日报!P$3)<>0,SUMIFS(合格品入库记录!$G:$G,合格品入库记录!$E:$E,日报!$D:$D,合格品入库记录!$A:$A,日报!P$3),"") | Q10: =IF(SUMIFS(合格品入库记录!$G:$G,合格品入库记录!$E:$E,日报!$D:$D,合格品入库记录!$A:$A,日报!Q$3)<>0,SUMIFS(合格品入库记录!$G:$G,合格品入库记录!$E:$E,日报!$D:$D,合格品入库记录!$A:$A,日报!Q$3),"") | R10: =IF(SUMIFS(合格品入库记录!$G:$G,合格品入库记录!$E:$E,日报!$D:$D,合格品入库记录!$A:$A,日报!R$3)<>0,SUMIFS(合格品入库记录!$G:$G,合格品入库记录!$E:$E,日报!$D:$D,合格品入库记录!$A:$A,日报!R$3),"") | S10: =IF(SUMIFS(合格品入库记录!$G:$G,合格品入库记录!$E:$E,日报!$D:$D,合格品入库记录!$A:$A,日报!S$3)<>0,SUMIFS(合格品入库记录!$G:$G,合格品入库记录!$E:$E,日报!$D:$D,合格品入库记录!$A:$A,日报!S$3),"") | T10: =IF(SUMIFS(合格品入库记录!$G:$G,合格品入库记录!$E:$E,日报!$D:$D,合格品入库记录!$A:$A,日报!T$3)<>0,SUMIFS(合格品入库记录!$G:$G,合格品入库记录!$E:$E,日报!$D:$D,合格品入库记录!$A:$A,日报!T$3),"") | U10: =IF(SUMIFS(合格品入库记录!$G:$G,合格品入库记录!$E:$E,日报!$D:$D,合格品入库记录!$A:$A,日报!U$3)<>0,SUMIFS(合格品入库记录!$G:$G,合格品入库记录!$E:$E,日报!$D:$D,合格品入库记录!$A:$A,日报!U$3),"") | V10: =IF(SUMIFS(合格品入库记录!$G:$G,合格品入库记录!$E:$E,日报!$D:$D,合格品入库记录!$A:$A,日报!V$3)<>0,SUMIFS(合格品入库记录!$G:$G,合格品入库记录!$E:$E,日报!$D:$D,合格品入库记录!$A:$A,日报!V$3),"") | W10: =IF(SUMIFS(合格品入库记录!$G:$G,合格品入库记录!$E:$E,日报!$D:$D,合格品入库记录!$A:$A,日报!W$3)<>0,SUMIFS(合格品入库记录!$G:$G,合格品入库记录!$E:$E,日报!$D:$D,合格品入库记录!$A:$A,日报!W$3),"") | ... AT10: =IF(SUMIFS(合格品入库记录!$G:$G,合格品入库记录!$E:$E,日报!$D:$D,合格品入库记录!$A:$A,日报!AT$3)<>0,SUMIFS(合格品入库记录!$G:$G,合格品入库记录!$E:$E,日报!$D:$D,合格品入库记录!$A:$A,日报!AT$3),"") | AU10: =IF(SUMIFS(合格品出库记录!$G:$G,合格品出库记录!$E:$E,日报!$D:$D,合格品出库记录!$A:$A,日报!AU$3)<>0,SUMIFS(合格品出库记录!$G:$G,合格品出库记录!$E:$E,日报!$D:$D,合格品出库记录!$A:$A,日报!AU$3),"") | AV10: =IF(SUMIFS(合格品出库记录!$G:$G,合格品出库记录!$E:$E,日报!$D:$D,合格品出库记录!$A:$A,日报!AV$3)<>0,SUMIFS(合格品出库记录!$G:$G,合格品出库记录!$E:$E,日报!$D:$D,合格品出库记录!$A:$A,日报!AV$3),"") | AW10: =IF(SUMIFS(合格品出库记录!$G:$G,合格品出库记录!$E:$E,日报!$D:$D,合格品出库记录!$A:$A,日报!AW$3)<>0,SUMIFS(合格品出库记录!$G:$G,合格品出库记录!$E:$E,日报!$D:$D,合格品出库记录!$A:$A,日报!AW$3),"") | AX10: =IF(SUMIFS(合格品出库记录!$G:$G,合格品出库记录!$E:$E,日报!$D:$D,合格品出库记录!$A:$A,日报!AX$3)<>0,SUMIFS(合格品出库记录!$G:$G,合格品出库记录!$E:$E,日报!$D:$D,合格品出库记录!$A:$A,日报!AX$3),"") | AY10: =IF(SUMIFS(合格品出库记录!$G:$G,合格品出库记录!$E:$E,日报!$D:$D,合格品出库记录!$A:$A,日报!AY$3)<>0,SUMIFS(合格品出库记录!$G:$G,合格品出库记录!$E:$E,日报!$D:$D,合格品出库记录!$A:$A,日报!AY$3),"") | AZ10: =IF(SUMIFS(合格品出库记录!$G:$G,合格品出库记录!$E:$E,日报!$D:$D,合格品出库记录!$A:$A,日报!AZ$3)<>0,SUMIFS(合格品出库记录!$G:$G,合格品出库记录!$E:$E,日报!$D:$D,合格品出库记录!$A:$A,日报!AZ$3),"") | BA10: =IF(SUMIFS(合格品出库记录!$G:$G,合格品出库记录!$E:$E,日报!$D:$D,合格品出库记录!$A:$A,日报!BA$3)<>0,SUMIFS(合格品出库记录!$G:$G,合格品出库记录!$E:$E,日报!$D:$D,合格品出库记录!$A:$A,日报!BA$3),"") | BB10: =IF(SUMIFS(合格品出库记录!$G:$G,合格品出库记录!$E:$E,日报!$D:$D,合格品出库记录!$A:$A,日报!BB$3)<>0,SUMIFS(合格品出库记录!$G:$G,合格品出库记录!$E:$E,日报!$D:$D,合格品出库记录!$A:$A,日报!BB$3),"") | ... BY10: =IF(SUMIFS(合格品出库记录!$G:$G,合格品出库记录!$E:$E,日报!$D:$D,合格品出库记录!$A:$A,日报!BY$3)<>0,SUMIFS(合格品出库记录!$G:$G,合格品出库记录!$E:$E,日报!$D:$D,合格品出库记录!$A:$A,日报!BY$3),"") | BZ10: =IF(SUMIFS(领跑良品退回!$G:$G,领跑良品退回!$E:$E,日报!$D:$D,领跑良品退回!$A:$A,日报!BZ$3)<>0,SUMIFS(领跑良品退回!$G:$G,领跑良品退回!$E:$E,日报!$D:$D,领跑良品退回!$A:$A,日报!BZ$3),"") | CA10: =IF(SUMIFS(领跑良品退回!$G:$G,领跑良品退回!$E:$E,日报!$D:$D,领跑良品退回!$A:$A,日报!CA$3)<>0,SUMIFS(领跑良品退回!$G:$G,领跑良品退回!$E:$E,日报!$D:$D,领跑良品退回!$A:$A,日报!CA$3),"") | CB10: =IF(SUMIFS(领跑良品退回!$G:$G,领跑良品退回!$E:$E,日报!$D:$D,领跑良品退回!$A:$A,日报!CB$3)<>0,SUMIFS(领跑良品退回!$G:$G,领跑良品退回!$E:$E,日报!$D:$D,领跑良品退回!$A:$A,日报!CB$3),"") | CC10: =IF(SUMIFS(领跑良品退回!$G:$G,领跑良品退回!$E:$E,日报!$D:$D,领跑良品退回!$A:$A,日报!CC$3)<>0,SUMIFS(领跑良品退回!$G:$G,领跑良品退回!$E:$E,日报!$D:$D,领跑良品退回!$A:$A,日报!CC$3),"") | CD10: =IF(SUMIFS(领跑良品退回!$G:$G,领跑良品退回!$E:$E,日报!$D:$D,领跑良品退回!$A:$A,日报!CD$3)<>0,SUMIFS(领跑良品退回!$G:$G,领跑良品退回!$E:$E,日报!$D:$D,领跑良品退回!$A:$A,日报!CD$3),"") | CE10: =IF(SUMIFS(领跑良品退回!$G:$G,领跑良品退回!$E:$E,日报!$D:$D,领跑良品退回!$A:$A,日报!CE$3)<>0,SUMIFS(领跑良品退回!$G:$G,领跑良品退回!$E:$E,日报!$D:$D,领跑良品退回!$A:$A,日报!CE$3),"") | CF10: =IF(SUMIFS(领跑良品退回!$G:$G,领跑良品退回!$E:$E,日报!$D:$D,领跑良品退回!$A:$A,日报!CF$3)<>0,SUMIFS(领跑良品退回!$G:$G,领跑良品退回!$E:$E,日报!$D:$D,领跑良品退回!$A:$A,日报!CF$3),"") | CG10: =IF(SUMIFS(领跑良品退回!$G:$G,领跑良品退回!$E:$E,日报!$D:$D,领跑良品退回!$A:$A,日报!CG$3)<>0,SUMIFS(领跑良品退回!$G:$G,领跑良品退回!$E:$E,日报!$D:$D,领跑良品退回!$A:$A,日报!CG$3),"") | ... DD10: =IF(SUMIFS(领跑良品退回!$G:$G,领跑良品退回!$E:$E,日报!$D:$D,领跑良品退回!$A:$A,日报!DD$3)<>0,SUMIFS(领跑良品退回!$G:$G,领跑良品退回!$E:$E,日报!$D:$D,领跑良品退回!$A:$A,日报!DD$3),"")
A11: 8 | B11: 1AC | C11: 宁波天下汽配有限公司 | D11: 3.2.42.20.00047-000 | E11: DC输出正极保护罩下-本色 | F11: =IFERROR(VLOOKUP(D11,基础信息!D:F,3,FALSE),"0") -> 0 | G11: 4471 | H11: =SUMIF(合格品入库记录!E:E,日报!D11,合格品入库记录!G:G) -> 0 | I11: =SUMIF(合格品出库记录!E:E,日报!D11,合格品出库记录!G:G) -> 0 | J11: =SUMIF(领跑良品退回!E:E,D11,领跑良品退回!G:G) -> 0 | K11: =M11+L11 -> 4497 | L11: =SUMIF(不良品库存!D:D,D:D,不良品库存!F:F) -> 26 | M11: =G11+H11-I11+J11 -> 4471 | N11: #N/A | O11: 1 | P11: =IF(SUMIFS(合格品入库记录!$G:$G,合格品入库记录!$E:$E,日报!$D:$D,合格品入库记录!$A:$A,日报!P$3)<>0,SUMIFS(合格品入库记录!$G:$G,合格品入库记录!$E:$E,日报!$D:$D,合格品入库记录!$A:$A,日报!P$3),"") | Q11: =IF(SUMIFS(合格品入库记录!$G:$G,合格品入库记录!$E:$E,日报!$D:$D,合格品入库记录!$A:$A,日报!Q$3)<>0,SUMIFS(合格品入库记录!$G:$G,合格品入库记录!$E:$E,日报!$D:$D,合格品入库记录!$A:$A,日报!Q$3),"") | R11: =IF(SUMIFS(合格品入库记录!$G:$G,合格品入库记录!$E:$E,日报!$D:$D,合格品入库记录!$A:$A,日报!R$3)<>0,SUMIFS(合格品入库记录!$G:$G,合格品入库记录!$E:$E,日报!$D:$D,合格品入库记录!$A:$A,日报!R$3),"") | S11: =IF(SUMIFS(合格品入库记录!$G:$G,合格品入库记录!$E:$E,日报!$D:$D,合格品入库记录!$A:$A,日报!S$3)<>0,SUMIFS(合格品入库记录!$G:$G,合格品入库记录!$E:$E,日报!$D:$D,合格品入库记录!$A:$A,日报!S$3),"") | T11: =IF(SUMIFS(合格品入库记录!$G:$G,合格品入库记录!$E:$E,日报!$D:$D,合格品入库记录!$A:$A,日报!T$3)<>0,SUMIFS(合格品入库记录!$G:$G,合格品入库记录!$E:$E,日报!$D:$D,合格品入库记录!$A:$A,日报!T$3),"") | U11: =IF(SUMIFS(合格品入库记录!$G:$G,合格品入库记录!$E:$E,日报!$D:$D,合格品入库记录!$A:$A,日报!U$3)<>0,SUMIFS(合格品入库记录!$G:$G,合格品入库记录!$E:$E,日报!$D:$D,合格品入库记录!$A:$A,日报!U$3),"") | V11: =IF(SUMIFS(合格品入库记录!$G:$G,合格品入库记录!$E:$E,日报!$D:$D,合格品入库记录!$A:$A,日报!V$3)<>0,SUMIFS(合格品入库记录!$G:$G,合格品入库记录!$E:$E,日报!$D:$D,合格品入库记录!$A:$A,日报!V$3),"") | W11: =IF(SUMIFS(合格品入库记录!$G:$G,合格品入库记录!$E:$E,日报!$D:$D,合格品入库记录!$A:$A,日报!W$3)<>0,SUMIFS(合格品入库记录!$G:$G,合格品入库记录!$E:$E,日报!$D:$D,合格品入库记录!$A:$A,日报!W$3),"") | ... AT11: =IF(SUMIFS(合格品入库记录!$G:$G,合格品入库记录!$E:$E,日报!$D:$D,合格品入库记录!$A:$A,日报!AT$3)<>0,SUMIFS(合格品入库记录!$G:$G,合格品入库记录!$E:$E,日报!$D:$D,合格品入库记录!$A:$A,日报!AT$3),"") | AU11: =IF(SUMIFS(合格品出库记录!$G:$G,合格品出库记录!$E:$E,日报!$D:$D,合格品出库记录!$A:$A,日报!AU$3)<>0,SUMIFS(合格品出库记录!$G:$G,合格品出库记录!$E:$E,日报!$D:$D,合格品出库记录!$A:$A,日报!AU$3),"") | AV11: =IF(SUMIFS(合格品出库记录!$G:$G,合格品出库记录!$E:$E,日报!$D:$D,合格品出库记录!$A:$A,日报!AV$3)<>0,SUMIFS(合格品出库记录!$G:$G,合格品出库记录!$E:$E,日报!$D:$D,合格品出库记录!$A:$A,日报!AV$3),"") | AW11: =IF(SUMIFS(合格品出库记录!$G:$G,合格品出库记录!$E:$E,日报!$D:$D,合格品出库记录!$A:$A,日报!AW$3)<>0,SUMIFS(合格品出库记录!$G:$G,合格品出库记录!$E:$E,日报!$D:$D,合格品出库记录!$A:$A,日报!AW$3),"") | AX11: =IF(SUMIFS(合格品出库记录!$G:$G,合格品出库记录!$E:$E,日报!$D:$D,合格品出库记录!$A:$A,日报!AX$3)<>0,SUMIFS(合格品出库记录!$G:$G,合格品出库记录!$E:$E,日报!$D:$D,合格品出库记录!$A:$A,日报!AX$3),"") | AY11: =IF(SUMIFS(合格品出库记录!$G:$G,合格品出库记录!$E:$E,日报!$D:$D,合格品出库记录!$A:$A,日报!AY$3)<>0,SUMIFS(合格品出库记录!$G:$G,合格品出库记录!$E:$E,日报!$D:$D,合格品出库记录!$A:$A,日报!AY$3),"") | AZ11: =IF(SUMIFS(合格品出库记录!$G:$G,合格品出库记录!$E:$E,日报!$D:$D,合格品出库记录!$A:$A,日报!AZ$3)<>0,SUMIFS(合格品出库记录!$G:$G,合格品出库记录!$E:$E,日报!$D:$D,合格品出库记录!$A:$A,日报!AZ$3),"") | BA11: =IF(SUMIFS(合格品出库记录!$G:$G,合格品出库记录!$E:$E,日报!$D:$D,合格品出库记录!$A:$A,日报!BA$3)<>0,SUMIFS(合格品出库记录!$G:$G,合格品出库记录!$E:$E,日报!$D:$D,合格品出库记录!$A:$A,日报!BA$3),"") | BB11: =IF(SUMIFS(合格品出库记录!$G:$G,合格品出库记录!$E:$E,日报!$D:$D,合格品出库记录!$A:$A,日报!BB$3)<>0,SUMIFS(合格品出库记录!$G:$G,合格品出库记录!$E:$E,日报!$D:$D,合格品出库记录!$A:$A,日报!BB$3),"") | ... BY11: =IF(SUMIFS(合格品出库记录!$G:$G,合格品出库记录!$E:$E,日报!$D:$D,合格品出库记录!$A:$A,日报!BY$3)<>0,SUMIFS(合格品出库记录!$G:$G,合格品出库记录!$E:$E,日报!$D:$D,合格品出库记录!$A:$A,日报!BY$3),"") | BZ11: =IF(SUMIFS(领跑良品退回!$G:$G,领跑良品退回!$E:$E,日报!$D:$D,领跑良品退回!$A:$A,日报!BZ$3)<>0,SUMIFS(领跑良品退回!$G:$G,领跑良品退回!$E:$E,日报!$D:$D,领跑良品退回!$A:$A,日报!BZ$3),"") | CA11: =IF(SUMIFS(领跑良品退回!$G:$G,领跑良品退回!$E:$E,日报!$D:$D,领跑良品退回!$A:$A,日报!CA$3)<>0,SUMIFS(领跑良品退回!$G:$G,领跑良品退回!$E:$E,日报!$D:$D,领跑良品退回!$A:$A,日报!CA$3),"") | CB11: =IF(SUMIFS(领跑良品退回!$G:$G,领跑良品退回!$E:$E,日报!$D:$D,领跑良品退回!$A:$A,日报!CB$3)<>0,SUMIFS(领跑良品退回!$G:$G,领跑良品退回!$E:$E,日报!$D:$D,领跑良品退回!$A:$A,日报!CB$3),"") | CC11: =IF(SUMIFS(领跑良品退回!$G:$G,领跑良品退回!$E:$E,日报!$D:$D,领跑良品退回!$A:$A,日报!CC$3)<>0,SUMIFS(领跑良品退回!$G:$G,领跑良品退回!$E:$E,日报!$D:$D,领跑良品退回!$A:$A,日报!CC$3),"") | CD11: =IF(SUMIFS(领跑良品退回!$G:$G,领跑良品退回!$E:$E,日报!$D:$D,领跑良品退回!$A:$A,日报!CD$3)<>0,SUMIFS(领跑良品退回!$G:$G,领跑良品退回!$E:$E,日报!$D:$D,领跑良品退回!$A:$A,日报!CD$3),"") | CE11: =IF(SUMIFS(领跑良品退回!$G:$G,领跑良品退回!$E:$E,日报!$D:$D,领跑良品退回!$A:$A,日报!CE$3)<>0,SUMIFS(领跑良品退回!$G:$G,领跑良品退回!$E:$E,日报!$D:$D,领跑良品退回!$A:$A,日报!CE$3),"") | CF11: =IF(SUMIFS(领跑良品退回!$G:$G,领跑良品退回!$E:$E,日报!$D:$D,领跑良品退回!$A:$A,日报!CF$3)<>0,SUMIFS(领跑良品退回!$G:$G,领跑良品退回!$E:$E,日报!$D:$D,领跑良品退回!$A:$A,日报!CF$3),"") | CG11: =IF(SUMIFS(领跑良品退回!$G:$G,领跑良品退回!$E:$E,日报!$D:$D,领跑良品退回!$A:$A,日报!CG$3)<>0,SUMIFS(领跑良品退回!$G:$G,领跑良品退回!$E:$E,日报!$D:$D,领跑良品退回!$A:$A,日报!CG$3),"") | ... DD11: =IF(SUMIFS(领跑良品退回!$G:$G,领跑良品退回!$E:$E,日报!$D:$D,领跑良品退回!$A:$A,日报!DD$3)<>0,SUMIFS(领跑良品退回!$G:$G,领跑良品退回!$E:$E,日报!$D:$D,领跑良品退回!$A:$A,日报!DD$3),"")
A12: 9 | B12: 1AC | C12: 宁波天下汽配有限公司 | D12: 3.2.42.20.00048-000 | E12: DC输出正极保护罩上-本色 | F12: =IFERROR(VLOOKUP(D12,基础信息!D:F,3,FALSE),"0") -> 0 | G12: 4471 | H12: =SUMIF(合格品入库记录!E:E,日报!D12,合格品入库记录!G:G) -> 0 | I12: =SUMIF(合格品出库记录!E:E,日报!D12,合格品出库记录!G:G) -> 0 | J12: =SUMIF(领跑良品退回!E:E,D12,领跑良品退回!G:G) -> 0 | K12: =M12+L12 -> 4490 | L12: =SUMIF(不良品库存!D:D,D:D,不良品库存!F:F) -> 19 | M12: =G12+H12-I12+J12 -> 4471 | N12: #N/A | O12: 1 | P12: =IF(SUMIFS(合格品入库记录!$G:$G,合格品入库记录!$E:$E,日报!$D:$D,合格品入库记录!$A:$A,日报!P$3)<>0,SUMIFS(合格品入库记录!$G:$G,合格品入库记录!$E:$E,日报!$D:$D,合格品入库记录!$A:$A,日报!P$3),"") | Q12: =IF(SUMIFS(合格品入库记录!$G:$G,合格品入库记录!$E:$E,日报!$D:$D,合格品入库记录!$A:$A,日报!Q$3)<>0,SUMIFS(合格品入库记录!$G:$G,合格品入库记录!$E:$E,日报!$D:$D,合格品入库记录!$A:$A,日报!Q$3),"") | R12: =IF(SUMIFS(合格品入库记录!$G:$G,合格品入库记录!$E:$E,日报!$D:$D,合格品入库记录!$A:$A,日报!R$3)<>0,SUMIFS(合格品入库记录!$G:$G,合格品入库记录!$E:$E,日报!$D:$D,合格品入库记录!$A:$A,日报!R$3),"") | S12: =IF(SUMIFS(合格品入库记录!$G:$G,合格品入库记录!$E:$E,日报!$D:$D,合格品入库记录!$A:$A,日报!S$3)<>0,SUMIFS(合格品入库记录!$G:$G,合格品入库记录!$E:$E,日报!$D:$D,合格品入库记录!$A:$A,日报!S$3),"") | T12: =IF(SUMIFS(合格品入库记录!$G:$G,合格品入库记录!$E:$E,日报!$D:$D,合格品入库记录!$A:$A,日报!T$3)<>0,SUMIFS(合格品入库记录!$G:$G,合格品入库记录!$E:$E,日报!$D:$D,合格品入库记录!$A:$A,日报!T$3),"") | U12: =IF(SUMIFS(合格品入库记录!$G:$G,合格品入库记录!$E:$E,日报!$D:$D,合格品入库记录!$A:$A,日报!U$3)<>0,SUMIFS(合格品入库记录!$G:$G,合格品入库记录!$E:$E,日报!$D:$D,合格品入库记录!$A:$A,日报!U$3),"") | V12: =IF(SUMIFS(合格品入库记录!$G:$G,合格品入库记录!$E:$E,日报!$D:$D,合格品入库记录!$A:$A,日报!V$3)<>0,SUMIFS(合格品入库记录!$G:$G,合格品入库记录!$E:$E,日报!$D:$D,合格品入库记录!$A:$A,日报!V$3),"") | W12: =IF(SUMIFS(合格品入库记录!$G:$G,合格品入库记录!$E:$E,日报!$D:$D,合格品入库记录!$A:$A,日报!W$3)<>0,SUMIFS(合格品入库记录!$G:$G,合格品入库记录!$E:$E,日报!$D:$D,合格品入库记录!$A:$A,日报!W$3),"") | ... AT12: =IF(SUMIFS(合格品入库记录!$G:$G,合格品入库记录!$E:$E,日报!$D:$D,合格品入库记录!$A:$A,日报!AT$3)<>0,SUMIFS(合格品入库记录!$G:$G,合格品入库记录!$E:$E,日报!$D:$D,合格品入库记录!$A:$A,日报!AT$3),"") | AU12: =IF(SUMIFS(合格品出库记录!$G:$G,合格品出库记录!$E:$E,日报!$D:$D,合格品出库记录!$A:$A,日报!AU$3)<>0,SUMIFS(合格品出库记录!$G:$G,合格品出库记录!$E:$E,日报!$D:$D,合格品出库记录!$A:$A,日报!AU$3),"") | AV12: =IF(SUMIFS(合格品出库记录!$G:$G,合格品出库记录!$E:$E,日报!$D:$D,合格品出库记录!$A:$A,日报!AV$3)<>0,SUMIFS(合格品出库记录!$G:$G,合格品出库记录!$E:$E,日报!$D:$D,合格品出库记录!$A:$A,日报!AV$3),"") | AW12: =IF(SUMIFS(合格品出库记录!$G:$G,合格品出库记录!$E:$E,日报!$D:$D,合格品出库记录!$A:$A,日报!AW$3)<>0,SUMIFS(合格品出库记录!$G:$G,合格品出库记录!$E:$E,日报!$D:$D,合格品出库记录!$A:$A,日报!AW$3),"") | AX12: =IF(SUMIFS(合格品出库记录!$G:$G,合格品出库记录!$E:$E,日报!$D:$D,合格品出库记录!$A:$A,日报!AX$3)<>0,SUMIFS(合格品出库记录!$G:$G,合格品出库记录!$E:$E,日报!$D:$D,合格品出库记录!$A:$A,日报!AX$3),"") | AY12: =IF(SUMIFS(合格品出库记录!$G:$G,合格品出库记录!$E:$E,日报!$D:$D,合格品出库记录!$A:$A,日报!AY$3)<>0,SUMIFS(合格品出库记录!$G:$G,合格品出库记录!$E:$E,日报!$D:$D,合格品出库记录!$A:$A,日报!AY$3),"") | AZ12: =IF(SUMIFS(合格品出库记录!$G:$G,合格品出库记录!$E:$E,日报!$D:$D,合格品出库记录!$A:$A,日报!AZ$3)<>0,SUMIFS(合格品出库记录!$G:$G,合格品出库记录!$E:$E,日报!$D:$D,合格品出库记录!$A:$A,日报!AZ$3),"") | BA12: =IF(SUMIFS(合格品出库记录!$G:$G,合格品出库记录!$E:$E,日报!$D:$D,合格品出库记录!$A:$A,日报!BA$3)<>0,SUMIFS(合格品出库记录!$G:$G,合格品出库记录!$E:$E,日报!$D:$D,合格品出库记录!$A:$A,日报!BA$3),"") | BB12: =IF(SUMIFS(合格品出库记录!$G:$G,合格品出库记录!$E:$E,日报!$D:$D,合格品出库记录!$A:$A,日报!BB$3)<>0,SUMIFS(合格品出库记录!$G:$G,合格品出库记录!$E:$E,日报!$D:$D,合格品出库记录!$A:$A,日报!BB$3),"") | ... BY12: =IF(SUMIFS(合格品出库记录!$G:$G,合格品出库记录!$E:$E,日报!$D:$D,合格品出库记录!$A:$A,日报!BY$3)<>0,SUMIFS(合格品出库记录!$G:$G,合格品出库记录!$E:$E,日报!$D:$D,合格品出库记录!$A:$A,日报!BY$3),"") | BZ12: =IF(SUMIFS(领跑良品退回!$G:$G,领跑良品退回!$E:$E,日报!$D:$D,领跑良品退回!$A:$A,日报!BZ$3)<>0,SUMIFS(领跑良品退回!$G:$G,领跑良品退回!$E:$E,日报!$D:$D,领跑良品退回!$A:$A,日报!BZ$3),"") | CA12: =IF(SUMIFS(领跑良品退回!$G:$G,领跑良品退回!$E:$E,日报!$D:$D,领跑良品退回!$A:$A,日报!CA$3)<>0,SUMIFS(领跑良品退回!$G:$G,领跑良品退回!$E:$E,日报!$D:$D,领跑良品退回!$A:$A,日报!CA$3),"") | CB12: =IF(SUMIFS(领跑良品退回!$G:$G,领跑良品退回!$E:$E,日报!$D:$D,领跑良品退回!$A:$A,日报!CB$3)<>0,SUMIFS(领跑良品退回!$G:$G,领跑良品退回!$E:$E,日报!$D:$D,领跑良品退回!$A:$A,日报!CB$3),"") | CC12: =IF(SUMIFS(领跑良品退回!$G:$G,领跑良品退回!$E:$E,日报!$D:$D,领跑良品退回!$A:$A,日报!CC$3)<>0,SUMIFS(领跑良品退回!$G:$G,领跑良品退回!$E:$E,日报!$D:$D,领跑良品退回!$A:$A,日报!CC$3),"") | CD12: =IF(SUMIFS(领跑良品退回!$G:$G,领跑良品退回!$E:$E,日报!$D:$D,领跑良品退回!$A:$A,日报!CD$3)<>0,SUMIFS(领跑良品退回!$G:$G,领跑良品退回!$E:$E,日报!$D:$D,领跑良品退回!$A:$A,日报!CD$3),"") | CE12: =IF(SUMIFS(领跑良品退回!$G:$G,领跑良品退回!$E:$E,日报!$D:$D,领跑良品退回!$A:$A,日报!CE$3)<>0,SUMIFS(领跑良品退回!$G:$G,领跑良品退回!$E:$E,日报!$D:$D,领跑良品退回!$A:$A,日报!CE$3),"") | CF12: =IF(SUMIFS(领跑良品退回!$G:$G,领跑良品退回!$E:$E,日报!$D:$D,领跑良品退回!$A:$A,日报!CF$3)<>0,SUMIFS(领跑良品退回!$G:$G,领跑良品退回!$E:$E,日报!$D:$D,领跑良品退回!$A:$A,日报!CF$3),"") | CG12: =IF(SUMIFS(领跑良品退回!$G:$G,领跑良品退回!$E:$E,日报!$D:$D,领跑良品退回!$A:$A,日报!CG$3)<>0,SUMIFS(领跑良品退回!$G:$G,领跑良品退回!$E:$E,日报!$D:$D,领跑良品退回!$A:$A,日报!CG$3),"") | ... DD12: =IF(SUMIFS(领跑良品退回!$G:$G,领跑良品退回!$E:$E,日报!$D:$D,领跑良品退回!$A:$A,日报!DD$3)<>0,SUMIFS(领跑良品退回!$G:$G,领跑良品退回!$E:$E,日报!$D:$D,领跑良品退回!$A:$A,日报!DD$3),"")
A13: 10 | B13: 1AC | C13: 宁波天下汽配有限公司 | D13: 3.2.42.30.00379-000 | E13: 插座绝缘防护罩 | F13: =IFERROR(VLOOKUP(D13,基础信息!D:F,3,FALSE),"0") -> 155 | G13: 3650 | H13: =SUMIF(合格品入库记录!E:E,日报!D13,合格品入库记录!G:G) -> 0 | I13: =SUMIF(合格品出库记录!E:E,日报!D13,合格品出库记录!G:G) -> 0 | J13: =SUMIF(领跑良品退回!E:E,D13,领跑良品退回!G:G) -> 0 | K13: =M13+L13 -> 3650 | L13: =SUMIF(不良品库存!D:D,D:D,不良品库存!F:F) -> 0 | M13: =G13+H13-I13+J13 -> 3650 | N13: 3720 | O13: 1 | P13: =IF(SUMIFS(合格品入库记录!$G:$G,合格品入库记录!$E:$E,日报!$D:$D,合格品入库记录!$A:$A,日报!P$3)<>0,SUMIFS(合格品入库记录!$G:$G,合格品入库记录!$E:$E,日报!$D:$D,合格品入库记录!$A:$A,日报!P$3),"") | Q13: =IF(SUMIFS(合格品入库记录!$G:$G,合格品入库记录!$E:$E,日报!$D:$D,合格品入库记录!$A:$A,日报!Q$3)<>0,SUMIFS(合格品入库记录!$G:$G,合格品入库记录!$E:$E,日报!$D:$D,合格品入库记录!$A:$A,日报!Q$3),"") | R13: =IF(SUMIFS(合格品入库记录!$G:$G,合格品入库记录!$E:$E,日报!$D:$D,合格品入库记录!$A:$A,日报!R$3)<>0,SUMIFS(合格品入库记录!$G:$G,合格品入库记录!$E:$E,日报!$D:$D,合格品入库记录!$A:$A,日报!R$3),"") | S13: =IF(SUMIFS(合格品入库记录!$G:$G,合格品入库记录!$E:$E,日报!$D:$D,合格品入库记录!$A:$A,日报!S$3)<>0,SUMIFS(合格品入库记录!$G:$G,合格品入库记录!$E:$E,日报!$D:$D,合格品入库记录!$A:$A,日报!S$3),"") | T13: =IF(SUMIFS(合格品入库记录!$G:$G,合格品入库记录!$E:$E,日报!$D:$D,合格品入库记录!$A:$A,日报!T$3)<>0,SUMIFS(合格品入库记录!$G:$G,合格品入库记录!$E:$E,日报!$D:$D,合格品入库记录!$A:$A,日报!T$3),"") | U13: =IF(SUMIFS(合格品入库记录!$G:$G,合格品入库记录!$E:$E,日报!$D:$D,合格品入库记录!$A:$A,日报!U$3)<>0,SUMIFS(合格品入库记录!$G:$G,合格品入库记录!$E:$E,日报!$D:$D,合格品入库记录!$A:$A,日报!U$3),"") | V13: =IF(SUMIFS(合格品入库记录!$G:$G,合格品入库记录!$E:$E,日报!$D:$D,合格品入库记录!$A:$A,日报!V$3)<>0,SUMIFS(合格品入库记录!$G:$G,合格品入库记录!$E:$E,日报!$D:$D,合格品入库记录!$A:$A,日报!V$3),"") | W13: =IF(SUMIFS(合格品入库记录!$G:$G,合格品入库记录!$E:$E,日报!$D:$D,合格品入库记录!$A:$A,日报!W$3)<>0,SUMIFS(合格品入库记录!$G:$G,合格品入库记录!$E:$E,日报!$D:$D,合格品入库记录!$A:$A,日报!W$3),"") | ... AT13: =IF(SUMIFS(合格品入库记录!$G:$G,合格品入库记录!$E:$E,日报!$D:$D,合格品入库记录!$A:$A,日报!AT$3)<>0,SUMIFS(合格品入库记录!$G:$G,合格品入库记录!$E:$E,日报!$D:$D,合格品入库记录!$A:$A,日报!AT$3),"") | AU13: =IF(SUMIFS(合格品出库记录!$G:$G,合格品出库记录!$E:$E,日报!$D:$D,合格品出库记录!$A:$A,日报!AU$3)<>0,SUMIFS(合格品出库记录!$G:$G,合格品出库记录!$E:$E,日报!$D:$D,合格品出库记录!$A:$A,日报!AU$3),"") | AV13: =IF(SUMIFS(合格品出库记录!$G:$G,合格品出库记录!$E:$E,日报!$D:$D,合格品出库记录!$A:$A,日报!AV$3)<>0,SUMIFS(合格品出库记录!$G:$G,合格品出库记录!$E:$E,日报!$D:$D,合格品出库记录!$A:$A,日报!AV$3),"") | AW13: =IF(SUMIFS(合格品出库记录!$G:$G,合格品出库记录!$E:$E,日报!$D:$D,合格品出库记录!$A:$A,日报!AW$3)<>0,SUMIFS(合格品出库记录!$G:$G,合格品出库记录!$E:$E,日报!$D:$D,合格品出库记录!$A:$A,日报!AW$3),"") | AX13: =IF(SUMIFS(合格品出库记录!$G:$G,合格品出库记录!$E:$E,日报!$D:$D,合格品出库记录!$A:$A,日报!AX$3)<>0,SUMIFS(合格品出库记录!$G:$G,合格品出库记录!$E:$E,日报!$D:$D,合格品出库记录!$A:$A,日报!AX$3),"") | AY13: =IF(SUMIFS(合格品出库记录!$G:$G,合格品出库记录!$E:$E,日报!$D:$D,合格品出库记录!$A:$A,日报!AY$3)<>0,SUMIFS(合格品出库记录!$G:$G,合格品出库记录!$E:$E,日报!$D:$D,合格品出库记录!$A:$A,日报!AY$3),"") | AZ13: =IF(SUMIFS(合格品出库记录!$G:$G,合格品出库记录!$E:$E,日报!$D:$D,合格品出库记录!$A:$A,日报!AZ$3)<>0,SUMIFS(合格品出库记录!$G:$G,合格品出库记录!$E:$E,日报!$D:$D,合格品出库记录!$A:$A,日报!AZ$3),"") | BA13: =IF(SUMIFS(合格品出库记录!$G:$G,合格品出库记录!$E:$E,日报!$D:$D,合格品出库记录!$A:$A,日报!BA$3)<>0,SUMIFS(合格品出库记录!$G:$G,合格品出库记录!$E:$E,日报!$D:$D,合格品出库记录!$A:$A,日报!BA$3),"") | BB13: =IF(SUMIFS(合格品出库记录!$G:$G,合格品出库记录!$E:$E,日报!$D:$D,合格品出库记录!$A:$A,日报!BB$3)<>0,SUMIFS(合格品出库记录!$G:$G,合格品出库记录!$E:$E,日报!$D:$D,合格品出库记录!$A:$A,日报!BB$3),"") | ... BY13: =IF(SUMIFS(合格品出库记录!$G:$G,合格品出库记录!$E:$E,日报!$D:$D,合格品出库记录!$A:$A,日报!BY$3)<>0,SUMIFS(合格品出库记录!$G:$G,合格品出库记录!$E:$E,日报!$D:$D,合格品出库记录!$A:$A,日报!BY$3),"") | BZ13: =IF(SUMIFS(领跑良品退回!$G:$G,领跑良品退回!$E:$E,日报!$D:$D,领跑良品退回!$A:$A,日报!BZ$3)<>0,SUMIFS(领跑良品退回!$G:$G,领跑良品退回!$E:$E,日报!$D:$D,领跑良品退回!$A:$A,日报!BZ$3),"") | CA13: =IF(SUMIFS(领跑良品退回!$G:$G,领跑良品退回!$E:$E,日报!$D:$D,领跑良品退回!$A:$A,日报!CA$3)<>0,SUMIFS(领跑良品退回!$G:$G,领跑良品退回!$E:$E,日报!$D:$D,领跑良品退回!$A:$A,日报!CA$3),"") | CB13: =IF(SUMIFS(领跑良品退回!$G:$G,领跑良品退回!$E:$E,日报!$D:$D,领跑良品退回!$A:$A,日报!CB$3)<>0,SUMIFS(领跑良品退回!$G:$G,领跑良品退回!$E:$E,日报!$D:$D,领跑良品退回!$A:$A,日报!CB$3),"") | CC13: =IF(SUMIFS(领跑良品退回!$G:$G,领跑良品退回!$E:$E,日报!$D:$D,领跑良品退回!$A:$A,日报!CC$3)<>0,SUMIFS(领跑良品退回!$G:$G,领跑良品退回!$E:$E,日报!$D:$D,领跑良品退回!$A:$A,日报!CC$3),"") | CD13: =IF(SUMIFS(领跑良品退回!$G:$G,领跑良品退回!$E:$E,日报!$D:$D,领跑良品退回!$A:$A,日报!CD$3)<>0,SUMIFS(领跑良品退回!$G:$G,领跑良品退回!$E:$E,日报!$D:$D,领跑良品退回!$A:$A,日报!CD$3),"") | CE13: =IF(SUMIFS(领跑良品退回!$G:$G,领跑良品退回!$E:$E,日报!$D:$D,领跑良品退回!$A:$A,日报!CE$3)<>0,SUMIFS(领跑良品退回!$G:$G,领跑良品退回!$E:$E,日报!$D:$D,领跑良品退回!$A:$A,日报!CE$3),"") | CF13: =IF(SUMIFS(领跑良品退回!$G:$G,领跑良品退回!$E:$E,日报!$D:$D,领跑良品退回!$A:$A,日报!CF$3)<>0,SUMIFS(领跑良品退回!$G:$G,领跑良品退回!$E:$E,日报!$D:$D,领跑良品退回!$A:$A,日报!CF$3),"") | CG13: =IF(SUMIFS(领跑良品退回!$G:$G,领跑良品退回!$E:$E,日报!$D:$D,领跑良品退回!$A:$A,日报!CG$3)<>0,SUMIFS(领跑良品退回!$G:$G,领跑良品退回!$E:$E,日报!$D:$D,领跑良品退回!$A:$A,日报!CG$3),"") | ... DD13: =IF(SUMIFS(领跑良品退回!$G:$G,领跑良品退回!$E:$E,日报!$D:$D,领跑良品退回!$A:$A,日报!DD$3)<>0,SUMIFS(领跑良品退回!$G:$G,领跑良品退回!$E:$E,日报!$D:$D,领跑良品退回!$A:$A,日报!DD$3),"")
A14: 11 | B14: 1AC | C14: 宁波天下汽配有限公司 | D14: 3.2.42.30.00475-000 | E14: 塑料支架-8 | F14: =IFERROR(VLOOKUP(D14,基础信息!D:F,3,FALSE),"0") -> 276 | G14: 1347 | H14: =SUMIF(合格品入库记录!E:E,日报!D14,合格品入库记录!G:G) -> 0 | I14: =SUMIF(合格品出库记录!E:E,日报!D14,合格品出库记录!G:G) -> 0 | J14: =SUMIF(领跑良品退回!E:E,D14,领跑良品退回!G:G) -> 0 | K14: =M14+L14 -> 1347 | L14: =SUMIF(不良品库存!D:D,D:D,不良品库存!F:F) -> 0 | M14: =G14+H14-I14+J14 -> 1347 | N14: 9936 | O14: 1 | P14: =IF(SUMIFS(合格品入库记录!$G:$G,合格品入库记录!$E:$E,日报!$D:$D,合格品入库记录!$A:$A,日报!P$3)<>0,SUMIFS(合格品入库记录!$G:$G,合格品入库记录!$E:$E,日报!$D:$D,合格品入库记录!$A:$A,日报!P$3),"") | Q14: =IF(SUMIFS(合格品入库记录!$G:$G,合格品入库记录!$E:$E,日报!$D:$D,合格品入库记录!$A:$A,日报!Q$3)<>0,SUMIFS(合格品入库记录!$G:$G,合格品入库记录!$E:$E,日报!$D:$D,合格品入库记录!$A:$A,日报!Q$3),"") | R14: =IF(SUMIFS(合格品入库记录!$G:$G,合格品入库记录!$E:$E,日报!$D:$D,合格品入库记录!$A:$A,日报!R$3)<>0,SUMIFS(合格品入库记录!$G:$G,合格品入库记录!$E:$E,日报!$D:$D,合格品入库记录!$A:$A,日报!R$3),"") | S14: =IF(SUMIFS(合格品入库记录!$G:$G,合格品入库记录!$E:$E,日报!$D:$D,合格品入库记录!$A:$A,日报!S$3)<>0,SUMIFS(合格品入库记录!$G:$G,合格品入库记录!$E:$E,日报!$D:$D,合格品入库记录!$A:$A,日报!S$3),"") | T14: =IF(SUMIFS(合格品入库记录!$G:$G,合格品入库记录!$E:$E,日报!$D:$D,合格品入库记录!$A:$A,日报!T$3)<>0,SUMIFS(合格品入库记录!$G:$G,合格品入库记录!$E:$E,日报!$D:$D,合格品入库记录!$A:$A,日报!T$3),"") | U14: =IF(SUMIFS(合格品入库记录!$G:$G,合格品入库记录!$E:$E,日报!$D:$D,合格品入库记录!$A:$A,日报!U$3)<>0,SUMIFS(合格品入库记录!$G:$G,合格品入库记录!$E:$E,日报!$D:$D,合格品入库记录!$A:$A,日报!U$3),"") | V14: =IF(SUMIFS(合格品入库记录!$G:$G,合格品入库记录!$E:$E,日报!$D:$D,合格品入库记录!$A:$A,日报!V$3)<>0,SUMIFS(合格品入库记录!$G:$G,合格品入库记录!$E:$E,日报!$D:$D,合格品入库记录!$A:$A,日报!V$3),"") | W14: =IF(SUMIFS(合格品入库记录!$G:$G,合格品入库记录!$E:$E,日报!$D:$D,合格品入库记录!$A:$A,日报!W$3)<>0,SUMIFS(合格品入库记录!$G:$G,合格品入库记录!$E:$E,日报!$D:$D,合格品入库记录!$A:$A,日报!W$3),"") | ... AT14: =IF(SUMIFS(合格品入库记录!$G:$G,合格品入库记录!$E:$E,日报!$D:$D,合格品入库记录!$A:$A,日报!AT$3)<>0,SUMIFS(合格品入库记录!$G:$G,合格品入库记录!$E:$E,日报!$D:$D,合格品入库记录!$A:$A,日报!AT$3),"") | AU14: =IF(SUMIFS(合格品出库记录!$G:$G,合格品出库记录!$E:$E,日报!$D:$D,合格品出库记录!$A:$A,日报!AU$3)<>0,SUMIFS(合格品出库记录!$G:$G,合格品出库记录!$E:$E,日报!$D:$D,合格品出库记录!$A:$A,日报!AU$3),"") | AV14: =IF(SUMIFS(合格品出库记录!$G:$G,合格品出库记录!$E:$E,日报!$D:$D,合格品出库记录!$A:$A,日报!AV$3)<>0,SUMIFS(合格品出库记录!$G:$G,合格品出库记录!$E:$E,日报!$D:$D,合格品出库记录!$A:$A,日报!AV$3),"") | AW14: =IF(SUMIFS(合格品出库记录!$G:$G,合格品出库记录!$E:$E,日报!$D:$D,合格品出库记录!$A:$A,日报!AW$3)<>0,SUMIFS(合格品出库记录!$G:$G,合格品出库记录!$E:$E,日报!$D:$D,合格品出库记录!$A:$A,日报!AW$3),"") | AX14: =IF(SUMIFS(合格品出库记录!$G:$G,合格品出库记录!$E:$E,日报!$D:$D,合格品出库记录!$A:$A,日报!AX$3)<>0,SUMIFS(合格品出库记录!$G:$G,合格品出库记录!$E:$E,日报!$D:$D,合格品出库记录!$A:$A,日报!AX$3),"") | AY14: =IF(SUMIFS(合格品出库记录!$G:$G,合格品出库记录!$E:$E,日报!$D:$D,合格品出库记录!$A:$A,日报!AY$3)<>0,SUMIFS(合格品出库记录!$G:$G,合格品出库记录!$E:$E,日报!$D:$D,合格品出库记录!$A:$A,日报!AY$3),"") | AZ14: =IF(SUMIFS(合格品出库记录!$G:$G,合格品出库记录!$E:$E,日报!$D:$D,合格品出库记录!$A:$A,日报!AZ$3)<>0,SUMIFS(合格品出库记录!$G:$G,合格品出库记录!$E:$E,日报!$D:$D,合格品出库记录!$A:$A,日报!AZ$3),"") | BA14: =IF(SUMIFS(合格品出库记录!$G:$G,合格品出库记录!$E:$E,日报!$D:$D,合格品出库记录!$A:$A,日报!BA$3)<>0,SUMIFS(合格品出库记录!$G:$G,合格品出库记录!$E:$E,日报!$D:$D,合格品出库记录!$A:$A,日报!BA$3),"") | BB14: =IF(SUMIFS(合格品出库记录!$G:$G,合格品出库记录!$E:$E,日报!$D:$D,合格品出库记录!$A:$A,日报!BB$3)<>0,SUMIFS(合格品出库记录!$G:$G,合格品出库记录!$E:$E,日报!$D:$D,合格品出库记录!$A:$A,日报!BB$3),"") | ... BY14: =IF(SUMIFS(合格品出库记录!$G:$G,合格品出库记录!$E:$E,日报!$D:$D,合格品出库记录!$A:$A,日报!BY$3)<>0,SUMIFS(合格品出库记录!$G:$G,合格品出库记录!$E:$E,日报!$D:$D,合格品出库记录!$A:$A,日报!BY$3),"") | BZ14: =IF(SUMIFS(领跑良品退回!$G:$G,领跑良品退回!$E:$E,日报!$D:$D,领跑良品退回!$A:$A,日报!BZ$3)<>0,SUMIFS(领跑良品退回!$G:$G,领跑良品退回!$E:$E,日报!$D:$D,领跑良品退回!$A:$A,日报!BZ$3),"") | CA14: =IF(SUMIFS(领跑良品退回!$G:$G,领跑良品退回!$E:$E,日报!$D:$D,领跑良品退回!$A:$A,日报!CA$3)<>0,SUMIFS(领跑良品退回!$G:$G,领跑良品退回!$E:$E,日报!$D:$D,领跑良品退回!$A:$A,日报!CA$3),"") | CB14: =IF(SUMIFS(领跑良品退回!$G:$G,领跑良品退回!$E:$E,日报!$D:$D,领跑良品退回!$A:$A,日报!CB$3)<>0,SUMIFS(领跑良品退回!$G:$G,领跑良品退回!$E:$E,日报!$D:$D,领跑良品退回!$A:$A,日报!CB$3),"") | CC14: =IF(SUMIFS(领跑良品退回!$G:$G,领跑良品退回!$E:$E,日报!$D:$D,领跑良品退回!$A:$A,日报!CC$3)<>0,SUMIFS(领跑良品退回!$G:$G,领跑良品退回!$E:$E,日报!$D:$D,领跑良品退回!$A:$A,日报!CC$3),"") | CD14: =IF(SUMIFS(领跑良品退回!$G:$G,领跑良品退回!$E:$E,日报!$D:$D,领跑良品退回!$A:$A,日报!CD$3)<>0,SUMIFS(领跑良品退回!$G:$G,领跑良品退回!$E:$E,日报!$D:$D,领跑良品退回!$A:$A,日报!CD$3),"") | CE14: =IF(SUMIFS(领跑良品退回!$G:$G,领跑良品退回!$E:$E,日报!$D:$D,领跑良品退回!$A:$A,日报!CE$3)<>0,SUMIFS(领跑良品退回!$G:$G,领跑良品退回!$E:$E,日报!$D:$D,领跑良品退回!$A:$A,日报!CE$3),"") | CF14: =IF(SUMIFS(领跑良品退回!$G:$G,领跑良品退回!$E:$E,日报!$D:$D,领跑良品退回!$A:$A,日报!CF$3)<>0,SUMIFS(领跑良品退回!$G:$G,领跑良品退回!$E:$E,日报!$D:$D,领跑良品退回!$A:$A,日报!CF$3),"") | CG14: =IF(SUMIFS(领跑良品退回!$G:$G,领跑良品退回!$E:$E,日报!$D:$D,领跑良品退回!$A:$A,日报!CG$3)<>0,SUMIFS(领跑良品退回!$G:$G,领跑良品退回!$E:$E,日报!$D:$D,领跑良品退回!$A:$A,日报!CG$3),"") | ... DD14: =IF(SUMIFS(领跑良品退回!$G:$G,领跑良品退回!$E:$E,日报!$D:$D,领跑良品退回!$A:$A,日报!DD$3)<>0,SUMIFS(领跑良品退回!$G:$G,领跑良品退回!$E:$E,日报!$D:$D,领跑良品退回!$A:$A,日报!DD$3),"")
A15: 12 | B15: 1AC | C15: 宁波天下汽配有限公司 | D15: 3.2.42.30.00535-000 | E15: 输出极底座 | F15: =IFERROR(VLOOKUP(D15,基础信息!D:F,3,FALSE),"0") -> 1400 | G15: 32232 | H15: =SUMIF(合格品入库记录!E:E,日报!D15,合格品入库记录!G:G) -> 1400 | I15: =SUMIF(合格品出库记录!E:E,日报!D15,合格品出库记录!G:G) -> 0 | J15: =SUMIF(领跑良品退回!E:E,D15,领跑良品退回!G:G) -> 0 | K15: =M15+L15 -> 33632 | L15: =SUMIF(不良品库存!D:D,D:D,不良品库存!F:F) -> 0 | M15: =G15+H15-I15+J15 -> 33632 | N15: 33600 | O15: 12 | P15: =IF(SUMIFS(合格品入库记录!$G:$G,合格品入库记录!$E:$E,日报!$D:$D,合格品入库记录!$A:$A,日报!P$3)<>0,SUMIFS(合格品入库记录!$G:$G,合格品入库记录!$E:$E,日报!$D:$D,合格品入库记录!$A:$A,日报!P$3),"") | Q15: =IF(SUMIFS(合格品入库记录!$G:$G,合格品入库记录!$E:$E,日报!$D:$D,合格品入库记录!$A:$A,日报!Q$3)<>0,SUMIFS(合格品入库记录!$G:$G,合格品入库记录!$E:$E,日报!$D:$D,合格品入库记录!$A:$A,日报!Q$3),"") | R15: =IF(SUMIFS(合格品入库记录!$G:$G,合格品入库记录!$E:$E,日报!$D:$D,合格品入库记录!$A:$A,日报!R$3)<>0,SUMIFS(合格品入库记录!$G:$G,合格品入库记录!$E:$E,日报!$D:$D,合格品入库记录!$A:$A,日报!R$3),"") | S15: =IF(SUMIFS(合格品入库记录!$G:$G,合格品入库记录!$E:$E,日报!$D:$D,合格品入库记录!$A:$A,日报!S$3)<>0,SUMIFS(合格品入库记录!$G:$G,合格品入库记录!$E:$E,日报!$D:$D,合格品入库记录!$A:$A,日报!S$3),"") | T15: =IF(SUMIFS(合格品入库记录!$G:$G,合格品入库记录!$E:$E,日报!$D:$D,合格品入库记录!$A:$A,日报!T$3)<>0,SUMIFS(合格品入库记录!$G:$G,合格品入库记录!$E:$E,日报!$D:$D,合格品入库记录!$A:$A,日报!T$3),"") -> 1400 | U15: =IF(SUMIFS(合格品入库记录!$G:$G,合格品入库记录!$E:$E,日报!$D:$D,合格品入库记录!$A:$A,日报!U$3)<>0,SUMIFS(合格品入库记录!$G:$G,合格品入库记录!$E:$E,日报!$D:$D,合格品入库记录!$A:$A,日报!U$3),"") | V15: =IF(SUMIFS(合格品入库记录!$G:$G,合格品入库记录!$E:$E,日报!$D:$D,合格品入库记录!$A:$A,日报!V$3)<>0,SUMIFS(合格品入库记录!$G:$G,合格品入库记录!$E:$E,日报!$D:$D,合格品入库记录!$A:$A,日报!V$3),"") | W15: =IF(SUMIFS(合格品入库记录!$G:$G,合格品入库记录!$E:$E,日报!$D:$D,合格品入库记录!$A:$A,日报!W$3)<>0,SUMIFS(合格品入库记录!$G:$G,合格品入库记录!$E:$E,日报!$D:$D,合格品入库记录!$A:$A,日报!W$3),"") | ... AT15: =IF(SUMIFS(合格品入库记录!$G:$G,合格品入库记录!$E:$E,日报!$D:$D,合格品入库记录!$A:$A,日报!AT$3)<>0,SUMIFS(合格品入库记录!$G:$G,合格品入库记录!$E:$E,日报!$D:$D,合格品入库记录!$A:$A,日报!AT$3),"") | AU15: =IF(SUMIFS(合格品出库记录!$G:$G,合格品出库记录!$E:$E,日报!$D:$D,合格品出库记录!$A:$A,日报!AU$3)<>0,SUMIFS(合格品出库记录!$G:$G,合格品出库记录!$E:$E,日报!$D:$D,合格品出库记录!$A:$A,日报!AU$3),"") | AV15: =IF(SUMIFS(合格品出库记录!$G:$G,合格品出库记录!$E:$E,日报!$D:$D,合格品出库记录!$A:$A,日报!AV$3)<>0,SUMIFS(合格品出库记录!$G:$G,合格品出库记录!$E:$E,日报!$D:$D,合格品出库记录!$A:$A,日报!AV$3),"") | AW15: =IF(SUMIFS(合格品出库记录!$G:$G,合格品出库记录!$E:$E,日报!$D:$D,合格品出库记录!$A:$A,日报!AW$3)<>0,SUMIFS(合格品出库记录!$G:$G,合格品出库记录!$E:$E,日报!$D:$D,合格品出库记录!$A:$A,日报!AW$3),"") | AX15: =IF(SUMIFS(合格品出库记录!$G:$G,合格品出库记录!$E:$E,日报!$D:$D,合格品出库记录!$A:$A,日报!AX$3)<>0,SUMIFS(合格品出库记录!$G:$G,合格品出库记录!$E:$E,日报!$D:$D,合格品出库记录!$A:$A,日报!AX$3),"") | AY15: =IF(SUMIFS(合格品出库记录!$G:$G,合格品出库记录!$E:$E,日报!$D:$D,合格品出库记录!$A:$A,日报!AY$3)<>0,SUMIFS(合格品出库记录!$G:$G,合格品出库记录!$E:$E,日报!$D:$D,合格品出库记录!$A:$A,日报!AY$3),"") | AZ15: =IF(SUMIFS(合格品出库记录!$G:$G,合格品出库记录!$E:$E,日报!$D:$D,合格品出库记录!$A:$A,日报!AZ$3)<>0,SUMIFS(合格品出库记录!$G:$G,合格品出库记录!$E:$E,日报!$D:$D,合格品出库记录!$A:$A,日报!AZ$3),"") | BA15: =IF(SUMIFS(合格品出库记录!$G:$G,合格品出库记录!$E:$E,日报!$D:$D,合格品出库记录!$A:$A,日报!BA$3)<>0,SUMIFS(合格品出库记录!$G:$G,合格品出库记录!$E:$E,日报!$D:$D,合格品出库记录!$A:$A,日报!BA$3),"") | BB15: =IF(SUMIFS(合格品出库记录!$G:$G,合格品出库记录!$E:$E,日报!$D:$D,合格品出库记录!$A:$A,日报!BB$3)<>0,SUMIFS(合格品出库记录!$G:$G,合格品出库记录!$E:$E,日报!$D:$D,合格品出库记录!$A:$A,日报!BB$3),"") | ... BY15: =IF(SUMIFS(合格品出库记录!$G:$G,合格品出库记录!$E:$E,日报!$D:$D,合格品出库记录!$A:$A,日报!BY$3)<>0,SUMIFS(合格品出库记录!$G:$G,合格品出库记录!$E:$E,日报!$D:$D,合格品出库记录!$A:$A,日报!BY$3),"") | BZ15: =IF(SUMIFS(领跑良品退回!$G:$G,领跑良品退回!$E:$E,日报!$D:$D,领跑良品退回!$A:$A,日报!BZ$3)<>0,SUMIFS(领跑良品退回!$G:$G,领跑良品退回!$E:$E,日报!$D:$D,领跑良品退回!$A:$A,日报!BZ$3),"") | CA15: =IF(SUMIFS(领跑良品退回!$G:$G,领跑良品退回!$E:$E,日报!$D:$D,领跑良品退回!$A:$A,日报!CA$3)<>0,SUMIFS(领跑良品退回!$G:$G,领跑良品退回!$E:$E,日报!$D:$D,领跑良品退回!$A:$A,日报!CA$3),"") | CB15: =IF(SUMIFS(领跑良品退回!$G:$G,领跑良品退回!$E:$E,日报!$D:$D,领跑良品退回!$A:$A,日报!CB$3)<>0,SUMIFS(领跑良品退回!$G:$G,领跑良品退回!$E:$E,日报!$D:$D,领跑良品退回!$A:$A,日报!CB$3),"") | CC15: =IF(SUMIFS(领跑良品退回!$G:$G,领跑良品退回!$E:$E,日报!$D:$D,领跑良品退回!$A:$A,日报!CC$3)<>0,SUMIFS(领跑良品退回!$G:$G,领跑良品退回!$E:$E,日报!$D:$D,领跑良品退回!$A:$A,日报!CC$3),"") | CD15: =IF(SUMIFS(领跑良品退回!$G:$G,领跑良品退回!$E:$E,日报!$D:$D,领跑良品退回!$A:$A,日报!CD$3)<>0,SUMIFS(领跑良品退回!$G:$G,领跑良品退回!$E:$E,日报!$D:$D,领跑良品退回!$A:$A,日报!CD$3),"") | CE15: =IF(SUMIFS(领跑良品退回!$G:$G,领跑良品退回!$E:$E,日报!$D:$D,领跑良品退回!$A:$A,日报!CE$3)<>0,SUMIFS(领跑良品退回!$G:$G,领跑良品退回!$E:$E,日报!$D:$D,领跑良品退回!$A:$A,日报!CE$3),"") | CF15: =IF(SUMIFS(领跑良品退回!$G:$G,领跑良品退回!$E:$E,日报!$D:$D,领跑良品退回!$A:$A,日报!CF$3)<>0,SUMIFS(领跑良品退回!$G:$G,领跑良品退回!$E:$E,日报!$D:$D,领跑良品退回!$A:$A,日报!CF$3),"") | CG15: =IF(SUMIFS(领跑良品退回!$G:$G,领跑良品退回!$E:$E,日报!$D:$D,领跑良品退回!$A:$A,日报!CG$3)<>0,SUMIFS(领跑良品退回!$G:$G,领跑良品退回!$E:$E,日报!$D:$D,领跑良品退回!$A:$A,日报!CG$3),"") | ... DD15: =IF(SUMIFS(领跑良品退回!$G:$G,领跑良品退回!$E:$E,日报!$D:$D,领跑良品退回!$A:$A,日报!DD$3)<>0,SUMIFS(领跑良品退回!$G:$G,领跑良品退回!$E:$E,日报!$D:$D,领跑良品退回!$A:$A,日报!DD$3),"")
A16: 13 | B16: 1AC | C16: 宁波天下汽配有限公司 | D16: 3.2.42.30.00511-000 | E16: 极柱防护盖 | F16: =IFERROR(VLOOKUP(D16,基础信息!D:F,3,FALSE),"0") -> 0 | G16: 0 | H16: =SUMIF(合格品入库记录!E:E,日报!D16,合格品入库记录!G:G) -> 0 | I16: =SUMIF(合格品出库记录!E:E,日报!D16,合格品出库记录!G:G) -> 0 | J16: =SUMIF(领跑良品退回!E:E,D16,领跑良品退回!G:G) -> 0 | K16: =M16+L16 -> 0 | L16: =SUMIF(不良品库存!D:D,D:D,不良品库存!F:F) -> 0 | M16: =G16+H16-I16+J16 -> 0 | N16: #N/A | O16: 8 | P16: =IF(SUMIFS(合格品入库记录!$G:$G,合格品入库记录!$E:$E,日报!$D:$D,合格品入库记录!$A:$A,日报!P$3)<>0,SUMIFS(合格品入库记录!$G:$G,合格品入库记录!$E:$E,日报!$D:$D,合格品入库记录!$A:$A,日报!P$3),"") | Q16: =IF(SUMIFS(合格品入库记录!$G:$G,合格品入库记录!$E:$E,日报!$D:$D,合格品入库记录!$A:$A,日报!Q$3)<>0,SUMIFS(合格品入库记录!$G:$G,合格品入库记录!$E:$E,日报!$D:$D,合格品入库记录!$A:$A,日报!Q$3),"") | R16: =IF(SUMIFS(合格品入库记录!$G:$G,合格品入库记录!$E:$E,日报!$D:$D,合格品入库记录!$A:$A,日报!R$3)<>0,SUMIFS(合格品入库记录!$G:$G,合格品入库记录!$E:$E,日报!$D:$D,合格品入库记录!$A:$A,日报!R$3),"") | S16: =IF(SUMIFS(合格品入库记录!$G:$G,合格品入库记录!$E:$E,日报!$D:$D,合格品入库记录!$A:$A,日报!S$3)<>0,SUMIFS(合格品入库记录!$G:$G,合格品入库记录!$E:$E,日报!$D:$D,合格品入库记录!$A:$A,日报!S$3),"") | T16: =IF(SUMIFS(合格品入库记录!$G:$G,合格品入库记录!$E:$E,日报!$D:$D,合格品入库记录!$A:$A,日报!T$3)<>0,SUMIFS(合格品入库记录!$G:$G,合格品入库记录!$E:$E,日报!$D:$D,合格品入库记录!$A:$A,日报!T$3),"") | U16: =IF(SUMIFS(合格品入库记录!$G:$G,合格品入库记录!$E:$E,日报!$D:$D,合格品入库记录!$A:$A,日报!U$3)<>0,SUMIFS(合格品入库记录!$G:$G,合格品入库记录!$E:$E,日报!$D:$D,合格品入库记录!$A:$A,日报!U$3),"") | V16: =IF(SUMIFS(合格品入库记录!$G:$G,合格品入库记录!$E:$E,日报!$D:$D,合格品入库记录!$A:$A,日报!V$3)<>0,SUMIFS(合格品入库记录!$G:$G,合格品入库记录!$E:$E,日报!$D:$D,合格品入库记录!$A:$A,日报!V$3),"") | W16: =IF(SUMIFS(合格品入库记录!$G:$G,合格品入库记录!$E:$E,日报!$D:$D,合格品入库记录!$A:$A,日报!W$3)<>0,SUMIFS(合格品入库记录!$G:$G,合格品入库记录!$E:$E,日报!$D:$D,合格品入库记录!$A:$A,日报!W$3),"") | ... AT16: =IF(SUMIFS(合格品入库记录!$G:$G,合格品入库记录!$E:$E,日报!$D:$D,合格品入库记录!$A:$A,日报!AT$3)<>0,SUMIFS(合格品入库记录!$G:$G,合格品入库记录!$E:$E,日报!$D:$D,合格品入库记录!$A:$A,日报!AT$3),"") | AU16: =IF(SUMIFS(合格品出库记录!$G:$G,合格品出库记录!$E:$E,日报!$D:$D,合格品出库记录!$A:$A,日报!AU$3)<>0,SUMIFS(合格品出库记录!$G:$G,合格品出库记录!$E:$E,日报!$D:$D,合格品出库记录!$A:$A,日报!AU$3),"") | AV16: =IF(SUMIFS(合格品出库记录!$G:$G,合格品出库记录!$E:$E,日报!$D:$D,合格品出库记录!$A:$A,日报!AV$3)<>0,SUMIFS(合格品出库记录!$G:$G,合格品出库记录!$E:$E,日报!$D:$D,合格品出库记录!$A:$A,日报!AV$3),"") | AW16: =IF(SUMIFS(合格品出库记录!$G:$G,合格品出库记录!$E:$E,日报!$D:$D,合格品出库记录!$A:$A,日报!AW$3)<>0,SUMIFS(合格品出库记录!$G:$G,合格品出库记录!$E:$E,日报!$D:$D,合格品出库记录!$A:$A,日报!AW$3),"") | AX16: =IF(SUMIFS(合格品出库记录!$G:$G,合格品出库记录!$E:$E,日报!$D:$D,合格品出库记录!$A:$A,日报!AX$3)<>0,SUMIFS(合格品出库记录!$G:$G,合格品出库记录!$E:$E,日报!$D:$D,合格品出库记录!$A:$A,日报!AX$3),"") | AY16: =IF(SUMIFS(合格品出库记录!$G:$G,合格品出库记录!$E:$E,日报!$D:$D,合格品出库记录!$A:$A,日报!AY$3)<>0,SUMIFS(合格品出库记录!$G:$G,合格品出库记录!$E:$E,日报!$D:$D,合格品出库记录!$A:$A,日报!AY$3),"") | AZ16: =IF(SUMIFS(合格品出库记录!$G:$G,合格品出库记录!$E:$E,日报!$D:$D,合格品出库记录!$A:$A,日报!AZ$3)<>0,SUMIFS(合格品出库记录!$G:$G,合格品出库记录!$E:$E,日报!$D:$D,合格品出库记录!$A:$A,日报!AZ$3),"") | BA16: =IF(SUMIFS(合格品出库记录!$G:$G,合格品出库记录!$E:$E,日报!$D:$D,合格品出库记录!$A:$A,日报!BA$3)<>0,SUMIFS(合格品出库记录!$G:$G,合格品出库记录!$E:$E,日报!$D:$D,合格品出库记录!$A:$A,日报!BA$3),"") | BB16: =IF(SUMIFS(合格品出库记录!$G:$G,合格品出库记录!$E:$E,日报!$D:$D,合格品出库记录!$A:$A,日报!BB$3)<>0,SUMIFS(合格品出库记录!$G:$G,合格品出库记录!$E:$E,日报!$D:$D,合格品出库记录!$A:$A,日报!BB$3),"") | ... BY16: =IF(SUMIFS(合格品出库记录!$G:$G,合格品出库记录!$E:$E,日报!$D:$D,合格品出库记录!$A:$A,日报!BY$3)<>0,SUMIFS(合格品出库记录!$G:$G,合格品出库记录!$E:$E,日报!$D:$D,合格品出库记录!$A:$A,日报!BY$3),"") | BZ16: =IF(SUMIFS(领跑良品退回!$G:$G,领跑良品退回!$E:$E,日报!$D:$D,领跑良品退回!$A:$A,日报!BZ$3)<>0,SUMIFS(领跑良品退回!$G:$G,领跑良品退回!$E:$E,日报!$D:$D,领跑良品退回!$A:$A,日报!BZ$3),"") | CA16: =IF(SUMIFS(领跑良品退回!$G:$G,领跑良品退回!$E:$E,日报!$D:$D,领跑良品退回!$A:$A,日报!CA$3)<>0,SUMIFS(领跑良品退回!$G:$G,领跑良品退回!$E:$E,日报!$D:$D,领跑良品退回!$A:$A,日报!CA$3),"") | CB16: =IF(SUMIFS(领跑良品退回!$G:$G,领跑良品退回!$E:$E,日报!$D:$D,领跑良品退回!$A:$A,日报!CB$3)<>0,SUMIFS(领跑良品退回!$G:$G,领跑良品退回!$E:$E,日报!$D:$D,领跑良品退回!$A:$A,日报!CB$3),"") | CC16: =IF(SUMIFS(领跑良品退回!$G:$G,领跑良品退回!$E:$E,日报!$D:$D,领跑良品退回!$A:$A,日报!CC$3)<>0,SUMIFS(领跑良品退回!$G:$G,领跑良品退回!$E:$E,日报!$D:$D,领跑良品退回!$A:$A,日报!CC$3),"") | CD16: =IF(SUMIFS(领跑良品退回!$G:$G,领跑良品退回!$E:$E,日报!$D:$D,领跑良品退回!$A:$A,日报!CD$3)<>0,SUMIFS(领跑良品退回!$G:$G,领跑良品退回!$E:$E,日报!$D:$D,领跑良品退回!$A:$A,日报!CD$3),"") | CE16: =IF(SUMIFS(领跑良品退回!$G:$G,领跑良品退回!$E:$E,日报!$D:$D,领跑良品退回!$A:$A,日报!CE$3)<>0,SUMIFS(领跑良品退回!$G:$G,领跑良品退回!$E:$E,日报!$D:$D,领跑良品退回!$A:$A,日报!CE$3),"") | CF16: =IF(SUMIFS(领跑良品退回!$G:$G,领跑良品退回!$E:$E,日报!$D:$D,领跑良品退回!$A:$A,日报!CF$3)<>0,SUMIFS(领跑良品退回!$G:$G,领跑良品退回!$E:$E,日报!$D:$D,领跑良品退回!$A:$A,日报!CF$3),"") | CG16: =IF(SUMIFS(领跑良品退回!$G:$G,领跑良品退回!$E:$E,日报!$D:$D,领跑良品退回!$A:$A,日报!CG$3)<>0,SUMIFS(领跑良品退回!$G:$G,领跑良品退回!$E:$E,日报!$D:$D,领跑良品退回!$A:$A,日报!CG$3),"") | ... DD16: =IF(SUMIFS(领跑良品退回!$G:$G,领跑良品退回!$E:$E,日报!$D:$D,领跑良品退回!$A:$A,日报!DD$3)<>0,SUMIFS(领跑良品退回!$G:$G,领跑良品退回!$E:$E,日报!$D:$D,领跑良品退回!$A:$A,日报!DD$3),"")
