Workbook

Sheet 日报
A1: 46143 | F1: 注：“可用结存”列中红色数据代表库存量过低;
A2: 序号 | B2: 供应商代码 | C2: 供应商名称 | D2: 供应商内部料号 | E2: 零跑零件编号 | F2: 零件名称 | G2: SNP | H2: 器具类型 | I2: 良品上月结存 | J2: 不良品上月结存 | K2: 累进 | L2: 累出 | M2: 零跑退回 | N2: 库内不良 | O2: 退回供应商 | P2: 不合格品库存 | Q2: 可用结存 | R2: 最高库存量 | S2: 单车用量 | T2: 入库 | AY2: 出库
T3: 46143 | U3: 46144 | V3: 46145 | W3: 46146 | X3: 46147 | Y3: 46148 | Z3: 46149 | AA3: 46150 | AB3: 46151 | AC3: 46152 | AD3: 46153 | AE3: 46154 | AF3: 46155 | AG3: 46156 | AH3: 46157 | AI3: 46158 | AJ3: 46159 | AK3: 46160 | AL3: 46161 | AM3: 46162 | AN3: 46163 | AO3: 46164 | AP3: 46165 | AQ3: 46166 | AR3: 46167 | AS3: 46168 | AT3: 46169 | AU3: 46170 | AV3: 46171 | AW3: 46172 | AX3: 46173 | AY3: 46143 | AZ3: 46144 | BA3: 46145 | BB3: 46146 | BC3: 46147 | BD3: 46148 | BE3: 46149 | BF3: 46150 | BG3: 46151 | BH3: 46152 | BI3: 46153 | BJ3: 46154 | BK3: 46155 | BL3: 46156 | BM3: 46157 | BN3: 46158 | BO3: 46159 | BP3: 46160 | BQ3: 46161 | BR3: 46162 | BS3: 46163 | BT3: 46164 | BU3: 46165 | BV3: 46166 | BW3: 46167 | BX3: 46168 | BY3: 46169 | BZ3: 46170 | CA3: 46171 | CB3: 46172 | CC3: 46173
A4: 1 | B4: 6ABE | C4: 力高新能源技术股份有限公司 | D4: F5000000156 | E4: 3.1.01.30.00344 | F4: LX-SHUNT010-AA_V100_STLA_HY_三防漆双面933_001 | G4: 162 | H4: 料盒 | I4: 0 | J4: 0 | K4: 1403 | L4: 810 | M4: 0 | N4: 0 | O4: 0 | P4: 0 | Q4: 593 | W4: 486 | Z4: 324 | AB4: 123 | AD4: 162 | AE4: 308 | BG4: 810
A5: 2 | B5: 6ABE | C5: 力高新能源技术股份有限公司 | D5: F5000000022 | E5: 3.1.01.30.00399 | F5: LP_SHUNT010-AA_A12EV_V1_三防漆双面925_007 | G5: 162 | H5: 料盒 | I5: 0 | J5: 0 | K5: 10513 | L5: 9217 | M5: 0 | N5: 0 | O5: 0 | P5: 0 | Q5: 1296 | U5: 3564 | Y5: 1620 | Z5: 648 | AA5: 799 | AB5: 1290 | AC5: 324 | AD5: 2106 | AE5: 162 | AZ5: 2916 | BA5: 648 | BD5: 486 | BE5: 1782 | BF5: 799 | BG5: 1290 | BJ5: 1296
A6: 3 | B6: 6ABE | C6: 力高新能源技术股份有限公司 | D6: F5000000013 | E6: 3.1.01.30.00341 | F6: LP-BSU053-AA_V100_TI_32A2_BTW三防漆双面922_0截 | G6: 36 | H6: 料盒 | I6: 756 | J6: 0 | K6: 2664 | L6: 3276 | M6: 0 | N6: 0 | O6: 0 | P6: 0 | Q6: 144 | U6: 1548 | W6: 468 | AB6: 504 | AE6: 144 | BA6: 576 | BE6: 576 | BG6: 2124
A7: 4 | B7: 6ABE | C7: 力高新能源技术股份有限公司 | D7: F5000000014 | E7: 3.1.01.30.00342 | F7: LP-BSU054-AA_V100_TI_32B1_BTW三防漆双面923_0截 | G7: 36 | H7: 料盒 | I7: 0 | J7: 0 | K7: 3312 | L7: 3312 | M7: 0 | N7: 0 | O7: 0 | P7: 0 | Q7: 0 | U7: 2088 | V7: 36 | X7: 324 | AA7: 144 | AB7: 720 | BE7: 432 | BG7: 2880
A8: 5 | B8: 6ABE | C8: 力高新能源技术股份有限公司 | D8: F5000000016 | E8: 3.1.01.30.00347 | F8: LP-BSU050-AA_V100_TI_32B2_HW_三防漆双面911_0截 | G8: 36 | H8: 料盒 | I8: 684 | J8: 0 | K8: 2016 | L8: 2700 | M8: 0 | N8: 0 | O8: 0 | P8: 0 | Q8: 0 | U8: 468 | W8: 36 | X8: 792 | Y8: 504 | Z8: 144 | AB8: 72 | BC8: 468 | BG8: 2160 | BH8: 72
A9: 6 | B9: 6ABE | C9: 力高新能源技术股份有限公司 | D9: F5000000282 | E9: 3.1.01.30.00401 | F9: LP-BSU051-AA_V100_TI_31A三防漆双面916_019 | G9: 36 | H9: 料盒 | I9: 1076 | J9: 0 | K9: 3960 | L9: 2016 | M9: 0 | N9: 0 | O9: 0 | P9: 0 | Q9: 3020 | U9: 144 | V9: 1188 | W9: 1044 | X9: 360 | AB9: 1224 | BB9: 2016
A10: 7 | B10: 6ABE | C10: 力高新能源技术股份有限公司 | D10: F5000000203 | E10: 3.1.01.30.00448 | F10: LP-BSU050-AA_V100_TI_32B_SS三防漆双面911_057 | G10: 36 | H10: 料盒 | I10: 0 | J10: 0 | K10: 0 | L10: 0 | M10: 0 | N10: 0 | O10: 0 | P10: 0 | Q10: 0
A11: 8 | B11: 6ABE | C11: 力高新能源技术股份有限公司 | D11: F5000000207 | E11: 3.1.01.30.00449 | F11: LP-BSU051-AA_V100_TI_32A_SS三防漆双面916_019 | G11: 36 | H11: 料盒 | I11: 0 | J11: 0 | K11: 0 | L11: 0 | M11: 0 | N11: 0 | O11: 0 | P11: 0 | Q11: 0
A12: 9 | B12: 6ABE | C12: 力高新能源技术股份有限公司 | D12: F5000000015 | E12: 3.1.01.30.00346 | F12: LP-BSU051-AA_V100_TI_32A1_HW_三防漆双面916_019 | G12: 36 | H12: 料盒 | I12: 1692 | J12: 0 | K12: 2484 | L12: 2304 | M12: 0 | N12: 0 | O12: 0 | P12: 0 | Q12: 1872 | U12: 252 | W12: 324 | X12: 720 | Y12: 468 | Z12: 108 | AA12: 216 | AB12: 396 | BA12: 576 | BE12: 576 | BH12: 1152
A13: 10 | B13: 6ABE | C13: 力高新能源技术股份有限公司 | D13: F5000000355 | E13: 3.1.04.30.00019 | F13: LXA12EV10-BSU总成-01 | G13: 20 | H13: 料盒 | I13: 8817 | J13: 0 | K13: 5915 | L13: 9886 | M13: 0 | N13: 0 | O13: 0 | P13: 0 | Q13: 4846 | V13: 960 | W13: 3055 | X13: 660 | Y13: 760 | AB13: 480 | BA13: 1920 | BC13: 2880 | BD13: 606 | BH13: 1280 | BI13: 960 | BJ13: 2240
A14: 11 | B14: 6ABE | C14: 力高新能源技术股份有限公司 | D14: F5000000356 | E14: 3.1.04.30.00020 | F14: LXA12EV10-BSU总成-02 | G14: 20 | H14: 料盒 | I14: 2866 | J14: 0 | K14: 8882 | L14: 9566 | M14: 0 | N14: 0 | O14: 0 | P14: 0 | Q14: 2182 | U14: 440 | V14: 820 | W14: 480 | X14: 480 | Y14: 1160 | Z14: 960 | AA14: 220 | AB14: 780 | AC14: 960 | AD14: 322 | AE14: 2260 | BA14: 1280 | BC14: 2880 | BD14: 926 | BH14: 1280 | BI14: 960 | BJ14: 2240
A15: 12 | B15: 6ABE | C15: 力高新能源技术股份有限公司 | D15: F5000000328 | E15: 3.1.01.20.00433 | F15: LS-MCUP006-AA-V1.10三防漆双面904.158 | G15: 210 | H15: 料盒 | I15: 10692 | J15: 0 | K15: 420 | L15: 4200 | M15: 0 | N15: 0 | O15: 0 | P15: 0 | Q15: 6912 | U15: 420 | BC15: 2100 | BD15: 2100
A16: 13 | B16: 6ABE | C16: 力高新能源技术股份有限公司 | D16: F50000000507 | E16: 3.1.03.20.00108 | F16: IGBT组件（A平台国内版NON-FUSA一体板结构PCBA） | G16: 12 | H16: 料盒 | I16: 3960 | J16: 0 | K16: 7113 | L16: 6360 | M16: 0 | N16: 0 | O16: 0 | P16: 0 | Q16: 4713 | U16: 1625 | V16: 552 | W16: 492 | X16: 420 | Y16: 552 | Z16: 540 | AA16: 456 | AB16: 436 | AD16: 828 | AE16: 1212 | BC16: 1080 | BD16: 1080 | BE16: 648 | BG16: 1392 | BI16: 1080 | BJ16: 1080
A17: 14 | B17: 6ABE | C17: 力高新能源技术股份有限公司 | D17: F50000000503 | E17: 3.1.01.20.00491 | F17: LS-CCUB001-AC-V1.02 三防漆双面 926_018 | G17: 240 | H17: 料盒 | I17: 2979 | J17: 0 | K17: 7920 | L17: 3699 | M17: 0 | N17: 0 | O17: 0 | P17: 0 | Q17: 7200 | Z17: 960 | AA17: 3480 | AC17: 120 | AD17: 2880 | AE17: 480 | BB17: 480 | BC17: 720 | BD17: 1006 | BI17: 893 | BJ17: 600
A18: 15 | B18: 6ABE | C18: 力高新能源技术股份有限公司 | D18: F5000000352 | E18: 3.1.01.20.00458 | F18: LS-CCMM024-AA-V1.01_三防漆双面 930_006 | G18: 24 | H18: 料盒 | I18: 0 | J18: 0 | K18: 3552 | L18: 3405 | M18: 0 | N18: 3 | O18: 0 | P18: 3 | Q18: 144 | U18: 504 | V18: 600 | W18: 120 | X18: 48 | Y18: 384 | Z18: 288 | AA18: 1464 | AB18: 120 | AC18: 24 | BC18: 720 | BD18: 549 | BE18: 384 | BG18: 1752
A19: 16 | B19: 6ABE | C19: 力高新能源技术股份有限公司 | D19: F50000000500 | E19: 3.1.01.20.00488 | F19: LS-CCUC001-AA-CM1-V1.03 三防漆双面 930_010 | G19: 108 | H19: 料盒 | I19: 5112 | J19: 0 | K19: 864 | L19: 0 | M19: 0 | N19: 0 | O19: 0 | P19: 0 | Q19: 5976 | U19: 864
A20: 17 | B20: 6ABE | C20: 力高新能源技术股份有限公司 | D20: F50000000523 | E20: 3.1.01.20.00501 | F20: LS-CCUM001-AA-V1.05 三防漆双面 908_065 | G20: 8 | H20: 料盒 | I20: 0 | J20: 0 | K20: 0 | L20: 0 | M20: 0 | N20: 0 | O20: 0 | P20: 0 | Q20: 0
A21: 18 | B21: 6ABE | C21: 力高新能源技术股份有限公司 | D21: F50000000522 | E21: 3.1.01.20.00493 | F21: LS-CCUG001-AA-V1.03 三防漆单面 926_014 | G21: 72 | H21: 料盒 | I21: 1680 | J21: 0 | K21: 3783 | L21: 4200 | M21: 0 | N21: 0 | O21: 0 | P21: 0 | Q21: 1263 | U21: 576 | Y21: 648 | Z21: 576 | AA21: 360 | AB21: 1368 | AC21: 72 | AD21: 39 | AE21: 144 | BB21: 720 | BC21: 1392 | BD21: 144 | BE21: 648 | BI21: 576 | BJ21: 720
A22: 19 | B22: 6ABE | C22: 力高新能源技术股份有限公司 | D22: F50000000504 | E22: 3.1.01.20.00452 | F22: LS-CCUG001-AB-V1.02 三防漆单面 924_028 | G22: 72 | H22: 料盒 | I22: 144 | J22: 0 | K22: 5545 | L22: 3492 | M22: 0 | N22: 0 | O22: 0 | P22: 0 | Q22: 2197 | U22: 792 | V22: 288 | W22: 468 | X22: 360 | Y22: 144 | Z22: 648 | AB22: 492 | AC22: 360 | AD22: 697 | AE22: 1296 | BB22: 936 | BC22: 612 | BE22: 648 | BI22: 648 | BJ22: 648
A23: 20 | B23: 6ABE | C23: 力高新能源技术股份有限公司 | D23: F50000000499 | E23: 3.1.01.20.00487 | F23: LS-CCUG001-AB-V1.02 三防漆单面 924_029 | G23: 24 | H23: 料盒 | I23: 960 | J23: 0 | K23: 960 | L23: 0 | M23: 0 | N23: 0 | O23: 0 | P23: 0 | Q23: 1920 | U23: 528 | W23: 336 | X23: 96
A24: 21 | B24: 6ABE | C24: 力高新能源技术股份有限公司 | D24: F50000000501 | E24: 3.1.01.20.00489 | F24: LS-CCUC001-AA-DM2-V1.03 三防漆双面 930_010 | G24: 108 | H24: 料盒 | I24: 0 | J24: 0 | K24: 4276 | L24: 3088 | M24: 0 | N24: 0 | O24: 0 | P24: 0 | Q24: 1188 | U24: 216 | AA24: 712 | AB24: 3024 | AC24: 324 | BB24: 216 | BG24: 712 | BH24: 864 | BI24: 648 | BJ24: 648
A25: 22 | B25: 6ABE | C25: 力高新能源技术股份有限公司 | D25: F50000000497 | E25: 3.1.01.20.00486 | F25: LS-CCUB001-AA-DM2-V1.03 三防漆单面 931_007 | G25: 24 | H25: 料盒 | I25: 0 | J25: 0 | K25: 3888 | L25: 3696 | M25: 0 | N25: 0 | O25: 0 | P25: 0 | Q25: 192 | U25: 1440 | W25: 1248 | X25: 408 | Y25: 504 | Z25: 96 | AE25: 192 | BB25: 480 | BD25: 480 | BE25: 768 | BH25: 720 | BI25: 720 | BJ25: 528
A26: 23 | B26: 6ABE | C26: 力高新能源技术股份有限公司 | D26: F50000000498 | E26: 3.1.01.20.00485 | F26: LS-CCUB001-AB-V1.04 三防漆双面 904_219 | G26: 54 | H26: 料盒 | I26: 0 | J26: 0 | K26: 0 | L26: 0 | M26: 0 | N26: 0 | O26: 0 | P26: 0 | Q26: 0
A27: 24 | B27: 6ABE | C27: 力高新能源技术股份有限公司 | D27: F50000000751 | E27: 3.1.01.20.00536 | F27: LS-MCUM027-CA-V1.20 三防漆双面 908_068（B平台高压中 | G27: 12 | H27: 料盒 | I27: 0 | J27: 0 | K27: 0 | L27: 0 | M27: 0 | N27: 0 | O27: 0 | P27: 0 | Q27: 0
A28: 25 | B28: 6ABE | C28: 力高新能源技术股份有限公司 | D28: F50000000427 | E28: 3.1.01.20.00459 | F28: LS-MCUM026-AA-V1.10_后驱_三防漆双面_926_009（中车版 | G28: 8 | H28: 料盒 | I28: 535 | J28: 0 | K28: 0 | L28: 0 | M28: 0 | N28: 0 | O28: 0 | P28: 0 | Q28: 535
A29: 26 | B29: 6ABE | C29: 力高新能源技术股份有限公司 | D29: F50000000420 | E29: 3.1.01.20.00368 | F29: LS-MCUM018-BA-V1.21_前驱_三防漆双面_924_017（中车截 | G29: 8 | H29: 料盒 | I29: 0 | J29: 0 | K29: 0 | L29: 0 | M29: 0 | N29: 0 | O29: 0 | P29: 0 | Q29: 0
A30: 27 | B30: 6ABE | C30: 力高新能源技术股份有限公司 | D30: F50000000359 | E30: 3.1.01.20.00399 | F30: LS-MCUM017-BB-V2.30 三防漆双面 926_008（A平台海外截 | G30: 12 | H30: 料盒 | I30: 389 | J30: 0 | K30: 2434 | L30: 1905 | M30: 0 | N30: 0 | O30: 0 | P30: 0 | Q30: 918 | U30: 456 | V30: 155 | W30: 257 | X30: 600 | Y30: 192 | Z30: 444 | AA30: 174 | AD30: 156 | BD30: 856 | BE30: 689 | BG30: 360
A31: 28 | B31: 6ABE | C31: 力高新能源技术股份有限公司 | D31: F50000000432 | E31: 3.1.01.20.00403 | F31: LS-MCUM112-CL-V2.30 三防漆双面 926_008（B平台士兰截 | G31: 12 | H31: 料盒 | I31: 0 | J31: 0 | K31: 0 | L31: 0 | M31: 0 | N31: 0 | O31: 0 | P31: 0 | Q31: 0
A32: 29 | B32: 6ABE | C32: 力高新能源技术股份有限公司 | D32: F50000000792 | E32: 3.1.01.20.00566 | F32: LS-CCUM001-AA-V1.06 三防漆双面 908_067 | G32: 8 | H32: 料盒 | I32: 704 | J32: 0 | K32: 5688 | L32: 3904 | M32: 0 | N32: 0 | O32: 0 | P32: 0 | Q32: 2488 | U32: 1560 | W32: 248 | X32: 520 | Y32: 320 | Z32: 384 | AA32: 576 | AB32: 544 | AC32: 464 | AD32: 288 | AE32: 784 | BB32: 720 | BC32: 720 | BD32: 544 | BH32: 640 | BI32: 640 | BJ32: 640
A33: 30 | B33: 6ABE | C33: 力高新能源技术股份有限公司 | D33: F50000000793 | E33: 3.1.01.20.00580 | F33: LS-CCUB001-AB-V1.04 三防漆双面 904_219 | G33: 54 | H33: 料盒 | I33: 1404 | J33: 0 | K33: 3007 | L33: 3277 | M33: 0 | N33: 0 | O33: 0 | P33: 0 | Q33: 1134 | U33: 54 | V33: 270 | X33: 270 | Y33: 108 | AB33: 199 | AC33: 324 | AD33: 1350 | AE33: 432 | BB33: 540 | BC33: 540 | BD33: 648 | BE33: 378 | BI33: 523 | BJ33: 648
A34: 31 | B34: 6ABE | C34: 力高新能源技术股份有限公司 | D34: F50000000674 | E34: 3.1.04.30.00036 | F34: LXT05EV20-BSU总成-03 | G34: 44 | H34: 料盒 | I34: 532 | J34: 0 | K34: 132 | L34: 0 | M34: 0 | N34: 0 | O34: 0 | P34: 0 | Q34: 664 | V34: 132
A35: 32 | B35: 6ABE | C35: 力高新能源技术股份有限公司 | D35: F50000000675 | E35: 3.1.04.30.00037 | F35: LXT05EV20-BSU总成-04 | G35: 16 | H35: 料盒 | I35: 272 | J35: 0 | K35: 352 | L35: 624 | M35: 0 | N35: 0 | O35: 0 | P35: 0 | Q35: 0 | U35: 112 | V35: 240 | AZ35: 384 | BA35: 240
A36: 33 | B36: 6ABE | C36: 力高新能源技术股份有限公司 | D36: F50000000814 | E36: 3.1.01.20.00550 | F36: LS-MCUM027-CB-V2.00 三防漆双面 926_024（B平台高压纳芯微版本） | G36: 12 | H36: 料盒 | I36: 0 | J36: 0 | K36: 0 | L36: 0 | M36: 0 | N36: 0 | O36: 0 | P36: 0 | Q36: 0
A37: 34 | B37: 6ABE | C37: 力高新能源技术股份有限公司 | D37: F50000000575 | E37: 3.1.01.30.00546 | F37: LP-BSU051-AA_V100_TI_32A1-SISO_HW_三防漆双面截 | G37: 36 | H37: 纸箱 | I37: 13 | J37: 0 | K37: 0 | L37: 0 | M37: 0 | N37: 0 | O37: 0 | P37: 0 | Q37: 13
A38: 35 | B38: 6ABE | C38: 力高新能源技术股份有限公司 | D38: F50000000576 | E38: 3.1.01.30.00547 | F38: LP-BSU050-AA_V100_TI_32B2-SISO-HW_三防漆双面截 | G38: 36 | H38: 纸箱 | I38: 13 | J38: 0 | K38: 0 | L38: 0 | M38: 0 | N38: 0 | O38: 0 | P38: 0 | Q38: 13
A39: 36 | B39: 6ABE | C39: 力高新能源技术股份有限公司 | D39: F50000000606 | E39: 3.1.01.30.00337 | F39: LP-UAV010-AA-12S_HSD_OZ3717D_V1.20三防漆双截 | G39: 72 | H39: 纸箱 | I39: 249 | J39: 0 | K39: 31 | L39: 280 | M39: 0 | N39: 0 | O39: 0 | P39: 0 | Q39: 0 | U39: 31 | BE39: 280
A40: 37 | B40: 6ABE | C40: 力高新能源技术股份有限公司 | D40: F50000000715 | E40: 3.1.01.20.00477 | F40: LS-CCMM026-AA-V1.00_三防漆双面908_063（瞻芯3代版本） | G40: 45 | H40: 料盒 | I40: 0 | J40: 0 | K40: 189 | L40: 0 | M40: 0 | N40: 0 | O40: 0 | P40: 0 | Q40: 189 | U40: 45 | X40: 144
...

Sheet 合格品入货记录
A1: 到货日期 | B1: 厂家代码 | C1: 供应商名称 | D1: 到货单号 | E1: 零件编号 | F1: 零件名称 | G1: 收货数量 | H1: 包装类型 | I1: 包装数量 | J1: 备注 | K1: 箱数
A2: 46144 | B2: 6ABE | C2: 力高新能源技术股份有限公司 | D2: L1-K350-2604001519 | E2: 3.1.01.30.00347 | F2: LP-BSU050-AA_V100_TI_32B2_HW_三防漆双面911_0截 | G2: 468 | H2: 料盒 | I2: 36 | J2: 昌 玉 | K2: 13
A3: 46144 | B3: 6ABE | C3: 力高新能源技术股份有限公司 | D3: L1-K350-2604001562 | E3: 3.1.01.30.00401 | F3: LP-BSU051-AA_V100_TI_31A三防漆双面916_019 | G3: 108 | H3: 料盒 | I3: 36 | J3: 昌 玉 | K3: 3
A4: 46144 | B4: 6ABE | C4: 力高新能源技术股份有限公司 | D4: L1-K350-2604001560 | E4: 3.1.01.30.00399 | F4: LP_SHUNT010-AA_A12EV_V1_三防漆双面925_007 | G4: 810 | H4: 料盒 | I4: 162 | J4: 昌 玉 | K4: 5
A5: 46144 | B5: 6ABE | C5: 力高新能源技术股份有限公司 | D5: L1-K350-2604001551 | E5: 3.1.01.30.00342 | F5: LP-BSU054-AA_V100_TI_32B1_BTW三防漆双面923_0截 | G5: 612 | H5: 料盒 | I5: 36 | J5: 昌 玉 | K5: 17
A6: 46144 | B6: 6ABE | C6: 力高新能源技术股份有限公司 | D6: L1-K350-2604001518 | E6: 3.1.01.30.00399 | F6: LP_SHUNT010-AA_A12EV_V1_三防漆双面925_007 | G6: 810 | H6: 料盒 | I6: 162 | J6: 昌 玉 | K6: 5
A7: 46144 | B7: 6ABE | C7: 力高新能源技术股份有限公司 | D7: L1-K350-2604001558 | E7: 3.1.01.30.00341 | F7: LP-BSU053-AA_V100_TI_32A2_BTW三防漆双面922_0截 | G7: 432 | H7: 料盒 | I7: 36 | J7: 昌 玉 | K7: 12
A8: 46144 | B8: 6ABE | C8: 力高新能源技术股份有限公司 | D8: L1-K350-2604001521 | E8: 3.1.01.30.00341 | F8: LP-BSU053-AA_V100_TI_32A2_BTW三防漆双面922_0截 | G8: 540 | H8: 料盒 | I8: 36 | J8: 昌 玉 | K8: 15
A9: 46144 | B9: 6ABE | C9: 力高新能源技术股份有限公司 | D9: L1-K350-2604001600 | E9: 3.1.01.30.00342 | F9: LP-BSU054-AA_V100_TI_32B1_BTW三防漆双面923_0截 | G9: 756 | H9: 料盒 | I9: 36 | J9: 昌 玉 | K9: 21
A10: 46144 | B10: 6ABE | C10: 力高新能源技术股份有限公司 | D10: L1-K350-2604001609 | E10: 3.1.01.30.00341 | F10: LP-BSU053-AA_V100_TI_32A2_BTW三防漆双面922_0截 | G10: 216 | H10: 料盒 | I10: 36 | J10: 昌 玉 | K10: 6
A11: 46144 | B11: 6ABE | C11: 力高新能源技术股份有限公司 | D11: L1-K350-2604001613 | E11: 3.1.01.30.00399 | F11: LP_SHUNT010-AA_A12EV_V1_三防漆双面925_007 | G11: 810 | H11: 料盒 | I11: 162 | J11: 昌 玉 | K11: 5
A12: 46144 | B12: 6ABE | C12: 力高新能源技术股份有限公司 | D12: L1-K350-2605000032 | E12: 3.1.04.30.00037 | F12: LXT05EV20-BSU总成-04 | G12: 112 | H12: 料盒 | I12: 16 | J12: 昌 玉 | K12: 7
A13: 46144 | B13: 6ABE | C13: 力高新能源技术股份有限公司 | D13: L1-K350-2605000049 | E13: 3.1.01.30.00342 | F13: LP-BSU054-AA_V100_TI_32B1_BTW三防漆双面923_0截 | G13: 720 | H13: 料盒 | I13: 36 | J13: 昌 玉 | K13: 20
... A43: 46144 | B43: 6ABE | C43: 力高新能源技术股份有限公司 | D43: L1-K350-2604001552 | E43: 3.1.01.20.00458 | F43: LS-CCMM024-AA-V1.01_三防漆双面 930_006 | G43: 312 | H43: 料盒 | I43: 24 | J43: 昌 玉 | K43: 13
A44: 46144 | B44: 6ABE | C44: 力高新能源技术股份有限公司 | D44: L1-K350-2604001530 | E44: 3.1.01.30.00606 | F44: LP-BSU057-AA_V100_TI_29S-TE_三防漆双面919_081 | G44: 14 | H44: 0 | I44: 0 | J44: 昌 玉
A45: 46144 | B45: 6ABE | C45: 力高新能源技术股份有限公司 | D45: L1-K350-2605000067 | E45: 3.1.03.20.00108 | F45: IGBT组件（A平台国内版NON-FUSA一体板结构PCBA） | G45: 348 | H45: 料盒 | I45: 12 | J45: 昌 玉 | K45: 29
A46: 46144 | B46: 6ABE | C46: 力高新能源技术股份有限公司 | D46: L1-K350-2605000043 | E46: 3.1.03.20.00108 | F46: IGBT组件（A平台国内版NON-FUSA一体板结构PCBA） | G46: 120 | H46: 料盒 | I46: 12 | J46: 昌 玉 | K46: 10
A47: 46144 | B47: 6ABE | C47: 力高新能源技术股份有限公司 | D47: L1-K350-2605000085 | E47: 3.1.01.20.00486 | F47: LS-CCUB001-AA-DM2-V1.03 三防漆单面 931_007 | G47: 144 | H47: 料盒 | I47: 24 | J47: 昌 玉 | K47: 6
A48: 46144 | B48: 6ABE | C48: 力高新能源技术股份有限公司 | D48: L1-K350-2605000079 | E48: 3.1.01.20.00566 | F48: LS-CCUM001-AA-V1.06 三防漆双面 908_067 | G48: 456 | H48: 料盒 | I48: 8 | J48: 昌 玉 | K48: 57
A49: 46144 | B49: 2CQ | C49: 宁波隆源股份有限公司 | D49: 0000081398 | E49: 3.2.44.20.01461-000 | F49: DM2上箱体 | G49: 702 | H49: 围板箱 | I49: 54 | J49: 昌 玉 | K49: 13
A50: 46144 | B50: 2CQ | C50: 宁波隆源股份有限公司 | D50: 0000081398 | E50: 3.2.44.20.01460-000 | F50: DM2下箱体 | G50: 660 | H50: 围板箱 | I50: 66 | J50: 昌 玉 | K50: 10
A51: 46144 | B51: 2CQ | C51: 宁波隆源股份有限公司 | D51: 0000081398 | E51: 3.2.44.20.01636-000 | F51: D06电源壳体 | G51: 352 | H51: 围板箱 | I51: 176 | J51: 昌 玉 | K51: 2
A52: 46144 | B52: 2FZ | C52: 索恩格汽车电动系统有限公司 | D52: 1261039562 | E52: 3.1.02.20.00611 | F52: 电机转子部件 | G52: 480 | H52: 围板箱 | I52: 48 | J52: 昌 玉 | K52: 10
A53: 46144 | B53: 2FZ | C53: 索恩格汽车电动系统有限公司 | D53: 1261039561 | E53: 3.1.02.20.00554 | F53: 定子成品组件 | G53: 48 | H53: 围板箱 | I53: 24 | J53: 昌 玉 | K53: 2
A54: 46144 | B54: 2FZ | C54: 索恩格汽车电动系统有限公司 | D54: 1261039563 | E54: 3.1.02.20.00551 | F54: 定子成品组件 | G54: 1248 | H54: 围板箱 | I54: 24 | J54: 昌 玉 | K54: 52
A55: 46144 | B55: 2FM | C55: 东实精工齿轮（武汉）有限公司 | D55: 202604280044 | E55: 3.1.02.20.00605 | F55: T05差速器总成 | G55: 1250 | H55: 围板箱 | I55: 125 | J55: 昌 玉 | K55: 10
A56: 46144 | B56: 2CM | C56: 天津天海精密锻造股份有限公司 | D56: 20260430 | E56: 3.2.44.20.01142-000 | F56: 电机轴 | G56: 1560 | H56: 围板箱 | I56: 156 | J56: 昌 玉 | K56: 10
A57: 46145 | B57: 6ABE | C57: 力高新能源技术股份有限公司 | D57: L1-K350-2605000092 | E57: 3.1.01.30.00401 | F57: LP-BSU051-AA_V100_TI_31A三防漆双面916_019 | G57: 684 | H57: 料盒 | I57: 36 | J57: 昌 玉 | K57: 19
A58: 46145 | B58: 6ABE | C58: 力高新能源技术股份有限公司 | D58: L1-K350-2605000091 | E58: 3.1.01.20.00399 | F58: LS-MCUM017-BB-V2.30 三防漆双面 926_008（A平台海外截 | G58: 155 | H58: 料盒 | I58: 12 | J58: 昌 玉 | K58: 12.916667
A59: 46145 | B59: 6ABE | C59: 力高新能源技术股份有限公司 | D59: L1-K350-2605000131 | E59: 3.1.04.30.00037 | F59: LXT05EV20-BSU总成-04 | G59: 112 | H59: 料盒 | I59: 16 | J59: 昌 玉 | K59: 7
A60: 46145 | B60: 6ABE | C60: 力高新能源技术股份有限公司 | D60: L1-K350-2605000099 | E60: 3.1.01.20.00452 | F60: LS-CCUG001-AB-V1.02 三防漆单面 924_028 | G60: 288 | H60: 料盒 | I60: 72 | J60: 昌 玉 | K60: 4
A61: 46145 | B61: 6ABE | C61: 力高新能源技术股份有限公司 | D61: L1-K350-2605000081 | E61: 3.1.01.20.00458 | F61: LS-CCMM024-AA-V1.01_三防漆双面 930_006 | G61: 600 | H61: 料盒 | I61: 24 | J61: 昌 玉 | K61: 25
A62: 46145 | B62: 6ABE | C62: 力高新能源技术股份有限公司 | D62: L1-K350-2605000133 | E62: 3.1.04.30.00020 | F62: LXA12EV10-BSU总成-02 | G62: 380 | H62: 料盒 | I62: 20 | J62: 昌 玉 | K62: 19
A63: 46145 | B63: 6ABE | C63: 力高新能源技术股份有限公司 | D63: L1-K350-2605000130 | E63: 3.1.04.30.00036 | F63: LXT05EV20-BSU总成-03 | G63: 132 | H63: 料盒 | I63: 44 | J63: 昌 玉 | K63: 3
A64: 46145 | B64: 6ABE | C64: 力高新能源技术股份有限公司 | D64: L1-K350-2605000118 | E64: 3.1.01.20.00580 | F64: LS-CCUB001-AB-V1.04 三防漆双面 904_219 | G64: 270 | H64: 料盒 | I64: 54 | J64: 昌 玉 | K64: 5
A65: 46145 | B65: 6ABE | C65: 力高新能源技术股份有限公司 | D65: L1-K350-2605000088 | E65: 3.1.01.30.00342 | F65: LP-BSU054-AA_V100_TI_32B1_BTW三防漆双面923_0截 | G65: 36 | H65: 料盒 | I65: 36 | J65: 昌 玉 | K65: 1
A66: 46145 | B66: 6ABE | C66: 力高新能源技术股份有限公司 | D66: L1-K350-2605000142 | E66: 3.1.03.20.00108 | F66: IGBT组件（A平台国内版NON-FUSA一体板结构PCBA） | G66: 552 | H66: 料盒 | I66: 12 | J66: 昌 玉 | K66: 46
A67: 46145 | B67: 6ABE | C67: 力高新能源技术股份有限公司 | D67: L1-K350-2605000155 | E67: 3.1.01.30.00401 | F67: LP-BSU051-AA_V100_TI_31A三防漆双面916_019 | G67: 504 | H67: 料盒 | I67: 36 | J67: 昌 玉 | K67: 14
A68: 46145 | B68: 6ABE | C68: 力高新能源技术股份有限公司 | D68: L1-K350-2605000157 | E68: 3.1.04.30.00037 | F68: LXT05EV20-BSU总成-04 | G68: 128 | H68: 料盒 | I68: 16 | J68: 昌 玉 | K68: 8
... A97: 46146 | B97: 2CQ | C97: 宁波隆源股份有限公司 | D97: 0000081422 | E97: 3.2.44.20.01636-000 | F97: D06电源壳体 | G97: 176 | H97: 围板箱 | I97: 176 | J97: 昌 玉 | K97: 1
...

Sheet 合格品出库记录
A1: 发货日期 | B1: 厂家代码 | C1: 供应商名称 | D1: 装箱单号 | E1: 零件编号 | F1: 零件名称 | G1: 发货数量 | H1: 包装类型 | I1: 包装数量 | J1: 备注 | K1: 箱数
A2: 46144 | B2: 6ABE | C2: 力高新能源技术股份有限公司 | D2: 652328522 | E2: 3.1.01.30.00399 | F2: LP_SHUNT010-AA_A12EV_V1_三防漆双面925_007 | G2: 2430 | H2: 料盒 | I2: 162 | J2: 昌 玉 | K2: 15
A3: 46144 | B3: 6ABE | C3: 力高新能源技术股份有限公司 | D3: 652328830 | E3: 3.1.01.30.00399 | F3: LP_SHUNT010-AA_A12EV_V1_三防漆双面925_007 | G3: 486 | H3: 料盒 | I3: 162 | J3: 昌 玉 | K3: 3
A4: 46144 | B4: 6ABE | C4: 力高新能源技术股份有限公司 | D4: 调拨武义 | E4: 3.1.04.30.00037 | F4: LXT05EV20-BSU总成-04 | G4: 384 | J4: 昌 玉
A5: 46145 | B5: 6ABE | C5: 力高新能源技术股份有限公司 | D5: 652331361 | E5: 3.1.04.30.00019 | F5: =VLOOKUP(E5,[1]基础数据!E:H,2,0) -> LXA12EV10-BSU总成-01 | G5: 1640 | H5: =VLOOKUP(E5,[1]基础数据!E:H,4,0) -> 料盒 | I5: =VLOOKUP(E5,[1]基础数据!E:G,3,0) -> 20 | J5: 昌 玉 | K5: =IFERROR(G5/I5,"") -> 82
A6: 46145 | B6: 6ABE | C6: 力高新能源技术股份有限公司 | D6: 652331361 | E6: 3.1.04.30.00020 | F6: =VLOOKUP(E6,[1]基础数据!E:H,2,0) -> LXA12EV10-BSU总成-02 | G6: 1280 | H6: =VLOOKUP(E6,[1]基础数据!E:H,4,0) -> 料盒 | I6: =VLOOKUP(E6,[1]基础数据!E:G,3,0) -> 20 | J6: 昌 玉 | K6: =IFERROR(G6/I6,"") -> 64
A7: 46145 | B7: 6ABE | C7: 力高新能源技术股份有限公司 | D7: 652331497 | E7: 3.1.04.30.00019 | F7: =VLOOKUP(E7,[1]基础数据!E:H,2,0) -> LXA12EV10-BSU总成-01 | G7: 280 | H7: =VLOOKUP(E7,[1]基础数据!E:H,4,0) -> 料盒 | I7: =VLOOKUP(E7,[1]基础数据!E:G,3,0) -> 20 | J7: 昌 玉 | K7: =IFERROR(G7/I7,"") -> 14
A8: 46145 | B8: 6ABE | C8: 力高新能源技术股份有限公司 | D8: 652332150 | E8: 3.1.01.30.00399 | F8: =VLOOKUP(E8,[1]基础数据!E:H,2,0) -> LP_SHUNT010-AA_A12EV_V1_三防漆双面925_007 | G8: 648 | H8: =VLOOKUP(E8,[1]基础数据!E:H,4,0) -> 料盒 | I8: =VLOOKUP(E8,[1]基础数据!E:G,3,0) -> 162 | J8: 昌 玉 | K8: =IFERROR(G8/I8,"") -> 4
A9: 46145 | B9: 6ABE | C9: 力高新能源技术股份有限公司 | D9: 652332150 | E9: 3.1.04.30.00037 | F9: =VLOOKUP(E9,[1]基础数据!E:H,2,0) -> LXT05EV20-BSU总成-04 | G9: 240 | H9: =VLOOKUP(E9,[1]基础数据!E:H,4,0) -> 料盒 | I9: =VLOOKUP(E9,[1]基础数据!E:G,3,0) -> 16 | J9: 昌 玉 | K9: =IFERROR(G9/I9,"") -> 15
A10: 46145 | B10: 6ABE | C10: 力高新能源技术股份有限公司 | D10: 652332229 | E10: 3.1.01.30.00346 | F10: =VLOOKUP(E10,[1]基础数据!E:H,2,0) -> LP-BSU051-AA_V100_TI_32A1_HW_三防漆双面916_019 | G10: 576 | H10: =VLOOKUP(E10,[1]基础数据!E:H,4,0) -> 料盒 | I10: =VLOOKUP(E10,[1]基础数据!E:G,3,0) -> 36 | J10: 昌 玉 | K10: =IFERROR(G10/I10,"") -> 16
A11: 46145 | B11: 6ABE | C11: 力高新能源技术股份有限公司 | D11: 652332229 | E11: 3.1.01.30.00341 | F11: =VLOOKUP(E11,[1]基础数据!E:H,2,0) -> LP-BSU053-AA_V100_TI_32A2_BTW三防漆双面922_0截 | G11: 576 | H11: =VLOOKUP(E11,[1]基础数据!E:H,4,0) -> 料盒 | I11: =VLOOKUP(E11,[1]基础数据!E:G,3,0) -> 36 | J11: 昌 玉 | K11: =IFERROR(G11/I11,"") -> 16
A12: 46146 | B12: 6ABE | C12: 力高新能源技术股份有限公司 | D12: 652337948 | E12: 3.1.01.20.00566 | F12: =VLOOKUP(E12,[2]基础数据!E:H,2,0) -> LS-CCUM001-AA-V1.06 三防漆双面 908_067 | G12: 720 | H12: =VLOOKUP(E12,[2]基础数据!E:H,4,0) -> 料盒 | I12: =VLOOKUP(E12,[2]基础数据!E:G,3,0) -> 8 | J12: 昌 玉 | K12: =IFERROR(G12/I12,"") -> 90
A13: 46146 | B13: 6ABE | C13: 力高新能源技术股份有限公司 | D13: 652337948 | E13: 3.1.01.20.00452 | F13: =VLOOKUP(E13,[2]基础数据!E:H,2,0) -> LS-CCUG001-AB-V1.02 三防漆单面 924_028 | G13: 936 | H13: =VLOOKUP(E13,[2]基础数据!E:H,4,0) -> 料盒 | I13: =VLOOKUP(E13,[2]基础数据!E:G,3,0) -> 72 | J13: 昌 玉 | K13: =IFERROR(G13/I13,"") -> 13
A14: 46146 | B14: 6ABE | C14: 力高新能源技术股份有限公司 | D14: 652337948 | E14: 3.1.01.20.00486 | F14: =VLOOKUP(E14,[2]基础数据!E:H,2,0) -> LS-CCUB001-AA-DM2-V1.03 三防漆单面 931_007 | G14: 480 | H14: =VLOOKUP(E14,[2]基础数据!E:H,4,0) -> 料盒 | I14: =VLOOKUP(E14,[2]基础数据!E:G,3,0) -> 24 | J14: 昌 玉 | K14: =IFERROR(G14/I14,"") -> 20
A15: 46146 | B15: 6ABE | C15: 力高新能源技术股份有限公司 | D15: 652337948 | E15: 3.1.01.20.00489 | F15: =VLOOKUP(E15,[2]基础数据!E:H,2,0) -> LS-CCUC001-AA-DM2-V1.03 三防漆双面 930_010 | G15: 216 | H15: =VLOOKUP(E15,[2]基础数据!E:H,4,0) -> 料盒 | I15: =VLOOKUP(E15,[2]基础数据!E:G,3,0) -> 108 | J15: 昌 玉 | K15: =IFERROR(G15/I15,"") -> 2
A16: 46146 | B16: 6ABE | C16: 力高新能源技术股份有限公司 | D16: 652337948 | E16: 3.1.01.20.00493 | F16: =VLOOKUP(E16,[2]基础数据!E:H,2,0) -> LS-CCUG001-AA-V1.03 三防漆单面 926_014 | G16: 720 | H16: =VLOOKUP(E16,[2]基础数据!E:H,4,0) -> 料盒 | I16: =VLOOKUP(E16,[2]基础数据!E:G,3,0) -> 72 | J16: 昌 玉 | K16: =IFERROR(G16/I16,"") -> 10
A17: 46146 | B17: 6ABE | C17: 力高新能源技术股份有限公司 | D17: 652337948 | E17: 3.1.01.20.00580 | F17: =VLOOKUP(E17,[2]基础数据!E:H,2,0) -> LS-CCUB001-AB-V1.04 三防漆双面 904_219 | G17: 540 | H17: =VLOOKUP(E17,[2]基础数据!E:H,4,0) -> 料盒 | I17: =VLOOKUP(E17,[2]基础数据!E:G,3,0) -> 54 | J17: 昌 玉 | K17: =IFERROR(G17/I17,"") -> 10
A18: 46146 | B18: 6ABE | C18: 力高新能源技术股份有限公司 | D18: 652337948 | E18: 3.1.01.20.00491 | F18: =VLOOKUP(E18,[2]基础数据!E:H,2,0) -> LS-CCUB001-AC-V1.02 三防漆双面 926_018 | G18: 480 | H18: =VLOOKUP(E18,[2]基础数据!E:H,4,0) -> 料盒 | I18: =VLOOKUP(E18,[2]基础数据!E:G,3,0) -> 240 | J18: 昌 玉 | K18: =IFERROR(G18/I18,"") -> 2
A19: 46146 | B19: 6ABE | C19: 力高新能源技术股份有限公司 | D19: 652338990 | E19: 3.1.01.30.00401 | F19: =VLOOKUP(E19,[2]基础数据!E:H,2,0) -> LP-BSU051-AA_V100_TI_31A三防漆双面916_019 | G19: 2016 | H19: =VLOOKUP(E19,[2]基础数据!E:H,4,0) -> 料盒 | I19: =VLOOKUP(E19,[2]基础数据!E:G,3,0) -> 36 | J19: 昌 玉 | K19: =IFERROR(G19/I19,"") -> 56
A20: 46147 | B20: 6ABE | C20: 力高新能源技术股份有限公司 | D20: 652344163 | E20: 3.1.01.20.00452 | F20: =VLOOKUP(E20,[3]基础数据!E:H,2,0) -> LS-CCUG001-AB-V1.02 三防漆单面 924_028 | G20: 612 | H20: =VLOOKUP(E20,[3]基础数据!E:H,4,0) -> 料盒 | I20: =VLOOKUP(E20,[3]基础数据!E:G,3,0) -> 72 | J20: 昌 玉 | K20: =IFERROR(G20/I20,"") -> 8.5
A21: 46147 | B21: 6ABE | C21: 力高新能源技术股份有限公司 | D21: 652344163 | E21: 3.1.01.20.00491 | F21: =VLOOKUP(E21,[3]基础数据!E:H,2,0) -> LS-CCUB001-AC-V1.02 三防漆双面 926_018 | G21: 720 | H21: =VLOOKUP(E21,[3]基础数据!E:H,4,0) -> 料盒 | I21: =VLOOKUP(E21,[3]基础数据!E:G,3,0) -> 240 | J21: 昌 玉 | K21: =IFERROR(G21/I21,"") -> 3
A22: 46147 | B22: 6ABE | C22: 力高新能源技术股份有限公司 | D22: 652344163 | E22: 3.1.01.20.00458 | F22: =VLOOKUP(E22,[3]基础数据!E:H,2,0) -> LS-CCMM024-AA-V1.01_三防漆双面 930_006 | G22: 720 | H22: =VLOOKUP(E22,[3]基础数据!E:H,4,0) -> 料盒 | I22: =VLOOKUP(E22,[3]基础数据!E:G,3,0) -> 24 | J22: 昌 玉 | K22: =IFERROR(G22/I22,"") -> 30
A23: 46147 | B23: 6ABE | C23: 力高新能源技术股份有限公司 | D23: 652344163 | E23: 3.1.01.20.00433 | F23: =VLOOKUP(E23,[3]基础数据!E:H,2,0) -> LS-MCUP006-AA-V1.10三防漆双面904.158 | G23: 2100 | H23: =VLOOKUP(E23,[3]基础数据!E:H,4,0) -> 料盒 | I23: =VLOOKUP(E23,[3]基础数据!E:G,3,0) -> 210 | J23: 昌 玉 | K23: =IFERROR(G23/I23,"") -> 10
A24: 46147 | B24: 6ABE | C24: 力高新能源技术股份有限公司 | D24: 652344163 | E24: 3.1.01.20.00566 | F24: =VLOOKUP(E24,[3]基础数据!E:H,2,0) -> LS-CCUM001-AA-V1.06 三防漆双面 908_067 | G24: 720 | H24: =VLOOKUP(E24,[3]基础数据!E:H,4,0) -> 料盒 | I24: =VLOOKUP(E24,[3]基础数据!E:G,3,0) -> 8 | J24: 昌 玉 | K24: =IFERROR(G24/I24,"") -> 90
A25: 46147 | B25: 6ABE | C25: 力高新能源技术股份有限公司 | D25: 652344163 | E25: 3.1.01.20.00580 | F25: =VLOOKUP(E25,[3]基础数据!E:H,2,0) -> LS-CCUB001-AB-V1.04 三防漆双面 904_219 | G25: 540 | H25: =VLOOKUP(E25,[3]基础数据!E:H,4,0) -> 料盒 | I25: =VLOOKUP(E25,[3]基础数据!E:G,3,0) -> 54 | J25: 昌 玉 | K25: =IFERROR(G25/I25,"") -> 10
A26: 46147 | B26: 6ABE | C26: 力高新能源技术股份有限公司 | D26: 652344163 | E26: 3.1.01.20.00493 | F26: =VLOOKUP(E26,[3]基础数据!E:H,2,0) -> LS-CCUG001-AA-V1.03 三防漆单面 926_014 | G26: 71 | H26: =VLOOKUP(E26,[3]基础数据!E:H,4,0) -> 料盒 | I26: =VLOOKUP(E26,[3]基础数据!E:G,3,0) -> 72 | J26: 昌 玉 | K26: =IFERROR(G26/I26,"") -> 0.98611111
A27: 46147 | B27: 6ABE | C27: 力高新能源技术股份有限公司 | D27: 652344163 | E27: 3.1.01.20.00493 | F27: =VLOOKUP(E27,[3]基础数据!E:H,2,0) -> LS-CCUG001-AA-V1.03 三防漆单面 926_014 | G27: 1293 | H27: =VLOOKUP(E27,[3]基础数据!E:H,4,0) -> 料盒 | I27: =VLOOKUP(E27,[3]基础数据!E:G,3,0) -> 72 | J27: 昌 玉 | K27: =IFERROR(G27/I27,"") -> 17.958333
A28: 46147 | B28: 6ABE | C28: 力高新能源技术股份有限公司 | D28: 652344163 | E28: 3.1.01.20.00493 | F28: =VLOOKUP(E28,[3]基础数据!E:H,2,0) -> LS-CCUG001-AA-V1.03 三防漆单面 926_014 | G28: 28 | H28: =VLOOKUP(E28,[3]基础数据!E:H,4,0) -> 料盒 | I28: =VLOOKUP(E28,[3]基础数据!E:G,3,0) -> 72 | J28: 昌 玉 | K28: =IFERROR(G28/I28,"") -> 0.38888889
A29: 46147 | B29: 6ABE | C29: 力高新能源技术股份有限公司 | D29: 652335960 | E29: 3.1.03.20.00108 | F29: =VLOOKUP(E29,[3]基础数据!E:H,2,0) -> IGBT组件（A平台国内版NON-FUSA一体板结构PCBA） | G29: 1080 | H29: =VLOOKUP(E29,[3]基础数据!E:H,4,0) -> 料盒 | I29: =VLOOKUP(E29,[3]基础数据!E:G,3,0) -> 12 | J29: 昌 玉 | K29: =IFERROR(G29/I29,"") -> 90
A30: 46147 | B30: 6ABE | C30: 力高新能源技术股份有限公司 | D30: 652341446 | E30: 3.1.01.30.00347 | F30: =VLOOKUP(E30,[3]基础数据!E:H,2,0) -> LP-BSU050-AA_V100_TI_32B2_HW_三防漆双面911_0截 | G30: 468 | H30: =VLOOKUP(E30,[3]基础数据!E:H,4,0) -> 料盒 | I30: =VLOOKUP(E30,[3]基础数据!E:G,3,0) -> 36 | J30: 昌 玉 | K30: =IFERROR(G30/I30,"") -> 13
A31: 46147 | B31: 6ABE | C31: 力高新能源技术股份有限公司 | D31: 652345612 | E31: 3.1.04.30.00019 | F31: =VLOOKUP(E31,[3]基础数据!E:H,2,0) -> LXA12EV10-BSU总成-01 | G31: 1280 | H31: =VLOOKUP(E31,[3]基础数据!E:H,4,0) -> 料盒 | I31: =VLOOKUP(E31,[3]基础数据!E:G,3,0) -> 20 | J31: 昌 玉 | K31: =IFERROR(G31/I31,"") -> 64
... A34: 46147 | B34: 6ABE | C34: 力高新能源技术股份有限公司 | D34: 652345623 | E34: 3.1.04.30.00020 | F34: =VLOOKUP(E34,[3]基础数据!E:H,2,0) -> LXA12EV10-BSU总成-02 | G34: 1600 | H34: =VLOOKUP(E34,[3]基础数据!E:H,4,0) -> 料盒 | I34: =VLOOKUP(E34,[3]基础数据!E:G,3,0) -> 20 | J34: 昌 玉 | K34: =IFERROR(G34/I34,"") -> 80
A35: 46148 | B35: 6ABE | C35: 力高新能源技术股份有限公司 | D35: 652350054 | E35: 3.1.01.20.00566 | F35: =VLOOKUP(E35,[4]基础数据!E:H,2,0) -> LS-CCUM001-AA-V1.06 三防漆双面 908_067 | G35: 544 | H35: =VLOOKUP(E35,[4]基础数据!E:H,4,0) -> 料盒 | I35: =VLOOKUP(E35,[4]基础数据!E:G,3,0) -> 8 | J35: 昌 玉 | K35: =IFERROR(G35/I35,"") -> 68
A36: 46148 | B36: 6ABE | C36: 力高新能源技术股份有限公司 | D36: 652350054 | E36: 3.1.01.20.00493 | F36: =VLOOKUP(E36,[4]基础数据!E:H,2,0) -> LS-CCUG001-AA-V1.03 三防漆单面 926_014 | G36: 144 | H36: =VLOOKUP(E36,[4]基础数据!E:H,4,0) -> 料盒 | I36: =VLOOKUP(E36,[4]基础数据!E:G,3,0) -> 72 | J36: 昌 玉 | K36: =IFERROR(G36/I36,"") -> 2
A37: 46148 | B37: 6ABE | C37: 力高新能源技术股份有限公司 | D37: 652350054 | E37: 3.1.01.20.00458 | F37: =VLOOKUP(E37,[4]基础数据!E:H,2,0) -> LS-CCMM024-AA-V1.01_三防漆双面 930_006 | G37: 549 | H37: =VLOOKUP(E37,[4]基础数据!E:H,4,0) -> 料盒 | I37: =VLOOKUP(E37,[4]基础数据!E:G,3,0) -> 24 | J37: 昌 玉 | K37: =IFERROR(G37/I37,"") -> 22.875
A38: 46148 | B38: 6ABE | C38: 力高新能源技术股份有限公司 | D38: 652350054 | E38: 3.1.01.20.00486 | F38: =VLOOKUP(E38,[4]基础数据!E:H,2,0) -> LS-CCUB001-AA-DM2-V1.03 三防漆单面 931_007 | G38: 480 | H38: =VLOOKUP(E38,[4]基础数据!E:H,4,0) -> 料盒 | I38: =VLOOKUP(E38,[4]基础数据!E:G,3,0) -> 24 | J38: 昌 玉 | K38: =IFERROR(G38/I38,"") -> 20
A39: 46148 | B39: 6ABE | C39: 力高新能源技术股份有限公司 | D39: 652350054 | E39: 3.1.01.20.00491 | F39: =VLOOKUP(E39,[4]基础数据!E:H,2,0) -> LS-CCUB001-AC-V1.02 三防漆双面 926_018 | G39: 717 | H39: =VLOOKUP(E39,[4]基础数据!E:H,4,0) -> 料盒 | I39: =VLOOKUP(E39,[4]基础数据!E:G,3,0) -> 240 | J39: 昌 玉 | K39: =IFERROR(G39/I39,"") -> 2.9875
A40: 46148 | B40: 6ABE | C40: 力高新能源技术股份有限公司 | D40: 652350054 | E40: 3.1.01.20.00491 | F40: =VLOOKUP(E40,[4]基础数据!E:H,2,0) -> LS-CCUB001-AC-V1.02 三防漆双面 926_018 | G40: 170 | H40: =VLOOKUP(E40,[4]基础数据!E:H,4,0) -> 料盒 | I40: =VLOOKUP(E40,[4]基础数据!E:G,3,0) -> 240 | J40: 昌 玉 | K40: =IFERROR(G40/I40,"") -> 0.70833333
A41: 46148 | B41: 6ABE | C41: 力高新能源技术股份有限公司 | D41: 652350054 | E41: 3.1.01.20.00491 | F41: =VLOOKUP(E41,[4]基础数据!E:H,2,0) -> LS-CCUB001-AC-V1.02 三防漆双面 926_018 | G41: 80 | H41: =VLOOKUP(E41,[4]基础数据!E:H,4,0) -> 料盒 | I41: =VLOOKUP(E41,[4]基础数据!E:G,3,0) -> 240 | J41: 昌 玉 | K41: =IFERROR(G41/I41,"") -> 0.33333333
A42: 46148 | B42: 6ABE | C42: 力高新能源技术股份有限公司 | D42: 652350054 | E42: 3.1.01.20.00491 | F42: =VLOOKUP(E42,[4]基础数据!E:H,2,0) -> LS-CCUB001-AC-V1.02 三防漆双面 926_018 | G42: 39 | H42: =VLOOKUP(E42,[4]基础数据!E:H,4,0) -> 料盒 | I42: =VLOOKUP(E42,[4]基础数据!E:G,3,0) -> 240 | J42: 昌 玉 | K42: =IFERROR(G42/I42,"") -> 0.1625
...

Sheet 零跑退回
A1: 日期 | B1: 厂家代码 | C1: 供应商名称 | D1: 零件名称 | E1: 退货数量 | F1: 发货人 | G1: 备注 | H1: 单号 | I1: 备注2
A2: 46113 | B2: 2CQ | C2: 宁波隆源股份有限公司 | D2: 3.2.44.20.01636-000 | E2: D06电源壳体 | F2: 757 | G2: 邓冰芯 | H2: 零跑退回不良品
A3: 46135 | B3: 2AAV | C3: 格林精密部件(苏州)有限公司 | D3: 3.2.44.20.01142-000 | E3: 电机轴180CM1 | F3: 60 | H3: 9485395
D4: =IFERROR(VLOOKUP(#REF!,基础数据!E:F,2,0),"")
D5: =IFERROR(VLOOKUP(#REF!,基础数据!E:F,2,0),"")
D6: =IFERROR(VLOOKUP(#REF!,基础数据!E:F,2,0),"")
D7: =IFERROR(VLOOKUP(#REF!,基础数据!E:F,2,0),"")
D8: =IFERROR(VLOOKUP(#REF!,基础数据!E:F,2,0),"")
D9: =IFERROR(VLOOKUP(#REF!,基础数据!E:F,2,0),"")
D10: =IFERROR(VLOOKUP(#REF!,基础数据!E:F,2,0),"")
D11: =IFERROR(VLOOKUP(#REF!,基础数据!E:F,2,0),"")
D12: =IFERROR(VLOOKUP(#REF!,基础数据!E:F,2,0),"")
D13: =IFERROR(VLOOKUP(#REF!,基础数据!E:F,2,0),"")
D14: =IFERROR(VLOOKUP(#REF!,基础数据!E:F,2,0),"")
D15: =IFERROR(VLOOKUP(#REF!,基础数据!E:F,2,0),"")
... D24: =IFERROR(VLOOKUP(#REF!,基础数据!E:F,2,0),"")

Sheet 退回供应商
A1: 日期 | B1: 厂家代码 | C1: 供应商名称 | D1: 零件号/空盛具 | E1: 零件名称 | F1: 退货数量 | G1: 发货人 | H1: 备注 | I1: 单号 | J1: 备注2
E2: =IFERROR(VLOOKUP(D2,基础数据!E:F,2,0),"")
E3: =IFERROR(VLOOKUP(D3,基础数据!E:F,2,0),"")
E4: =IFERROR(VLOOKUP(D4,基础数据!E:F,2,0),"")
E5: =IFERROR(VLOOKUP(D5,基础数据!E:F,2,0),"")
E6: =IFERROR(VLOOKUP(D6,基础数据!E:F,2,0),"")
E7: =IFERROR(VLOOKUP(D7,基础数据!E:F,2,0),"")
E8: =IFERROR(VLOOKUP(D8,基础数据!E:F,2,0),"")
E9: =IFERROR(VLOOKUP(D9,基础数据!E:F,2,0),"")
E10: =IFERROR(VLOOKUP(D10,基础数据!E:F,2,0),"")
E11: =IFERROR(VLOOKUP(D11,基础数据!E:F,2,0),"")
E12: =IFERROR(VLOOKUP(D12,基础数据!E:F,2,0),"")
E13: =IFERROR(VLOOKUP(D13,基础数据!E:F,2,0),"")
... E26: =IFERROR(VLOOKUP(D26,基础数据!E:F,2,0),"")

Sheet 库内不良
A1: 日期 | B1: 厂家代码 | C1: 供应商名称 | D1: 零件号/空盛具 | E1: 零件名称 | F1: 退货数量 | G1: 发货人 | H1: 备注 | I1: 单号 | J1: 备注2
E2: =IFERROR(VLOOKUP(D2,基础数据!E:F,2,0),"")
E3: =IFERROR(VLOOKUP(D3,基础数据!E:F,2,0),"")
E4: =IFERROR(VLOOKUP(D4,基础数据!E:F,2,0),"")
E5: =IFERROR(VLOOKUP(D5,基础数据!E:F,2,0),"")
E6: =IFERROR(VLOOKUP(D6,基础数据!E:F,2,0),"")
E7: =IFERROR(VLOOKUP(D7,基础数据!E:F,2,0),"")
E8: =IFERROR(VLOOKUP(D8,基础数据!E:F,2,0),"")
E9: =IFERROR(VLOOKUP(D9,基础数据!E:F,2,0),"")
E10: =IFERROR(VLOOKUP(D10,基础数据!E:F,2,0),"")
E11: =IFERROR(VLOOKUP(D11,基础数据!E:F,2,0),"")
E12: =IFERROR(VLOOKUP(D12,基础数据!E:F,2,0),"")
E13: =IFERROR(VLOOKUP(D13,基础数据!E:F,2,0),"")
... E24: =IFERROR(VLOOKUP(D24,基础数据!E:F,2,0),"")

Sheet 基础数据
A1: 序号 | B1: 供应商代码 | C1: 供应商名称 | D1: 供应商内部料号 | E1: 零跑零件编号 | F1: 零件名称 | G1: SNP | H1: 器具类型
A3: =ROW()-2 -> 1 | B3: 1AZ | C3: 芜湖博康机电股份有限公司 | E3: 3.2.50.30.00806-000 | F3: A12-高压支路连接线束-500 | G3: 20 | H3: 料盒
A4: =ROW()-2 -> 2 | B4: 1AZ | C4: 芜湖博康机电股份有限公司 | E4: 3.2.50.30.00927-000 | F4: A12-外部通讯连接线束 | G4: 100 | H4: 料盒
A5: =ROW()-2 -> 3 | B5: 1AZ | C5: 芜湖博康机电股份有限公司 | E5: 3.2.50.30.01736-000 | F5: A12EV10-预充电阻连接线束 | G5: 100 | H5: 料盒
A6: =ROW()-2 -> 4 | B6: 1AZ | C6: 芜湖博康机电股份有限公司 | E6: 3.2.50.30.00808-000 | F6: A12-预充电阻连接线束1 | G6: 1500 | H6: 料盒
A7: =ROW()-2 -> 5 | B7: 1AZ | C7: 芜湖博康机电股份有限公司 | E7: 3.2.50.30.00842-000 | F7: A12-菊花链线束 | G7: 1500 | H7: 料盒
A8: =ROW()-2 -> 6 | B8: 1AZ | C8: 芜湖博康机电股份有限公司 | E8: 3.2.50.30.02116-000 | F8: A12EV10-通讯-水温-互锁集成线束-500 | G8: 30 | H8: 料盒
A9: =ROW()-2 -> 7 | B9: 1AZ | C9: 芜湖博康机电股份有限公司 | E9: 3.2.50.30.02118-000 | F9: A12EV10-BDU-采样集成线束 | G9: 50 | H9: 料盒
A10: =ROW()-2 -> 8 | H10: 料盒
A11: =ROW()-2 -> 9 | H11: 料盒
A12: =ROW()-2 -> 10 | H12: 料盒
A13: =ROW()-2 -> 11 | H13: 料盒
A14: =ROW()-2 -> 12 | H14: 料盒
A15: =ROW()-2 -> 13 | H15: 料盒
A16: =ROW()-2 -> 14 | H16: 料盒

Sheet 售后配件
A1: 计划生产日期 | B1: 订单号 | C1: 物料 | D1: 物料名称 | E1: 供应商名称 | F1: 指示数量 | G1: 实发 | H1: 签收日期 | I1: 发货SNP | J1: 箱数 | K1: 备注
D2: =VLOOKUP(C:C,日报!E:F,2,0) -> #N/A | E2: 安徽晨阳 | I2: =VLOOKUP(C:C,日报!E:I,4,0) -> #N/A | J2: =G2/I2 -> #N/A

Sheet 预警

Sheet Sheet1
A1: 供应商 | B1: 零件代码 | C1: 零件编号 | D1: 零件名称 | E1: 可用结存 | F1: 43977 | G1: 差异 | H1: 43978 | I1: 差异 | J1: 43979 | K1: 差异
A2: 华通 | B2: 12036504 | C2: KK7B17C871AA | D2: CD539C MCA中支架总成 | E2: 48 | F2: 96 | G2: -48 | H2: 96 | I2: -144 | J2: 96 | K2: -240
A3: 华通 | B3: 12036505 | C3: KK7B17D995AA | D3: CD539C MCA刚度支架总成-左 | E3: 840 | F3: 28 | G3: 812 | H3: 28 | I3: 784 | J3: 28 | K3: 756
A4: 华通 | B4: 12036506 | C4: KK7B17D995BA | D4: CD539C MCA刚度支架总成-右 | E4: 756 | F4: 28 | G4: 728 | H4: 28 | I4: 700 | J4: 28 | K4: 672
A5: 翰氏 | B5: 12036502 | C5: KK7B17D948AB | D5: CD539C MCA尾灯支架总成-右 | E5: 96 | F5: 84 | G5: 12 | H5: 84 | I5: -72 | J5: 84 | K5: -156
A6: 翰氏 | B6: 12036503 | C6: KK7B17D949AB | D6: CD539C MCA尾灯支架总成-左 | E6: -25 | F6: 84 | G6: -109 | H6: 84 | I6: -193 | J6: 84 | K6: -277
A7: 翰氏 | B7: 12036500 | C7: KK7B17E850AB | D7: CD539C MCA侧围支架总成-右 | E7: -285 | F7: 64 | G7: -349 | H7: 64 | I7: -413 | J7: 64 | K7: -477
A8: 翰氏 | B8: 12036501 | C8: KK7B17E851AB | D8: CD539C MCA侧围支架总成-左 | E8: -267 | F8: 64 | G8: -331 | H8: 64 | I8: -395 | J8: 64 | K8: -459
A9: 塑源 | B9: 11988184 | C9: KK7B17D995VB | D9: CD539C MCA刚度支架总成-左-高配 | E9: 595 | F9: 72 | G9: 523 | H9: 72 | I9: 451 | J9: 72 | K9: 379
A10: 塑源 | B10: 11988185 | C10: KK7B17D995XB | D10: CD539C MCA刚度支架总成-右-高配 | E10: 596 | F10: 72 | G10: 524 | H10: 72 | I10: 452 | J10: 72 | K10: 380
