Workbook

Sheet 日报
A1: 46143 | F1: 注：“可用结存”列中红色数据代表库存量过低; | T1: 入库 | AY1: 出库
A2: 序号 | B2: 供应商代码 | C2: 供应商名称 | D2: 供应商内部料号 | E2: 零跑零件编号 | F2: 零件名称 | G2: SNP | H2: 器具类型 | I2: 良品上月结存 | J2: 不良品上月结存 | K2: 累进 | L2: 累出 | M2: 零跑退回 | N2: 库内不良 | O2: 退回供应商 | P2: 不合格品库存 | Q2: 可用结存 | R2: 最高库存量 | S2: 单车用量 | T2: 入库 | AY2: 出库
T3: 46143 | U3: =T3+1 -> 46144 | V3: =U3+1 -> 46145 | W3: =V3+1 -> 46146 | X3: =W3+1 -> 46147 | Y3: =X3+1 -> 46148 | Z3: =Y3+1 -> 46149 | AA3: =Z3+1 -> 46150 | AB3: =AA3+1 -> 46151 | ... AX3: =AW3+1 -> 46173 | AY3: 46143 | AZ3: =AY3+1 -> 46144 | BA3: =AZ3+1 -> 46145 | BB3: =BA3+1 -> 46146 | BC3: =BB3+1 -> 46147 | BD3: =BC3+1 -> 46148 | BE3: =BD3+1 -> 46149 | BF3: =BE3+1 -> 46150 | BG3: =BF3+1 -> 46151 | ... CC3: =CB3+1 -> 46173
A4: =ROW()-3 -> 1 | B4: =IFERROR(VLOOKUP(基础数据!B3,基础数据!B:B,1,0),"") -> 1AZ | C4: =IFERROR(VLOOKUP(基础数据!C3,基础数据!C:C,1,0),"") -> 芜湖博康机电股份有限公司 | E4: =IFERROR(VLOOKUP(基础数据!E3,基础数据!E:E,1,0),"") -> 3.2.50.30.00806-000 | F4: =IFERROR(VLOOKUP(基础数据!F3,基础数据!F:F,1,0),"") -> A12-高压支路连接线束-500 | G4: =IFERROR(VLOOKUP(基础数据!G3,基础数据!G:G,1,0),"") -> 20 | H4: =IFERROR(VLOOKUP(基础数据!H3,基础数据!H:H,1,0),"") -> 料盒 | I4: 4560 | J4: 0 | K4: =SUMIF(合格品入货记录!E:E,日报!E4,合格品入货记录!G:G) -> 3000 | L4: =SUMIF(合格品出库记录!E:E,日报!E4,合格品出库记录!G:G) -> 5260 | M4: =SUMIF(零跑退回!D:D,日报!E:E,零跑退回!F:F) -> 0 | N4: =SUMIF(库内不良!D:D,E:E,库内不良!F:F) -> 0 | O4: =SUMIF(退回供应商!D:D,日报!E:E,退回供应商!F:F) -> 0 | P4: =J4+M4+N4-O4 -> 0 | Q4: =I4+K4-L4-N4 -> 2300 | T4: =IF(SUMIFS(合格品入货记录!$G:$G,合格品入货记录!$E:$E,日报!$E:$E,合格品入货记录!$A:$A,日报!T$3)<>0,SUMIFS(合格品入货记录!$G:$G,合格品入货记录!$E:$E,日报!$E:$E,合格品入货记录!$A:$A,日报!T$3),"") | U4: =IF(SUMIFS(合格品入货记录!$G:$G,合格品入货记录!$E:$E,日报!$E:$E,合格品入货记录!$A:$A,日报!U$3)<>0,SUMIFS(合格品入货记录!$G:$G,合格品入货记录!$E:$E,日报!$E:$E,合格品入货记录!$A:$A,日报!U$3),"") | V4: =IF(SUMIFS(合格品入货记录!$G:$G,合格品入货记录!$E:$E,日报!$E:$E,合格品入货记录!$A:$A,日报!V$3)<>0,SUMIFS(合格品入货记录!$G:$G,合格品入货记录!$E:$E,日报!$E:$E,合格品入货记录!$A:$A,日报!V$3),"") | W4: =IF(SUMIFS(合格品入货记录!$G:$G,合格品入货记录!$E:$E,日报!$E:$E,合格品入货记录!$A:$A,日报!W$3)<>0,SUMIFS(合格品入货记录!$G:$G,合格品入货记录!$E:$E,日报!$E:$E,合格品入货记录!$A:$A,日报!W$3),"") | X4: =IF(SUMIFS(合格品入货记录!$G:$G,合格品入货记录!$E:$E,日报!$E:$E,合格品入货记录!$A:$A,日报!X$3)<>0,SUMIFS(合格品入货记录!$G:$G,合格品入货记录!$E:$E,日报!$E:$E,合格品入货记录!$A:$A,日报!X$3),"") | Y4: =IF(SUMIFS(合格品入货记录!$G:$G,合格品入货记录!$E:$E,日报!$E:$E,合格品入货记录!$A:$A,日报!Y$3)<>0,SUMIFS(合格品入货记录!$G:$G,合格品入货记录!$E:$E,日报!$E:$E,合格品入货记录!$A:$A,日报!Y$3),"") -> 700 | Z4: =IF(SUMIFS(合格品入货记录!$G:$G,合格品入货记录!$E:$E,日报!$E:$E,合格品入货记录!$A:$A,日报!Z$3)<>0,SUMIFS(合格品入货记录!$G:$G,合格品入货记录!$E:$E,日报!$E:$E,合格品入货记录!$A:$A,日报!Z$3),"") | AA4: =IF(SUMIFS(合格品入货记录!$G:$G,合格品入货记录!$E:$E,日报!$E:$E,合格品入货记录!$A:$A,日报!AA$3)<>0,SUMIFS(合格品入货记录!$G:$G,合格品入货记录!$E:$E,日报!$E:$E,合格品入货记录!$A:$A,日报!AA$3),"") | ... AU4: =IF(SUMIFS(合格品入货记录!$G:$G,合格品入货记录!$E:$E,日报!$E:$E,合格品入货记录!$A:$A,日报!AU$3)<>0,SUMIFS(合格品入货记录!$G:$G,合格品入货记录!$E:$E,日报!$E:$E,合格品入货记录!$A:$A,日报!AU$3),"") | AY4: =IF(SUMIFS(合格品出库记录!$G:$G,合格品出库记录!$E:$E,日报!$E:$E,合格品出库记录!$A:$A,日报!AY$3)<>0,SUMIFS(合格品出库记录!$G:$G,合格品出库记录!$E:$E,日报!$E:$E,合格品出库记录!$A:$A,日报!AY$3),"") | AZ4: =IF(SUMIFS(合格品出库记录!$G:$G,合格品出库记录!$E:$E,日报!$E:$E,合格品出库记录!$A:$A,日报!AZ$3)<>0,SUMIFS(合格品出库记录!$G:$G,合格品出库记录!$E:$E,日报!$E:$E,合格品出库记录!$A:$A,日报!AZ$3),"") | BA4: =IF(SUMIFS(合格品出库记录!$G:$G,合格品出库记录!$E:$E,日报!$E:$E,合格品出库记录!$A:$A,日报!BA$3)<>0,SUMIFS(合格品出库记录!$G:$G,合格品出库记录!$E:$E,日报!$E:$E,合格品出库记录!$A:$A,日报!BA$3),"") -> 1000 | BB4: =IF(SUMIFS(合格品出库记录!$G:$G,合格品出库记录!$E:$E,日报!$E:$E,合格品出库记录!$A:$A,日报!BB$3)<>0,SUMIFS(合格品出库记录!$G:$G,合格品出库记录!$E:$E,日报!$E:$E,合格品出库记录!$A:$A,日报!BB$3),"") | BC4: =IF(SUMIFS(合格品出库记录!$G:$G,合格品出库记录!$E:$E,日报!$E:$E,合格品出库记录!$A:$A,日报!BC$3)<>0,SUMIFS(合格品出库记录!$G:$G,合格品出库记录!$E:$E,日报!$E:$E,合格品出库记录!$A:$A,日报!BC$3),"") -> 1500 | BD4: =IF(SUMIFS(合格品出库记录!$G:$G,合格品出库记录!$E:$E,日报!$E:$E,合格品出库记录!$A:$A,日报!BD$3)<>0,SUMIFS(合格品出库记录!$G:$G,合格品出库记录!$E:$E,日报!$E:$E,合格品出库记录!$A:$A,日报!BD$3),"") | BE4: =IF(SUMIFS(合格品出库记录!$G:$G,合格品出库记录!$E:$E,日报!$E:$E,合格品出库记录!$A:$A,日报!BE$3)<>0,SUMIFS(合格品出库记录!$G:$G,合格品出库记录!$E:$E,日报!$E:$E,合格品出库记录!$A:$A,日报!BE$3),"") | BF4: =IF(SUMIFS(合格品出库记录!$G:$G,合格品出库记录!$E:$E,日报!$E:$E,合格品出库记录!$A:$A,日报!BF$3)<>0,SUMIFS(合格品出库记录!$G:$G,合格品出库记录!$E:$E,日报!$E:$E,合格品出库记录!$A:$A,日报!BF$3),"") | ... CC4: =IF(SUMIFS(合格品出库记录!$G:$G,合格品出库记录!$E:$E,日报!$E:$E,合格品出库记录!$A:$A,日报!CC$3)<>0,SUMIFS(合格品出库记录!$G:$G,合格品出库记录!$E:$E,日报!$E:$E,合格品出库记录!$A:$A,日报!CC$3),"")
A5: =ROW()-3 -> 2 | B5: =IFERROR(VLOOKUP(基础数据!B4,基础数据!B:B,1,0),"") -> 1AZ | C5: =IFERROR(VLOOKUP(基础数据!C4,基础数据!C:C,1,0),"") -> 芜湖博康机电股份有限公司 | E5: =IFERROR(VLOOKUP(基础数据!E4,基础数据!E:E,1,0),"") -> 3.2.50.30.00927-000 | F5: =IFERROR(VLOOKUP(基础数据!F4,基础数据!F:F,1,0),"") -> A12-外部通讯连接线束 | G5: =IFERROR(VLOOKUP(基础数据!G4,基础数据!G:G,1,0),"") -> 100 | H5: =IFERROR(VLOOKUP(基础数据!H4,基础数据!H:H,1,0),"") -> 料盒 | I5: 1500 | J5: 0 | K5: =SUMIF(合格品入货记录!E:E,日报!E5,合格品入货记录!G:G) -> 3000 | L5: =SUMIF(合格品出库记录!E:E,日报!E5,合格品出库记录!G:G) -> 4500 | M5: =SUMIF(零跑退回!D:D,日报!E:E,零跑退回!F:F) -> 0 | N5: =SUMIF(库内不良!D:D,E:E,库内不良!F:F) -> 0 | O5: =SUMIF(退回供应商!D:D,日报!E:E,退回供应商!F:F) -> 0 | P5: =J5+M5+N5-O5 -> 0 | Q5: =I5+K5-L5-N5 -> 0 | T5: =IF(SUMIFS(合格品入货记录!$G:$G,合格品入货记录!$E:$E,日报!$E:$E,合格品入货记录!$A:$A,日报!T$3)<>0,SUMIFS(合格品入货记录!$G:$G,合格品入货记录!$E:$E,日报!$E:$E,合格品入货记录!$A:$A,日报!T$3),"") | U5: =IF(SUMIFS(合格品入货记录!$G:$G,合格品入货记录!$E:$E,日报!$E:$E,合格品入货记录!$A:$A,日报!U$3)<>0,SUMIFS(合格品入货记录!$G:$G,合格品入货记录!$E:$E,日报!$E:$E,合格品入货记录!$A:$A,日报!U$3),"") | V5: =IF(SUMIFS(合格品入货记录!$G:$G,合格品入货记录!$E:$E,日报!$E:$E,合格品入货记录!$A:$A,日报!V$3)<>0,SUMIFS(合格品入货记录!$G:$G,合格品入货记录!$E:$E,日报!$E:$E,合格品入货记录!$A:$A,日报!V$3),"") | W5: =IF(SUMIFS(合格品入货记录!$G:$G,合格品入货记录!$E:$E,日报!$E:$E,合格品入货记录!$A:$A,日报!W$3)<>0,SUMIFS(合格品入货记录!$G:$G,合格品入货记录!$E:$E,日报!$E:$E,合格品入货记录!$A:$A,日报!W$3),"") | X5: =IF(SUMIFS(合格品入货记录!$G:$G,合格品入货记录!$E:$E,日报!$E:$E,合格品入货记录!$A:$A,日报!X$3)<>0,SUMIFS(合格品入货记录!$G:$G,合格品入货记录!$E:$E,日报!$E:$E,合格品入货记录!$A:$A,日报!X$3),"") | Y5: =IF(SUMIFS(合格品入货记录!$G:$G,合格品入货记录!$E:$E,日报!$E:$E,合格品入货记录!$A:$A,日报!Y$3)<>0,SUMIFS(合格品入货记录!$G:$G,合格品入货记录!$E:$E,日报!$E:$E,合格品入货记录!$A:$A,日报!Y$3),"") -> 1500 | Z5: =IF(SUMIFS(合格品入货记录!$G:$G,合格品入货记录!$E:$E,日报!$E:$E,合格品入货记录!$A:$A,日报!Z$3)<>0,SUMIFS(合格品入货记录!$G:$G,合格品入货记录!$E:$E,日报!$E:$E,合格品入货记录!$A:$A,日报!Z$3),"") | AA5: =IF(SUMIFS(合格品入货记录!$G:$G,合格品入货记录!$E:$E,日报!$E:$E,合格品入货记录!$A:$A,日报!AA$3)<>0,SUMIFS(合格品入货记录!$G:$G,合格品入货记录!$E:$E,日报!$E:$E,合格品入货记录!$A:$A,日报!AA$3),"") | ... AU5: =IF(SUMIFS(合格品入货记录!$G:$G,合格品入货记录!$E:$E,日报!$E:$E,合格品入货记录!$A:$A,日报!AU$3)<>0,SUMIFS(合格品入货记录!$G:$G,合格品入货记录!$E:$E,日报!$E:$E,合格品入货记录!$A:$A,日报!AU$3),"") | AY5: =IF(SUMIFS(合格品出库记录!$G:$G,合格品出库记录!$E:$E,日报!$E:$E,合格品出库记录!$A:$A,日报!AY$3)<>0,SUMIFS(合格品出库记录!$G:$G,合格品出库记录!$E:$E,日报!$E:$E,合格品出库记录!$A:$A,日报!AY$3),"") | AZ5: =IF(SUMIFS(合格品出库记录!$G:$G,合格品出库记录!$E:$E,日报!$E:$E,合格品出库记录!$A:$A,日报!AZ$3)<>0,SUMIFS(合格品出库记录!$G:$G,合格品出库记录!$E:$E,日报!$E:$E,合格品出库记录!$A:$A,日报!AZ$3),"") | BA5: =IF(SUMIFS(合格品出库记录!$G:$G,合格品出库记录!$E:$E,日报!$E:$E,合格品出库记录!$A:$A,日报!BA$3)<>0,SUMIFS(合格品出库记录!$G:$G,合格品出库记录!$E:$E,日报!$E:$E,合格品出库记录!$A:$A,日报!BA$3),"") | BB5: =IF(SUMIFS(合格品出库记录!$G:$G,合格品出库记录!$E:$E,日报!$E:$E,合格品出库记录!$A:$A,日报!BB$3)<>0,SUMIFS(合格品出库记录!$G:$G,合格品出库记录!$E:$E,日报!$E:$E,合格品出库记录!$A:$A,日报!BB$3),"") | BC5: =IF(SUMIFS(合格品出库记录!$G:$G,合格品出库记录!$E:$E,日报!$E:$E,合格品出库记录!$A:$A,日报!BC$3)<>0,SUMIFS(合格品出库记录!$G:$G,合格品出库记录!$E:$E,日报!$E:$E,合格品出库记录!$A:$A,日报!BC$3),"") | BD5: =IF(SUMIFS(合格品出库记录!$G:$G,合格品出库记录!$E:$E,日报!$E:$E,合格品出库记录!$A:$A,日报!BD$3)<>0,SUMIFS(合格品出库记录!$G:$G,合格品出库记录!$E:$E,日报!$E:$E,合格品出库记录!$A:$A,日报!BD$3),"") -> 1500 | BE5: =IF(SUMIFS(合格品出库记录!$G:$G,合格品出库记录!$E:$E,日报!$E:$E,合格品出库记录!$A:$A,日报!BE$3)<>0,SUMIFS(合格品出库记录!$G:$G,合格品出库记录!$E:$E,日报!$E:$E,合格品出库记录!$A:$A,日报!BE$3),"") | BF5: =IF(SUMIFS(合格品出库记录!$G:$G,合格品出库记录!$E:$E,日报!$E:$E,合格品出库记录!$A:$A,日报!BF$3)<>0,SUMIFS(合格品出库记录!$G:$G,合格品出库记录!$E:$E,日报!$E:$E,合格品出库记录!$A:$A,日报!BF$3),"") -> 1500 | ... CC5: =IF(SUMIFS(合格品出库记录!$G:$G,合格品出库记录!$E:$E,日报!$E:$E,合格品出库记录!$A:$A,日报!CC$3)<>0,SUMIFS(合格品出库记录!$G:$G,合格品出库记录!$E:$E,日报!$E:$E,合格品出库记录!$A:$A,日报!CC$3),"")
A6: =ROW()-3 -> 3 | B6: =IFERROR(VLOOKUP(基础数据!B5,基础数据!B:B,1,0),"") -> 1AZ | C6: =IFERROR(VLOOKUP(基础数据!C5,基础数据!C:C,1,0),"") -> 芜湖博康机电股份有限公司 | E6: =IFERROR(VLOOKUP(基础数据!E5,基础数据!E:E,1,0),"") -> 3.2.50.30.01736-000 | F6: =IFERROR(VLOOKUP(基础数据!F5,基础数据!F:F,1,0),"") -> A12EV10-预充电阻连接线束 | G6: =IFERROR(VLOOKUP(基础数据!G5,基础数据!G:G,1,0),"") -> 100 | H6: =IFERROR(VLOOKUP(基础数据!H5,基础数据!H:H,1,0),"") -> 料盒 | I6: 1500 | J6: 0 | K6: =SUMIF(合格品入货记录!E:E,日报!E6,合格品入货记录!G:G) -> 3000 | L6: =SUMIF(合格品出库记录!E:E,日报!E6,合格品出库记录!G:G) -> 4500 | M6: =SUMIF(零跑退回!D:D,日报!E:E,零跑退回!F:F) -> 0 | N6: =SUMIF(库内不良!D:D,E:E,库内不良!F:F) -> 0 | O6: =SUMIF(退回供应商!D:D,日报!E:E,退回供应商!F:F) -> 0 | P6: =J6+M6+N6-O6 -> 0 | Q6: =I6+K6-L6-N6 -> 0 | T6: =IF(SUMIFS(合格品入货记录!$G:$G,合格品入货记录!$E:$E,日报!$E:$E,合格品入货记录!$A:$A,日报!T$3)<>0,SUMIFS(合格品入货记录!$G:$G,合格品入货记录!$E:$E,日报!$E:$E,合格品入货记录!$A:$A,日报!T$3),"") | U6: =IF(SUMIFS(合格品入货记录!$G:$G,合格品入货记录!$E:$E,日报!$E:$E,合格品入货记录!$A:$A,日报!U$3)<>0,SUMIFS(合格品入货记录!$G:$G,合格品入货记录!$E:$E,日报!$E:$E,合格品入货记录!$A:$A,日报!U$3),"") | V6: =IF(SUMIFS(合格品入货记录!$G:$G,合格品入货记录!$E:$E,日报!$E:$E,合格品入货记录!$A:$A,日报!V$3)<>0,SUMIFS(合格品入货记录!$G:$G,合格品入货记录!$E:$E,日报!$E:$E,合格品入货记录!$A:$A,日报!V$3),"") | W6: =IF(SUMIFS(合格品入货记录!$G:$G,合格品入货记录!$E:$E,日报!$E:$E,合格品入货记录!$A:$A,日报!W$3)<>0,SUMIFS(合格品入货记录!$G:$G,合格品入货记录!$E:$E,日报!$E:$E,合格品入货记录!$A:$A,日报!W$3),"") | X6: =IF(SUMIFS(合格品入货记录!$G:$G,合格品入货记录!$E:$E,日报!$E:$E,合格品入货记录!$A:$A,日报!X$3)<>0,SUMIFS(合格品入货记录!$G:$G,合格品入货记录!$E:$E,日报!$E:$E,合格品入货记录!$A:$A,日报!X$3),"") | Y6: =IF(SUMIFS(合格品入货记录!$G:$G,合格品入货记录!$E:$E,日报!$E:$E,合格品入货记录!$A:$A,日报!Y$3)<>0,SUMIFS(合格品入货记录!$G:$G,合格品入货记录!$E:$E,日报!$E:$E,合格品入货记录!$A:$A,日报!Y$3),"") -> 1500 | Z6: =IF(SUMIFS(合格品入货记录!$G:$G,合格品入货记录!$E:$E,日报!$E:$E,合格品入货记录!$A:$A,日报!Z$3)<>0,SUMIFS(合格品入货记录!$G:$G,合格品入货记录!$E:$E,日报!$E:$E,合格品入货记录!$A:$A,日报!Z$3),"") | AA6: =IF(SUMIFS(合格品入货记录!$G:$G,合格品入货记录!$E:$E,日报!$E:$E,合格品入货记录!$A:$A,日报!AA$3)<>0,SUMIFS(合格品入货记录!$G:$G,合格品入货记录!$E:$E,日报!$E:$E,合格品入货记录!$A:$A,日报!AA$3),"") | ... AU6: =IF(SUMIFS(合格品入货记录!$G:$G,合格品入货记录!$E:$E,日报!$E:$E,合格品入货记录!$A:$A,日报!AU$3)<>0,SUMIFS(合格品入货记录!$G:$G,合格品入货记录!$E:$E,日报!$E:$E,合格品入货记录!$A:$A,日报!AU$3),"") | AY6: =IF(SUMIFS(合格品出库记录!$G:$G,合格品出库记录!$E:$E,日报!$E:$E,合格品出库记录!$A:$A,日报!AY$3)<>0,SUMIFS(合格品出库记录!$G:$G,合格品出库记录!$E:$E,日报!$E:$E,合格品出库记录!$A:$A,日报!AY$3),"") | AZ6: =IF(SUMIFS(合格品出库记录!$G:$G,合格品出库记录!$E:$E,日报!$E:$E,合格品出库记录!$A:$A,日报!AZ$3)<>0,SUMIFS(合格品出库记录!$G:$G,合格品出库记录!$E:$E,日报!$E:$E,合格品出库记录!$A:$A,日报!AZ$3),"") | BA6: =IF(SUMIFS(合格品出库记录!$G:$G,合格品出库记录!$E:$E,日报!$E:$E,合格品出库记录!$A:$A,日报!BA$3)<>0,SUMIFS(合格品出库记录!$G:$G,合格品出库记录!$E:$E,日报!$E:$E,合格品出库记录!$A:$A,日报!BA$3),"") | BB6: =IF(SUMIFS(合格品出库记录!$G:$G,合格品出库记录!$E:$E,日报!$E:$E,合格品出库记录!$A:$A,日报!BB$3)<>0,SUMIFS(合格品出库记录!$G:$G,合格品出库记录!$E:$E,日报!$E:$E,合格品出库记录!$A:$A,日报!BB$3),"") | BC6: =IF(SUMIFS(合格品出库记录!$G:$G,合格品出库记录!$E:$E,日报!$E:$E,合格品出库记录!$A:$A,日报!BC$3)<>0,SUMIFS(合格品出库记录!$G:$G,合格品出库记录!$E:$E,日报!$E:$E,合格品出库记录!$A:$A,日报!BC$3),"") | BD6: =IF(SUMIFS(合格品出库记录!$G:$G,合格品出库记录!$E:$E,日报!$E:$E,合格品出库记录!$A:$A,日报!BD$3)<>0,SUMIFS(合格品出库记录!$G:$G,合格品出库记录!$E:$E,日报!$E:$E,合格品出库记录!$A:$A,日报!BD$3),"") | BE6: =IF(SUMIFS(合格品出库记录!$G:$G,合格品出库记录!$E:$E,日报!$E:$E,合格品出库记录!$A:$A,日报!BE$3)<>0,SUMIFS(合格品出库记录!$G:$G,合格品出库记录!$E:$E,日报!$E:$E,合格品出库记录!$A:$A,日报!BE$3),"") | BF6: =IF(SUMIFS(合格品出库记录!$G:$G,合格品出库记录!$E:$E,日报!$E:$E,合格品出库记录!$A:$A,日报!BF$3)<>0,SUMIFS(合格品出库记录!$G:$G,合格品出库记录!$E:$E,日报!$E:$E,合格品出库记录!$A:$A,日报!BF$3),"") -> 1500 | ... CC6: =IF(SUMIFS(合格品出库记录!$G:$G,合格品出库记录!$E:$E,日报!$E:$E,合格品出库记录!$A:$A,日报!CC$3)<>0,SUMIFS(合格品出库记录!$G:$G,合格品出库记录!$E:$E,日报!$E:$E,合格品出库记录!$A:$A,日报!CC$3),"")
A7: =ROW()-3 -> 4 | B7: =IFERROR(VLOOKUP(基础数据!B6,基础数据!B:B,1,0),"") -> 1AZ | C7: =IFERROR(VLOOKUP(基础数据!C6,基础数据!C:C,1,0),"") -> 芜湖博康机电股份有限公司 | E7: =IFERROR(VLOOKUP(基础数据!E6,基础数据!E:E,1,0),"") -> 3.2.50.30.00808-000 | F7: =IFERROR(VLOOKUP(基础数据!F6,基础数据!F:F,1,0),"") -> A12-预充电阻连接线束1 | G7: =IFERROR(VLOOKUP(基础数据!G6,基础数据!G:G,1,0),"") -> 1500 | H7: =IFERROR(VLOOKUP(基础数据!H6,基础数据!H:H,1,0),"") -> 料盒 | I7: 0 | J7: 0 | K7: =SUMIF(合格品入货记录!E:E,日报!E7,合格品入货记录!G:G) -> 4500 | L7: =SUMIF(合格品出库记录!E:E,日报!E7,合格品出库记录!G:G) -> 4500 | M7: =SUMIF(零跑退回!D:D,日报!E:E,零跑退回!F:F) -> 0 | N7: =SUMIF(库内不良!D:D,E:E,库内不良!F:F) -> 0 | O7: =SUMIF(退回供应商!D:D,日报!E:E,退回供应商!F:F) -> 0 | P7: =J7+M7+N7-O7 -> 0 | Q7: =I7+K7-L7-N7 -> 0 | T7: =IF(SUMIFS(合格品入货记录!$G:$G,合格品入货记录!$E:$E,日报!$E:$E,合格品入货记录!$A:$A,日报!T$3)<>0,SUMIFS(合格品入货记录!$G:$G,合格品入货记录!$E:$E,日报!$E:$E,合格品入货记录!$A:$A,日报!T$3),"") | U7: =IF(SUMIFS(合格品入货记录!$G:$G,合格品入货记录!$E:$E,日报!$E:$E,合格品入货记录!$A:$A,日报!U$3)<>0,SUMIFS(合格品入货记录!$G:$G,合格品入货记录!$E:$E,日报!$E:$E,合格品入货记录!$A:$A,日报!U$3),"") | V7: =IF(SUMIFS(合格品入货记录!$G:$G,合格品入货记录!$E:$E,日报!$E:$E,合格品入货记录!$A:$A,日报!V$3)<>0,SUMIFS(合格品入货记录!$G:$G,合格品入货记录!$E:$E,日报!$E:$E,合格品入货记录!$A:$A,日报!V$3),"") | W7: =IF(SUMIFS(合格品入货记录!$G:$G,合格品入货记录!$E:$E,日报!$E:$E,合格品入货记录!$A:$A,日报!W$3)<>0,SUMIFS(合格品入货记录!$G:$G,合格品入货记录!$E:$E,日报!$E:$E,合格品入货记录!$A:$A,日报!W$3),"") | X7: =IF(SUMIFS(合格品入货记录!$G:$G,合格品入货记录!$E:$E,日报!$E:$E,合格品入货记录!$A:$A,日报!X$3)<>0,SUMIFS(合格品入货记录!$G:$G,合格品入货记录!$E:$E,日报!$E:$E,合格品入货记录!$A:$A,日报!X$3),"") | Y7: =IF(SUMIFS(合格品入货记录!$G:$G,合格品入货记录!$E:$E,日报!$E:$E,合格品入货记录!$A:$A,日报!Y$3)<>0,SUMIFS(合格品入货记录!$G:$G,合格品入货记录!$E:$E,日报!$E:$E,合格品入货记录!$A:$A,日报!Y$3),"") -> 3000 | Z7: =IF(SUMIFS(合格品入货记录!$G:$G,合格品入货记录!$E:$E,日报!$E:$E,合格品入货记录!$A:$A,日报!Z$3)<>0,SUMIFS(合格品入货记录!$G:$G,合格品入货记录!$E:$E,日报!$E:$E,合格品入货记录!$A:$A,日报!Z$3),"") | AA7: =IF(SUMIFS(合格品入货记录!$G:$G,合格品入货记录!$E:$E,日报!$E:$E,合格品入货记录!$A:$A,日报!AA$3)<>0,SUMIFS(合格品入货记录!$G:$G,合格品入货记录!$E:$E,日报!$E:$E,合格品入货记录!$A:$A,日报!AA$3),"") | ... AU7: =IF(SUMIFS(合格品入货记录!$G:$G,合格品入货记录!$E:$E,日报!$E:$E,合格品入货记录!$A:$A,日报!AU$3)<>0,SUMIFS(合格品入货记录!$G:$G,合格品入货记录!$E:$E,日报!$E:$E,合格品入货记录!$A:$A,日报!AU$3),"") | AY7: =IF(SUMIFS(合格品出库记录!$G:$G,合格品出库记录!$E:$E,日报!$E:$E,合格品出库记录!$A:$A,日报!AY$3)<>0,SUMIFS(合格品出库记录!$G:$G,合格品出库记录!$E:$E,日报!$E:$E,合格品出库记录!$A:$A,日报!AY$3),"") | AZ7: =IF(SUMIFS(合格品出库记录!$G:$G,合格品出库记录!$E:$E,日报!$E:$E,合格品出库记录!$A:$A,日报!AZ$3)<>0,SUMIFS(合格品出库记录!$G:$G,合格品出库记录!$E:$E,日报!$E:$E,合格品出库记录!$A:$A,日报!AZ$3),"") | BA7: =IF(SUMIFS(合格品出库记录!$G:$G,合格品出库记录!$E:$E,日报!$E:$E,合格品出库记录!$A:$A,日报!BA$3)<>0,SUMIFS(合格品出库记录!$G:$G,合格品出库记录!$E:$E,日报!$E:$E,合格品出库记录!$A:$A,日报!BA$3),"") | BB7: =IF(SUMIFS(合格品出库记录!$G:$G,合格品出库记录!$E:$E,日报!$E:$E,合格品出库记录!$A:$A,日报!BB$3)<>0,SUMIFS(合格品出库记录!$G:$G,合格品出库记录!$E:$E,日报!$E:$E,合格品出库记录!$A:$A,日报!BB$3),"") | BC7: =IF(SUMIFS(合格品出库记录!$G:$G,合格品出库记录!$E:$E,日报!$E:$E,合格品出库记录!$A:$A,日报!BC$3)<>0,SUMIFS(合格品出库记录!$G:$G,合格品出库记录!$E:$E,日报!$E:$E,合格品出库记录!$A:$A,日报!BC$3),"") | BD7: =IF(SUMIFS(合格品出库记录!$G:$G,合格品出库记录!$E:$E,日报!$E:$E,合格品出库记录!$A:$A,日报!BD$3)<>0,SUMIFS(合格品出库记录!$G:$G,合格品出库记录!$E:$E,日报!$E:$E,合格品出库记录!$A:$A,日报!BD$3),"") -> 3000 | BE7: =IF(SUMIFS(合格品出库记录!$G:$G,合格品出库记录!$E:$E,日报!$E:$E,合格品出库记录!$A:$A,日报!BE$3)<>0,SUMIFS(合格品出库记录!$G:$G,合格品出库记录!$E:$E,日报!$E:$E,合格品出库记录!$A:$A,日报!BE$3),"") | BF7: =IF(SUMIFS(合格品出库记录!$G:$G,合格品出库记录!$E:$E,日报!$E:$E,合格品出库记录!$A:$A,日报!BF$3)<>0,SUMIFS(合格品出库记录!$G:$G,合格品出库记录!$E:$E,日报!$E:$E,合格品出库记录!$A:$A,日报!BF$3),"") | ... CC7: =IF(SUMIFS(合格品出库记录!$G:$G,合格品出库记录!$E:$E,日报!$E:$E,合格品出库记录!$A:$A,日报!CC$3)<>0,SUMIFS(合格品出库记录!$G:$G,合格品出库记录!$E:$E,日报!$E:$E,合格品出库记录!$A:$A,日报!CC$3),"")
A8: =ROW()-3 -> 5 | B8: =IFERROR(VLOOKUP(基础数据!B7,基础数据!B:B,1,0),"") -> 1AZ | C8: =IFERROR(VLOOKUP(基础数据!C7,基础数据!C:C,1,0),"") -> 芜湖博康机电股份有限公司 | E8: =IFERROR(VLOOKUP(基础数据!E7,基础数据!E:E,1,0),"") -> 3.2.50.30.00842-000 | F8: =IFERROR(VLOOKUP(基础数据!F7,基础数据!F:F,1,0),"") -> A12-菊花链线束 | G8: 1500 | H8: =IFERROR(VLOOKUP(基础数据!H7,基础数据!H:H,1,0),"") -> 料盒 | I8: 4500 | J8: 0 | K8: =SUMIF(合格品入货记录!E:E,日报!E8,合格品入货记录!G:G) -> 9000 | L8: =SUMIF(合格品出库记录!E:E,日报!E8,合格品出库记录!G:G) -> 13500 | M8: =SUMIF(零跑退回!D:D,日报!E:E,零跑退回!F:F) -> 0 | N8: =SUMIF(库内不良!D:D,E:E,库内不良!F:F) -> 0 | O8: =SUMIF(退回供应商!D:D,日报!E:E,退回供应商!F:F) -> 0 | P8: =J8+M8+N8-O8 -> 0 | Q8: =I8+K8-L8-N8 -> 0 | T8: =IF(SUMIFS(合格品入货记录!$G:$G,合格品入货记录!$E:$E,日报!$E:$E,合格品入货记录!$A:$A,日报!T$3)<>0,SUMIFS(合格品入货记录!$G:$G,合格品入货记录!$E:$E,日报!$E:$E,合格品入货记录!$A:$A,日报!T$3),"") | U8: =IF(SUMIFS(合格品入货记录!$G:$G,合格品入货记录!$E:$E,日报!$E:$E,合格品入货记录!$A:$A,日报!U$3)<>0,SUMIFS(合格品入货记录!$G:$G,合格品入货记录!$E:$E,日报!$E:$E,合格品入货记录!$A:$A,日报!U$3),"") | V8: =IF(SUMIFS(合格品入货记录!$G:$G,合格品入货记录!$E:$E,日报!$E:$E,合格品入货记录!$A:$A,日报!V$3)<>0,SUMIFS(合格品入货记录!$G:$G,合格品入货记录!$E:$E,日报!$E:$E,合格品入货记录!$A:$A,日报!V$3),"") | W8: =IF(SUMIFS(合格品入货记录!$G:$G,合格品入货记录!$E:$E,日报!$E:$E,合格品入货记录!$A:$A,日报!W$3)<>0,SUMIFS(合格品入货记录!$G:$G,合格品入货记录!$E:$E,日报!$E:$E,合格品入货记录!$A:$A,日报!W$3),"") | X8: =IF(SUMIFS(合格品入货记录!$G:$G,合格品入货记录!$E:$E,日报!$E:$E,合格品入货记录!$A:$A,日报!X$3)<>0,SUMIFS(合格品入货记录!$G:$G,合格品入货记录!$E:$E,日报!$E:$E,合格品入货记录!$A:$A,日报!X$3),"") | Y8: =IF(SUMIFS(合格品入货记录!$G:$G,合格品入货记录!$E:$E,日报!$E:$E,合格品入货记录!$A:$A,日报!Y$3)<>0,SUMIFS(合格品入货记录!$G:$G,合格品入货记录!$E:$E,日报!$E:$E,合格品入货记录!$A:$A,日报!Y$3),"") -> 4500 | Z8: =IF(SUMIFS(合格品入货记录!$G:$G,合格品入货记录!$E:$E,日报!$E:$E,合格品入货记录!$A:$A,日报!Z$3)<>0,SUMIFS(合格品入货记录!$G:$G,合格品入货记录!$E:$E,日报!$E:$E,合格品入货记录!$A:$A,日报!Z$3),"") | AA8: =IF(SUMIFS(合格品入货记录!$G:$G,合格品入货记录!$E:$E,日报!$E:$E,合格品入货记录!$A:$A,日报!AA$3)<>0,SUMIFS(合格品入货记录!$G:$G,合格品入货记录!$E:$E,日报!$E:$E,合格品入货记录!$A:$A,日报!AA$3),"") | ... AU8: =IF(SUMIFS(合格品入货记录!$G:$G,合格品入货记录!$E:$E,日报!$E:$E,合格品入货记录!$A:$A,日报!AU$3)<>0,SUMIFS(合格品入货记录!$G:$G,合格品入货记录!$E:$E,日报!$E:$E,合格品入货记录!$A:$A,日报!AU$3),"") | AY8: =IF(SUMIFS(合格品出库记录!$G:$G,合格品出库记录!$E:$E,日报!$E:$E,合格品出库记录!$A:$A,日报!AY$3)<>0,SUMIFS(合格品出库记录!$G:$G,合格品出库记录!$E:$E,日报!$E:$E,合格品出库记录!$A:$A,日报!AY$3),"") | AZ8: =IF(SUMIFS(合格品出库记录!$G:$G,合格品出库记录!$E:$E,日报!$E:$E,合格品出库记录!$A:$A,日报!AZ$3)<>0,SUMIFS(合格品出库记录!$G:$G,合格品出库记录!$E:$E,日报!$E:$E,合格品出库记录!$A:$A,日报!AZ$3),"") -> 4500 | BA8: =IF(SUMIFS(合格品出库记录!$G:$G,合格品出库记录!$E:$E,日报!$E:$E,合格品出库记录!$A:$A,日报!BA$3)<>0,SUMIFS(合格品出库记录!$G:$G,合格品出库记录!$E:$E,日报!$E:$E,合格品出库记录!$A:$A,日报!BA$3),"") | BB8: =IF(SUMIFS(合格品出库记录!$G:$G,合格品出库记录!$E:$E,日报!$E:$E,合格品出库记录!$A:$A,日报!BB$3)<>0,SUMIFS(合格品出库记录!$G:$G,合格品出库记录!$E:$E,日报!$E:$E,合格品出库记录!$A:$A,日报!BB$3),"") | BC8: =IF(SUMIFS(合格品出库记录!$G:$G,合格品出库记录!$E:$E,日报!$E:$E,合格品出库记录!$A:$A,日报!BC$3)<>0,SUMIFS(合格品出库记录!$G:$G,合格品出库记录!$E:$E,日报!$E:$E,合格品出库记录!$A:$A,日报!BC$3),"") | BD8: =IF(SUMIFS(合格品出库记录!$G:$G,合格品出库记录!$E:$E,日报!$E:$E,合格品出库记录!$A:$A,日报!BD$3)<>0,SUMIFS(合格品出库记录!$G:$G,合格品出库记录!$E:$E,日报!$E:$E,合格品出库记录!$A:$A,日报!BD$3),"") -> 4500 | BE8: =IF(SUMIFS(合格品出库记录!$G:$G,合格品出库记录!$E:$E,日报!$E:$E,合格品出库记录!$A:$A,日报!BE$3)<>0,SUMIFS(合格品出库记录!$G:$G,合格品出库记录!$E:$E,日报!$E:$E,合格品出库记录!$A:$A,日报!BE$3),"") | BF8: =IF(SUMIFS(合格品出库记录!$G:$G,合格品出库记录!$E:$E,日报!$E:$E,合格品出库记录!$A:$A,日报!BF$3)<>0,SUMIFS(合格品出库记录!$G:$G,合格品出库记录!$E:$E,日报!$E:$E,合格品出库记录!$A:$A,日报!BF$3),"") | ... CC8: =IF(SUMIFS(合格品出库记录!$G:$G,合格品出库记录!$E:$E,日报!$E:$E,合格品出库记录!$A:$A,日报!CC$3)<>0,SUMIFS(合格品出库记录!$G:$G,合格品出库记录!$E:$E,日报!$E:$E,合格品出库记录!$A:$A,日报!CC$3),"")
A9: =ROW()-3 -> 6 | B9: =IFERROR(VLOOKUP(基础数据!B8,基础数据!B:B,1,0),"") -> 1AZ | C9: =IFERROR(VLOOKUP(基础数据!C8,基础数据!C:C,1,0),"") -> 芜湖博康机电股份有限公司 | E9: =IFERROR(VLOOKUP(基础数据!E8,基础数据!E:E,1,0),"") -> 3.2.50.30.02116-000 | F9: =IFERROR(VLOOKUP(基础数据!F8,基础数据!F:F,1,0),"") -> A12EV10-通讯-水温-互锁集成线束-500 | G9: =IFERROR(VLOOKUP(基础数据!G8,基础数据!G:G,1,0),"") -> 30 | H9: =IFERROR(VLOOKUP(基础数据!H8,基础数据!H:H,1,0),"") -> 料盒 | I9: 2520 | J9: 0 | K9: =SUMIF(合格品入货记录!E:E,日报!E9,合格品入货记录!G:G) -> 1500 | L9: =SUMIF(合格品出库记录!E:E,日报!E9,合格品出库记录!G:G) -> 4020 | M9: =SUMIF(零跑退回!D:D,日报!E:E,零跑退回!F:F) -> 0 | N9: =SUMIF(库内不良!D:D,E:E,库内不良!F:F) -> 0 | O9: =SUMIF(退回供应商!D:D,日报!E:E,退回供应商!F:F) -> 0 | P9: =J9+M9+N9-O9 -> 0 | Q9: =I9+K9-L9-N9 -> 0 | T9: =IF(SUMIFS(合格品入货记录!$G:$G,合格品入货记录!$E:$E,日报!$E:$E,合格品入货记录!$A:$A,日报!T$3)<>0,SUMIFS(合格品入货记录!$G:$G,合格品入货记录!$E:$E,日报!$E:$E,合格品入货记录!$A:$A,日报!T$3),"") | U9: =IF(SUMIFS(合格品入货记录!$G:$G,合格品入货记录!$E:$E,日报!$E:$E,合格品入货记录!$A:$A,日报!U$3)<>0,SUMIFS(合格品入货记录!$G:$G,合格品入货记录!$E:$E,日报!$E:$E,合格品入货记录!$A:$A,日报!U$3),"") | V9: =IF(SUMIFS(合格品入货记录!$G:$G,合格品入货记录!$E:$E,日报!$E:$E,合格品入货记录!$A:$A,日报!V$3)<>0,SUMIFS(合格品入货记录!$G:$G,合格品入货记录!$E:$E,日报!$E:$E,合格品入货记录!$A:$A,日报!V$3),"") | W9: =IF(SUMIFS(合格品入货记录!$G:$G,合格品入货记录!$E:$E,日报!$E:$E,合格品入货记录!$A:$A,日报!W$3)<>0,SUMIFS(合格品入货记录!$G:$G,合格品入货记录!$E:$E,日报!$E:$E,合格品入货记录!$A:$A,日报!W$3),"") | X9: =IF(SUMIFS(合格品入货记录!$G:$G,合格品入货记录!$E:$E,日报!$E:$E,合格品入货记录!$A:$A,日报!X$3)<>0,SUMIFS(合格品入货记录!$G:$G,合格品入货记录!$E:$E,日报!$E:$E,合格品入货记录!$A:$A,日报!X$3),"") | Y9: =IF(SUMIFS(合格品入货记录!$G:$G,合格品入货记录!$E:$E,日报!$E:$E,合格品入货记录!$A:$A,日报!Y$3)<>0,SUMIFS(合格品入货记录!$G:$G,合格品入货记录!$E:$E,日报!$E:$E,合格品入货记录!$A:$A,日报!Y$3),"") -> 1500 | Z9: =IF(SUMIFS(合格品入货记录!$G:$G,合格品入货记录!$E:$E,日报!$E:$E,合格品入货记录!$A:$A,日报!Z$3)<>0,SUMIFS(合格品入货记录!$G:$G,合格品入货记录!$E:$E,日报!$E:$E,合格品入货记录!$A:$A,日报!Z$3),"") | AA9: =IF(SUMIFS(合格品入货记录!$G:$G,合格品入货记录!$E:$E,日报!$E:$E,合格品入货记录!$A:$A,日报!AA$3)<>0,SUMIFS(合格品入货记录!$G:$G,合格品入货记录!$E:$E,日报!$E:$E,合格品入货记录!$A:$A,日报!AA$3),"") | ... AU9: =IF(SUMIFS(合格品入货记录!$G:$G,合格品入货记录!$E:$E,日报!$E:$E,合格品入货记录!$A:$A,日报!AU$3)<>0,SUMIFS(合格品入货记录!$G:$G,合格品入货记录!$E:$E,日报!$E:$E,合格品入货记录!$A:$A,日报!AU$3),"") | AY9: =IF(SUMIFS(合格品出库记录!$G:$G,合格品出库记录!$E:$E,日报!$E:$E,合格品出库记录!$A:$A,日报!AY$3)<>0,SUMIFS(合格品出库记录!$G:$G,合格品出库记录!$E:$E,日报!$E:$E,合格品出库记录!$A:$A,日报!AY$3),"") | AZ9: =IF(SUMIFS(合格品出库记录!$G:$G,合格品出库记录!$E:$E,日报!$E:$E,合格品出库记录!$A:$A,日报!AZ$3)<>0,SUMIFS(合格品出库记录!$G:$G,合格品出库记录!$E:$E,日报!$E:$E,合格品出库记录!$A:$A,日报!AZ$3),"") | BA9: =IF(SUMIFS(合格品出库记录!$G:$G,合格品出库记录!$E:$E,日报!$E:$E,合格品出库记录!$A:$A,日报!BA$3)<>0,SUMIFS(合格品出库记录!$G:$G,合格品出库记录!$E:$E,日报!$E:$E,合格品出库记录!$A:$A,日报!BA$3),"") | BB9: =IF(SUMIFS(合格品出库记录!$G:$G,合格品出库记录!$E:$E,日报!$E:$E,合格品出库记录!$A:$A,日报!BB$3)<>0,SUMIFS(合格品出库记录!$G:$G,合格品出库记录!$E:$E,日报!$E:$E,合格品出库记录!$A:$A,日报!BB$3),"") | BC9: =IF(SUMIFS(合格品出库记录!$G:$G,合格品出库记录!$E:$E,日报!$E:$E,合格品出库记录!$A:$A,日报!BC$3)<>0,SUMIFS(合格品出库记录!$G:$G,合格品出库记录!$E:$E,日报!$E:$E,合格品出库记录!$A:$A,日报!BC$3),"") -> 2520 | BD9: =IF(SUMIFS(合格品出库记录!$G:$G,合格品出库记录!$E:$E,日报!$E:$E,合格品出库记录!$A:$A,日报!BD$3)<>0,SUMIFS(合格品出库记录!$G:$G,合格品出库记录!$E:$E,日报!$E:$E,合格品出库记录!$A:$A,日报!BD$3),"") | BE9: =IF(SUMIFS(合格品出库记录!$G:$G,合格品出库记录!$E:$E,日报!$E:$E,合格品出库记录!$A:$A,日报!BE$3)<>0,SUMIFS(合格品出库记录!$G:$G,合格品出库记录!$E:$E,日报!$E:$E,合格品出库记录!$A:$A,日报!BE$3),"") | BF9: =IF(SUMIFS(合格品出库记录!$G:$G,合格品出库记录!$E:$E,日报!$E:$E,合格品出库记录!$A:$A,日报!BF$3)<>0,SUMIFS(合格品出库记录!$G:$G,合格品出库记录!$E:$E,日报!$E:$E,合格品出库记录!$A:$A,日报!BF$3),"") -> 1500 | ... CC9: =IF(SUMIFS(合格品出库记录!$G:$G,合格品出库记录!$E:$E,日报!$E:$E,合格品出库记录!$A:$A,日报!CC$3)<>0,SUMIFS(合格品出库记录!$G:$G,合格品出库记录!$E:$E,日报!$E:$E,合格品出库记录!$A:$A,日报!CC$3),"")
A10: =ROW()-3 -> 7 | B10: =IFERROR(VLOOKUP(基础数据!B9,基础数据!B:B,1,0),"") -> 1AZ | C10: =IFERROR(VLOOKUP(基础数据!C9,基础数据!C:C,1,0),"") -> 芜湖博康机电股份有限公司 | E10: =IFERROR(VLOOKUP(基础数据!E9,基础数据!E:E,1,0),"") -> 3.2.50.30.02118-000 | F10: =IFERROR(VLOOKUP(基础数据!F9,基础数据!F:F,1,0),"") -> A12EV10-BDU-采样集成线束 | G10: =IFERROR(VLOOKUP(基础数据!G9,基础数据!G:G,1,0),"") -> 50 | H10: =IFERROR(VLOOKUP(基础数据!H9,基础数据!H:H,1,0),"") -> 料盒 | I10: 1500 | J10: 0 | K10: =SUMIF(合格品入货记录!E:E,日报!E10,合格品入货记录!G:G) -> 3000 | L10: =SUMIF(合格品出库记录!E:E,日报!E10,合格品出库记录!G:G) -> 4500 | M10: =SUMIF(零跑退回!D:D,日报!E:E,零跑退回!F:F) -> 0 | N10: =SUMIF(库内不良!D:D,E:E,库内不良!F:F) -> 0 | O10: =SUMIF(退回供应商!D:D,日报!E:E,退回供应商!F:F) -> 0 | P10: =J10+M10+N10-O10 -> 0 | Q10: =I10+K10-L10-N10 -> 0 | T10: =IF(SUMIFS(合格品入货记录!$G:$G,合格品入货记录!$E:$E,日报!$E:$E,合格品入货记录!$A:$A,日报!T$3)<>0,SUMIFS(合格品入货记录!$G:$G,合格品入货记录!$E:$E,日报!$E:$E,合格品入货记录!$A:$A,日报!T$3),"") | U10: =IF(SUMIFS(合格品入货记录!$G:$G,合格品入货记录!$E:$E,日报!$E:$E,合格品入货记录!$A:$A,日报!U$3)<>0,SUMIFS(合格品入货记录!$G:$G,合格品入货记录!$E:$E,日报!$E:$E,合格品入货记录!$A:$A,日报!U$3),"") | V10: =IF(SUMIFS(合格品入货记录!$G:$G,合格品入货记录!$E:$E,日报!$E:$E,合格品入货记录!$A:$A,日报!V$3)<>0,SUMIFS(合格品入货记录!$G:$G,合格品入货记录!$E:$E,日报!$E:$E,合格品入货记录!$A:$A,日报!V$3),"") | W10: =IF(SUMIFS(合格品入货记录!$G:$G,合格品入货记录!$E:$E,日报!$E:$E,合格品入货记录!$A:$A,日报!W$3)<>0,SUMIFS(合格品入货记录!$G:$G,合格品入货记录!$E:$E,日报!$E:$E,合格品入货记录!$A:$A,日报!W$3),"") | X10: =IF(SUMIFS(合格品入货记录!$G:$G,合格品入货记录!$E:$E,日报!$E:$E,合格品入货记录!$A:$A,日报!X$3)<>0,SUMIFS(合格品入货记录!$G:$G,合格品入货记录!$E:$E,日报!$E:$E,合格品入货记录!$A:$A,日报!X$3),"") | Y10: =IF(SUMIFS(合格品入货记录!$G:$G,合格品入货记录!$E:$E,日报!$E:$E,合格品入货记录!$A:$A,日报!Y$3)<>0,SUMIFS(合格品入货记录!$G:$G,合格品入货记录!$E:$E,日报!$E:$E,合格品入货记录!$A:$A,日报!Y$3),"") -> 1500 | Z10: =IF(SUMIFS(合格品入货记录!$G:$G,合格品入货记录!$E:$E,日报!$E:$E,合格品入货记录!$A:$A,日报!Z$3)<>0,SUMIFS(合格品入货记录!$G:$G,合格品入货记录!$E:$E,日报!$E:$E,合格品入货记录!$A:$A,日报!Z$3),"") | AA10: =IF(SUMIFS(合格品入货记录!$G:$G,合格品入货记录!$E:$E,日报!$E:$E,合格品入货记录!$A:$A,日报!AA$3)<>0,SUMIFS(合格品入货记录!$G:$G,合格品入货记录!$E:$E,日报!$E:$E,合格品入货记录!$A:$A,日报!AA$3),"") | ... AU10: =IF(SUMIFS(合格品入货记录!$G:$G,合格品入货记录!$E:$E,日报!$E:$E,合格品入货记录!$A:$A,日报!AU$3)<>0,SUMIFS(合格品入货记录!$G:$G,合格品入货记录!$E:$E,日报!$E:$E,合格品入货记录!$A:$A,日报!AU$3),"") | AY10: =IF(SUMIFS(合格品出库记录!$G:$G,合格品出库记录!$E:$E,日报!$E:$E,合格品出库记录!$A:$A,日报!AY$3)<>0,SUMIFS(合格品出库记录!$G:$G,合格品出库记录!$E:$E,日报!$E:$E,合格品出库记录!$A:$A,日报!AY$3),"") | AZ10: =IF(SUMIFS(合格品出库记录!$G:$G,合格品出库记录!$E:$E,日报!$E:$E,合格品出库记录!$A:$A,日报!AZ$3)<>0,SUMIFS(合格品出库记录!$G:$G,合格品出库记录!$E:$E,日报!$E:$E,合格品出库记录!$A:$A,日报!AZ$3),"") | BA10: =IF(SUMIFS(合格品出库记录!$G:$G,合格品出库记录!$E:$E,日报!$E:$E,合格品出库记录!$A:$A,日报!BA$3)<>0,SUMIFS(合格品出库记录!$G:$G,合格品出库记录!$E:$E,日报!$E:$E,合格品出库记录!$A:$A,日报!BA$3),"") | BB10: =IF(SUMIFS(合格品出库记录!$G:$G,合格品出库记录!$E:$E,日报!$E:$E,合格品出库记录!$A:$A,日报!BB$3)<>0,SUMIFS(合格品出库记录!$G:$G,合格品出库记录!$E:$E,日报!$E:$E,合格品出库记录!$A:$A,日报!BB$3),"") | BC10: =IF(SUMIFS(合格品出库记录!$G:$G,合格品出库记录!$E:$E,日报!$E:$E,合格品出库记录!$A:$A,日报!BC$3)<>0,SUMIFS(合格品出库记录!$G:$G,合格品出库记录!$E:$E,日报!$E:$E,合格品出库记录!$A:$A,日报!BC$3),"") -> 1500 | BD10: =IF(SUMIFS(合格品出库记录!$G:$G,合格品出库记录!$E:$E,日报!$E:$E,合格品出库记录!$A:$A,日报!BD$3)<>0,SUMIFS(合格品出库记录!$G:$G,合格品出库记录!$E:$E,日报!$E:$E,合格品出库记录!$A:$A,日报!BD$3),"") | BE10: =IF(SUMIFS(合格品出库记录!$G:$G,合格品出库记录!$E:$E,日报!$E:$E,合格品出库记录!$A:$A,日报!BE$3)<>0,SUMIFS(合格品出库记录!$G:$G,合格品出库记录!$E:$E,日报!$E:$E,合格品出库记录!$A:$A,日报!BE$3),"") | BF10: =IF(SUMIFS(合格品出库记录!$G:$G,合格品出库记录!$E:$E,日报!$E:$E,合格品出库记录!$A:$A,日报!BF$3)<>0,SUMIFS(合格品出库记录!$G:$G,合格品出库记录!$E:$E,日报!$E:$E,合格品出库记录!$A:$A,日报!BF$3),"") -> 1500 | ... CC10: =IF(SUMIFS(合格品出库记录!$G:$G,合格品出库记录!$E:$E,日报!$E:$E,合格品出库记录!$A:$A,日报!CC$3)<>0,SUMIFS(合格品出库记录!$G:$G,合格品出库记录!$E:$E,日报!$E:$E,合格品出库记录!$A:$A,日报!CC$3),"")
A11: =ROW()-3 -> 8 | B11: =IFERROR(VLOOKUP(基础数据!B10,基础数据!B:B,1,0),"") -> 1AZ | C11: =IFERROR(VLOOKUP(基础数据!C10,基础数据!C:C,1,0),"") -> 芜湖博康机电股份有限公司 | E11: =IFERROR(VLOOKUP(基础数据!E10,基础数据!E:E,1,0),"") -> 3.2.50.30.00596-000 | F11: =IFERROR(VLOOKUP(基础数据!F10,基础数据!F:F,1,0),"") -> CTC_高压插座线束 | G11: =IFERROR(VLOOKUP(基础数据!G10,基础数据!G:G,1,0),"") -> 70 | H11: =IFERROR(VLOOKUP(基础数据!H10,基础数据!H:H,1,0),"") -> 料盒 | I11: 1190 | J11: 0 | K11: =SUMIF(合格品入货记录!E:E,日报!E11,合格品入货记录!G:G) -> 1400 | L11: =SUMIF(合格品出库记录!E:E,日报!E11,合格品出库记录!G:G) -> 0 | M11: =SUMIF(零跑退回!D:D,日报!E:E,零跑退回!F:F) -> 0 | N11: =SUMIF(库内不良!D:D,E:E,库内不良!F:F) -> 0 | O11: =SUMIF(退回供应商!D:D,日报!E:E,退回供应商!F:F) -> 0 | P11: =J11+M11+N11-O11 -> 0 | Q11: =I11+K11-L11-N11 -> 2590 | T11: =IF(SUMIFS(合格品入货记录!$G:$G,合格品入货记录!$E:$E,日报!$E:$E,合格品入货记录!$A:$A,日报!T$3)<>0,SUMIFS(合格品入货记录!$G:$G,合格品入货记录!$E:$E,日报!$E:$E,合格品入货记录!$A:$A,日报!T$3),"") | U11: =IF(SUMIFS(合格品入货记录!$G:$G,合格品入货记录!$E:$E,日报!$E:$E,合格品入货记录!$A:$A,日报!U$3)<>0,SUMIFS(合格品入货记录!$G:$G,合格品入货记录!$E:$E,日报!$E:$E,合格品入货记录!$A:$A,日报!U$3),"") | V11: =IF(SUMIFS(合格品入货记录!$G:$G,合格品入货记录!$E:$E,日报!$E:$E,合格品入货记录!$A:$A,日报!V$3)<>0,SUMIFS(合格品入货记录!$G:$G,合格品入货记录!$E:$E,日报!$E:$E,合格品入货记录!$A:$A,日报!V$3),"") | W11: =IF(SUMIFS(合格品入货记录!$G:$G,合格品入货记录!$E:$E,日报!$E:$E,合格品入货记录!$A:$A,日报!W$3)<>0,SUMIFS(合格品入货记录!$G:$G,合格品入货记录!$E:$E,日报!$E:$E,合格品入货记录!$A:$A,日报!W$3),"") | X11: =IF(SUMIFS(合格品入货记录!$G:$G,合格品入货记录!$E:$E,日报!$E:$E,合格品入货记录!$A:$A,日报!X$3)<>0,SUMIFS(合格品入货记录!$G:$G,合格品入货记录!$E:$E,日报!$E:$E,合格品入货记录!$A:$A,日报!X$3),"") | Y11: =IF(SUMIFS(合格品入货记录!$G:$G,合格品入货记录!$E:$E,日报!$E:$E,合格品入货记录!$A:$A,日报!Y$3)<>0,SUMIFS(合格品入货记录!$G:$G,合格品入货记录!$E:$E,日报!$E:$E,合格品入货记录!$A:$A,日报!Y$3),"") -> 1400 | Z11: =IF(SUMIFS(合格品入货记录!$G:$G,合格品入货记录!$E:$E,日报!$E:$E,合格品入货记录!$A:$A,日报!Z$3)<>0,SUMIFS(合格品入货记录!$G:$G,合格品入货记录!$E:$E,日报!$E:$E,合格品入货记录!$A:$A,日报!Z$3),"") | AA11: =IF(SUMIFS(合格品入货记录!$G:$G,合格品入货记录!$E:$E,日报!$E:$E,合格品入货记录!$A:$A,日报!AA$3)<>0,SUMIFS(合格品入货记录!$G:$G,合格品入货记录!$E:$E,日报!$E:$E,合格品入货记录!$A:$A,日报!AA$3),"") | ... AU11: =IF(SUMIFS(合格品入货记录!$G:$G,合格品入货记录!$E:$E,日报!$E:$E,合格品入货记录!$A:$A,日报!AU$3)<>0,SUMIFS(合格品入货记录!$G:$G,合格品入货记录!$E:$E,日报!$E:$E,合格品入货记录!$A:$A,日报!AU$3),"") | AY11: =IF(SUMIFS(合格品出库记录!$G:$G,合格品出库记录!$E:$E,日报!$E:$E,合格品出库记录!$A:$A,日报!AY$3)<>0,SUMIFS(合格品出库记录!$G:$G,合格品出库记录!$E:$E,日报!$E:$E,合格品出库记录!$A:$A,日报!AY$3),"") | AZ11: =IF(SUMIFS(合格品出库记录!$G:$G,合格品出库记录!$E:$E,日报!$E:$E,合格品出库记录!$A:$A,日报!AZ$3)<>0,SUMIFS(合格品出库记录!$G:$G,合格品出库记录!$E:$E,日报!$E:$E,合格品出库记录!$A:$A,日报!AZ$3),"") | BA11: =IF(SUMIFS(合格品出库记录!$G:$G,合格品出库记录!$E:$E,日报!$E:$E,合格品出库记录!$A:$A,日报!BA$3)<>0,SUMIFS(合格品出库记录!$G:$G,合格品出库记录!$E:$E,日报!$E:$E,合格品出库记录!$A:$A,日报!BA$3),"") | BB11: =IF(SUMIFS(合格品出库记录!$G:$G,合格品出库记录!$E:$E,日报!$E:$E,合格品出库记录!$A:$A,日报!BB$3)<>0,SUMIFS(合格品出库记录!$G:$G,合格品出库记录!$E:$E,日报!$E:$E,合格品出库记录!$A:$A,日报!BB$3),"") | BC11: =IF(SUMIFS(合格品出库记录!$G:$G,合格品出库记录!$E:$E,日报!$E:$E,合格品出库记录!$A:$A,日报!BC$3)<>0,SUMIFS(合格品出库记录!$G:$G,合格品出库记录!$E:$E,日报!$E:$E,合格品出库记录!$A:$A,日报!BC$3),"") | BD11: =IF(SUMIFS(合格品出库记录!$G:$G,合格品出库记录!$E:$E,日报!$E:$E,合格品出库记录!$A:$A,日报!BD$3)<>0,SUMIFS(合格品出库记录!$G:$G,合格品出库记录!$E:$E,日报!$E:$E,合格品出库记录!$A:$A,日报!BD$3),"") | BE11: =IF(SUMIFS(合格品出库记录!$G:$G,合格品出库记录!$E:$E,日报!$E:$E,合格品出库记录!$A:$A,日报!BE$3)<>0,SUMIFS(合格品出库记录!$G:$G,合格品出库记录!$E:$E,日报!$E:$E,合格品出库记录!$A:$A,日报!BE$3),"") | BF11: =IF(SUMIFS(合格品出库记录!$G:$G,合格品出库记录!$E:$E,日报!$E:$E,合格品出库记录!$A:$A,日报!BF$3)<>0,SUMIFS(合格品出库记录!$G:$G,合格品出库记录!$E:$E,日报!$E:$E,合格品出库记录!$A:$A,日报!BF$3),"") | ... CC11: =IF(SUMIFS(合格品出库记录!$G:$G,合格品出库记录!$E:$E,日报!$E:$E,合格品出库记录!$A:$A,日报!CC$3)<>0,SUMIFS(合格品出库记录!$G:$G,合格品出库记录!$E:$E,日报!$E:$E,合格品出库记录!$A:$A,日报!CC$3),"")
A12: =ROW()-3 -> 9 | B12: =IFERROR(VLOOKUP(基础数据!B11,基础数据!B:B,1,0),"") -> 1AZ | C12: =IFERROR(VLOOKUP(基础数据!C11,基础数据!C:C,1,0),"") -> 芜湖博康机电股份有限公司 | E12: =IFERROR(VLOOKUP(基础数据!E11,基础数据!E:E,1,0),"") -> 3.2.50.30.01656-000 | F12: =IFERROR(VLOOKUP(基础数据!F11,基础数据!F:F,1,0),"") -> LXC11EV1A-水温-互锁集成线束 | G12: =IFERROR(VLOOKUP(基础数据!G11,基础数据!G:G,1,0),"") -> 15 | H12: =IFERROR(VLOOKUP(基础数据!H11,基础数据!H:H,1,0),"") -> 料盒 | I12: 0 | J12: 0 | K12: =SUMIF(合格品入货记录!E:E,日报!E12,合格品入货记录!G:G) -> 0 | L12: =SUMIF(合格品出库记录!E:E,日报!E12,合格品出库记录!G:G) -> 0 | M12: =SUMIF(零跑退回!D:D,日报!E:E,零跑退回!F:F) -> 0 | N12: =SUMIF(库内不良!D:D,E:E,库内不良!F:F) -> 0 | O12: =SUMIF(退回供应商!D:D,日报!E:E,退回供应商!F:F) -> 0 | P12: =J12+M12+N12-O12 -> 0 | Q12: =I12+K12-L12-N12 -> 0 | T12: =IF(SUMIFS(合格品入货记录!$G:$G,合格品入货记录!$E:$E,日报!$E:$E,合格品入货记录!$A:$A,日报!T$3)<>0,SUMIFS(合格品入货记录!$G:$G,合格品入货记录!$E:$E,日报!$E:$E,合格品入货记录!$A:$A,日报!T$3),"") | U12: =IF(SUMIFS(合格品入货记录!$G:$G,合格品入货记录!$E:$E,日报!$E:$E,合格品入货记录!$A:$A,日报!U$3)<>0,SUMIFS(合格品入货记录!$G:$G,合格品入货记录!$E:$E,日报!$E:$E,合格品入货记录!$A:$A,日报!U$3),"") | V12: =IF(SUMIFS(合格品入货记录!$G:$G,合格品入货记录!$E:$E,日报!$E:$E,合格品入货记录!$A:$A,日报!V$3)<>0,SUMIFS(合格品入货记录!$G:$G,合格品入货记录!$E:$E,日报!$E:$E,合格品入货记录!$A:$A,日报!V$3),"") | W12: =IF(SUMIFS(合格品入货记录!$G:$G,合格品入货记录!$E:$E,日报!$E:$E,合格品入货记录!$A:$A,日报!W$3)<>0,SUMIFS(合格品入货记录!$G:$G,合格品入货记录!$E:$E,日报!$E:$E,合格品入货记录!$A:$A,日报!W$3),"") | X12: =IF(SUMIFS(合格品入货记录!$G:$G,合格品入货记录!$E:$E,日报!$E:$E,合格品入货记录!$A:$A,日报!X$3)<>0,SUMIFS(合格品入货记录!$G:$G,合格品入货记录!$E:$E,日报!$E:$E,合格品入货记录!$A:$A,日报!X$3),"") | Y12: =IF(SUMIFS(合格品入货记录!$G:$G,合格品入货记录!$E:$E,日报!$E:$E,合格品入货记录!$A:$A,日报!Y$3)<>0,SUMIFS(合格品入货记录!$G:$G,合格品入货记录!$E:$E,日报!$E:$E,合格品入货记录!$A:$A,日报!Y$3),"") | Z12: =IF(SUMIFS(合格品入货记录!$G:$G,合格品入货记录!$E:$E,日报!$E:$E,合格品入货记录!$A:$A,日报!Z$3)<>0,SUMIFS(合格品入货记录!$G:$G,合格品入货记录!$E:$E,日报!$E:$E,合格品入货记录!$A:$A,日报!Z$3),"") | AA12: =IF(SUMIFS(合格品入货记录!$G:$G,合格品入货记录!$E:$E,日报!$E:$E,合格品入货记录!$A:$A,日报!AA$3)<>0,SUMIFS(合格品入货记录!$G:$G,合格品入货记录!$E:$E,日报!$E:$E,合格品入货记录!$A:$A,日报!AA$3),"") | ... AU12: =IF(SUMIFS(合格品入货记录!$G:$G,合格品入货记录!$E:$E,日报!$E:$E,合格品入货记录!$A:$A,日报!AU$3)<>0,SUMIFS(合格品入货记录!$G:$G,合格品入货记录!$E:$E,日报!$E:$E,合格品入货记录!$A:$A,日报!AU$3),"") | AY12: =IF(SUMIFS(合格品出库记录!$G:$G,合格品出库记录!$E:$E,日报!$E:$E,合格品出库记录!$A:$A,日报!AY$3)<>0,SUMIFS(合格品出库记录!$G:$G,合格品出库记录!$E:$E,日报!$E:$E,合格品出库记录!$A:$A,日报!AY$3),"") | AZ12: =IF(SUMIFS(合格品出库记录!$G:$G,合格品出库记录!$E:$E,日报!$E:$E,合格品出库记录!$A:$A,日报!AZ$3)<>0,SUMIFS(合格品出库记录!$G:$G,合格品出库记录!$E:$E,日报!$E:$E,合格品出库记录!$A:$A,日报!AZ$3),"") | BA12: =IF(SUMIFS(合格品出库记录!$G:$G,合格品出库记录!$E:$E,日报!$E:$E,合格品出库记录!$A:$A,日报!BA$3)<>0,SUMIFS(合格品出库记录!$G:$G,合格品出库记录!$E:$E,日报!$E:$E,合格品出库记录!$A:$A,日报!BA$3),"") | BB12: =IF(SUMIFS(合格品出库记录!$G:$G,合格品出库记录!$E:$E,日报!$E:$E,合格品出库记录!$A:$A,日报!BB$3)<>0,SUMIFS(合格品出库记录!$G:$G,合格品出库记录!$E:$E,日报!$E:$E,合格品出库记录!$A:$A,日报!BB$3),"") | BC12: =IF(SUMIFS(合格品出库记录!$G:$G,合格品出库记录!$E:$E,日报!$E:$E,合格品出库记录!$A:$A,日报!BC$3)<>0,SUMIFS(合格品出库记录!$G:$G,合格品出库记录!$E:$E,日报!$E:$E,合格品出库记录!$A:$A,日报!BC$3),"") | BD12: =IF(SUMIFS(合格品出库记录!$G:$G,合格品出库记录!$E:$E,日报!$E:$E,合格品出库记录!$A:$A,日报!BD$3)<>0,SUMIFS(合格品出库记录!$G:$G,合格品出库记录!$E:$E,日报!$E:$E,合格品出库记录!$A:$A,日报!BD$3),"") | BE12: =IF(SUMIFS(合格品出库记录!$G:$G,合格品出库记录!$E:$E,日报!$E:$E,合格品出库记录!$A:$A,日报!BE$3)<>0,SUMIFS(合格品出库记录!$G:$G,合格品出库记录!$E:$E,日报!$E:$E,合格品出库记录!$A:$A,日报!BE$3),"") | BF12: =IF(SUMIFS(合格品出库记录!$G:$G,合格品出库记录!$E:$E,日报!$E:$E,合格品出库记录!$A:$A,日报!BF$3)<>0,SUMIFS(合格品出库记录!$G:$G,合格品出库记录!$E:$E,日报!$E:$E,合格品出库记录!$A:$A,日报!BF$3),"") | ... CC12: =IF(SUMIFS(合格品出库记录!$G:$G,合格品出库记录!$E:$E,日报!$E:$E,合格品出库记录!$A:$A,日报!CC$3)<>0,SUMIFS(合格品出库记录!$G:$G,合格品出库记录!$E:$E,日报!$E:$E,合格品出库记录!$A:$A,日报!CC$3),"")
A13: =ROW()-3 -> 10 | B13: =IFERROR(VLOOKUP(基础数据!B12,基础数据!B:B,1,0),"") -> 1AZ | C13: =IFERROR(VLOOKUP(基础数据!C12,基础数据!C:C,1,0),"") -> 芜湖博康机电股份有限公司 | E13: =IFERROR(VLOOKUP(基础数据!E12,基础数据!E:E,1,0),"") -> 3.2.50.30.01657-000 | F13: =IFERROR(VLOOKUP(基础数据!F12,基础数据!F:F,1,0),"") -> LXC11EV1A-高压支路线束 | G13: =IFERROR(VLOOKUP(基础数据!G12,基础数据!G:G,1,0),"") -> 20 | H13: =IFERROR(VLOOKUP(基础数据!H12,基础数据!H:H,1,0),"") -> 料盒 | I13: 0 | J13: 0 | K13: =SUMIF(合格品入货记录!E:E,日报!E13,合格品入货记录!G:G) -> 0 | L13: =SUMIF(合格品出库记录!E:E,日报!E13,合格品出库记录!G:G) -> 0 | M13: =SUMIF(零跑退回!D:D,日报!E:E,零跑退回!F:F) -> 0 | N13: =SUMIF(库内不良!D:D,E:E,库内不良!F:F) -> 0 | O13: =SUMIF(退回供应商!D:D,日报!E:E,退回供应商!F:F) -> 0 | P13: =J13+M13+N13-O13 -> 0 | Q13: =I13+K13-L13-N13 -> 0 | T13: =IF(SUMIFS(合格品入货记录!$G:$G,合格品入货记录!$E:$E,日报!$E:$E,合格品入货记录!$A:$A,日报!T$3)<>0,SUMIFS(合格品入货记录!$G:$G,合格品入货记录!$E:$E,日报!$E:$E,合格品入货记录!$A:$A,日报!T$3),"") | U13: =IF(SUMIFS(合格品入货记录!$G:$G,合格品入货记录!$E:$E,日报!$E:$E,合格品入货记录!$A:$A,日报!U$3)<>0,SUMIFS(合格品入货记录!$G:$G,合格品入货记录!$E:$E,日报!$E:$E,合格品入货记录!$A:$A,日报!U$3),"") | V13: =IF(SUMIFS(合格品入货记录!$G:$G,合格品入货记录!$E:$E,日报!$E:$E,合格品入货记录!$A:$A,日报!V$3)<>0,SUMIFS(合格品入货记录!$G:$G,合格品入货记录!$E:$E,日报!$E:$E,合格品入货记录!$A:$A,日报!V$3),"") | W13: =IF(SUMIFS(合格品入货记录!$G:$G,合格品入货记录!$E:$E,日报!$E:$E,合格品入货记录!$A:$A,日报!W$3)<>0,SUMIFS(合格品入货记录!$G:$G,合格品入货记录!$E:$E,日报!$E:$E,合格品入货记录!$A:$A,日报!W$3),"") | X13: =IF(SUMIFS(合格品入货记录!$G:$G,合格品入货记录!$E:$E,日报!$E:$E,合格品入货记录!$A:$A,日报!X$3)<>0,SUMIFS(合格品入货记录!$G:$G,合格品入货记录!$E:$E,日报!$E:$E,合格品入货记录!$A:$A,日报!X$3),"") | Y13: =IF(SUMIFS(合格品入货记录!$G:$G,合格品入货记录!$E:$E,日报!$E:$E,合格品入货记录!$A:$A,日报!Y$3)<>0,SUMIFS(合格品入货记录!$G:$G,合格品入货记录!$E:$E,日报!$E:$E,合格品入货记录!$A:$A,日报!Y$3),"") | Z13: =IF(SUMIFS(合格品入货记录!$G:$G,合格品入货记录!$E:$E,日报!$E:$E,合格品入货记录!$A:$A,日报!Z$3)<>0,SUMIFS(合格品入货记录!$G:$G,合格品入货记录!$E:$E,日报!$E:$E,合格品入货记录!$A:$A,日报!Z$3),"") | AA13: =IF(SUMIFS(合格品入货记录!$G:$G,合格品入货记录!$E:$E,日报!$E:$E,合格品入货记录!$A:$A,日报!AA$3)<>0,SUMIFS(合格品入货记录!$G:$G,合格品入货记录!$E:$E,日报!$E:$E,合格品入货记录!$A:$A,日报!AA$3),"") | ... AU13: =IF(SUMIFS(合格品入货记录!$G:$G,合格品入货记录!$E:$E,日报!$E:$E,合格品入货记录!$A:$A,日报!AU$3)<>0,SUMIFS(合格品入货记录!$G:$G,合格品入货记录!$E:$E,日报!$E:$E,合格品入货记录!$A:$A,日报!AU$3),"") | AY13: =IF(SUMIFS(合格品出库记录!$G:$G,合格品出库记录!$E:$E,日报!$E:$E,合格品出库记录!$A:$A,日报!AY$3)<>0,SUMIFS(合格品出库记录!$G:$G,合格品出库记录!$E:$E,日报!$E:$E,合格品出库记录!$A:$A,日报!AY$3),"") | AZ13: =IF(SUMIFS(合格品出库记录!$G:$G,合格品出库记录!$E:$E,日报!$E:$E,合格品出库记录!$A:$A,日报!AZ$3)<>0,SUMIFS(合格品出库记录!$G:$G,合格品出库记录!$E:$E,日报!$E:$E,合格品出库记录!$A:$A,日报!AZ$3),"") | BA13: =IF(SUMIFS(合格品出库记录!$G:$G,合格品出库记录!$E:$E,日报!$E:$E,合格品出库记录!$A:$A,日报!BA$3)<>0,SUMIFS(合格品出库记录!$G:$G,合格品出库记录!$E:$E,日报!$E:$E,合格品出库记录!$A:$A,日报!BA$3),"") | BB13: =IF(SUMIFS(合格品出库记录!$G:$G,合格品出库记录!$E:$E,日报!$E:$E,合格品出库记录!$A:$A,日报!BB$3)<>0,SUMIFS(合格品出库记录!$G:$G,合格品出库记录!$E:$E,日报!$E:$E,合格品出库记录!$A:$A,日报!BB$3),"") | BC13: =IF(SUMIFS(合格品出库记录!$G:$G,合格品出库记录!$E:$E,日报!$E:$E,合格品出库记录!$A:$A,日报!BC$3)<>0,SUMIFS(合格品出库记录!$G:$G,合格品出库记录!$E:$E,日报!$E:$E,合格品出库记录!$A:$A,日报!BC$3),"") | BD13: =IF(SUMIFS(合格品出库记录!$G:$G,合格品出库记录!$E:$E,日报!$E:$E,合格品出库记录!$A:$A,日报!BD$3)<>0,SUMIFS(合格品出库记录!$G:$G,合格品出库记录!$E:$E,日报!$E:$E,合格品出库记录!$A:$A,日报!BD$3),"") | BE13: =IF(SUMIFS(合格品出库记录!$G:$G,合格品出库记录!$E:$E,日报!$E:$E,合格品出库记录!$A:$A,日报!BE$3)<>0,SUMIFS(合格品出库记录!$G:$G,合格品出库记录!$E:$E,日报!$E:$E,合格品出库记录!$A:$A,日报!BE$3),"") | BF13: =IF(SUMIFS(合格品出库记录!$G:$G,合格品出库记录!$E:$E,日报!$E:$E,合格品出库记录!$A:$A,日报!BF$3)<>0,SUMIFS(合格品出库记录!$G:$G,合格品出库记录!$E:$E,日报!$E:$E,合格品出库记录!$A:$A,日报!BF$3),"") | ... CC13: =IF(SUMIFS(合格品出库记录!$G:$G,合格品出库记录!$E:$E,日报!$E:$E,合格品出库记录!$A:$A,日报!CC$3)<>0,SUMIFS(合格品出库记录!$G:$G,合格品出库记录!$E:$E,日报!$E:$E,合格品出库记录!$A:$A,日报!CC$3),"")
A14: =ROW()-3 -> 11 | B14: =IFERROR(VLOOKUP(基础数据!B13,基础数据!B:B,1,0),"") -> 1AZ | C14: =IFERROR(VLOOKUP(基础数据!C13,基础数据!C:C,1,0),"") -> 芜湖博康机电股份有限公司 | E14: =IFERROR(VLOOKUP(基础数据!E13,基础数据!E:E,1,0),"") -> 3.2.50.30.01661-000 | F14: =IFERROR(VLOOKUP(基础数据!F13,基础数据!F:F,1,0),"") -> LXC11EV1A-BDU内部线束 | G14: =IFERROR(VLOOKUP(基础数据!G13,基础数据!G:G,1,0),"") -> 50 | H14: =IFERROR(VLOOKUP(基础数据!H13,基础数据!H:H,1,0),"") -> 料盒 | I14: 0 | J14: 0 | K14: =SUMIF(合格品入货记录!E:E,日报!E14,合格品入货记录!G:G) -> 0 | L14: =SUMIF(合格品出库记录!E:E,日报!E14,合格品出库记录!G:G) -> 0 | M14: =SUMIF(零跑退回!D:D,日报!E:E,零跑退回!F:F) -> 0 | N14: =SUMIF(库内不良!D:D,E:E,库内不良!F:F) -> 0 | O14: =SUMIF(退回供应商!D:D,日报!E:E,退回供应商!F:F) -> 0 | P14: =J14+M14+N14-O14 -> 0 | Q14: =I14+K14-L14-N14 -> 0 | T14: =IF(SUMIFS(合格品入货记录!$G:$G,合格品入货记录!$E:$E,日报!$E:$E,合格品入货记录!$A:$A,日报!T$3)<>0,SUMIFS(合格品入货记录!$G:$G,合格品入货记录!$E:$E,日报!$E:$E,合格品入货记录!$A:$A,日报!T$3),"") | U14: =IF(SUMIFS(合格品入货记录!$G:$G,合格品入货记录!$E:$E,日报!$E:$E,合格品入货记录!$A:$A,日报!U$3)<>0,SUMIFS(合格品入货记录!$G:$G,合格品入货记录!$E:$E,日报!$E:$E,合格品入货记录!$A:$A,日报!U$3),"") | V14: =IF(SUMIFS(合格品入货记录!$G:$G,合格品入货记录!$E:$E,日报!$E:$E,合格品入货记录!$A:$A,日报!V$3)<>0,SUMIFS(合格品入货记录!$G:$G,合格品入货记录!$E:$E,日报!$E:$E,合格品入货记录!$A:$A,日报!V$3),"") | W14: =IF(SUMIFS(合格品入货记录!$G:$G,合格品入货记录!$E:$E,日报!$E:$E,合格品入货记录!$A:$A,日报!W$3)<>0,SUMIFS(合格品入货记录!$G:$G,合格品入货记录!$E:$E,日报!$E:$E,合格品入货记录!$A:$A,日报!W$3),"") | X14: =IF(SUMIFS(合格品入货记录!$G:$G,合格品入货记录!$E:$E,日报!$E:$E,合格品入货记录!$A:$A,日报!X$3)<>0,SUMIFS(合格品入货记录!$G:$G,合格品入货记录!$E:$E,日报!$E:$E,合格品入货记录!$A:$A,日报!X$3),"") | Y14: =IF(SUMIFS(合格品入货记录!$G:$G,合格品入货记录!$E:$E,日报!$E:$E,合格品入货记录!$A:$A,日报!Y$3)<>0,SUMIFS(合格品入货记录!$G:$G,合格品入货记录!$E:$E,日报!$E:$E,合格品入货记录!$A:$A,日报!Y$3),"") | Z14: =IF(SUMIFS(合格品入货记录!$G:$G,合格品入货记录!$E:$E,日报!$E:$E,合格品入货记录!$A:$A,日报!Z$3)<>0,SUMIFS(合格品入货记录!$G:$G,合格品入货记录!$E:$E,日报!$E:$E,合格品入货记录!$A:$A,日报!Z$3),"") | AA14: =IF(SUMIFS(合格品入货记录!$G:$G,合格品入货记录!$E:$E,日报!$E:$E,合格品入货记录!$A:$A,日报!AA$3)<>0,SUMIFS(合格品入货记录!$G:$G,合格品入货记录!$E:$E,日报!$E:$E,合格品入货记录!$A:$A,日报!AA$3),"") | ... AU14: =IF(SUMIFS(合格品入货记录!$G:$G,合格品入货记录!$E:$E,日报!$E:$E,合格品入货记录!$A:$A,日报!AU$3)<>0,SUMIFS(合格品入货记录!$G:$G,合格品入货记录!$E:$E,日报!$E:$E,合格品入货记录!$A:$A,日报!AU$3),"") | AY14: =IF(SUMIFS(合格品出库记录!$G:$G,合格品出库记录!$E:$E,日报!$E:$E,合格品出库记录!$A:$A,日报!AY$3)<>0,SUMIFS(合格品出库记录!$G:$G,合格品出库记录!$E:$E,日报!$E:$E,合格品出库记录!$A:$A,日报!AY$3),"") | AZ14: =IF(SUMIFS(合格品出库记录!$G:$G,合格品出库记录!$E:$E,日报!$E:$E,合格品出库记录!$A:$A,日报!AZ$3)<>0,SUMIFS(合格品出库记录!$G:$G,合格品出库记录!$E:$E,日报!$E:$E,合格品出库记录!$A:$A,日报!AZ$3),"") | BA14: =IF(SUMIFS(合格品出库记录!$G:$G,合格品出库记录!$E:$E,日报!$E:$E,合格品出库记录!$A:$A,日报!BA$3)<>0,SUMIFS(合格品出库记录!$G:$G,合格品出库记录!$E:$E,日报!$E:$E,合格品出库记录!$A:$A,日报!BA$3),"") | BB14: =IF(SUMIFS(合格品出库记录!$G:$G,合格品出库记录!$E:$E,日报!$E:$E,合格品出库记录!$A:$A,日报!BB$3)<>0,SUMIFS(合格品出库记录!$G:$G,合格品出库记录!$E:$E,日报!$E:$E,合格品出库记录!$A:$A,日报!BB$3),"") | BC14: =IF(SUMIFS(合格品出库记录!$G:$G,合格品出库记录!$E:$E,日报!$E:$E,合格品出库记录!$A:$A,日报!BC$3)<>0,SUMIFS(合格品出库记录!$G:$G,合格品出库记录!$E:$E,日报!$E:$E,合格品出库记录!$A:$A,日报!BC$3),"") | BD14: =IF(SUMIFS(合格品出库记录!$G:$G,合格品出库记录!$E:$E,日报!$E:$E,合格品出库记录!$A:$A,日报!BD$3)<>0,SUMIFS(合格品出库记录!$G:$G,合格品出库记录!$E:$E,日报!$E:$E,合格品出库记录!$A:$A,日报!BD$3),"") | BE14: =IF(SUMIFS(合格品出库记录!$G:$G,合格品出库记录!$E:$E,日报!$E:$E,合格品出库记录!$A:$A,日报!BE$3)<>0,SUMIFS(合格品出库记录!$G:$G,合格品出库记录!$E:$E,日报!$E:$E,合格品出库记录!$A:$A,日报!BE$3),"") | BF14: =IF(SUMIFS(合格品出库记录!$G:$G,合格品出库记录!$E:$E,日报!$E:$E,合格品出库记录!$A:$A,日报!BF$3)<>0,SUMIFS(合格品出库记录!$G:$G,合格品出库记录!$E:$E,日报!$E:$E,合格品出库记录!$A:$A,日报!BF$3),"") | ... CC14: =IF(SUMIFS(合格品出库记录!$G:$G,合格品出库记录!$E:$E,日报!$E:$E,合格品出库记录!$A:$A,日报!CC$3)<>0,SUMIFS(合格品出库记录!$G:$G,合格品出库记录!$E:$E,日报!$E:$E,合格品出库记录!$A:$A,日报!CC$3),"")
A15: =ROW()-3 -> 12 | B15: =IFERROR(VLOOKUP(基础数据!B14,基础数据!B:B,1,0),"") -> 1AZ | C15: =IFERROR(VLOOKUP(基础数据!C14,基础数据!C:C,1,0),"") -> 芜湖博康机电股份有限公司 | E15: =IFERROR(VLOOKUP(基础数据!E14,基础数据!E:E,1,0),"") -> 3.2.50.30.01625-000 | F15: =IFERROR(VLOOKUP(基础数据!F14,基础数据!F:F,1,0),"") -> LXC11EV1A-快充高压插座线束 | G15: =IFERROR(VLOOKUP(基础数据!G14,基础数据!G:G,1,0),"") -> 48 | H15: =IFERROR(VLOOKUP(基础数据!H14,基础数据!H:H,1,0),"") -> 料盒 | I15: 0 | J15: 0 | K15: =SUMIF(合格品入货记录!E:E,日报!E15,合格品入货记录!G:G) -> 0 | L15: =SUMIF(合格品出库记录!E:E,日报!E15,合格品出库记录!G:G) -> 0 | M15: =SUMIF(零跑退回!D:D,日报!E:E,零跑退回!F:F) -> 0 | N15: =SUMIF(库内不良!D:D,E:E,库内不良!F:F) -> 0 | O15: =SUMIF(退回供应商!D:D,日报!E:E,退回供应商!F:F) -> 0 | P15: =J15+M15+N15-O15 -> 0 | Q15: =I15+K15-L15-N15 -> 0 | T15: =IF(SUMIFS(合格品入货记录!$G:$G,合格品入货记录!$E:$E,日报!$E:$E,合格品入货记录!$A:$A,日报!T$3)<>0,SUMIFS(合格品入货记录!$G:$G,合格品入货记录!$E:$E,日报!$E:$E,合格品入货记录!$A:$A,日报!T$3),"") | U15: =IF(SUMIFS(合格品入货记录!$G:$G,合格品入货记录!$E:$E,日报!$E:$E,合格品入货记录!$A:$A,日报!U$3)<>0,SUMIFS(合格品入货记录!$G:$G,合格品入货记录!$E:$E,日报!$E:$E,合格品入货记录!$A:$A,日报!U$3),"") | V15: =IF(SUMIFS(合格品入货记录!$G:$G,合格品入货记录!$E:$E,日报!$E:$E,合格品入货记录!$A:$A,日报!V$3)<>0,SUMIFS(合格品入货记录!$G:$G,合格品入货记录!$E:$E,日报!$E:$E,合格品入货记录!$A:$A,日报!V$3),"") | W15: =IF(SUMIFS(合格品入货记录!$G:$G,合格品入货记录!$E:$E,日报!$E:$E,合格品入货记录!$A:$A,日报!W$3)<>0,SUMIFS(合格品入货记录!$G:$G,合格品入货记录!$E:$E,日报!$E:$E,合格品入货记录!$A:$A,日报!W$3),"") | X15: =IF(SUMIFS(合格品入货记录!$G:$G,合格品入货记录!$E:$E,日报!$E:$E,合格品入货记录!$A:$A,日报!X$3)<>0,SUMIFS(合格品入货记录!$G:$G,合格品入货记录!$E:$E,日报!$E:$E,合格品入货记录!$A:$A,日报!X$3),"") | Y15: =IF(SUMIFS(合格品入货记录!$G:$G,合格品入货记录!$E:$E,日报!$E:$E,合格品入货记录!$A:$A,日报!Y$3)<>0,SUMIFS(合格品入货记录!$G:$G,合格品入货记录!$E:$E,日报!$E:$E,合格品入货记录!$A:$A,日报!Y$3),"") | Z15: =IF(SUMIFS(合格品入货记录!$G:$G,合格品入货记录!$E:$E,日报!$E:$E,合格品入货记录!$A:$A,日报!Z$3)<>0,SUMIFS(合格品入货记录!$G:$G,合格品入货记录!$E:$E,日报!$E:$E,合格品入货记录!$A:$A,日报!Z$3),"") | AA15: =IF(SUMIFS(合格品入货记录!$G:$G,合格品入货记录!$E:$E,日报!$E:$E,合格品入货记录!$A:$A,日报!AA$3)<>0,SUMIFS(合格品入货记录!$G:$G,合格品入货记录!$E:$E,日报!$E:$E,合格品入货记录!$A:$A,日报!AA$3),"") | ... AU15: =IF(SUMIFS(合格品入货记录!$G:$G,合格品入货记录!$E:$E,日报!$E:$E,合格品入货记录!$A:$A,日报!AU$3)<>0,SUMIFS(合格品入货记录!$G:$G,合格品入货记录!$E:$E,日报!$E:$E,合格品入货记录!$A:$A,日报!AU$3),"") | AY15: =IF(SUMIFS(合格品出库记录!$G:$G,合格品出库记录!$E:$E,日报!$E:$E,合格品出库记录!$A:$A,日报!AY$3)<>0,SUMIFS(合格品出库记录!$G:$G,合格品出库记录!$E:$E,日报!$E:$E,合格品出库记录!$A:$A,日报!AY$3),"") | AZ15: =IF(SUMIFS(合格品出库记录!$G:$G,合格品出库记录!$E:$E,日报!$E:$E,合格品出库记录!$A:$A,日报!AZ$3)<>0,SUMIFS(合格品出库记录!$G:$G,合格品出库记录!$E:$E,日报!$E:$E,合格品出库记录!$A:$A,日报!AZ$3),"") | BA15: =IF(SUMIFS(合格品出库记录!$G:$G,合格品出库记录!$E:$E,日报!$E:$E,合格品出库记录!$A:$A,日报!BA$3)<>0,SUMIFS(合格品出库记录!$G:$G,合格品出库记录!$E:$E,日报!$E:$E,合格品出库记录!$A:$A,日报!BA$3),"") | BB15: =IF(SUMIFS(合格品出库记录!$G:$G,合格品出库记录!$E:$E,日报!$E:$E,合格品出库记录!$A:$A,日报!BB$3)<>0,SUMIFS(合格品出库记录!$G:$G,合格品出库记录!$E:$E,日报!$E:$E,合格品出库记录!$A:$A,日报!BB$3),"") | BC15: =IF(SUMIFS(合格品出库记录!$G:$G,合格品出库记录!$E:$E,日报!$E:$E,合格品出库记录!$A:$A,日报!BC$3)<>0,SUMIFS(合格品出库记录!$G:$G,合格品出库记录!$E:$E,日报!$E:$E,合格品出库记录!$A:$A,日报!BC$3),"") | BD15: =IF(SUMIFS(合格品出库记录!$G:$G,合格品出库记录!$E:$E,日报!$E:$E,合格品出库记录!$A:$A,日报!BD$3)<>0,SUMIFS(合格品出库记录!$G:$G,合格品出库记录!$E:$E,日报!$E:$E,合格品出库记录!$A:$A,日报!BD$3),"") | BE15: =IF(SUMIFS(合格品出库记录!$G:$G,合格品出库记录!$E:$E,日报!$E:$E,合格品出库记录!$A:$A,日报!BE$3)<>0,SUMIFS(合格品出库记录!$G:$G,合格品出库记录!$E:$E,日报!$E:$E,合格品出库记录!$A:$A,日报!BE$3),"") | BF15: =IF(SUMIFS(合格品出库记录!$G:$G,合格品出库记录!$E:$E,日报!$E:$E,合格品出库记录!$A:$A,日报!BF$3)<>0,SUMIFS(合格品出库记录!$G:$G,合格品出库记录!$E:$E,日报!$E:$E,合格品出库记录!$A:$A,日报!BF$3),"") | ... CC15: =IF(SUMIFS(合格品出库记录!$G:$G,合格品出库记录!$E:$E,日报!$E:$E,合格品出库记录!$A:$A,日报!CC$3)<>0,SUMIFS(合格品出库记录!$G:$G,合格品出库记录!$E:$E,日报!$E:$E,合格品出库记录!$A:$A,日报!CC$3),"")
A16: =ROW()-3 -> 13 | B16: =IFERROR(VLOOKUP(基础数据!B15,基础数据!B:B,1,0),"") -> 1AZ | C16: =IFERROR(VLOOKUP(基础数据!C15,基础数据!C:C,1,0),"") -> 芜湖博康机电股份有限公司 | E16: =IFERROR(VLOOKUP(基础数据!E15,基础数据!E:E,1,0),"") -> 3.2.50.30.01626-000 | F16: =IFERROR(VLOOKUP(基础数据!F15,基础数据!F:F,1,0),"") -> LXC11EV1A-电机口高压插座线束 | G16: =IFERROR(VLOOKUP(基础数据!G15,基础数据!G:G,1,0),"") -> 70 | H16: =IFERROR(VLOOKUP(基础数据!H15,基础数据!H:H,1,0),"") -> 料盒 | I16: 0 | J16: 0 | K16: =SUMIF(合格品入货记录!E:E,日报!E16,合格品入货记录!G:G) -> 0 | L16: =SUMIF(合格品出库记录!E:E,日报!E16,合格品出库记录!G:G) -> 0 | M16: =SUMIF(零跑退回!D:D,日报!E:E,零跑退回!F:F) -> 0 | N16: =SUMIF(库内不良!D:D,E:E,库内不良!F:F) -> 0 | O16: =SUMIF(退回供应商!D:D,日报!E:E,退回供应商!F:F) -> 0 | P16: =J16+M16+N16-O16 -> 0 | Q16: =I16+K16-L16-N16 -> 0 | T16: =IF(SUMIFS(合格品入货记录!$G:$G,合格品入货记录!$E:$E,日报!$E:$E,合格品入货记录!$A:$A,日报!T$3)<>0,SUMIFS(合格品入货记录!$G:$G,合格品入货记录!$E:$E,日报!$E:$E,合格品入货记录!$A:$A,日报!T$3),"") | U16: =IF(SUMIFS(合格品入货记录!$G:$G,合格品入货记录!$E:$E,日报!$E:$E,合格品入货记录!$A:$A,日报!U$3)<>0,SUMIFS(合格品入货记录!$G:$G,合格品入货记录!$E:$E,日报!$E:$E,合格品入货记录!$A:$A,日报!U$3),"") | V16: =IF(SUMIFS(合格品入货记录!$G:$G,合格品入货记录!$E:$E,日报!$E:$E,合格品入货记录!$A:$A,日报!V$3)<>0,SUMIFS(合格品入货记录!$G:$G,合格品入货记录!$E:$E,日报!$E:$E,合格品入货记录!$A:$A,日报!V$3),"") | W16: =IF(SUMIFS(合格品入货记录!$G:$G,合格品入货记录!$E:$E,日报!$E:$E,合格品入货记录!$A:$A,日报!W$3)<>0,SUMIFS(合格品入货记录!$G:$G,合格品入货记录!$E:$E,日报!$E:$E,合格品入货记录!$A:$A,日报!W$3),"") | X16: =IF(SUMIFS(合格品入货记录!$G:$G,合格品入货记录!$E:$E,日报!$E:$E,合格品入货记录!$A:$A,日报!X$3)<>0,SUMIFS(合格品入货记录!$G:$G,合格品入货记录!$E:$E,日报!$E:$E,合格品入货记录!$A:$A,日报!X$3),"") | Y16: =IF(SUMIFS(合格品入货记录!$G:$G,合格品入货记录!$E:$E,日报!$E:$E,合格品入货记录!$A:$A,日报!Y$3)<>0,SUMIFS(合格品入货记录!$G:$G,合格品入货记录!$E:$E,日报!$E:$E,合格品入货记录!$A:$A,日报!Y$3),"") | Z16: =IF(SUMIFS(合格品入货记录!$G:$G,合格品入货记录!$E:$E,日报!$E:$E,合格品入货记录!$A:$A,日报!Z$3)<>0,SUMIFS(合格品入货记录!$G:$G,合格品入货记录!$E:$E,日报!$E:$E,合格品入货记录!$A:$A,日报!Z$3),"") | AA16: =IF(SUMIFS(合格品入货记录!$G:$G,合格品入货记录!$E:$E,日报!$E:$E,合格品入货记录!$A:$A,日报!AA$3)<>0,SUMIFS(合格品入货记录!$G:$G,合格品入货记录!$E:$E,日报!$E:$E,合格品入货记录!$A:$A,日报!AA$3),"") | ... AU16: =IF(SUMIFS(合格品入货记录!$G:$G,合格品入货记录!$E:$E,日报!$E:$E,合格品入货记录!$A:$A,日报!AU$3)<>0,SUMIFS(合格品入货记录!$G:$G,合格品入货记录!$E:$E,日报!$E:$E,合格品入货记录!$A:$A,日报!AU$3),"") | AY16: =IF(SUMIFS(合格品出库记录!$G:$G,合格品出库记录!$E:$E,日报!$E:$E,合格品出库记录!$A:$A,日报!AY$3)<>0,SUMIFS(合格品出库记录!$G:$G,合格品出库记录!$E:$E,日报!$E:$E,合格品出库记录!$A:$A,日报!AY$3),"") | AZ16: =IF(SUMIFS(合格品出库记录!$G:$G,合格品出库记录!$E:$E,日报!$E:$E,合格品出库记录!$A:$A,日报!AZ$3)<>0,SUMIFS(合格品出库记录!$G:$G,合格品出库记录!$E:$E,日报!$E:$E,合格品出库记录!$A:$A,日报!AZ$3),"") | BA16: =IF(SUMIFS(合格品出库记录!$G:$G,合格品出库记录!$E:$E,日报!$E:$E,合格品出库记录!$A:$A,日报!BA$3)<>0,SUMIFS(合格品出库记录!$G:$G,合格品出库记录!$E:$E,日报!$E:$E,合格品出库记录!$A:$A,日报!BA$3),"") | BB16: =IF(SUMIFS(合格品出库记录!$G:$G,合格品出库记录!$E:$E,日报!$E:$E,合格品出库记录!$A:$A,日报!BB$3)<>0,SUMIFS(合格品出库记录!$G:$G,合格品出库记录!$E:$E,日报!$E:$E,合格品出库记录!$A:$A,日报!BB$3),"") | BC16: =IF(SUMIFS(合格品出库记录!$G:$G,合格品出库记录!$E:$E,日报!$E:$E,合格品出库记录!$A:$A,日报!BC$3)<>0,SUMIFS(合格品出库记录!$G:$G,合格品出库记录!$E:$E,日报!$E:$E,合格品出库记录!$A:$A,日报!BC$3),"") | BD16: =IF(SUMIFS(合格品出库记录!$G:$G,合格品出库记录!$E:$E,日报!$E:$E,合格品出库记录!$A:$A,日报!BD$3)<>0,SUMIFS(合格品出库记录!$G:$G,合格品出库记录!$E:$E,日报!$E:$E,合格品出库记录!$A:$A,日报!BD$3),"") | BE16: =IF(SUMIFS(合格品出库记录!$G:$G,合格品出库记录!$E:$E,日报!$E:$E,合格品出库记录!$A:$A,日报!BE$3)<>0,SUMIFS(合格品出库记录!$G:$G,合格品出库记录!$E:$E,日报!$E:$E,合格品出库记录!$A:$A,日报!BE$3),"") | BF16: =IF(SUMIFS(合格品出库记录!$G:$G,合格品出库记录!$E:$E,日报!$E:$E,合格品出库记录!$A:$A,日报!BF$3)<>0,SUMIFS(合格品出库记录!$G:$G,合格品出库记录!$E:$E,日报!$E:$E,合格品出库记录!$A:$A,日报!BF$3),"") | ... CC16: =IF(SUMIFS(合格品出库记录!$G:$G,合格品出库记录!$E:$E,日报!$E:$E,合格品出库记录!$A:$A,日报!CC$3)<>0,SUMIFS(合格品出库记录!$G:$G,合格品出库记录!$E:$E,日报!$E:$E,合格品出库记录!$A:$A,日报!CC$3),"")
A17: =ROW()-3 -> 14 | B17: =IFERROR(VLOOKUP(基础数据!B16,基础数据!B:B,1,0),"") -> 1AZ | C17: =IFERROR(VLOOKUP(基础数据!C16,基础数据!C:C,1,0),"") -> 芜湖博康机电股份有限公司 | E17: =IFERROR(VLOOKUP(基础数据!E16,基础数据!E:E,1,0),"") -> 3.1.02.30.00776 | F17: LX00148-CCS总成 | G17: =IFERROR(VLOOKUP(基础数据!G16,基础数据!G:G,1,0),"") -> 12 | H17: =IFERROR(VLOOKUP(基础数据!H16,基础数据!H:H,1,0),"") -> 纸箱 | I17: 3996 | J17: 0 | K17: =SUMIF(合格品入货记录!E:E,日报!E17,合格品入货记录!G:G) -> 8100 | L17: =SUMIF(合格品出库记录!E:E,日报!E17,合格品出库记录!G:G) -> 9996 | M17: =SUMIF(零跑退回!D:D,日报!E:E,零跑退回!F:F) -> 0 | N17: =SUMIF(库内不良!D:D,E:E,库内不良!F:F) -> 0 | O17: =SUMIF(退回供应商!D:D,日报!E:E,退回供应商!F:F) -> 0 | P17: =J17+M17+N17-O17 -> 0 | Q17: =I17+K17-L17-N17 -> 2100 | T17: =IF(SUMIFS(合格品入货记录!$G:$G,合格品入货记录!$E:$E,日报!$E:$E,合格品入货记录!$A:$A,日报!T$3)<>0,SUMIFS(合格品入货记录!$G:$G,合格品入货记录!$E:$E,日报!$E:$E,合格品入货记录!$A:$A,日报!T$3),"") | U17: =IF(SUMIFS(合格品入货记录!$G:$G,合格品入货记录!$E:$E,日报!$E:$E,合格品入货记录!$A:$A,日报!U$3)<>0,SUMIFS(合格品入货记录!$G:$G,合格品入货记录!$E:$E,日报!$E:$E,合格品入货记录!$A:$A,日报!U$3),"") -> 900 | V17: =IF(SUMIFS(合格品入货记录!$G:$G,合格品入货记录!$E:$E,日报!$E:$E,合格品入货记录!$A:$A,日报!V$3)<>0,SUMIFS(合格品入货记录!$G:$G,合格品入货记录!$E:$E,日报!$E:$E,合格品入货记录!$A:$A,日报!V$3),"") | W17: =IF(SUMIFS(合格品入货记录!$G:$G,合格品入货记录!$E:$E,日报!$E:$E,合格品入货记录!$A:$A,日报!W$3)<>0,SUMIFS(合格品入货记录!$G:$G,合格品入货记录!$E:$E,日报!$E:$E,合格品入货记录!$A:$A,日报!W$3),"") | X17: =IF(SUMIFS(合格品入货记录!$G:$G,合格品入货记录!$E:$E,日报!$E:$E,合格品入货记录!$A:$A,日报!X$3)<>0,SUMIFS(合格品入货记录!$G:$G,合格品入货记录!$E:$E,日报!$E:$E,合格品入货记录!$A:$A,日报!X$3),"") -> 600 | Y17: =IF(SUMIFS(合格品入货记录!$G:$G,合格品入货记录!$E:$E,日报!$E:$E,合格品入货记录!$A:$A,日报!Y$3)<>0,SUMIFS(合格品入货记录!$G:$G,合格品入货记录!$E:$E,日报!$E:$E,合格品入货记录!$A:$A,日报!Y$3),"") -> 600 | Z17: =IF(SUMIFS(合格品入货记录!$G:$G,合格品入货记录!$E:$E,日报!$E:$E,合格品入货记录!$A:$A,日报!Z$3)<>0,SUMIFS(合格品入货记录!$G:$G,合格品入货记录!$E:$E,日报!$E:$E,合格品入货记录!$A:$A,日报!Z$3),"") | AA17: =IF(SUMIFS(合格品入货记录!$G:$G,合格品入货记录!$E:$E,日报!$E:$E,合格品入货记录!$A:$A,日报!AA$3)<>0,SUMIFS(合格品入货记录!$G:$G,合格品入货记录!$E:$E,日报!$E:$E,合格品入货记录!$A:$A,日报!AA$3),"") -> 3000 | ... AU17: =IF(SUMIFS(合格品入货记录!$G:$G,合格品入货记录!$E:$E,日报!$E:$E,合格品入货记录!$A:$A,日报!AU$3)<>0,SUMIFS(合格品入货记录!$G:$G,合格品入货记录!$E:$E,日报!$E:$E,合格品入货记录!$A:$A,日报!AU$3),"") | AY17: =IF(SUMIFS(合格品出库记录!$G:$G,合格品出库记录!$E:$E,日报!$E:$E,合格品出库记录!$A:$A,日报!AY$3)<>0,SUMIFS(合格品出库记录!$G:$G,合格品出库记录!$E:$E,日报!$E:$E,合格品出库记录!$A:$A,日报!AY$3),"") | AZ17: =IF(SUMIFS(合格品出库记录!$G:$G,合格品出库记录!$E:$E,日报!$E:$E,合格品出库记录!$A:$A,日报!AZ$3)<>0,SUMIFS(合格品出库记录!$G:$G,合格品出库记录!$E:$E,日报!$E:$E,合格品出库记录!$A:$A,日报!AZ$3),"") | BA17: =IF(SUMIFS(合格品出库记录!$G:$G,合格品出库记录!$E:$E,日报!$E:$E,合格品出库记录!$A:$A,日报!BA$3)<>0,SUMIFS(合格品出库记录!$G:$G,合格品出库记录!$E:$E,日报!$E:$E,合格品出库记录!$A:$A,日报!BA$3),"") | BB17: =IF(SUMIFS(合格品出库记录!$G:$G,合格品出库记录!$E:$E,日报!$E:$E,合格品出库记录!$A:$A,日报!BB$3)<>0,SUMIFS(合格品出库记录!$G:$G,合格品出库记录!$E:$E,日报!$E:$E,合格品出库记录!$A:$A,日报!BB$3),"") -> 2076 | BC17: =IF(SUMIFS(合格品出库记录!$G:$G,合格品出库记录!$E:$E,日报!$E:$E,合格品出库记录!$A:$A,日报!BC$3)<>0,SUMIFS(合格品出库记录!$G:$G,合格品出库记录!$E:$E,日报!$E:$E,合格品出库记录!$A:$A,日报!BC$3),"") -> 1200 | BD17: =IF(SUMIFS(合格品出库记录!$G:$G,合格品出库记录!$E:$E,日报!$E:$E,合格品出库记录!$A:$A,日报!BD$3)<>0,SUMIFS(合格品出库记录!$G:$G,合格品出库记录!$E:$E,日报!$E:$E,合格品出库记录!$A:$A,日报!BD$3),"") | BE17: =IF(SUMIFS(合格品出库记录!$G:$G,合格品出库记录!$E:$E,日报!$E:$E,合格品出库记录!$A:$A,日报!BE$3)<>0,SUMIFS(合格品出库记录!$G:$G,合格品出库记录!$E:$E,日报!$E:$E,合格品出库记录!$A:$A,日报!BE$3),"") -> 2040 | BF17: =IF(SUMIFS(合格品出库记录!$G:$G,合格品出库记录!$E:$E,日报!$E:$E,合格品出库记录!$A:$A,日报!BF$3)<>0,SUMIFS(合格品出库记录!$G:$G,合格品出库记录!$E:$E,日报!$E:$E,合格品出库记录!$A:$A,日报!BF$3),"") -> 2040 | ... CC17: =IF(SUMIFS(合格品出库记录!$G:$G,合格品出库记录!$E:$E,日报!$E:$E,合格品出库记录!$A:$A,日报!CC$3)<>0,SUMIFS(合格品出库记录!$G:$G,合格品出库记录!$E:$E,日报!$E:$E,合格品出库记录!$A:$A,日报!CC$3),"")
A18: =ROW()-3 -> 15 | B18: =IFERROR(VLOOKUP(基础数据!B17,基础数据!B:B,1,0),"") -> 1AZ | C18: =IFERROR(VLOOKUP(基础数据!C17,基础数据!C:C,1,0),"") -> 芜湖博康机电股份有限公司 | E18: =IFERROR(VLOOKUP(基础数据!E17,基础数据!E:E,1,0),"") -> 3.2.50.30.01786-000 | F18: =IFERROR(VLOOKUP(基础数据!F17,基础数据!F:F,1,0),"") -> A03HW67.1-通讯集成线束 | G18: =IFERROR(VLOOKUP(基础数据!G17,基础数据!G:G,1,0),"") -> 100 | H18: =IFERROR(VLOOKUP(基础数据!H17,基础数据!H:H,1,0),"") -> 料盒 | I18: 100 | J18: 0 | K18: =SUMIF(合格品入货记录!E:E,日报!E18,合格品入货记录!G:G) -> 400 | L18: =SUMIF(合格品出库记录!E:E,日报!E18,合格品出库记录!G:G) -> 500 | M18: =SUMIF(零跑退回!D:D,日报!E:E,零跑退回!F:F) -> 0 | N18: =SUMIF(库内不良!D:D,E:E,库内不良!F:F) -> 0 | O18: =SUMIF(退回供应商!D:D,日报!E:E,退回供应商!F:F) -> 0 | P18: =J18+M18+N18-O18 -> 0 | Q18: =I18+K18-L18-N18 -> 0 | T18: =IF(SUMIFS(合格品入货记录!$G:$G,合格品入货记录!$E:$E,日报!$E:$E,合格品入货记录!$A:$A,日报!T$3)<>0,SUMIFS(合格品入货记录!$G:$G,合格品入货记录!$E:$E,日报!$E:$E,合格品入货记录!$A:$A,日报!T$3),"") | U18: =IF(SUMIFS(合格品入货记录!$G:$G,合格品入货记录!$E:$E,日报!$E:$E,合格品入货记录!$A:$A,日报!U$3)<>0,SUMIFS(合格品入货记录!$G:$G,合格品入货记录!$E:$E,日报!$E:$E,合格品入货记录!$A:$A,日报!U$3),"") | V18: =IF(SUMIFS(合格品入货记录!$G:$G,合格品入货记录!$E:$E,日报!$E:$E,合格品入货记录!$A:$A,日报!V$3)<>0,SUMIFS(合格品入货记录!$G:$G,合格品入货记录!$E:$E,日报!$E:$E,合格品入货记录!$A:$A,日报!V$3),"") | W18: =IF(SUMIFS(合格品入货记录!$G:$G,合格品入货记录!$E:$E,日报!$E:$E,合格品入货记录!$A:$A,日报!W$3)<>0,SUMIFS(合格品入货记录!$G:$G,合格品入货记录!$E:$E,日报!$E:$E,合格品入货记录!$A:$A,日报!W$3),"") | X18: =IF(SUMIFS(合格品入货记录!$G:$G,合格品入货记录!$E:$E,日报!$E:$E,合格品入货记录!$A:$A,日报!X$3)<>0,SUMIFS(合格品入货记录!$G:$G,合格品入货记录!$E:$E,日报!$E:$E,合格品入货记录!$A:$A,日报!X$3),"") | Y18: =IF(SUMIFS(合格品入货记录!$G:$G,合格品入货记录!$E:$E,日报!$E:$E,合格品入货记录!$A:$A,日报!Y$3)<>0,SUMIFS(合格品入货记录!$G:$G,合格品入货记录!$E:$E,日报!$E:$E,合格品入货记录!$A:$A,日报!Y$3),"") -> 400 | Z18: =IF(SUMIFS(合格品入货记录!$G:$G,合格品入货记录!$E:$E,日报!$E:$E,合格品入货记录!$A:$A,日报!Z$3)<>0,SUMIFS(合格品入货记录!$G:$G,合格品入货记录!$E:$E,日报!$E:$E,合格品入货记录!$A:$A,日报!Z$3),"") | AA18: =IF(SUMIFS(合格品入货记录!$G:$G,合格品入货记录!$E:$E,日报!$E:$E,合格品入货记录!$A:$A,日报!AA$3)<>0,SUMIFS(合格品入货记录!$G:$G,合格品入货记录!$E:$E,日报!$E:$E,合格品入货记录!$A:$A,日报!AA$3),"") | ... AU18: =IF(SUMIFS(合格品入货记录!$G:$G,合格品入货记录!$E:$E,日报!$E:$E,合格品入货记录!$A:$A,日报!AU$3)<>0,SUMIFS(合格品入货记录!$G:$G,合格品入货记录!$E:$E,日报!$E:$E,合格品入货记录!$A:$A,日报!AU$3),"") | AY18: =IF(SUMIFS(合格品出库记录!$G:$G,合格品出库记录!$E:$E,日报!$E:$E,合格品出库记录!$A:$A,日报!AY$3)<>0,SUMIFS(合格品出库记录!$G:$G,合格品出库记录!$E:$E,日报!$E:$E,合格品出库记录!$A:$A,日报!AY$3),"") | AZ18: =IF(SUMIFS(合格品出库记录!$G:$G,合格品出库记录!$E:$E,日报!$E:$E,合格品出库记录!$A:$A,日报!AZ$3)<>0,SUMIFS(合格品出库记录!$G:$G,合格品出库记录!$E:$E,日报!$E:$E,合格品出库记录!$A:$A,日报!AZ$3),"") | BA18: =IF(SUMIFS(合格品出库记录!$G:$G,合格品出库记录!$E:$E,日报!$E:$E,合格品出库记录!$A:$A,日报!BA$3)<>0,SUMIFS(合格品出库记录!$G:$G,合格品出库记录!$E:$E,日报!$E:$E,合格品出库记录!$A:$A,日报!BA$3),"") | BB18: =IF(SUMIFS(合格品出库记录!$G:$G,合格品出库记录!$E:$E,日报!$E:$E,合格品出库记录!$A:$A,日报!BB$3)<>0,SUMIFS(合格品出库记录!$G:$G,合格品出库记录!$E:$E,日报!$E:$E,合格品出库记录!$A:$A,日报!BB$3),"") | BC18: =IF(SUMIFS(合格品出库记录!$G:$G,合格品出库记录!$E:$E,日报!$E:$E,合格品出库记录!$A:$A,日报!BC$3)<>0,SUMIFS(合格品出库记录!$G:$G,合格品出库记录!$E:$E,日报!$E:$E,合格品出库记录!$A:$A,日报!BC$3),"") | BD18: =IF(SUMIFS(合格品出库记录!$G:$G,合格品出库记录!$E:$E,日报!$E:$E,合格品出库记录!$A:$A,日报!BD$3)<>0,SUMIFS(合格品出库记录!$G:$G,合格品出库记录!$E:$E,日报!$E:$E,合格品出库记录!$A:$A,日报!BD$3),"") -> 400 | BE18: =IF(SUMIFS(合格品出库记录!$G:$G,合格品出库记录!$E:$E,日报!$E:$E,合格品出库记录!$A:$A,日报!BE$3)<>0,SUMIFS(合格品出库记录!$G:$G,合格品出库记录!$E:$E,日报!$E:$E,合格品出库记录!$A:$A,日报!BE$3),"") | BF18: =IF(SUMIFS(合格品出库记录!$G:$G,合格品出库记录!$E:$E,日报!$E:$E,合格品出库记录!$A:$A,日报!BF$3)<>0,SUMIFS(合格品出库记录!$G:$G,合格品出库记录!$E:$E,日报!$E:$E,合格品出库记录!$A:$A,日报!BF$3),"") -> 100 | ... CC18: =IF(SUMIFS(合格品出库记录!$G:$G,合格品出库记录!$E:$E,日报!$E:$E,合格品出库记录!$A:$A,日报!CC$3)<>0,SUMIFS(合格品出库记录!$G:$G,合格品出库记录!$E:$E,日报!$E:$E,合格品出库记录!$A:$A,日报!CC$3),"")
A19: =ROW()-3 -> 16 | B19: =IFERROR(VLOOKUP(基础数据!B18,基础数据!B:B,1,0),"") -> 1AZ | C19: =IFERROR(VLOOKUP(基础数据!C18,基础数据!C:C,1,0),"") -> 芜湖博康机电股份有限公司 | E19: =IFERROR(VLOOKUP(基础数据!E18,基础数据!E:E,1,0),"") -> 3.2.50.30.01787-000 | F19: =IFERROR(VLOOKUP(基础数据!F18,基础数据!F:F,1,0),"") -> A03HW67.1-采样集成线束 | G19: =IFERROR(VLOOKUP(基础数据!G18,基础数据!G:G,1,0),"") -> 40 | H19: =IFERROR(VLOOKUP(基础数据!H18,基础数据!H:H,1,0),"") -> 料盒 | I19: 40 | J19: 0 | K19: =SUMIF(合格品入货记录!E:E,日报!E19,合格品入货记录!G:G) -> 400 | L19: =SUMIF(合格品出库记录!E:E,日报!E19,合格品出库记录!G:G) -> 440 | M19: =SUMIF(零跑退回!D:D,日报!E:E,零跑退回!F:F) -> 0 | N19: =SUMIF(库内不良!D:D,E:E,库内不良!F:F) -> 0 | O19: =SUMIF(退回供应商!D:D,日报!E:E,退回供应商!F:F) -> 0 | P19: =J19+M19+N19-O19 -> 0 | Q19: =I19+K19-L19-N19 -> 0 | T19: =IF(SUMIFS(合格品入货记录!$G:$G,合格品入货记录!$E:$E,日报!$E:$E,合格品入货记录!$A:$A,日报!T$3)<>0,SUMIFS(合格品入货记录!$G:$G,合格品入货记录!$E:$E,日报!$E:$E,合格品入货记录!$A:$A,日报!T$3),"") | U19: =IF(SUMIFS(合格品入货记录!$G:$G,合格品入货记录!$E:$E,日报!$E:$E,合格品入货记录!$A:$A,日报!U$3)<>0,SUMIFS(合格品入货记录!$G:$G,合格品入货记录!$E:$E,日报!$E:$E,合格品入货记录!$A:$A,日报!U$3),"") | V19: =IF(SUMIFS(合格品入货记录!$G:$G,合格品入货记录!$E:$E,日报!$E:$E,合格品入货记录!$A:$A,日报!V$3)<>0,SUMIFS(合格品入货记录!$G:$G,合格品入货记录!$E:$E,日报!$E:$E,合格品入货记录!$A:$A,日报!V$3),"") | W19: =IF(SUMIFS(合格品入货记录!$G:$G,合格品入货记录!$E:$E,日报!$E:$E,合格品入货记录!$A:$A,日报!W$3)<>0,SUMIFS(合格品入货记录!$G:$G,合格品入货记录!$E:$E,日报!$E:$E,合格品入货记录!$A:$A,日报!W$3),"") | X19: =IF(SUMIFS(合格品入货记录!$G:$G,合格品入货记录!$E:$E,日报!$E:$E,合格品入货记录!$A:$A,日报!X$3)<>0,SUMIFS(合格品入货记录!$G:$G,合格品入货记录!$E:$E,日报!$E:$E,合格品入货记录!$A:$A,日报!X$3),"") | Y19: =IF(SUMIFS(合格品入货记录!$G:$G,合格品入货记录!$E:$E,日报!$E:$E,合格品入货记录!$A:$A,日报!Y$3)<>0,SUMIFS(合格品入货记录!$G:$G,合格品入货记录!$E:$E,日报!$E:$E,合格品入货记录!$A:$A,日报!Y$3),"") -> 400 | Z19: =IF(SUMIFS(合格品入货记录!$G:$G,合格品入货记录!$E:$E,日报!$E:$E,合格品入货记录!$A:$A,日报!Z$3)<>0,SUMIFS(合格品入货记录!$G:$G,合格品入货记录!$E:$E,日报!$E:$E,合格品入货记录!$A:$A,日报!Z$3),"") | AA19: =IF(SUMIFS(合格品入货记录!$G:$G,合格品入货记录!$E:$E,日报!$E:$E,合格品入货记录!$A:$A,日报!AA$3)<>0,SUMIFS(合格品入货记录!$G:$G,合格品入货记录!$E:$E,日报!$E:$E,合格品入货记录!$A:$A,日报!AA$3),"") | ... AU19: =IF(SUMIFS(合格品入货记录!$G:$G,合格品入货记录!$E:$E,日报!$E:$E,合格品入货记录!$A:$A,日报!AU$3)<>0,SUMIFS(合格品入货记录!$G:$G,合格品入货记录!$E:$E,日报!$E:$E,合格品入货记录!$A:$A,日报!AU$3),"") | AY19: =IF(SUMIFS(合格品出库记录!$G:$G,合格品出库记录!$E:$E,日报!$E:$E,合格品出库记录!$A:$A,日报!AY$3)<>0,SUMIFS(合格品出库记录!$G:$G,合格品出库记录!$E:$E,日报!$E:$E,合格品出库记录!$A:$A,日报!AY$3),"") | AZ19: =IF(SUMIFS(合格品出库记录!$G:$G,合格品出库记录!$E:$E,日报!$E:$E,合格品出库记录!$A:$A,日报!AZ$3)<>0,SUMIFS(合格品出库记录!$G:$G,合格品出库记录!$E:$E,日报!$E:$E,合格品出库记录!$A:$A,日报!AZ$3),"") | BA19: =IF(SUMIFS(合格品出库记录!$G:$G,合格品出库记录!$E:$E,日报!$E:$E,合格品出库记录!$A:$A,日报!BA$3)<>0,SUMIFS(合格品出库记录!$G:$G,合格品出库记录!$E:$E,日报!$E:$E,合格品出库记录!$A:$A,日报!BA$3),"") | BB19: =IF(SUMIFS(合格品出库记录!$G:$G,合格品出库记录!$E:$E,日报!$E:$E,合格品出库记录!$A:$A,日报!BB$3)<>0,SUMIFS(合格品出库记录!$G:$G,合格品出库记录!$E:$E,日报!$E:$E,合格品出库记录!$A:$A,日报!BB$3),"") | BC19: =IF(SUMIFS(合格品出库记录!$G:$G,合格品出库记录!$E:$E,日报!$E:$E,合格品出库记录!$A:$A,日报!BC$3)<>0,SUMIFS(合格品出库记录!$G:$G,合格品出库记录!$E:$E,日报!$E:$E,合格品出库记录!$A:$A,日报!BC$3),"") | BD19: =IF(SUMIFS(合格品出库记录!$G:$G,合格品出库记录!$E:$E,日报!$E:$E,合格品出库记录!$A:$A,日报!BD$3)<>0,SUMIFS(合格品出库记录!$G:$G,合格品出库记录!$E:$E,日报!$E:$E,合格品出库记录!$A:$A,日报!BD$3),"") -> 400 | BE19: =IF(SUMIFS(合格品出库记录!$G:$G,合格品出库记录!$E:$E,日报!$E:$E,合格品出库记录!$A:$A,日报!BE$3)<>0,SUMIFS(合格品出库记录!$G:$G,合格品出库记录!$E:$E,日报!$E:$E,合格品出库记录!$A:$A,日报!BE$3),"") | BF19: =IF(SUMIFS(合格品出库记录!$G:$G,合格品出库记录!$E:$E,日报!$E:$E,合格品出库记录!$A:$A,日报!BF$3)<>0,SUMIFS(合格品出库记录!$G:$G,合格品出库记录!$E:$E,日报!$E:$E,合格品出库记录!$A:$A,日报!BF$3),"") -> 40 | ... CC19: =IF(SUMIFS(合格品出库记录!$G:$G,合格品出库记录!$E:$E,日报!$E:$E,合格品出库记录!$A:$A,日报!CC$3)<>0,SUMIFS(合格品出库记录!$G:$G,合格品出库记录!$E:$E,日报!$E:$E,合格品出库记录!$A:$A,日报!CC$3),"")
A20: =ROW()-3 -> 17 | B20: =IFERROR(VLOOKUP(基础数据!B19,基础数据!B:B,1,0),"") -> 1AZ | C20: =IFERROR(VLOOKUP(基础数据!C19,基础数据!C:C,1,0),"") -> 芜湖博康机电股份有限公司 | E20: =IFERROR(VLOOKUP(基础数据!E19,基础数据!E:E,1,0),"") -> 3.2.50.30.01784-000 | F20: =IFERROR(VLOOKUP(基础数据!F19,基础数据!F:F,1,0),"") -> A03HW56.2-通讯集成线束 | G20: =IFERROR(VLOOKUP(基础数据!G19,基础数据!G:G,1,0),"") -> 100 | H20: =IFERROR(VLOOKUP(基础数据!H19,基础数据!H:H,1,0),"") -> 料盒 | I20: 100 | J20: 0 | K20: =SUMIF(合格品入货记录!E:E,日报!E20,合格品入货记录!G:G) -> 0 | L20: =SUMIF(合格品出库记录!E:E,日报!E20,合格品出库记录!G:G) -> 0 | M20: =SUMIF(零跑退回!D:D,日报!E:E,零跑退回!F:F) -> 0 | N20: =SUMIF(库内不良!D:D,E:E,库内不良!F:F) -> 0 | O20: =SUMIF(退回供应商!D:D,日报!E:E,退回供应商!F:F) -> 0 | P20: =J20+M20+N20-O20 -> 0 | Q20: =I20+K20-L20-N20 -> 100 | T20: =IF(SUMIFS(合格品入货记录!$G:$G,合格品入货记录!$E:$E,日报!$E:$E,合格品入货记录!$A:$A,日报!T$3)<>0,SUMIFS(合格品入货记录!$G:$G,合格品入货记录!$E:$E,日报!$E:$E,合格品入货记录!$A:$A,日报!T$3),"") | U20: =IF(SUMIFS(合格品入货记录!$G:$G,合格品入货记录!$E:$E,日报!$E:$E,合格品入货记录!$A:$A,日报!U$3)<>0,SUMIFS(合格品入货记录!$G:$G,合格品入货记录!$E:$E,日报!$E:$E,合格品入货记录!$A:$A,日报!U$3),"") | V20: =IF(SUMIFS(合格品入货记录!$G:$G,合格品入货记录!$E:$E,日报!$E:$E,合格品入货记录!$A:$A,日报!V$3)<>0,SUMIFS(合格品入货记录!$G:$G,合格品入货记录!$E:$E,日报!$E:$E,合格品入货记录!$A:$A,日报!V$3),"") | W20: =IF(SUMIFS(合格品入货记录!$G:$G,合格品入货记录!$E:$E,日报!$E:$E,合格品入货记录!$A:$A,日报!W$3)<>0,SUMIFS(合格品入货记录!$G:$G,合格品入货记录!$E:$E,日报!$E:$E,合格品入货记录!$A:$A,日报!W$3),"") | X20: =IF(SUMIFS(合格品入货记录!$G:$G,合格品入货记录!$E:$E,日报!$E:$E,合格品入货记录!$A:$A,日报!X$3)<>0,SUMIFS(合格品入货记录!$G:$G,合格品入货记录!$E:$E,日报!$E:$E,合格品入货记录!$A:$A,日报!X$3),"") | Y20: =IF(SUMIFS(合格品入货记录!$G:$G,合格品入货记录!$E:$E,日报!$E:$E,合格品入货记录!$A:$A,日报!Y$3)<>0,SUMIFS(合格品入货记录!$G:$G,合格品入货记录!$E:$E,日报!$E:$E,合格品入货记录!$A:$A,日报!Y$3),"") | Z20: =IF(SUMIFS(合格品入货记录!$G:$G,合格品入货记录!$E:$E,日报!$E:$E,合格品入货记录!$A:$A,日报!Z$3)<>0,SUMIFS(合格品入货记录!$G:$G,合格品入货记录!$E:$E,日报!$E:$E,合格品入货记录!$A:$A,日报!Z$3),"") | AA20: =IF(SUMIFS(合格品入货记录!$G:$G,合格品入货记录!$E:$E,日报!$E:$E,合格品入货记录!$A:$A,日报!AA$3)<>0,SUMIFS(合格品入货记录!$G:$G,合格品入货记录!$E:$E,日报!$E:$E,合格品入货记录!$A:$A,日报!AA$3),"") | ... AU20: =IF(SUMIFS(合格品入货记录!$G:$G,合格品入货记录!$E:$E,日报!$E:$E,合格品入货记录!$A:$A,日报!AU$3)<>0,SUMIFS(合格品入货记录!$G:$G,合格品入货记录!$E:$E,日报!$E:$E,合格品入货记录!$A:$A,日报!AU$3),"") | AY20: =IF(SUMIFS(合格品出库记录!$G:$G,合格品出库记录!$E:$E,日报!$E:$E,合格品出库记录!$A:$A,日报!AY$3)<>0,SUMIFS(合格品出库记录!$G:$G,合格品出库记录!$E:$E,日报!$E:$E,合格品出库记录!$A:$A,日报!AY$3),"") | AZ20: =IF(SUMIFS(合格品出库记录!$G:$G,合格品出库记录!$E:$E,日报!$E:$E,合格品出库记录!$A:$A,日报!AZ$3)<>0,SUMIFS(合格品出库记录!$G:$G,合格品出库记录!$E:$E,日报!$E:$E,合格品出库记录!$A:$A,日报!AZ$3),"") | BA20: =IF(SUMIFS(合格品出库记录!$G:$G,合格品出库记录!$E:$E,日报!$E:$E,合格品出库记录!$A:$A,日报!BA$3)<>0,SUMIFS(合格品出库记录!$G:$G,合格品出库记录!$E:$E,日报!$E:$E,合格品出库记录!$A:$A,日报!BA$3),"") | BB20: =IF(SUMIFS(合格品出库记录!$G:$G,合格品出库记录!$E:$E,日报!$E:$E,合格品出库记录!$A:$A,日报!BB$3)<>0,SUMIFS(合格品出库记录!$G:$G,合格品出库记录!$E:$E,日报!$E:$E,合格品出库记录!$A:$A,日报!BB$3),"") | BC20: =IF(SUMIFS(合格品出库记录!$G:$G,合格品出库记录!$E:$E,日报!$E:$E,合格品出库记录!$A:$A,日报!BC$3)<>0,SUMIFS(合格品出库记录!$G:$G,合格品出库记录!$E:$E,日报!$E:$E,合格品出库记录!$A:$A,日报!BC$3),"") | BD20: =IF(SUMIFS(合格品出库记录!$G:$G,合格品出库记录!$E:$E,日报!$E:$E,合格品出库记录!$A:$A,日报!BD$3)<>0,SUMIFS(合格品出库记录!$G:$G,合格品出库记录!$E:$E,日报!$E:$E,合格品出库记录!$A:$A,日报!BD$3),"") | BE20: =IF(SUMIFS(合格品出库记录!$G:$G,合格品出库记录!$E:$E,日报!$E:$E,合格品出库记录!$A:$A,日报!BE$3)<>0,SUMIFS(合格品出库记录!$G:$G,合格品出库记录!$E:$E,日报!$E:$E,合格品出库记录!$A:$A,日报!BE$3),"") | BF20: =IF(SUMIFS(合格品出库记录!$G:$G,合格品出库记录!$E:$E,日报!$E:$E,合格品出库记录!$A:$A,日报!BF$3)<>0,SUMIFS(合格品出库记录!$G:$G,合格品出库记录!$E:$E,日报!$E:$E,合格品出库记录!$A:$A,日报!BF$3),"") | ... CC20: =IF(SUMIFS(合格品出库记录!$G:$G,合格品出库记录!$E:$E,日报!$E:$E,合格品出库记录!$A:$A,日报!CC$3)<>0,SUMIFS(合格品出库记录!$G:$G,合格品出库记录!$E:$E,日报!$E:$E,合格品出库记录!$A:$A,日报!CC$3),"")
